Workbook

Sheet 1101
A1: (창원) 일일매출/수금 마감현황
A2: 45962 | G2: [단위 : 원, VAT포함] [단위 : D/M] | K2: [단위 : L]
A3: 구분 | D3: 전일누계 | E3: 당일 | F3: 누계 | G3: 비고 | I3: 전일누계 | K3: 누계
A4: 판매현황 | B4: Mobil | E4: 31562388 | F4: =D4+E4 -> 31562388 | G4: =K4/200 -> 21.05 | J4: 4210 | K4: =I4+J4 -> 4210 | M4: =+K4+K6+K7+K8 -> 4615
B5: Mobil-MB | F5: =D5+E5 -> 0 | G5: =K5/200 -> 54.46 | J5: 10892 | K5: =I5+J5 -> 10892
B6: 블라자 | F6: =D6+E6 -> 0 | G6: =K6/200 -> 0 | K6: =I6+J6 -> 0
B7: 훅스 | E7: 2264570 | F7: =D7+E7 -> 2264570 | G7: =K7/200 -> 2.025 | J7: 405 | K7: =I7+J7 -> 405
B8: 기타(쉘 외 타사제품) | F8: =D8+E8 -> 0 | G8: =K8/200 -> 0 | K8: =I8+J8 -> 0
A9: 매출액 | D9: =SUM(D4:D8) -> 0 | E9: =SUM(E4:E8) -> 33826958 | F9: =SUM(F4:F8) -> 33826958 | G9: =SUM(G4:G8) -> 77.535 | I9: =SUM(I4:I8) -> 0 | J9: =SUM(J4:J8) -> 15507 | K9: =SUM(K4:K8) -> 15507
A10: 수금액 | B10: Cash | E10: 149600 | F10: =D10+E10 -> 149600
B11: 어음 | F11: =D11+E11 -> 0
B12: 카드 | F12: =D12+E12 -> 0
B13: 합계 | D13: =SUM(D10:D12) -> 0 | E13: =SUM(E10:E12) -> 149600 | F13: =SUM(F10:F12) -> 149600
A14: 매입/발주 | B14: 모빌 | C14: Vol(L) | F14: =D14+E14 -> 0 | G14: =F14/200 -> 0
C15: 금액 | F15: =D15+E15 -> 0
A16: IL (Flagship) | B16: 매출 | C16: Vol(L) | E16: 18 | F16: =D16+E16 -> 18
B17: 매입 | C17: Vol(L) | F17: =D17+E17 -> 0 | J17: [단위 : L]
A18: 재고 | B18: 구분 | D18: 전일재고 | E18: 입고 | F18: 출고 | G18: 재고 | I18: 입고 | J18: 출고
B19: Mobil | C19: D/M | D19: 653.59 | E19: =I19/200 -> 0 | F19: =J19/200 -> 20.45 | G19: =D19+E19-F19 -> 633.14 | J19: 4090
B20: Mobil-MB | D20: 130.16 | E20: =I20/200 -> 0 | F20: =J20/200 -> 54.46 | G20: =D20+E20-F20 -> 75.7 | J20: 10892
B21: 블라자 | E21: =I21/200 -> 0 | F21: =J21/200 -> 0 | G21: =D21+E21-F21 -> 0
B22: 훅스 | D22: 67.1 | E22: =I22/200 -> 0 | F22: =J22/200 -> 2.025 | G22: =D22+E22-F22 -> 65.075 | J22: 405
B23: 기타(쉘외 타사제품) | D23: 30.875 | E23: =I23/200 -> 0 | F23: =J23/200 -> 0 | G23: =D23+E23-F23 -> 30.875
B24: 합계 | D24: =SUM(D19:D23) -> 881.725 | E24: =SUM(E19:E23) -> 0 | F24: =SUM(F19:F23) -> 76.935 | G24: =SUM(G19:G23) -> 804.79 | I24: =SUM(I19:I23) -> 0 | J24: =SUM(J19:J23) -> 15387
A26: *. 주요현황
A27: 날짜 | B27: 상 호 | C27: 금 액 | D27: 비 고 | J27: 200
J28: =+J26/J27 -> 0
A30: *. 신규개척업체
A31: 날짜 | B31: 상 호 | C31: 소재지 | D31: 비 고

Sheet 1103
A1: (창원) 일일매출/수금 마감현황
A2: 45964 | G2: [단위 : 원, VAT포함] [단위 : D/M] | K2: [단위 : L]
A3: 구분 | D3: 전일누계 | E3: 당월 | F3: 누계 | G3: 비고 | I3: 전일누계 | J3: 당일 | K3: 누계
A4: 판매현황 | B4: Mobil | D4: =SUM('1101'!F4) -> 31562388 | E4: 93730544 | F4: =D4+E4 -> 125292932 | G4: =K4/200 -> 109.26 | I4: ='1101'!K4 -> 4210 | J4: 17642 | K4: =I4+J4 -> 21852 | M4: =+K4+K6+K7+K8 -> 28867
B5: Mobil-MB | D5: =SUM('1101'!F5) -> 0 | F5: =D5+E5 -> 0 | G5: =K5/200 -> 100.9 | I5: ='1101'!K5 -> 10892 | J5: 9288 | K5: =I5+J5 -> 20180
B6: 블라자 | D6: =SUM('1101'!F6) -> 0 | F6: =D6+E6 -> 0 | G6: =K6/200 -> 0 | I6: ='1101'!K6 -> 0 | K6: =I6+J6 -> 0
B7: 훅스 | D7: =SUM('1101'!F7) -> 2264570 | E7: 25522640 | F7: =D7+E7 -> 27787210 | G7: =K7/200 -> 31.075 | I7: ='1101'!K7 -> 405 | J7: 5810 | K7: =I7+J7 -> 6215
B8: 기타(쉘 외 타사제품) | D8: =SUM('1101'!F8) -> 0 | E8: 2046000 | F8: =D8+E8 -> 2046000 | G8: =K8/200 -> 4 | I8: ='1101'!K8 -> 0 | J8: 800 | K8: =I8+J8 -> 800
A9: 매출액 | D9: =SUM(D4:D8) -> 33826958 | E9: =SUM(E4:E8) -> 121299184 | F9: =SUM(F4:F8) -> 155126142 | G9: =SUM(G4:G8) -> 245.235 | I9: =SUM(I4:I8) -> 15507 | J9: =SUM(J4:J8) -> 33540 | K9: =SUM(K4:K8) -> 49047
A10: 수금액 | B10: Cash | D10: =SUM('1101'!F10) -> 149600 | E10: 6115340 | F10: =D10+E10 -> 6264940
B11: 어음 | D11: =SUM('1101'!F11) -> 0 | F11: =D11+E11 -> 0
B12: 카드 | D12: =SUM('1101'!F12) -> 0 | F12: =D12+E12 -> 0
B13: 합계 | D13: =SUM(D10:D12) -> 149600 | E13: =SUM(E10:E12) -> 6115340 | F13: =SUM(F10:F12) -> 6264940
A14: 매입/발주 | B14: 모빌 | C14: Vol(L) | D14: =SUM('1101'!F14) -> 0 | E14: 10621 | F14: =D14+E14 -> 10621 | G14: =F14/200 -> 53.105
C15: 금액 | D15: =SUM('1101'!F15) -> 0 | E15: 84709020 | F15: =D15+E15 -> 84709020
A16: IL (Flagship) | B16: 매출 | C16: Vol(L) | D16: =SUM('1101'!F16) -> 18 | E16: 1352 | F16: =D16+E16 -> 1370
B17: 매입 | C17: Vol(L) | D17: =SUM('1101'!F17) -> 0 | E17: 2277 | F17: =D17+E17 -> 2277 | J17: [단위 : L]
A18: 재고 | B18: 구분 | D18: 전일재고 | E18: 입고 | F18: 출고 | G18: 재고 | I18: 입고 | J18: 출고
B19: Mobil | C19: D/M | D19: ='1101'!G19 -> 633.14 | E19: =I19/200 -> 53.105 | F19: =J19/200 -> 91.57 | G19: =D19+E19-F19 -> 594.675 | I19: 10621 | J19: 18314
B20: Mobil-MB | D20: ='1101'!G20 -> 75.7 | E20: =I20/200 -> 0 | F20: =J20/200 -> 46.44 | G20: =D20+E20-F20 -> 29.26 | J20: 9288
B21: 블라자 | D21: ='1101'!G21 -> 0 | E21: =I21/200 -> 0 | F21: =J21/200 -> 0 | G21: =D21+E21-F21 -> 0
B22: 훅스 | D22: ='1101'!G22 -> 65.075 | E22: =I22/200 -> 14 | F22: =J22/200 -> 29.05 | G22: =D22+E22-F22 -> 50.025 | I22: 2800 | J22: 5810
B23: 기타(쉘외 타사제품) | D23: ='1101'!G23 -> 30.875 | E23: =I23/200 -> 0 | F23: =J23/200 -> 4 | G23: =D23+E23-F23 -> 26.875 | J23: 800
B24: 합계 | D24: =SUM(D19:D23) -> 804.79 | E24: =SUM(E19:E23) -> 67.105 | F24: =SUM(F19:F23) -> 171.06 | G24: =SUM(G19:G23) -> 700.835 | I24: =SUM(I19:I23) -> 13421 | J24: =SUM(J19:J23) -> 34212
A26: *. 주요현황
A27: 날짜 | B27: 상 호 | C27: 금 액 | D27: 비 고 | J27: 200
J28: =+J26/J27 -> 0
A30: *. 신규개척업체
A31: 날짜 | B31: 상 호 | C31: 소재지 | D31: 비 고

Sheet 1104
A1: (창원) 일일매출/수금 마감현황
A2: 45965 | G2: [단위 : 원, VAT포함] [단위 : D/M] | K2: [단위 : L]
A3: 구분 | D3: 전일누계 | E3: 당월 | F3: 누계 | G3: 비고 | I3: 전일누계 | J3: 당일 | K3: 누계
A4: 판매현황 | B4: Mobil | D4: =SUM('1103'!F4) -> 125292932 | E4: 17694710 | F4: =D4+E4 -> 142987642 | G4: =K4/200 -> 136.265 | I4: ='1103'!K4 -> 21852 | J4: 5401 | K4: =I4+J4 -> 27253 | M4: =+K4+K6+K7+K8 -> 34668
B5: Mobil-MB | D5: =SUM('1103'!F5) -> 0 | F5: =D5+E5 -> 0 | G5: =K5/200 -> 100.9 | I5: ='1103'!K5 -> 20180 | K5: =I5+J5 -> 20180
B6: 블라자 | D6: =SUM('1103'!F6) -> 0 | F6: =D6+E6 -> 0 | G6: =K6/200 -> 0 | I6: ='1103'!K6 -> 0 | K6: =I6+J6 -> 0
B7: 훅스 | D7: =SUM('1103'!F7) -> 27787210 | E7: 1595000 | F7: =D7+E7 -> 29382210 | G7: =K7/200 -> 33.075 | I7: ='1103'!K7 -> 6215 | J7: 400 | K7: =I7+J7 -> 6615
B8: 기타(쉘 외 타사제품) | D8: =SUM('1103'!F8) -> 2046000 | F8: =D8+E8 -> 2046000 | G8: =K8/200 -> 4 | I8: ='1103'!K8 -> 800 | K8: =I8+J8 -> 800
A9: 매출액 | D9: =SUM(D4:D8) -> 155126142 | E9: =SUM(E4:E8) -> 19289710 | F9: =SUM(F4:F8) -> 174415852 | G9: =SUM(G4:G8) -> 274.24 | I9: =SUM(I4:I8) -> 49047 | J9: =SUM(J4:J8) -> 5801 | K9: =SUM(K4:K8) -> 54848
A10: 수금액 | B10: Cash | D10: =SUM('1103'!F10) -> 6264940 | E10: 17755100 | F10: =D10+E10 -> 24020040
B11: 어음 | D11: =SUM('1103'!F11) -> 0 | F11: =D11+E11 -> 0
B12: 카드 | D12: =SUM('1103'!F12) -> 0 | F12: =D12+E12 -> 0
B13: 합계 | D13: =SUM(D10:D12) -> 6264940 | E13: =SUM(E10:E12) -> 17755100 | F13: =SUM(F10:F12) -> 24020040
A14: 매입/발주 | B14: 모빌 | C14: Vol(L) | D14: =SUM('1103'!F14) -> 10621 | E14: 11720 | F14: =D14+E14 -> 22341 | G14: =F14/200 -> 111.705
C15: 금액 | D15: =SUM('1103'!F15) -> 84709020 | E15: 35180200 | F15: =D15+E15 -> 119889220
A16: IL (Flagship) | B16: 매출 | C16: Vol(L) | D16: =SUM('1103'!F16) -> 1370 | F16: =D16+E16 -> 1370
B17: 매입 | C17: Vol(L) | D17: =SUM('1103'!F17) -> 2277 | F17: =D17+E17 -> 2277 | J17: [단위 : L]
A18: 재고 | B18: 구분 | D18: 전일재고 | E18: 입고 | F18: 출고 | G18: 재고 | I18: 입고 | J18: 출고
B19: Mobil | C19: D/M | D19: ='1103'!G19 -> 594.675 | E19: =I19/200 -> 58.8 | F19: =J19/200 -> 39.85 | G19: =D19+E19-F19 -> 613.625 | I19: 11760 | J19: 7970
B20: Mobil-MB | D20: ='1103'!G20 -> 29.26 | E20: =I20/200 -> 0 | F20: =J20/200 -> 0 | G20: =D20+E20-F20 -> 29.26
B21: 블라자 | D21: ='1103'!G21 -> 0 | E21: =I21/200 -> 0 | F21: =J21/200 -> 0 | G21: =D21+E21-F21 -> 0
B22: 훅스 | D22: ='1103'!G22 -> 50.025 | E22: =I22/200 -> 0 | F22: =J22/200 -> 2 | G22: =D22+E22-F22 -> 48.025 | J22: 400
B23: 기타(쉘외 타사제품) | D23: ='1103'!G23 -> 26.875 | E23: =I23/200 -> 5.2 | F23: =J23/200 -> 0 | G23: =D23+E23-F23 -> 32.075 | I23: 1040
B24: 합계 | D24: =SUM(D19:D23) -> 700.835 | E24: =SUM(E19:E23) -> 64 | F24: =SUM(F19:F23) -> 41.85 | G24: =SUM(G19:G23) -> 722.985 | I24: =SUM(I19:I23) -> 12800 | J24: =SUM(J19:J23) -> 8370
A26: *. 주요현황
A27: 날짜 | B27: 상 호 | C27: 금 액 | D27: 비 고 | J27: 200
J28: =+J26/J27 -> 0
A30: *. 신규개척업체
A31: 날짜 | B31: 상 호 | C31: 소재지 | D31: 비 고

Sheet 1105
A1: (창원) 일일매출/수금 마감현황
A2: 45966 | G2: [단위 : 원, VAT포함] [단위 : D/M] | K2: [단위 : L]
A3: 구분 | D3: 전일누계 | E3: 당월 | F3: 누계 | G3: 비고 | I3: 전일누계 | J3: 당일 | K3: 누계
A4: 판매현황 | B4: Mobil | D4: =SUM('1104'!F4) -> 142987642 | E4: 86280260 | F4: =D4+E4 -> 229267902 | G4: =K4/200 -> 192.445 | I4: ='1104'!K4 -> 27253 | J4: 11236 | K4: =I4+J4 -> 38489 | M4: =+K4+K6+K7+K8 -> 47914
B5: Mobil-MB | D5: =SUM('1104'!F5) -> 0 | F5: =D5+E5 -> 0 | G5: =K5/200 -> 100.9 | I5: ='1104'!K5 -> 20180 | K5: =I5+J5 -> 20180
B6: 블라자 | D6: =SUM('1104'!F6) -> 0 | F6: =D6+E6 -> 0 | G6: =K6/200 -> 0 | I6: ='1104'!K6 -> 0 | K6: =I6+J6 -> 0
B7: 훅스 | D7: =SUM('1104'!F7) -> 29382210 | E7: 7180140 | F7: =D7+E7 -> 36562350 | G7: =K7/200 -> 41.125 | I7: ='1104'!K7 -> 6615 | J7: 1610 | K7: =I7+J7 -> 8225
B8: 기타(쉘 외 타사제품) | D8: =SUM('1104'!F8) -> 2046000 | E8: 1023000 | F8: =D8+E8 -> 3069000 | G8: =K8/200 -> 6 | I8: ='1104'!K8 -> 800 | J8: 400 | K8: =I8+J8 -> 1200
A9: 매출액 | D9: =SUM(D4:D8) -> 174415852 | E9: =SUM(E4:E8) -> 94483400 | F9: =SUM(F4:F8) -> 268899252 | G9: =SUM(G4:G8) -> 340.47 | I9: =SUM(I4:I8) -> 54848 | J9: =SUM(J4:J8) -> 13246 | K9: =SUM(K4:K8) -> 68094
A10: 수금액 | B10: Cash | D10: =SUM('1104'!F10) -> 24020040 | E10: 20001410 | F10: =D10+E10 -> 44021450
B11: 어음 | D11: =SUM('1104'!F11) -> 0 | F11: =D11+E11 -> 0
B12: 카드 | D12: =SUM('1104'!F12) -> 0 | F12: =D12+E12 -> 0
B13: 합계 | D13: =SUM(D10:D12) -> 24020040 | E13: =SUM(E10:E12) -> 20001410 | F13: =SUM(F10:F12) -> 44021450
A14: 매입/발주 | B14: 모빌 | C14: Vol(L) | D14: =SUM('1104'!F14) -> 22341 | E14: 11186 | F14: =D14+E14 -> 33527 | G14: =F14/200 -> 167.635
C15: 금액 | D15: =SUM('1104'!F15) -> 119889220 | E15: 47381180 | F15: =D15+E15 -> 167270400
A16: IL (Flagship) | B16: 매출 | C16: Vol(L) | D16: =SUM('1104'!F16) -> 1370 | E16: 2800 | F16: =D16+E16 -> 4170
B17: 매입 | C17: Vol(L) | D17: =SUM('1104'!F17) -> 2277 | E17: 500 | F17: =D17+E17 -> 2777 | J17: [단위 : L]
A18: 재고 | B18: 구분 | D18: 전일재고 | E18: 입고 | F18: 출고 | G18: 재고 | I18: 입고 | J18: 출고
B19: Mobil | C19: D/M | D19: ='1104'!G19 -> 613.625 | E19: =I19/200 -> 55.93 | F19: =J19/200 -> 59.08 | G19: =D19+E19-F19 -> 610.475 | I19: 11186 | J19: 11816
B20: Mobil-MB | D20: ='1104'!G20 -> 29.26 | E20: =I20/200 -> 0 | F20: =J20/200 -> 0 | G20: =D20+E20-F20 -> 29.26
B21: 블라자 | D21: ='1104'!G21 -> 0 | E21: =I21/200 -> 0 | F21: =J21/200 -> 0 | G21: =D21+E21-F21 -> 0
B22: 훅스 | D22: ='1104'!G22 -> 48.025 | E22: =I22/200 -> 5 | F22: =J22/200 -> 8.05 | G22: =D22+E22-F22 -> 44.975 | I22: 1000 | J22: 1610
B23: 기타(쉘외 타사제품) | D23: ='1104'!G23 -> 32.075 | E23: =I23/200 -> 0 | F23: =J23/200 -> 2 | G23: =D23+E23-F23 -> 30.075 | J23: 400
B24: 합계 | D24: =SUM(D19:D23) -> 722.985 | E24: =SUM(E19:E23) -> 60.93 | F24: =SUM(F19:F23) -> 69.13 | G24: =SUM(G19:G23) -> 714.785 | I24: =SUM(I19:I23) -> 12186 | J24: =SUM(J19:J23) -> 13826
A26: *. 주요현황
A27: 날짜 | B27: 상 호 | C27: 금 액 | D27: 비 고 | J27: 200
J28: =+J26/J27 -> 0
A30: *. 신규개척업체
A31: 날짜 | B31: 상 호 | C31: 소재지 | D31: 비 고

Sheet 1106
A1: (창원) 일일매출/수금 마감현황
A2: 45967 | G2: [단위 : 원, VAT포함] [단위 : D/M] | K2: [단위 : L]
A3: 구분 | D3: 전일누계 | E3: 당일 | F3: 누계 | G3: 비고 | I3: 전일누계 | J3: 당일 | K3: 누계
A4: 판매현황 | B4: Mobil | D4: =SUM('1105'!F4) -> 229267902 | E4: 22511610 | F4: =D4+E4 -> 251779512 | G4: =K4/200 -> 214.675 | I4: =SUM('1105'!K4) -> 38489 | J4: 4446 | K4: =I4+J4 -> 42935 | M4: =+K4+K6+K7+K8 -> 56160
B5: Mobil-MB | D5: =SUM('1105'!F5) -> 0 | F5: =D5+E5 -> 0 | G5: =K5/200 -> 100.9 | I5: =SUM('1105'!K5) -> 20180 | K5: =I5+J5 -> 20180
B6: 블라자 | D6: =SUM('1105'!F6) -> 0 | F6: =D6+E6 -> 0 | G6: =K6/200 -> 0 | I6: =SUM('1105'!K6) -> 0 | K6: =I6+J6 -> 0
B7: 훅스 | D7: =SUM('1105'!F7) -> 36562350 | E7: 12853500 | F7: =D7+E7 -> 49415850 | G7: =K7/200 -> 56.125 | I7: =SUM('1105'!K7) -> 8225 | J7: 3000 | K7: =I7+J7 -> 11225
B8: 기타(쉘 외 타사제품) | D8: =SUM('1105'!F8) -> 3069000 | E8: 2046000 | F8: =D8+E8 -> 5115000 | G8: =K8/200 -> 10 | I8: =SUM('1105'!K8) -> 1200 | J8: 800 | K8: =I8+J8 -> 2000
A9: 매출액 | D9: =SUM(D4:D8) -> 268899252 | E9: =SUM(E4:E8) -> 37411110 | F9: =SUM(F4:F8) -> 306310362 | G9: =SUM(G4:G8) -> 381.7 | I9: =SUM(I4:I8) -> 68094 | J9: =SUM(J4:J8) -> 8246 | K9: =SUM(K4:K8) -> 76340
A10: 수금액 | B10: Cash | D10: =SUM('1105'!F10) -> 44021450 | E10: 1700600 | F10: =D10+E10 -> 45722050
B11: 어음 | D11: =SUM('1105'!F11) -> 0 | F11: =D11+E11 -> 0
B12: 카드 | D12: =SUM('1105'!F12) -> 0 | F12: =D12+E12 -> 0
B13: 합계 | D13: =SUM(D10:D12) -> 44021450 | E13: =SUM(E10:E12) -> 1700600 | F13: =SUM(F10:F12) -> 45722050
A14: 매입/발주 | B14: 모빌 | C14: Vol(L) | D14: =SUM('1105'!F14) -> 33527 | E14: 11713 | F14: =D14+E14 -> 45240 | G14: =F14/200 -> 226.2
C15: 금액 | D15: =SUM('1105'!F15) -> 167270400 | E15: 41175808 | F15: =D15+E15 -> 208446208
A16: IL (Flagship) | B16: 매출 | C16: Vol(L) | D16: =SUM('1105'!F16) -> 4170 | F16: =D16+E16 -> 4170
B17: 매입 | C17: Vol(L) | D17: =SUM('1105'!F17) -> 2777 | E17: 689 | F17: =D17+E17 -> 3466 | J17: [단위 : L]
A18: 재고 | B18: 구분 | D18: 전일재고 | E18: 입고 | F18: 출고 | G18: 재고 | I18: 입고 | J18: 출고
B19: Mobil | C19: D/M | D19: =SUM('1105'!G19) -> 610.475 | E19: =I19/200 -> 29.445 | F19: =J19/200 -> 25.31 | G19: =D19+E19-F19 -> 614.61 | I19: 5889 | J19: 5062
B20: Mobil-MB | D20: =SUM('1105'!G20) -> 29.26 | E20: =I20/200 -> 29.12 | F20: =J20/200 -> 9.36 | G20: =D20+E20-F20 -> 49.02 | I20: 5824 | J20: 1872
B21: 블라자 | D21: =SUM('1105'!G21) -> 0 | E21: =I21/200 -> 0 | F21: =J21/200 -> 0 | G21: =D21+E21-F21 -> 0
B22: 훅스 | D22: =SUM('1105'!G22) -> 44.975 | E22: =I22/200 -> 29 | F22: =J22/200 -> 15 | G22: =D22+E22-F22 -> 58.975 | I22: 5800 | J22: 3000
B23: 기타(쉘외 타사제품) | D23: =SUM('1105'!G23) -> 30.075 | E23: =I23/200 -> 12 | F23: =J23/200 -> 4 | G23: =D23+E23-F23 -> 38.075 | I23: 2400 | J23: 800
B24: 합계 | D24: =SUM(D19:D23) -> 714.785 | E24: =SUM(E19:E23) -> 99.565 | F24: =SUM(F19:F23) -> 53.67 | G24: =SUM(G19:G23) -> 760.68 | I24: =SUM(I19:I23) -> 19913 | J24: =SUM(J19:J23) -> 10734
A26: *. 주요현황
A27: 날짜 | B27: 상 호 | C27: 금 액 | D27: 비 고 | J27: 200
J28: =+J26/J27 -> 0
A30: *. 신규개척업체
A31: 날짜 | B31: 상 호 | C31: 소재지 | D31: 비 고

Sheet 1107
A1: (창원) 일일매출/수금 마감현황
A2: 45968 | G2: [단위 : 원, VAT포함] [단위 : D/M] | K2: [단위 : L]
A3: 구분 | D3: 전일누계 | E3: 당일 | F3: 누계 | G3: 비고 | I3: 전일누계 | J3: 당일 | K3: 누계
A4: 판매현황 | B4: Mobil | D4: =SUM('1106'!F4) -> 251779512 | E4: 49460587 | F4: =D4+E4 -> 301240099 | G4: =K4/200 -> 283.995 | I4: =SUM('1106'!K4) -> 42935 | J4: 13864 | K4: =I4+J4 -> 56799 | M4: =+K4+K6+K7+K8 -> 72884
B5: Mobil-MB | D5: =SUM('1106'!F5) -> 0 | F5: =D5+E5 -> 0 | G5: =K5/200 -> 100.9 | I5: =SUM('1106'!K5) -> 20180 | K5: =I5+J5 -> 20180
B6: 블라자 | D6: =SUM('1106'!F6) -> 0 | F6: =D6+E6 -> 0 | G6: =K6/200 -> 0 | I6: =SUM('1106'!K6) -> 0 | K6: =I6+J6 -> 0
B7: 훅스 | D7: =SUM('1106'!F7) -> 49415850 | E7: 6010730 | F7: =D7+E7 -> 55426580 | G7: =K7/200 -> 65.225 | I7: =SUM('1106'!K7) -> 11225 | J7: 1820 | K7: =I7+J7 -> 13045
B8: 기타(쉘 외 타사제품) | D8: =SUM('1106'!F8) -> 5115000 | E8: 9974800 | F8: =D8+E8 -> 15089800 | G8: =K8/200 -> 15.2 | I8: =SUM('1106'!K8) -> 2000 | J8: 1040 | K8: =I8+J8 -> 3040
A9: 매출액 | D9: =SUM(D4:D8) -> 306310362 | E9: =SUM(E4:E8) -> 65446117 | F9: =SUM(F4:F8) -> 371756479 | G9: =SUM(G4:G8) -> 465.32 | I9: =SUM(I4:I8) -> 76340 | J9: =SUM(J4:J8) -> 16724 | K9: =SUM(K4:K8) -> 93064
A10: 수금액 | B10: Cash | D10: =SUM('1106'!F10) -> 45722050 | E10: 436700 | F10: =D10+E10 -> 46158750
B11: 어음 | D11: =SUM('1106'!F11) -> 0 | E11: 44007150 | F11: =D11+E11 -> 44007150
B12: 카드 | D12: =SUM('1106'!F12) -> 0 | F12: =D12+E12 -> 0
B13: 합계 | D13: =SUM(D10:D12) -> 45722050 | E13: =SUM(E10:E12) -> 44443850 | F13: =SUM(F10:F12) -> 90165900
A14: 매입/발주 | B14: 모빌 | C14: Vol(L) | D14: =SUM('1106'!F14) -> 45240 | E14: 10623 | F14: =D14+E14 -> 55863 | G14: =F14/200 -> 279.315
C15: 금액 | D15: =SUM('1106'!F15) -> 208446208 | E15: 41024922 | F15: =D15+E15 -> 249471130
A16: IL (Flagship) | B16: 매출 | C16: Vol(L) | D16: =SUM('1106'!F16) -> 4170 | E16: 436 | F16: =D16+E16 -> 4606
B17: 매입 | C17: Vol(L) | D17: =SUM('1106'!F17) -> 3466 | E17: 40 | F17: =D17+E17 -> 3506 | J17: [단위 : L]
A18: 재고 | B18: 구분 | D18: 전일재고 | E18: 입고 | F18: 출고 | G18: 재고 | I18: 입고 | J18: 출고
B19: Mobil | C19: D/M | D19: =SUM('1106'!G19) -> 614.61 | E19: =I19/200 -> 45.075 | F19: =J19/200 -> 71.14 | G19: =D19+E19-F19 -> 588.545 | I19: 9015 | J19: 14228
B20: Mobil-MB | D20: =SUM('1106'!G20) -> 49.02 | E20: =I20/200 -> 8.04 | F20: =J20/200 -> 0 | G20: =D20+E20-F20 -> 57.06 | I20: 1608
B21: 블라자 | D21: =SUM('1106'!G21) -> 0 | E21: =I21/200 -> 0 | F21: =J21/200 -> 0 | G21: =D21+E21-F21 -> 0
B22: 훅스 | D22: =SUM('1106'!G22) -> 58.975 | E22: =I22/200 -> 0 | F22: =J22/200 -> 9.1 | G22: =D22+E22-F22 -> 49.875 | J22: 1820
B23: 기타(쉘외 타사제품) | D23: =SUM('1106'!G23) -> 38.075 | E23: =I23/200 -> 0 | F23: =J23/200 -> 5.2 | G23: =D23+E23-F23 -> 32.875 | J23: 1040
B24: 합계 | D24: =SUM(D19:D23) -> 760.68 | E24: =SUM(E19:E23) -> 53.115 | F24: =SUM(F19:F23) -> 85.44 | G24: =SUM(G19:G23) -> 728.355 | I24: =SUM(I19:I23) -> 10623 | J24: =SUM(J19:J23) -> 17088
A26: *. 주요현황
A27: 날짜 | B27: 상 호 | C27: 금 액 | D27: 비 고 | J27: 200
J28: =+J26/J27 -> 0
A30: *. 신규개척업체
A31: 날짜 | B31: 상 호 | C31: 소재지 | D31: 비 고

Sheet 1110
A1: (창원) 일일매출/수금 마감현황
A2: 45971 | G2: [단위 : 원, VAT포함] [단위 : D/M] | K2: [단위 : L]
A3: 구분 | D3: 전일누계 | E3: 당일 | F3: 누계 | G3: 비고 | I3: 전일누계 | J3: 당일 | K3: 누계
A4: 판매현황 | B4: Mobil | D4: =SUM('1107'!F4) -> 301240099 | E4: 71699870 | F4: =D4+E4 -> 372939969 | G4: =K4/200 -> 333.935 | I4: =SUM('1107'!K4) -> 56799 | J4: 9988 | K4: =I4+J4 -> 66787 | M4: =+K4+K6+K7+K8 -> 83872
B5: Mobil-MB | D5: =SUM('1107'!F5) -> 0 | F5: =D5+E5 -> 0 | G5: =K5/200 -> 151.98 | I5: =SUM('1107'!K5) -> 20180 | J5: 10216 | K5: =I5+J5 -> 30396
B6: 블라자 | D6: =SUM('1107'!F6) -> 0 | F6: =D6+E6 -> 0 | G6: =K6/200 -> 0 | I6: =SUM('1107'!K6) -> 0 | K6: =I6+J6 -> 0
B7: 훅스 | D7: =SUM('1107'!F7) -> 55426580 | E7: 3036000 | F7: =D7+E7 -> 58462580 | G7: =K7/200 -> 68.225 | I7: =SUM('1107'!K7) -> 13045 | J7: 600 | K7: =I7+J7 -> 13645
B8: 기타(쉘 외 타사제품) | D8: =SUM('1107'!F8) -> 15089800 | E8: 1023000 | F8: =D8+E8 -> 16112800 | G8: =K8/200 -> 17.2 | I8: =SUM('1107'!K8) -> 3040 | J8: 400 | K8: =I8+J8 -> 3440
A9: 매출액 | D9: =SUM(D4:D8) -> 371756479 | E9: =SUM(E4:E8) -> 75758870 | F9: =SUM(F4:F8) -> 447515349 | G9: =SUM(G4:G8) -> 571.34 | I9: =SUM(I4:I8) -> 93064 | J9: =SUM(J4:J8) -> 21204 | K9: =SUM(K4:K8) -> 114268
A10: 수금액 | B10: Cash | D10: =SUM('1107'!F10) -> 46158750 | E10: 82940137 | F10: =D10+E10 -> 129098887
B11: 어음 | D11: =SUM('1107'!F11) -> 44007150 | F11: =D11+E11 -> 44007150
B12: 카드 | D12: =SUM('1107'!F12) -> 0 | F12: =D12+E12 -> 0
B13: 합계 | D13: =SUM(D10:D12) -> 90165900 | F13: =SUM(F10:F12) -> 173106037
A14: 매입/발주 | B14: 모빌 | C14: Vol(L) | D14: =SUM('1107'!F14) -> 55863 | E14: 11680 | F14: =D14+E14 -> 67543 | G14: =F14/200 -> 337.715
C15: 금액 | D15: =SUM('1107'!F15) -> 249471130 | E15: 42526611 | F15: =D15+E15 -> 291997741
A16: IL (Flagship) | B16: 매출 | C16: Vol(L) | D16: =SUM('1107'!F16) -> 4606 | E16: 2720 | F16: =D16+E16 -> 7326
B17: 매입 | C17: Vol(L) | D17: =SUM('1107'!F17) -> 3506 | F17: =D17+E17 -> 3506 | J17: [단위 : L]
A18: 재고 | B18: 구분 | D18: 전일재고 | E18: 입고 | F18: 출고 | G18: 재고 | I18: 입고 | J18: 출고
B19: Mobil | C19: D/M | D19: =SUM('1107'!G19) -> 588.545 | E19: =I19/200 -> 37.6 | F19: =J19/200 -> 51.73 | G19: =D19+E19-F19 -> 574.415 | I19: 7520 | J19: 10346
B20: Mobil-MB | D20: =SUM('1107'!G20) -> 57.06 | E20: =I20/200 -> 20.8 | F20: =J20/200 -> 51.08 | G20: =D20+E20-F20 -> 26.78 | I20: 4160 | J20: 10216
B21: 블라자 | D21: =SUM('1107'!G21) -> 0 | E21: =I21/200 -> 0 | F21: =J21/200 -> 0 | G21: =D21+E21-F21 -> 0
B22: 훅스 | D22: =SUM('1107'!G22) -> 49.875 | E22: =I22/200 -> 14 | F22: =J22/200 -> 3 | G22: =D22+E22-F22 -> 60.875 | I22: 2800 | J22: 600
B23: 기타(쉘외 타사제품) | D23: =SUM('1107'!G23) -> 32.875 | E23: =I23/200 -> 0 | F23: =J23/200 -> 2 | G23: =D23+E23-F23 -> 30.875 | J23: 400
B24: 합계 | D24: =SUM(D19:D23) -> 728.355 | E24: =SUM(E19:E23) -> 72.4 | F24: =SUM(F19:F23) -> 107.81 | G24: =SUM(G19:G23) -> 692.945 | I24: =SUM(I19:I23) -> 14480 | J24: =SUM(J19:J23) -> 21562
A26: *. 주요현황
A27: 날짜 | B27: 상 호 | C27: 금 액 | D27: 비 고 | J27: 200
J28: =+J26/J27 -> 0
A30: *. 신규개척업체

Sheet 1111
A1: (창원) 일일매출/수금 마감현황
A2: 45972 | G2: [단위 : 원, VAT포함] [단위 : D/M] | K2: [단위 : L]
A3: 구분 | D3: 전일누계 | E3: 당일 | F3: 누계 | G3: 비고 | I3: 전일누계 | J3: 당일 | K3: 누계
A4: 판매현황 | B4: Mobil | D4: =SUM('1110'!F4) -> 372939969 | E4: 21931932 | F4: =D4+E4 -> 394871901 | G4: =K4/200 -> 369.115 | I4: =SUM('1110'!K4) -> 66787 | J4: 7036 | K4: =I4+J4 -> 73823 | M4: =+K4+K6+K7+K8 -> 91204
B5: Mobil-MB | D5: =SUM('1110'!F5) -> 0 | F5: =D5+E5 -> 0 | G5: =K5/200 -> 151.98 | I5: =SUM('1110'!K5) -> 30396 | K5: =I5+J5 -> 30396
B6: 블라자 | D6: =SUM('1110'!F6) -> 0 | F6: =D6+E6 -> 0 | G6: =K6/200 -> 0 | I6: =SUM('1110'!K6) -> 0 | K6: =I6+J6 -> 0
B7: 훅스 | D7: =SUM('1110'!F7) -> 58462580 | E7: 880000 | F7: =D7+E7 -> 59342580 | G7: =K7/200 -> 69.225 | I7: =SUM('1110'!K7) -> 13645 | J7: 200 | K7: =I7+J7 -> 13845
B8: 기타(쉘 외 타사제품) | D8: =SUM('1110'!F8) -> 16112800 | E8: 454080 | F8: =D8+E8 -> 16566880 | G8: =K8/200 -> 17.68 | I8: =SUM('1110'!K8) -> 3440 | J8: 96 | K8: =I8+J8 -> 3536
A9: 매출액 | D9: =SUM(D4:D8) -> 447515349 | E9: =SUM(E4:E8) -> 23266012 | F9: =SUM(F4:F8) -> 470781361 | G9: =SUM(G4:G8) -> 608 | I9: =SUM(I4:I8) -> 114268 | J9: =SUM(J4:J8) -> 7332 | K9: =SUM(K4:K8) -> 121600
A10: 수금액 | B10: Cash | D10: =SUM('1110'!F10) -> 129098887 | E10: 9702000 | F10: =D10+E10 -> 138800887
B11: 어음 | D11: =SUM('1110'!F11) -> 44007150 | F11: =D11+E11 -> 44007150
B12: 카드 | D12: =SUM('1110'!F12) -> 0 | F12: =D12+E12 -> 0
B13: 합계 | D13: =SUM(D10:D12) -> 173106037 | F13: =SUM(F10:F12) -> 182808037
A14: 매입/발주 | B14: 모빌 | C14: Vol(L) | D14: =SUM('1110'!F14) -> 67543 | E14: 11212 | F14: =D14+E14 -> 78755 | G14: =F14/200 -> 393.775
C15: 금액 | D15: =SUM('1110'!F15) -> 291997741 | E15: 54690412 | F15: =D15+E15 -> 346688153
A16: IL (Flagship) | B16: 매출 | C16: Vol(L) | D16: =SUM('1110'!F16) -> 7326 | F16: =D16+E16 -> 7326
B17: 매입 | C17: Vol(L) | D17: =SUM('1110'!F17) -> 3506 | E17: 1448 | F17: =D17+E17 -> 4954 | J17: [단위 : L]
A18: 재고 | B18: 구분 | D18: 전일재고 | E18: 입고 | F18: 출고 | G18: 재고 | I18: 입고 | J18: 출고
B19: Mobil | C19: D/M | D19: =SUM('1110'!G19) -> 574.415 | E19: =I19/200 -> 52.94 | F19: =J19/200 -> 35.88 | G19: =D19+E19-F19 -> 591.475 | I19: 10588 | J19: 7176
B20: Mobil-MB | D20: =SUM('1110'!G20) -> 26.78 | E20: =I20/200 -> 3.12 | F20: =J20/200 -> 0 | G20: =D20+E20-F20 -> 29.9 | I20: 624
B21: 블라자 | D21: =SUM('1110'!G21) -> 0 | E21: =I21/200 -> 0 | F21: =J21/200 -> 0 | G21: =D21+E21-F21 -> 0
B22: 훅스 | D22: =SUM('1110'!G22) -> 60.875 | E22: =I22/200 -> 0 | F22: =J22/200 -> 1 | G22: =D22+E22-F22 -> 59.875 | J22: 200
B23: 기타(쉘외 타사제품) | D23: =SUM('1110'!G23) -> 30.875 | E23: =I23/200 -> 0.48 | F23: =J23/200 -> 0.48 | G23: =D23+E23-F23 -> 30.875 | I23: 96 | J23: 96
B24: 합계 | D24: =SUM(D19:D23) -> 692.945 | E24: =SUM(E19:E23) -> 56.54 | F24: =SUM(F19:F23) -> 37.36 | G24: =SUM(G19:G23) -> 712.125 | I24: =SUM(I19:I23) -> 11308 | J24: =SUM(J19:J23) -> 7472
A26: *. 주요현황
A27: 날짜 | B27: 상 호 | C27: 금 액 | D27: 비 고 | J27: 200
J28: =+J26/J27 -> 0
A30: *. 신규개척업체
A31: 날짜 | B31: 상 호 | C31: 소재지 | D31: 비 고

Sheet 1112
A1: (창원) 일일매출/수금 마감현황
A2: 45973 | G2: [단위 : 원, VAT포함] [단위 : D/M] | K2: [단위 : L]
A3: 구분 | D3: 전일누계 | E3: 당일 | F3: 누계 | G3: 비고 | I3: 전일누계 | J3: 당일 | K3: 누계
A4: 판매현황 | B4: Mobil | D4: =SUM('1111'!F4) -> 394871901 | E4: 23435390 | F4: =SUM(D4:E4) -> 418307291 | G4: =K4/200 -> 406.395 | I4: =SUM('1111'!K4) -> 73823 | J4: 7456 | K4: =I4+J4 -> 81279 | M4: =+K4+K6+K7+K8 -> 99260
B5: Mobil-MB | D5: =SUM('1111'!F5) -> 0 | F5: =D5+E5 -> 0 | G5: =K5/200 -> 151.98 | I5: =SUM('1111'!K5) -> 30396 | K5: =I5+J5 -> 30396
B6: 블라자 | D6: =SUM('1111'!F6) -> 0 | F6: =D6+E6 -> 0 | G6: =K6/200 -> 0 | I6: =SUM('1111'!K6) -> 0 | K6: =I6+J6 -> 0
B7: 훅스 | D7: =SUM('1111'!F7) -> 59342580 | F7: =D7+E7 -> 59342580 | G7: =K7/200 -> 69.225 | I7: =SUM('1111'!K7) -> 13845 | K7: =I7+J7 -> 13845
B8: 기타(쉘 외 타사제품) | D8: =SUM('1111'!F8) -> 16566880 | E8: 2799500 | F8: =D8+E8 -> 19366380 | G8: =K8/200 -> 20.68 | I8: =SUM('1111'!K8) -> 3536 | J8: 600 | K8: =I8+J8 -> 4136
A9: 매출액 | D9: =SUM(D4:D8) -> 470781361 | E9: =SUM(E4:E8) -> 26234890 | F9: =SUM(F4:F8) -> 497016251 | G9: =SUM(G4:G8) -> 648.28 | I9: =SUM(I4:I8) -> 121600 | J9: =SUM(J4:J8) -> 8056 | K9: =SUM(K4:K8) -> 129656
A10: 수금액 | B10: Cash | D10: =SUM('1111'!F10) -> 138800887 | E10: 14998940 | F10: =SUM(D10:E10) -> 153799827
B11: 어음 | D11: =SUM('1111'!F11) -> 44007150 | E11: 4689410 | F11: =D11+E11 -> 48696560
B12: 카드 | D12: =SUM('1111'!F12) -> 0 | F12: =D12+E12 -> 0
B13: 합계 | D13: =SUM(D10:D12) -> 182808037 | E13: =SUM(E10:E12) -> 19688350 | F13: =SUM(F10:F12) -> 202496387
A14: 매입/발주 | B14: 모빌 | C14: Vol(L) | D14: =SUM('1111'!F14) -> 78755 | E14: 15805 | F14: =D14+E14 -> 94560 | G14: =F14/200 -> 472.8
C15: 금액 | D15: =SUM('1111'!F15) -> 346688153 | E15: 57444635 | F15: =D15+E15 -> 404132788
A16: IL (Flagship) | B16: 매출 | C16: Vol(L) | D16: =SUM('1111'!F16) -> 7326 | F16: =D16+E16 -> 7326
B17: 매입 | C17: Vol(L) | D17: =SUM('1111'!F17) -> 4954 | E17: 1308 | F17: =D17+E17 -> 6262 | J17: [단위 : L]
A18: 재고 | B18: 구분 | D18: 전일재고 | F18: 출고 | G18: 재고 | I18: 입고 | J18: 출고
B19: Mobil | C19: D/M | D19: =SUM('1111'!G19) -> 591.475 | E19: =I19/200 -> 53.305 | F19: =J19/200 -> 36.775 | G19: =D19+E19-F19 -> 608.005 | I19: 10661 | J19: 7355
B20: Mobil-MB | D20: =SUM('1111'!G20) -> 29.9 | E20: =I20/200 -> 25.72 | F20: =J20/200 -> 0.42 | G20: =D20+E20-F20 -> 55.2 | I20: 5144 | J20: 84
B21: 블라자 | D21: =SUM('1111'!G21) -> 0 | E21: =I21/200 -> 0 | F21: =J21/200 -> 0 | G21: =D21+E21-F21 -> 0
B22: 훅스 | D22: =SUM('1111'!G22) -> 59.875 | E22: =I22/200 -> 0 | F22: =J22/200 -> 0 | G22: =D22+E22-F22 -> 59.875
B23: 기타(쉘외 타사제품) | D23: =SUM('1111'!G23) -> 30.875 | E23: =I23/200 -> 0.1 | F23: =J23/200 -> 3 | G23: =D23+E23-F23 -> 27.975 | I23: 20 | J23: 600
B24: 합계 | D24: =SUM(D19:D23) -> 712.125 | E24: =SUM(E19:E23) -> 79.125 | F24: =SUM(F19:F23) -> 40.195 | G24: =SUM(G19:G23) -> 751.055 | I24: =SUM(I19:I23) -> 15825 | J24: =SUM(J19:J23) -> 8039
A26: *. 주요현황
A27: 날짜 | B27: 상 호 | C27: 금 액 | D27: 비 고 | J27: 200
J28: =+J26/J27 -> 0
A30: *. 신규개척업체
A31: 날짜 | B31: 상 호 | C31: 소재지 | D31: 비 고

Sheet 1113
A1: (창원) 일일매출/수금 마감현황
A2: 45974 | G2: [단위 : 원, VAT포함] [단위 : D/M] | K2: [단위 : L]
A3: 구분 | D3: 전일누계 | E3: 당일 | F3: 누계 | G3: 비고 | I3: 전일누계 | J3: 당일 | K3: 누계
A4: 판매현황 | B4: Mobil | D4: =SUM('1112'!F4) -> 418307291 | E4: 23592690 | F4: =D4+E4 -> 441899981 | G4: =K4/200 -> 437.635 | I4: =SUM('1112'!K4) -> 81279 | J4: 6248 | K4: =I4+J4 -> 87527 | M4: =+K4+K6+K7+K8 -> 106738
B5: Mobil-MB | D5: =SUM('1112'!F5) -> 0 | F5: =D5+E5 -> 0 | G5: =K5/200 -> 151.98 | I5: =SUM('1112'!K5) -> 30396 | K5: =I5+J5 -> 30396
B6: 블라자 | D6: =SUM('1112'!F6) -> 0 | F6: =D6+E6 -> 0 | G6: =K6/200 -> 0 | I6: =SUM('1112'!K6) -> 0 | K6: =I6+J6 -> 0
B7: 훅스 | D7: =SUM('1112'!F7) -> 59342580 | E7: 5057140 | F7: =D7+E7 -> 64399720 | G7: =K7/200 -> 75.275 | I7: =SUM('1112'!K7) -> 13845 | J7: 1210 | K7: =I7+J7 -> 15055
B8: 기타(쉘 외 타사제품) | D8: =SUM('1112'!F8) -> 19366380 | E8: 116600 | F8: =D8+E8 -> 19482980 | G8: =K8/200 -> 20.78 | I8: =SUM('1112'!K8) -> 4136 | J8: 20 | K8: =I8+J8 -> 4156
A9: 매출액 | D9: =SUM(D4:D8) -> 497016251 | E9: =SUM(E4:E8) -> 28766430 | F9: =SUM(F4:F8) -> 525782681 | G9: =SUM(G4:G8) -> 685.67 | I9: =SUM(I4:I8) -> 129656 | J9: =SUM(J4:J8) -> 7478 | K9: =SUM(K4:K8) -> 137134
A10: 수금액 | B10: Cash | D10: =SUM('1112'!F10) -> 153799827 | E10: 54351660 | F10: =D10+E10 -> 208151487
B11: 어음 | D11: =SUM('1112'!F11) -> 48696560 | F11: =D11+E11 -> 48696560
B12: 카드 | D12: =SUM('1112'!F12) -> 0 | F12: =D12+E12 -> 0
B13: 합계 | D13: =SUM(D10:D12) -> 202496387 | E13: =SUM(E10:E12) -> 54351660 | F13: =SUM(F10:F12) -> 256848047
A14: 매입/발주 | B14: 모빌 | C14: Vol(L) | D14: =SUM('1112'!F14) -> 94560 | E14: 11894 | F14: =D14+E14 -> 106454 | G14: =F14/200 -> 532.27
C15: 금액 | D15: =SUM('1112'!F15) -> 404132788 | E15: 28132940 | F15: =D15+E15 -> 432265728
A16: IL (Flagship) | B16: 매출 | C16: Vol(L) | D16: =SUM('1112'!F16) -> 7326 | E16: 428 | F16: =D16+E16 -> 7754
B17: 매입 | C17: Vol(L) | D17: =SUM('1112'!F17) -> 6262 | F17: =D17+E17 -> 6262 | J17: [단위 : L]
A18: 재고 | B18: 구분 | D18: 전일재고 | E18: 입고 | F18: 출고 | G18: 재고 | I18: 입고 | J18: 출고
B19: Mobil | C19: D/M | D19: =SUM('1112'!G19) -> 608.005 | E19: =I19/200 -> 59.77 | F19: =J19/200 -> 59.63 | G19: =D19+E19-F19 -> 608.145 | I19: 11954 | J19: 11926
B20: Mobil-MB | D20: =SUM('1112'!G20) -> 55.2 | E20: =I20/200 -> 0 | F20: =J20/200 -> 0 | G20: =D20+E20-F20 -> 55.2
B21: 블라자 | D21: =SUM('1112'!G21) -> 0 | E21: =I21/200 -> 0 | F21: =J21/200 -> 0 | G21: =D21+E21-F21 -> 0
B22: 훅스 | D22: =SUM('1112'!G22) -> 59.875 | E22: =I22/200 -> 8 | F22: =J22/200 -> 6.05 | G22: =D22+E22-F22 -> 61.825 | I22: 1600 | J22: 1210
B23: 기타(쉘외 타사제품) | D23: =SUM('1112'!G23) -> 27.975 | E23: =I23/200 -> 0 | F23: =J23/200 -> 0.1 | G23: =D23+E23-F23 -> 27.875 | J23: 20
B24: 합계 | D24: =SUM(D19:D23) -> 751.055 | E24: =SUM(E19:E23) -> 67.77 | F24: =SUM(F19:F23) -> 65.78 | G24: =SUM(G19:G23) -> 753.045 | I24: =SUM(I19:I23) -> 13554 | J24: =SUM(J19:J23) -> 13156
A26: *. 주요현황
A27: 날짜 | B27: 상 호 | C27: 금 액 | D27: 비 고 | J27: 200
J28: =+J26/J27 -> 0
A30: *. 신규개척업체

Sheet 1114
A1: (창원) 일일매출/수금 마감현황
A2: 45975 | G2: [단위 : 원, VAT포함] [단위 : D/M] | K2: [단위 : L]
A3: 구분 | D3: 전일누계 | E3: 당일 | F3: 누계 | G3: 비고 | I3: 전일누계 | J3: 당일 | K3: 누계
A4: 판매현황 | B4: Mobil | D4: =SUM('1113'!F4) -> 441899981 | E4: 32553400 | F4: =D4+E4 -> 474453381 | G4: =K4/200 -> 455.405 | I4: =SUM('1113'!K4) -> 87527 | J4: 3554 | K4: =I4+J4 -> 91081 | M4: =+K4+K6+K7+K8 -> 111697
B5: Mobil-MB | D5: =SUM('1113'!F5) -> 0 | F5: =D5+E5 -> 0 | G5: =K5/200 -> 151.98 | I5: =SUM('1113'!K5) -> 30396 | K5: =I5+J5 -> 30396
B6: 블라자 | D6: =SUM('1113'!F6) -> 0 | F6: =D6+E6 -> 0 | G6: =K6/200 -> 0 | I6: =SUM('1113'!K6) -> 0 | K6: =I6+J6 -> 0
B7: 훅스 | D7: =SUM('1113'!F7) -> 64399720 | E7: 8677570 | F7: =D7+E7 -> 73077290 | G7: =K7/200 -> 82.3 | I7: =SUM('1113'!K7) -> 15055 | J7: 1405 | K7: =I7+J7 -> 16460
B8: 기타(쉘 외 타사제품) | D8: =SUM('1113'!F8) -> 19482980 | F8: =D8+E8 -> 19482980 | G8: =K8/200 -> 20.78 | I8: =SUM('1113'!K8) -> 4156 | K8: =I8+J8 -> 4156
A9: 매출액 | D9: =SUM(D4:D8) -> 525782681 | E9: =SUM(E4:E8) -> 41230970 | F9: =SUM(F4:F8) -> 567013651 | G9: =SUM(G4:G8) -> 710.465 | I9: =SUM(I4:I8) -> 137134 | J9: =SUM(J4:J8) -> 4959 | K9: =SUM(K4:K8) -> 142093
A10: 수금액 | B10: Cash | D10: =SUM('1113'!F10) -> 208151487 | E10: 58543397 | F10: =D10+E10 -> 266694884
B11: 어음 | D11: =SUM('1113'!F11) -> 48696560 | F11: =D11+E11 -> 48696560
B12: 카드 | D12: =SUM('1113'!F12) -> 0 | F12: =D12+E12 -> 0
B13: 합계 | D13: =SUM(D10:D12) -> 256848047 | E13: =SUM(E10:E12) -> 58543397 | F13: =SUM(F10:F12) -> 315391444
A14: 매입/발주 | B14: 모빌 | C14: Vol(L) | D14: =SUM('1113'!F14) -> 106454 | F14: =D14+E14 -> 106454 | G14: =F14/200 -> 532.27
C15: 금액 | D15: =SUM('1113'!F15) -> 432265728 | F15: =D15+E15 -> 432265728
A16: IL (Flagship) | B16: 매출 | C16: Vol(L) | D16: =SUM('1113'!F16) -> 7754 | E16: 1078 | F16: =D16+E16 -> 8832
B17: 매입 | C17: Vol(L) | D17: =SUM('1113'!F17) -> 6262 | F17: =D17+E17 -> 6262 | J17: [단위 : L]
A18: 재고 | B18: 구분 | D18: 전일재고 | E18: 입고 | F18: 출고 | G18: 재고 | I18: 입고 | J18: 출고
B19: Mobil | C19: D/M | D19: =SUM('1113'!G19) -> 608.145 | E19: =I19/200 -> 0 | F19: =J19/200 -> 20.17 | G19: =D19+E19-F19 -> 587.975 | J19: 4034
B20: Mobil-MB | D20: =SUM('1113'!G20) -> 55.2 | E20: =I20/200 -> 0 | F20: =J20/200 -> 0 | G20: =D20+E20-F20 -> 55.2
B21: 블라자 | D21: =SUM('1113'!G21) -> 0 | E21: =I21/200 -> 0 | F21: =J21/200 -> 0 | G21: =D21+E21-F21 -> 0
B22: 훅스 | D22: =SUM('1113'!G22) -> 61.825 | E22: =I22/200 -> 5 | F22: =J22/200 -> 7.025 | G22: =D22+E22-F22 -> 59.8 | I22: 1000 | J22: 1405
B23: 기타(쉘외 타사제품) | D23: =SUM('1113'!G23) -> 27.875 | E23: =I23/200 -> 0 | F23: =J23/200 -> 0 | G23: =D23+E23-F23 -> 27.875
B24: 합계 | D24: =SUM(D19:D23) -> 753.045 | E24: =SUM(E19:E23) -> 5 | F24: =SUM(F19:F23) -> 27.195 | G24: =SUM(G19:G23) -> 730.85 | I24: =SUM(I19:I23) -> 1000 | J24: =SUM(J19:J23) -> 5439
A26: *. 주요현황
A27: 날짜 | B27: 상 호 | C27: 금 액 | D27: 비 고 | J27: 200
J28: =+J26/J27 -> 0
A30: *. 신규개척업체
A31: 날짜 | B31: 상 호 | C31: 소재지 | D31: 비 고

Sheet 1117
A1: (창원) 일일매출/수금 마감현황
A2: 45978 | G2: [단위 : 원, VAT포함] [단위 : D/M] | K2: [단위 : L]
A3: 구분 | D3: 전일누계 | E3: 당일 | F3: 누계 | G3: 비고 | I3: 전일누계 | J3: 당일 | K3: 누계
A4: 판매현황 | B4: Mobil | D4: =SUM('1114'!F4) -> 474453381 | E4: 35622510 | F4: =D4+E4 -> 510075891 | G4: =K4/200 -> 488.265 | I4: =SUM('1114'!K4) -> 91081 | J4: 6572 | K4: =I4+J4 -> 97653 | M4: =+K4+K6+K7+K8 -> 120329
B5: Mobil-MB | D5: =SUM('1114'!F5) -> 0 | F5: =D5+E5 -> 0 | G5: =K5/200 -> 200.7 | I5: =SUM('1114'!K5) -> 30396 | J5: 9744 | K5: =I5+J5 -> 40140
B6: 블라자 | D6: =SUM('1114'!F6) -> 0 | F6: =D6+E6 -> 0 | G6: =K6/200 -> 0 | I6: =SUM('1114'!K6) -> 0 | K6: =I6+J6 -> 0
B7: 훅스 | D7: =SUM('1114'!F7) -> 73077290 | E7: 6319500 | F7: =D7+E7 -> 79396790 | G7: =K7/200 -> 88.6 | I7: =SUM('1114'!K7) -> 16460 | J7: 1260 | K7: =I7+J7 -> 17720
B8: 기타(쉘 외 타사제품) | D8: =SUM('1114'!F8) -> 19482980 | E8: 2046000 | F8: =D8+E8 -> 21528980 | G8: =K8/200 -> 24.78 | I8: =SUM('1114'!K8) -> 4156 | J8: 800 | K8: =I8+J8 -> 4956
A9: 매출액 | D9: =SUM(D4:D8) -> 567013651 | E9: =SUM(E4:E8) -> 43988010 | F9: =SUM(F4:F8) -> 611001661 | G9: =SUM(G4:G8) -> 802.345 | I9: =SUM(I4:I8) -> 142093 | J9: =SUM(J4:J8) -> 18376 | K9: =SUM(K4:K8) -> 160469
A10: 수금액 | B10: Cash | D10: =SUM('1114'!F10) -> 266694884 | E10: 1816650 | F10: =D10+E10 -> 268511534
B11: 어음 | D11: =SUM('1114'!F11) -> 48696560 | F11: =D11+E11 -> 48696560
B12: 카드 | D12: =SUM('1114'!F12) -> 0 | F12: =D12+E12 -> 0
B13: 합계 | D13: =SUM(D10:D12) -> 315391444 | E13: =SUM(E10:E12) -> 1816650 | F13: =SUM(F10:F12) -> 317208094
A14: 매입/발주 | B14: 모빌 | C14: Vol(L) | D14: =SUM('1114'!F14) -> 106454 | E14: 16128 | F14: =D14+E14 -> 122582 | G14: =F14/200 -> 612.91
C15: 금액 | D15: =SUM('1114'!F15) -> 432265728 | E15: 59553243 | F15: =D15+E15 -> 491818971
A16: IL (Flagship) | B16: 매출 | C16: Vol(L) | D16: =SUM('1114'!F16) -> 8832 | E16: 220 | F16: =D16+E16 -> 9052
B17: 매입 | C17: Vol(L) | D17: =SUM('1114'!F17) -> 6262 | E17: 132 | F17: =D17+E17 -> 6394 | J17: [단위 : L]
A18: 재고 | B18: 구분 | D18: 전일재고 | E18: 입고 | F18: 출고 | G18: 재고 | I18: 입고 | J18: 출고
B19: Mobil | C19: D/M | D19: =SUM('1114'!G19) -> 587.975 | E19: =I19/200 -> 63.24 | F19: =J19/200 -> 32.86 | G19: =D19+E19-F19 -> 618.355 | I19: 12648 | J19: 6572
B20: Mobil-MB | D20: =SUM('1114'!G20) -> 55.2 | E20: =I20/200 -> 17.4 | F20: =J20/200 -> 53.48 | G20: =D20+E20-F20 -> 19.12 | I20: 3480 | J20: 10696
B21: 블라자 | D21: =SUM('1114'!G21) -> 0 | E21: =I21/200 -> 0 | F21: =J21/200 -> 0 | G21: =D21+E21-F21 -> 0
B22: 훅스 | D22: =SUM('1114'!G22) -> 59.8 | E22: =I22/200 -> 0 | F22: =J22/200 -> 6.3 | G22: =D22+E22-F22 -> 53.5 | J22: 1260
B23: 기타(쉘외 타사제품) | D23: =SUM('1114'!G23) -> 27.875 | E23: =I23/200 -> 6 | F23: =J23/200 -> 6 | G23: =D23+E23-F23 -> 27.875 | I23: 1200 | J23: 1200
B24: 합계 | D24: =SUM(D19:D23) -> 730.85 | E24: =SUM(E19:E23) -> 86.64 | F24: =SUM(F19:F23) -> 98.64 | G24: =SUM(G19:G23) -> 718.85 | I24: =SUM(I19:I23) -> 17328 | J24: =SUM(J19:J23) -> 19728
A26: *. 주요현황
A27: 날짜 | B27: 상 호 | C27: 금 액 | D27: 비 고 | J27: 200
J28: =+J26/J27 -> 0
A30: *. 신규개척업체
A31: 날짜 | B31: 상 호 | C31: 소재지 | D31: 비 고

Sheet 1024
A1: (창원) 일일매출/수금 마감현황
A2: 45954 | G2: [단위 : 원, VAT포함] [단위 : D/M] | K2: [단위 : L]
A3: 구분 | D3: 전일누계 | E3: 당일 | F3: 누계 | G3: 비고 | I3: 전일누계 | J3: 당일 | K3: 누계
A4: 판매현황 | B4: Mobil | D4: =SUM('1117'!F4) -> 510075891 | E4: 25041170 | F4: =D4+E4 -> 535117061 | G4: =K4/200 -> 508.61 | I4: =SUM('1117'!K4) -> 97653 | J4: 4069 | K4: =I4+J4 -> 101722 | M4: =+K4+K6+K7+K8 -> 124398
B5: Mobil-MB | D5: =SUM('1117'!F5) -> 0 | F5: =D5+E5 -> 0 | G5: =K5/200 -> 200.7 | I5: =SUM('1117'!K5) -> 40140 | K5: =I5+J5 -> 40140
B6: 블라자 | D6: =SUM('1117'!F6) -> 0 | F6: =D6+E6 -> 0 | G6: =K6/200 -> 0 | I6: =SUM('1117'!K6) -> 0 | K6: =I6+J6 -> 0
B7: 훅스 | D7: =SUM('1117'!F7) -> 79396790 | F7: =D7+E7 -> 79396790 | G7: =K7/200 -> 88.6 | I7: =SUM('1117'!K7) -> 17720 | K7: =I7+J7 -> 17720
B8: 기타(쉘 외 타사제품) | D8: =SUM('1117'!F8) -> 21528980 | F8: =D8+E8 -> 21528980 | G8: =K8/200 -> 24.78 | I8: =SUM('1117'!K8) -> 4956 | K8: =I8+J8 -> 4956
A9: 매출액 | D9: =SUM(D4:D8) -> 611001661 | E9: =SUM(E4:E8) -> 25041170 | F9: =SUM(F4:F8) -> 636042831 | G9: =SUM(G4:G8) -> 822.69 | I9: =SUM(I4:I8) -> 160469 | J9: =SUM(J4:J8) -> 4069 | K9: =SUM(K4:K8) -> 164538
A10: 수금액 | B10: Cash | D10: =SUM('1117'!F10) -> 268511534 | E10: 11233640 | F10: =D10+E10 -> 279745174
B11: 어음 | D11: =SUM('1117'!F11) -> 48696560 | E11: 23841730 | F11: =D11+E11 -> 72538290
B12: 카드 | D12: =SUM('1117'!F12) -> 0 | F12: =D12+E12 -> 0
B13: 합계 | D13: =SUM(D10:D12) -> 317208094 | E13: =SUM(E10:E12) -> 35075370 | F13: =SUM(F10:F12) -> 352283464
A14: 매입/발주 | B14: 모빌 | C14: Vol(L) | D14: =SUM('1117'!F14) -> 122582 | F14: =D14+E14 -> 122582 | G14: =F14/200 -> 612.91
C15: 금액 | D15: =SUM('1117'!F15) -> 491818971 | F15: =D15+E15 -> 491818971
A16: IL (Flagship) | B16: 매출 | C16: Vol(L) | D16: =SUM('1117'!F16) -> 9052 | E16: 605 | F16: =D16+E16 -> 9657
B17: 매입 | C17: Vol(L) | D17: =SUM('1117'!F17) -> 6394 | F17: =D17+E17 -> 6394 | J17: [단위 : L]
A18: 재고 | B18: 구분 | D18: 전일재고 | E18: 입고 | F18: 출고 | G18: 재고 | I18: 입고 | J18: 출고
B19: Mobil | C19: D/M | D19: =SUM('1117'!G19) -> 618.355 | E19: =I19/200 -> 0 | F19: =J19/200 -> 20.445 | G19: =D19+E19-F19 -> 597.91 | J19: 4089
B20: Mobil-MB | D20: =SUM('1117'!G20) -> 19.12 | E20: =I20/200 -> 0 | F20: =J20/200 -> 0 | G20: =D20+E20-F20 -> 19.12
B21: 블라자 | D21: =SUM('1117'!G21) -> 0 | E21: =I21/200 -> 0 | F21: =J21/200 -> 0 | G21: =D21+E21-F21 -> 0
B22: 훅스 | D22: =SUM('1117'!G22) -> 53.5 | E22: =I22/200 -> 0 | F22: =J22/200 -> 0 | G22: =D22+E22-F22 -> 53.5
B23: 기타(쉘외 타사제품) | D23: =SUM('1117'!G23) -> 27.875 | E23: =I23/200 -> 0 | F23: =J23/200 -> 0 | G23: =D23+E23-F23 -> 27.875
B24: 합계 | D24: =SUM(D19:D23) -> 718.85 | E24: =SUM(E19:E23) -> 0 | F24: =SUM(F19:F23) -> 20.445 | G24: =SUM(G19:G23) -> 698.405 | I24: =SUM(I19:I23) -> 0 | J24: =SUM(J19:J23) -> 4089
A26: *. 주요현황
A27: 날짜 | B27: 상 호 | C27: 금 액 | D27: 비 고 | J27: 200
J28: =+J26/J27 -> 0
A30: *. 신규개척업체
A31: 날짜 | B31: 상 호 | C31: 소재지 | D31: 비 고

Sheet 1027
A1: (창원) 일일매출/수금 마감현황
A2: 45957 | G2: [단위 : 원, VAT포함] [단위 : D/M] | K2: [단위 : L]
A3: 구분 | D3: 전일누계 | E3: 당일 | F3: 누계 | G3: 비고 | I3: 전일누계 | J3: 당일 | K3: 누계
A4: 판매현황 | B4: Mobil | D4: =SUM('1024'!F4) -> 535117061 | E4: 11628760 | F4: =D4+E4 -> 546745821 | G4: =K4/200 -> 521.05 | I4: =SUM('1024'!K4) -> 101722 | J4: 2488 | K4: =I4+J4 -> 104210 | M4: =+K4+K6+K7+K8 -> 126886
B5: Mobil-MB | D5: =SUM('1024'!F5) -> 0 | F5: =D5+E5 -> 0 | G5: =K5/200 -> 200.7 | I5: =SUM('1024'!K5) -> 40140 | K5: =I5+J5 -> 40140
B6: 블라자 | D6: =SUM('1024'!F6) -> 0 | F6: =D6+E6 -> 0 | G6: =K6/200 -> 0 | I6: =SUM('1024'!K6) -> 0 | K6: =I6+J6 -> 0
B7: 훅스 | D7: =SUM('1024'!F7) -> 79396790 | F7: =D7+E7 -> 79396790 | G7: =K7/200 -> 88.6 | I7: =SUM('1024'!K7) -> 17720 | K7: =I7+J7 -> 17720
B8: 기타(쉘 외 타사제품) | D8: =SUM('1024'!F8) -> 21528980 | F8: =D8+E8 -> 21528980 | G8: =K8/200 -> 24.78 | I8: =SUM('1024'!K8) -> 4956 | K8: =I8+J8 -> 4956
A9: 매출액 | D9: =SUM(D4:D8) -> 636042831 | E9: =SUM(E4:E8) -> 11628760 | F9: =SUM(F4:F8) -> 647671591 | G9: =SUM(G4:G8) -> 835.13 | I9: =SUM(I4:I8) -> 164538 | J9: =SUM(J4:J8) -> 2488 | K9: =SUM(K4:K8) -> 167026
A10: 수금액 | B10: Cash | D10: =SUM('1024'!F10) -> 279745174 | E10: 43379160 | F10: =D10+E10 -> 323124334
B11: 어음 | D11: =SUM('1024'!F11) -> 72538290 | F11: =D11+E11 -> 72538290
B12: 카드 | D12: =SUM('1024'!F12) -> 0 | F12: =D12+E12 -> 0
B13: 합계 | D13: =SUM(D10:D12) -> 352283464 | E13: =SUM(E10:E12) -> 43379160 | F13: =SUM(F10:F12) -> 395662624
A14: 매입/발주 | B14: 모빌 | C14: Vol(L) | D14: =SUM('1024'!F14) -> 122582 | E14: 10812 | F14: =D14+E14 -> 133394 | G14: =F14/200 -> 666.97
C15: 금액 | D15: =SUM('1024'!F15) -> 491818971 | E15: 37520718 | F15: =D15+E15 -> 529339689
A16: IL (Flagship) | B16: 매출 | C16: Vol(L) | D16: =SUM('1024'!F16) -> 9657 | E16: 208 | F16: =D16+E16 -> 9865
B17: 매입 | C17: Vol(L) | D17: =SUM('1024'!F17) -> 6394 | E17: 208 | F17: =D17+E17 -> 6602 | J17: [단위 : L]
A18: 재고 | B18: 구분 | D18: 전일재고 | E18: 입고 | F18: 출고 | G18: 재고 | I18: 입고 | J18: 출고
B19: Mobil | C19: D/M | D19: =SUM('1024'!G19) -> 597.91 | E19: =I19/200 -> 45.74 | F19: =J19/200 -> 21.755 | G19: =D19+E19-F19 -> 621.895 | I19: 9148 | J19: 4351
B20: Mobil-MB | D20: =SUM('1024'!G20) -> 19.12 | E20: =I20/200 -> 8.32 | F20: =J20/200 -> 0 | G20: =D20+E20-F20 -> 27.44 | I20: 1664
B21: 블라자 | D21: =SUM('1024'!G21) -> 0 | E21: =I21/200 -> 0 | F21: =J21/200 -> 0 | G21: =D21+E21-F21 -> 0
B22: 훅스 | D22: =SUM('1024'!G22) -> 53.5 | E22: =I22/200 -> 0 | F22: =J22/200 -> 0 | G22: =D22+E22-F22 -> 53.5
B23: 기타(쉘외 타사제품) | D23: =SUM('1024'!G23) -> 27.875 | E23: =I23/200 -> 0 | F23: =J23/200 -> 0 | G23: =D23+E23-F23 -> 27.875
B24: 합계 | D24: =SUM(D19:D23) -> 698.405 | E24: =SUM(E19:E23) -> 54.06 | F24: =SUM(F19:F23) -> 21.755 | G24: =SUM(G19:G23) -> 730.71 | I24: =SUM(I19:I23) -> 10812 | J24: =SUM(J19:J23) -> 4351
A26: *. 주요현황
A27: 날짜 | B27: 상 호 | C27: 금 액 | D27: 비 고 | J27: 200
J28: =+J26/J27 -> 0
A30: *. 신규개척업체
A31: 날짜 | B31: 상 호 | C31: 소재지 | D31: 비 고

Sheet 1028
A1: (창원) 일일매출/수금 마감현황
A2: 45958 | G2: [단위 : 원, VAT포함] [단위 : D/M] | K2: [단위 : L]
A3: 구분 | D3: 전일누계 | E3: 당일 | F3: 누계 | G3: 비고 | I3: 전일누계 | J3: 당일 | K3: 누계
A4: 판매현황 | B4: Mobil | D4: =SUM('1027'!F4) -> 546745821 | E4: 38013754 | F4: =D4+E4 -> 584759575 | G4: =K4/200 -> 551.52 | I4: =SUM('1027'!K4) -> 104210 | J4: 6094 | K4: =I4+J4 -> 110304 | M4: =+K4+K6+K7+K8 -> 132980
B5: Mobil-MB | D5: =SUM('1027'!F5) -> 0 | F5: =D5+E5 -> 0 | G5: =K5/200 -> 200.7 | I5: =SUM('1027'!K5) -> 40140 | K5: =I5+J5 -> 40140
B6: 블라자 | D6: =SUM('1027'!F6) -> 0 | F6: =D6+E6 -> 0 | G6: =K6/200 -> 0 | I6: =SUM('1027'!K6) -> 0 | K6: =I6+J6 -> 0
B7: 훅스 | D7: =SUM('1027'!F7) -> 79396790 | F7: =D7+E7 -> 79396790 | G7: =K7/200 -> 88.6 | I7: =SUM('1027'!K7) -> 17720 | K7: =I7+J7 -> 17720
B8: 기타(쉘 외 타사제품) | D8: =SUM('1027'!F8) -> 21528980 | F8: =D8+E8 -> 21528980 | G8: =K8/200 -> 24.78 | I8: =SUM('1027'!K8) -> 4956 | K8: =I8+J8 -> 4956
A9: 매출액 | D9: =SUM(D4:D8) -> 647671591 | E9: =SUM(E4:E8) -> 38013754 | F9: =SUM(F4:F8) -> 685685345 | G9: =SUM(G4:G8) -> 865.6 | I9: =SUM(I4:I8) -> 167026 | J9: =SUM(J4:J8) -> 6094 | K9: =SUM(K4:K8) -> 173120
A10: 수금액 | B10: Cash | D10: =SUM('1027'!F10) -> 323124334 | F10: =D10+E10 -> 323124334
B11: 어음 | D11: =SUM('1027'!F11) -> 72538290 | F11: =D11+E11 -> 72538290
B12: 카드 | D12: =SUM('1027'!F12) -> 0 | F12: =D12+E12 -> 0
B13: 합계 | D13: =SUM(D10:D12) -> 395662624 | E13: =SUM(E10:E12) -> 0 | F13: =SUM(F10:F12) -> 395662624
A14: 매입/발주 | B14: 모빌 | C14: Vol(L) | D14: =SUM('1027'!F14) -> 133394 | E14: 10864 | F14: =D14+E14 -> 144258 | G14: =F14/200 -> 721.29
C15: 금액 | D15: =SUM('1027'!F15) -> 529339689 | E15: 37670526 | F15: =D15+E15 -> 567010215
A16: IL (Flagship) | B16: 매출 | C16: Vol(L) | D16: =SUM('1027'!F16) -> 9865 | E16: 734 | F16: =D16+E16 -> 10599
B17: 매입 | C17: Vol(L) | D17: =SUM('1027'!F17) -> 6602 | E17: 160 | F17: =D17+E17 -> 6762 | J17: [단위 : L]
A18: 재고 | B18: 구분 | D18: 전일재고 | E18: 입고 | F18: 출고 | G18: 재고 | I18: 입고 | J18: 출고
B19: Mobil | C19: D/M | D19: =SUM('1027'!G19) -> 621.895 | E19: =I19/200 -> 41.18 | F19: =J19/200 -> 30.47 | G19: =D19+E19-F19 -> 632.605 | I19: 8236 | J19: 6094
B20: Mobil-MB | D20: =SUM('1027'!G20) -> 27.44 | E20: =I20/200 -> 13.52 | F20: =J20/200 -> 0 | G20: =D20+E20-F20 -> 40.96 | I20: 2704
B21: 블라자 | D21: =SUM('1027'!G21) -> 0 | E21: =I21/200 -> 0 | F21: =J21/200 -> 0 | G21: =D21+E21-F21 -> 0
B22: 훅스 | D22: =SUM('1027'!G22) -> 53.5 | E22: =I22/200 -> 6.15 | F22: =J22/200 -> 0 | G22: =D22+E22-F22 -> 59.65 | I22: 1230
B23: 기타(쉘외 타사제품) | D23: =SUM('1027'!G23) -> 27.875 | E23: =I23/200 -> 0 | F23: =J23/200 -> 0 | G23: =D23+E23-F23 -> 27.875
B24: 합계 | D24: =SUM(D19:D23) -> 730.71 | E24: =SUM(E19:E23) -> 60.85 | F24: =SUM(F19:F23) -> 30.47 | G24: =SUM(G19:G23) -> 761.09 | I24: =SUM(I19:I23) -> 12170 | J24: =SUM(J19:J23) -> 6094
A26: *. 주요현황
A27: 날짜 | B27: 상 호 | C27: 금 액 | D27: 비 고 | J27: 200
J28: =+J26/J27 -> 0
A30: *. 신규개척업체
A31: 날짜 | B31: 상 호 | C31: 소재지 | D31: 비 고

Sheet 1029
A1: (창원) 일일매출/수금 마감현황
A2: 45959 | G2: [단위 : 원, VAT포함] [단위 : D/M] | K2: [단위 : L]
A3: 구분 | D3: 전일누계 | E3: 당일 | F3: 누계 | G3: 비고 | I3: 전일누계 | J3: 당일 | K3: 누계
A4: 판매현황 | B4: Mobil | D4: =SUM('1028'!F4) -> 584759575 | E4: 30679748 | F4: =D4+E4 -> 615439323 | G4: =K4/200 -> 598.08 | I4: =SUM('1028'!K4) -> 110304 | J4: 9312 | K4: =I4+J4 -> 119616 | M4: =+K4+K6+K7+K8 -> 142372
B5: Mobil-MB | D5: =SUM('1028'!F5) -> 0 | F5: =D5+E5 -> 0 | G5: =K5/200 -> 200.7 | I5: =SUM('1028'!K5) -> 40140 | K5: =I5+J5 -> 40140
B6: 블라자 | D6: =SUM('1028'!F6) -> 0 | F6: =D6+E6 -> 0 | G6: =K6/200 -> 0 | I6: =SUM('1028'!K6) -> 0 | K6: =I6+J6 -> 0
B7: 훅스 | D7: =SUM('1028'!F7) -> 79396790 | E7: 396000 | F7: =D7+E7 -> 79792790 | G7: =K7/200 -> 89 | I7: =SUM('1028'!K7) -> 17720 | J7: 80 | K7: =I7+J7 -> 17800
B8: 기타(쉘 외 타사제품) | D8: =SUM('1028'!F8) -> 21528980 | F8: =D8+E8 -> 21528980 | G8: =K8/200 -> 24.78 | I8: =SUM('1028'!K8) -> 4956 | K8: =I8+J8 -> 4956
A9: 매출액 | D9: =SUM(D4:D8) -> 685685345 | E9: =SUM(E4:E8) -> 31075748 | F9: =SUM(F4:F8) -> 716761093 | G9: =SUM(G4:G8) -> 912.56 | I9: =SUM(I4:I8) -> 173120 | J9: =SUM(J4:J8) -> 9392 | K9: =SUM(K4:K8) -> 182512
A10: 수금액 | B10: Cash | D10: =SUM('1028'!F10) -> 323124334 | E10: 78100 | F10: =D10+E10 -> 323202434
B11: 어음 | D11: =SUM('1028'!F11) -> 72538290 | F11: =D11+E11 -> 72538290
B12: 카드 | D12: =SUM('1028'!F12) -> 0 | F12: =D12+E12 -> 0
B13: 합계 | D13: =SUM(D10:D12) -> 395662624 | E13: =SUM(E10:E12) -> 78100 | F13: =SUM(F10:F12) -> 395740724
A14: 매입/발주 | B14: 모빌 | C14: Vol(L) | D14: =SUM('1028'!F14) -> 144258 | E14: 5440 | F14: =D14+E14 -> 149698 | G14: =F14/200 -> 748.49
C15: 금액 | D15: =SUM('1028'!F15) -> 567010215 | E15: 14893340 | F15: =D15+E15 -> 581903555
A16: IL (Flagship) | B16: 매출 | C16: Vol(L) | D16: =SUM('1028'!F16) -> 10599 | E16: 16 | F16: =D16+E16 -> 10615
B17: 매입 | C17: Vol(L) | D17: =SUM('1028'!F17) -> 6762 | F17: =D17+E17 -> 6762 | J17: [단위 : L]
A18: 재고 | B18: 구분 | D18: 전일재고 | E18: 입고 | F18: 출고 | G18: 재고 | I18: 입고 | J18: 출고
B19: Mobil | C19: D/M | D19: =SUM('1028'!G19) -> 632.605 | E19: =I19/200 -> 27.2 | F19: =J19/200 -> 51.34 | G19: =D19+E19-F19 -> 608.465 | I19: 5440 | J19: 10268
B20: Mobil-MB | D20: =SUM('1028'!G20) -> 40.96 | E20: =I20/200 -> 0 | F20: =J20/200 -> 0 | G20: =D20+E20-F20 -> 40.96
B21: 블라자 | D21: =SUM('1028'!G21) -> 0 | E21: =I21/200 -> 0 | F21: =J21/200 -> 0 | G21: =D21+E21-F21 -> 0
B22: 훅스 | D22: =SUM('1028'!G22) -> 59.65 | E22: =I22/200 -> 4.5 | F22: =J22/200 -> 0.4 | G22: =D22+E22-F22 -> 63.75 | I22: 900 | J22: 80
B23: 기타(쉘외 타사제품) | D23: =SUM('1028'!G23) -> 27.875 | E23: =I23/200 -> 0 | F23: =J23/200 -> 0 | G23: =D23+E23-F23 -> 27.875
B24: 합계 | D24: =SUM(D19:D23) -> 761.09 | E24: =SUM(E19:E23) -> 31.7 | F24: =SUM(F19:F23) -> 51.74 | G24: =SUM(G19:G23) -> 741.05 | I24: =SUM(I19:I23) -> 6340 | J24: =SUM(J19:J23) -> 10348
A26: *. 주요현황
A27: 날짜 | B27: 상 호 | C27: 금 액 | D27: 비 고 | J27: 200
J28: =+J26/J27 -> 0
A30: *. 신규개척업체
A31: 날짜 | B31: 상 호 | C31: 소재지 | D31: 비 고

Sheet 0923
A1: (창원) 일일매출/수금 마감현황
A2: 45923 | G2: [단위 : 원, VAT포함] [단위 : D/M] | K2: [단위 : L]
A3: 구분 | D3: 전일누계 | E3: 당일 | F3: 누계 | G3: 비고 | I3: 전일누계 | J3: 당일 | K3: 누계
A4: 판매현황 | B4: Mobil | D4: =SUM('1029'!F4) -> 615439323 | E4: 24345618 | F4: =D4+E4 -> 639784941 | G4: =K4/200 -> 623.605 | I4: =SUM('1029'!K4) -> 119616 | J4: 5105 | K4: =I4+J4 -> 124721 | M4: =+K4+K6+K7+K8 -> 147897
B5: Mobil-MB | D5: =SUM('1029'!F5) -> 0 | F5: =D5+E5 -> 0 | G5: =K5/200 -> 200.7 | I5: =SUM('1029'!K5) -> 40140 | K5: =I5+J5 -> 40140
B6: 블라자 | D6: =SUM('1029'!F6) -> 0 | F6: =D6+E6 -> 0 | G6: =K6/200 -> 0 | I6: =SUM('1029'!K6) -> 0 | K6: =I6+J6 -> 0
B7: 훅스 | D7: =SUM('1029'!F7) -> 79792790 | E7: 1778700 | F7: =D7+E7 -> 81571490 | G7: =K7/200 -> 91.1 | I7: =SUM('1029'!K7) -> 17800 | J7: 420 | K7: =I7+J7 -> 18220
B8: 기타(쉘 외 타사제품) | D8: =SUM('1029'!F8) -> 21528980 | F8: =D8+E8 -> 21528980 | G8: =K8/200 -> 24.78 | I8: =SUM('1029'!K8) -> 4956 | K8: =I8+J8 -> 4956
A9: 매출액 | D9: =SUM(D4:D8) -> 716761093 | E9: =SUM(E4:E8) -> 26124318 | F9: =SUM(F4:F8) -> 742885411 | G9: =SUM(G4:G8) -> 940.185 | I9: =SUM(I4:I8) -> 182512 | J9: =SUM(J4:J8) -> 5525 | K9: =SUM(K4:K8) -> 188037
A10: 수금액 | B10: Cash | D10: =SUM('1029'!F10) -> 323202434 | E10: 2741200 | F10: =D10+E10 -> 325943634
B11: 어음 | D11: =SUM('1029'!F11) -> 72538290 | E11: 1610400 | F11: =D11+E11 -> 74148690
B12: 카드 | D12: =SUM('1029'!F12) -> 0 | F12: =D12+E12 -> 0
B13: 합계 | D13: =SUM(D10:D12) -> 395740724 | E13: =SUM(E10:E12) -> 4351600 | F13: =SUM(F10:F12) -> 400092324
A14: 매입/발주 | B14: 모빌 | C14: Vol(L) | D14: =SUM('1029'!F14) -> 149698 | E14: 11792 | F14: =D14+E14 -> 161490 | G14: =F14/200 -> 807.45
C15: 금액 | D15: =SUM('1029'!F15) -> 581903555 | E15: 47668060 | F15: =D15+E15 -> 629571615
A16: IL (Flagship) | B16: 매출 | C16: Vol(L) | D16: =SUM('1029'!F16) -> 10615 | E16: 57 | F16: =D16+E16 -> 10672
B17: 매입 | C17: Vol(L) | D17: =SUM('1029'!F17) -> 6762 | E17: 832 | F17: =D17+E17 -> 7594 | J17: [단위 : L]
A18: 재고 | B18: 구분 | D18: 전일재고 | F18: 출고 | G18: 재고 | I18: 입고 | J18: 출고
B19: Mobil | C19: D/M | D19: =SUM('1029'!G19) -> 608.465 | E19: =I19/200 -> 58.96 | F19: =J19/200 -> 25.72 | G19: =D19+E19-F19 -> 641.705 | I19: 11792 | J19: 5144
B20: Mobil-MB | D20: =SUM('1029'!G20) -> 40.96 | E20: =I20/200 -> 0 | F20: =J20/200 -> 0.12 | G20: =D20+E20-F20 -> 40.84 | J20: 24
B21: 블라자 | D21: =SUM('1029'!G21) -> 0 | E21: =I21/200 -> 0 | F21: =J21/200 -> 0 | G21: =D21+E21-F21 -> 0
B22: 훅스 | D22: =SUM('1029'!G22) -> 63.75 | E22: =I22/200 -> 1 | F22: =J22/200 -> 2.1 | G22: =D22+E22-F22 -> 62.65 | I22: 200 | J22: 420
B23: 기타(쉘외 타사제품) | D23: =SUM('1029'!G23) -> 27.875 | E23: =I23/200 -> 0 | F23: =J23/200 -> 0 | G23: =D23+E23-F23 -> 27.875
B24: 합계 | D24: =SUM(D19:D23) -> 741.05 | E24: =SUM(E19:E23) -> 59.96 | F24: =SUM(F19:F23) -> 27.94 | G24: =SUM(G19:G23) -> 773.07 | I24: =SUM(I19:I23) -> 11992 | J24: =SUM(J19:J23) -> 5588
A26: *. 주요현황
A27: 날짜 | B27: 상 호 | C27: 금 액 | D27: 비 고 | J27: 200
J28: =+J26/J27 -> 0
A30: *. 신규개척업체
A31: 날짜 | B31: 상 호 | C31: 소재지 | D31: 비 고

Sheet 0924
A1: (창원) 일일매출/수금 마감현황
A2: 45924 | G2: [단위 : 원, VAT포함] [단위 : D/M] | K2: [단위 : L]
A3: 구분 | D3: 전일누계 | E3: 당일 | F3: 누계 | G3: 비고 | I3: 전일누계 | J3: 당일 | K3: 누계
A4: 판매현황 | B4: Mobil | D4: =SUM('0923'!F4) -> 639784941 | E4: 57944260 | F4: =D4+E4 -> 697729201 | G4: =K4/200 -> 691.255 | I4: =SUM('0923'!K4) -> 124721 | J4: 13530 | K4: =I4+J4 -> 138251 | M4: =+K4+K6+K7+K8 -> 162497
B5: Mobil-MB | D5: =SUM('0923'!F5) -> 0 | F5: =D5+E5 -> 0 | G5: =K5/200 -> 200.7 | I5: =SUM('0923'!K5) -> 40140 | K5: =I5+J5 -> 40140
B6: 블라자 | D6: =SUM('0923'!F6) -> 0 | F6: =D6+E6 -> 0 | G6: =K6/200 -> 0 | I6: =SUM('0923'!K6) -> 0 | K6: =I6+J6 -> 0
B7: 훅스 | D7: =SUM('0923'!F7) -> 81571490 | E7: 2288000 | F7: =D7+E7 -> 83859490 | G7: =K7/200 -> 95.1 | I7: =SUM('0923'!K7) -> 18220 | J7: 800 | K7: =I7+J7 -> 19020
B8: 기타(쉘 외 타사제품) | D8: =SUM('0923'!F8) -> 21528980 | E8: 907500 | F8: =D8+E8 -> 22436480 | G8: =K8/200 -> 26.13 | I8: =SUM('0923'!K8) -> 4956 | J8: 270 | K8: =I8+J8 -> 5226
A9: 매출액 | D9: =SUM(D4:D8) -> 742885411 | E9: =SUM(E4:E8) -> 61139760 | F9: =SUM(F4:F8) -> 804025171 | G9: =SUM(G4:G8) -> 1013.185 | I9: =SUM(I4:I8) -> 188037 | J9: =SUM(J4:J8) -> 14600 | K9: =SUM(K4:K8) -> 202637
A10: 수금액 | B10: Cash | D10: =SUM('0923'!F10) -> 325943634 | E10: 2738010 | F10: =D10+E10 -> 328681644
B11: 어음 | D11: =SUM('0923'!F11) -> 74148690 | E11: 29768083 | F11: =D11+E11 -> 103916773
B12: 카드 | D12: =SUM('0923'!F12) -> 0 | F12: =D12+E12 -> 0
B13: 합계 | D13: =SUM(D10:D12) -> 400092324 | E13: =SUM(E10:E12) -> 32506093 | F13: =SUM(F10:F12) -> 432598417
A14: 매입/발주 | B14: 모빌 | C14: Vol(L) | D14: =SUM('0923'!F14) -> 161490 | E14: 3104 | F14: =D14+E14 -> 164594 | G14: =F14/200 -> 822.97
C15: 금액 | D15: =SUM('0923'!F15) -> 629571615 | E15: 9243080 | F15: =D15+E15 -> 638814695
A16: IL (Flagship) | B16: 매출 | C16: Vol(L) | D16: =SUM('0923'!F16) -> 10672 | E16: 38 | F16: =D16+E16 -> 10710
B17: 매입 | C17: Vol(L) | D17: =SUM('0923'!F17) -> 7594 | F17: =D17+E17 -> 7594 | J17: [단위 : L]
A18: 재고 | B18: 구분 | D18: 전일재고 | E18: 입고 | F18: 출고 | G18: 재고 | I18: 입고 | J18: 출고
B19: Mobil | C19: D/M | D19: =SUM('0923'!G19) -> 641.705 | E19: =I19/200 -> 15.52 | F19: =J19/200 -> 77.75 | G19: =D19+E19-F19 -> 579.475 | I19: 3104 | J19: 15550
B20: Mobil-MB | D20: =SUM('0923'!G20) -> 40.84 | E20: =I20/200 -> 0 | F20: =J20/200 -> 0 | G20: =D20+E20-F20 -> 40.84
B21: 블라자 | D21: =SUM('0923'!G21) -> 0 | E21: =I21/200 -> 0 | F21: =J21/200 -> 0 | G21: =D21+E21-F21 -> 0
B22: 훅스 | D22: =SUM('0923'!G22) -> 62.65 | E22: =I22/200 -> 0 | F22: =J22/200 -> 4 | G22: =D22+E22-F22 -> 58.65 | J22: 800
B23: 기타(쉘외 타사제품) | D23: =SUM('0923'!G23) -> 27.875 | E23: =I23/200 -> 0 | F23: =J23/200 -> 1.35 | G23: =D23+E23-F23 -> 26.525 | J23: 270
B24: 합계 | D24: =SUM(D19:D23) -> 773.07 | E24: =SUM(E19:E23) -> 15.52 | F24: =SUM(F19:F23) -> 83.1 | G24: =SUM(G19:G23) -> 705.49 | I24: =SUM(I19:I23) -> 3104 | J24: =SUM(J19:J23) -> 16620
A26: *. 주요현황
A27: 날짜 | B27: 상 호 | C27: 금 액 | D27: 비 고 | J27: 200
J28: =+J26/J27 -> 0
A30: *. 신규개척업체
A31: 날짜 | B31: 상 호 | C31: 소재지 | D31: 비 고

Sheet 0925
A1: (창원) 일일매출/수금 마감현황
A2: 45925 | G2: [단위 : 원, VAT포함] [단위 : D/M] | K2: [단위 : L]
A3: 구분 | D3: 전일누계 | E3: 당일 | F3: 누계 | G3: 비고 | I3: 전일누계 | J3: 당일 | K3: 누계
A4: 판매현황 | B4: Mobil | D4: =SUM('0924'!F4) -> 697729201 | E4: 7657320 | F4: =D4+E4 -> 705386521 | G4: =K4/200 -> 701.135 | I4: =SUM('0924'!K4) -> 138251 | J4: 1976 | K4: =I4+J4 -> 140227 | M4: =+K4+K6+K7+K8 -> 164493
B5: Mobil-MB | D5: =SUM('0924'!F5) -> 0 | F5: =D5+E5 -> 0 | G5: =K5/200 -> 200.7 | I5: =SUM('0924'!K5) -> 40140 | K5: =I5+J5 -> 40140
B6: 블라자 | D6: =SUM('0924'!F6) -> 0 | F6: =D6+E6 -> 0 | G6: =K6/200 -> 0 | I6: =SUM('0924'!K6) -> 0 | K6: =I6+J6 -> 0
B7: 훅스 | D7: =SUM('0924'!F7) -> 83859490 | F7: =D7+E7 -> 83859490 | G7: =K7/200 -> 95.1 | I7: =SUM('0924'!K7) -> 19020 | K7: =I7+J7 -> 19020
B8: 기타(쉘 외 타사제품) | D8: =SUM('0924'!F8) -> 22436480 | E8: 341000 | F8: =D8+E8 -> 22777480 | G8: =K8/200 -> 26.23 | I8: =SUM('0924'!K8) -> 5226 | J8: 20 | K8: =I8+J8 -> 5246
A9: 매출액 | D9: =SUM(D4:D8) -> 804025171 | E9: =SUM(E4:E8) -> 7998320 | F9: =SUM(F4:F8) -> 812023491 | G9: =SUM(G4:G8) -> 1023.165 | I9: =SUM(I4:I8) -> 202637 | J9: =SUM(J4:J8) -> 1996 | K9: =SUM(K4:K8) -> 204633
A10: 수금액 | B10: Cash | D10: =SUM('0924'!F10) -> 328681644 | E10: 133120680 | F10: =D10+E10 -> 461802324
B11: 어음 | D11: =SUM('0924'!F11) -> 103916773 | F11: =D11+E11 -> 103916773
B12: 카드 | D12: =SUM('0924'!F12) -> 0 | F12: =D12+E12 -> 0
B13: 합계 | D13: =SUM(D10:D12) -> 432598417 | E13: =SUM(E10:E12) -> 133120680 | F13: =SUM(F10:F12) -> 565719097
A14: 매입/발주 | B14: 모빌 | C14: Vol(L) | D14: =SUM('0924'!F14) -> 164594 | E14: 11254 | F14: =D14+E14 -> 175848 | G14: =F14/200 -> 879.24
C15: 금액 | D15: =SUM('0924'!F15) -> 638814695 | E15: 37623181 | F15: =D15+E15 -> 676437876
A16: IL (Flagship) | B16: 매출 | C16: Vol(L) | D16: =SUM('0924'!F16) -> 10710 | F16: =D16+E16 -> 10710
B17: 매입 | C17: Vol(L) | D17: =SUM('0924'!F17) -> 7594 | E17: 230 | F17: =D17+E17 -> 7824 | J17: [단위 : L]
A18: 재고 | B18: 구분 | D18: 전일재고 | E18: 입고 | F18: 출고 | G18: 재고 | I18: 입고 | J18: 출고
B19: Mobil | C19: D/M | D19: =SUM('0924'!G19) -> 579.475 | E19: =I19/200 -> 32.35 | F19: =J19/200 -> 14.445 | G19: =D19+E19-F19 -> 597.38 | I19: 6470 | J19: 2889
B20: Mobil-MB | D20: =SUM('0924'!G20) -> 40.84 | E20: =I20/200 -> 23.92 | F20: =J20/200 -> 0 | G20: =D20+E20-F20 -> 64.76 | I20: 4784
B21: 블라자 | D21: =SUM('0924'!G21) -> 0 | E21: =I21/200 -> 0 | F21: =J21/200 -> 0 | G21: =D21+E21-F21 -> 0
B22: 훅스 | D22: =SUM('0924'!G22) -> 58.65 | E22: =I22/200 -> 9.075 | F22: =J22/200 -> 0 | G22: =D22+E22-F22 -> 67.725 | I22: 1815
B23: 기타(쉘외 타사제품) | D23: =SUM('0924'!G23) -> 26.525 | E23: =I23/200 -> 0.1 | F23: =J23/200 -> 0.1 | G23: =D23+E23-F23 -> 26.525 | I23: 20 | J23: 20
B24: 합계 | D24: =SUM(D19:D23) -> 705.49 | E24: =SUM(E19:E23) -> 65.445 | F24: =SUM(F19:F23) -> 14.545 | G24: =SUM(G19:G23) -> 756.39 | I24: =SUM(I19:I23) -> 13089 | J24: =SUM(J19:J23) -> 2909
A26: *. 주요현황
A27: 날짜 | B27: 상 호 | C27: 금 액 | D27: 비 고 | J27: 200
J28: =+J26/J27 -> 0
A30: *. 신규개척업체
A31: 날짜 | B31: 상 호 | C31: 소재지 | D31: 비 고

Sheet 0926
A1: (창원) 일일매출/수금 마감현황
A2: 45926 | G2: [단위 : 원, VAT포함] [단위 : D/M] | K2: [단위 : L]
A3: 구분 | D3: 전일누계 | E3: 당일 | F3: 누계 | G3: 비고 | I3: 전일누계 | J3: 당일 | K3: 누계
A4: 판매현황 | B4: Mobil | D4: =SUM('0925'!F4) -> 705386521 | E4: 37585350 | F4: =D4+E4 -> 742971871 | G4: =K4/200 -> 741.01 | I4: =SUM('0925'!K4) -> 140227 | J4: 7975 | K4: =I4+J4 -> 148202 | M4: =+K4+K6+K7+K8 -> 172468
B5: Mobil-MB | D5: =SUM('0925'!F5) -> 0 | F5: =D5+E5 -> 0 | G5: =K5/200 -> 200.7 | I5: =SUM('0925'!K5) -> 40140 | K5: =I5+J5 -> 40140
B6: 블라자 | D6: =SUM('0925'!F6) -> 0 | F6: =D6+E6 -> 0 | G6: =K6/200 -> 0 | I6: =SUM('0925'!K6) -> 0 | K6: =I6+J6 -> 0
B7: 훅스 | D7: =SUM('0925'!F7) -> 83859490 | F7: =D7+E7 -> 83859490 | G7: =K7/200 -> 95.1 | I7: =SUM('0925'!K7) -> 19020 | K7: =I7+J7 -> 19020
B8: 기타(쉘 외 타사제품) | D8: =SUM('0925'!F8) -> 22777480 | F8: =D8+E8 -> 22777480 | G8: =K8/200 -> 26.23 | I8: =SUM('0925'!K8) -> 5246 | K8: =I8+J8 -> 5246
A9: 매출액 | D9: =SUM(D4:D8) -> 812023491 | E9: =SUM(E4:E8) -> 37585350 | F9: =SUM(F4:F8) -> 849608841 | G9: =SUM(G4:G8) -> 1063.04 | I9: =SUM(I4:I8) -> 204633 | J9: =SUM(J4:J8) -> 7975 | K9: =SUM(K4:K8) -> 212608
A10: 수금액 | B10: Cash | D10: =SUM('0925'!F10) -> 461802324 | E10: 83230400 | F10: =D10+E10 -> 545032724
B11: 어음 | D11: =SUM('0925'!F11) -> 103916773 | F11: =D11+E11 -> 103916773
B12: 카드 | D12: =SUM('0925'!F12) -> 0 | F12: =D12+E12 -> 0
B13: 합계 | D13: =SUM(D10:D12) -> 565719097 | E13: =SUM(E10:E12) -> 83230400 | F13: =SUM(F10:F12) -> 648949497
A14: 매입/발주 | B14: 모빌 | C14: Vol(L) | D14: =SUM('0925'!F14) -> 175848 | F14: =D14+E14 -> 175848 | G14: =F14/200 -> 879.24
C15: 금액 | D15: =SUM('0925'!F15) -> 676437876 | F15: =D15+E15 -> 676437876
A16: IL (Flagship) | B16: 매출 | C16: Vol(L) | D16: =SUM('0925'!F16) -> 10710 | E16: 982 | F16: =D16+E16 -> 11692
B17: 매입 | C17: Vol(L) | D17: =SUM('0925'!F17) -> 7824 | F17: =D17+E17 -> 7824 | J17: [단위 : L]
A18: 재고 | B18: 구분 | D18: 전일재고 | E18: 입고 | F18: 출고 | G18: 재고 | I18: 입고 | J18: 출고
B19: Mobil | C19: D/M | D19: =SUM('0925'!G19) -> 597.38 | E19: =I19/200 -> 0 | F19: =J19/200 -> 45.095 | G19: =D19+E19-F19 -> 552.285 | J19: 9019
B20: Mobil-MB | D20: =SUM('0925'!G20) -> 64.76 | E20: =I20/200 -> 0 | F20: =J20/200 -> 0 | G20: =D20+E20-F20 -> 64.76
B21: 블라자 | D21: =SUM('0925'!G21) -> 0 | E21: =I21/200 -> 0 | F21: =J21/200 -> 0 | G21: =D21+E21-F21 -> 0
B22: 훅스 | D22: =SUM('0925'!G22) -> 67.725 | E22: =I22/200 -> 0 | F22: =J22/200 -> 0 | G22: =D22+E22-F22 -> 67.725
B23: 기타(쉘외 타사제품) | D23: =SUM('0925'!G23) -> 26.525 | E23: =I23/200 -> 0 | F23: =J23/200 -> 0 | G23: =D23+E23-F23 -> 26.525
B24: 합계 | D24: =SUM(D19:D23) -> 756.39 | E24: =SUM(E19:E23) -> 0 | F24: =SUM(F19:F23) -> 45.095 | G24: =SUM(G19:G23) -> 711.295 | I24: =SUM(I19:I23) -> 0 | J24: =SUM(J19:J23) -> 9019
A26: *. 주요현황
A27: 날짜 | B27: 상 호 | C27: 금 액 | D27: 비 고 | J27: 200
J28: =+J26/J27 -> 0
A30: *. 신규개척업체
A31: 날짜 | B31: 상 호 | C31: 소재지 | D31: 비 고

Sheet 0930
A1: (창원) 일일매출/수금 마감현황
A2: 45930 | G2: [단위 : 원, VAT포함] [단위 : D/M] | K2: [단위 : L]
A3: 구분 | D3: 전일누계 | E3: 당일 | F3: 누계 | G3: 비고 | I3: 전일누계 | J3: 당일 | K3: 누계
A4: 판매현황 | B4: Mobil | D4: =SUM('0926'!F4) -> 742971871 | E4: 14055492 | F4: =D4+E4 -> 757027363 | G4: =K4/200 -> 757.545 | I4: =SUM('0926'!K4) -> 148202 | J4: 3307 | K4: =I4+J4 -> 151509 | M4: =+K4+K6+K7+K8 -> 175775
B5: Mobil-MB | D5: =SUM('0926'!F5) -> 0 | F5: =D5+E5 -> 0 | G5: =K5/200 -> 200.7 | I5: =SUM('0926'!K5) -> 40140 | K5: =I5+J5 -> 40140
B6: 블라자 | D6: =SUM('0926'!F6) -> 0 | F6: =D6+E6 -> 0 | G6: =K6/200 -> 0 | I6: =SUM('0926'!K6) -> 0 | K6: =I6+J6 -> 0
B7: 훅스 | D7: =SUM('0926'!F7) -> 83859490 | F7: =D7+E7 -> 83859490 | G7: =K7/200 -> 95.1 | I7: =SUM('0926'!K7) -> 19020 | K7: =I7+J7 -> 19020
B8: 기타(쉘 외 타사제품) | D8: =SUM('0926'!F8) -> 22777480 | F8: =D8+E8 -> 22777480 | G8: =K8/200 -> 26.23 | I8: =SUM('0926'!K8) -> 5246 | K8: =I8+J8 -> 5246
