Workbook

Sheet 화성
E2: 6월 | F2: 7월 | G2: 8월 | H2: 9월 | I2: 10월 | J2: 11월 | K2: 12월 | L2: 1월 | M2: 2월 | N2: 3월 | O2: 4월 | P2: 5월 | Q2: 6월 | R2: 7월 | S2: 8월 | T2: 9월 | U2: 10월 | V2: 11월 | W2: 12월 | X2: 01월 | Y2: 02월 | Z2: 03월 | AA2: 04월 | AB2: 05월 | AC2: 06월 | AD2: 07월 | AE2: 08월 | AF2: 09월 | AG2: 10월 | BB2: 화성사업소 | BG2: 화성사업소 | BP2: 화성사업소
B3: 구분 | C3: 제품명 | D3: 규격 | E3: 전재고 | F3: 전재고 | G3: 전재고 | H3: 전재고 | I3: 전재고 | J3: 전재고 | K3: 전재고 | L3: 전재고 | M3: 전재고 | N3: 전재고 | O3: 전재고 | P3: 현재고 | Q3: 현재고 | R3: 현재고 | S3: 현재고 | T3: 현재고 | U3: 현재고 | V3: 현재고 | W3: 현재고 | X3: 현재고 | Y3: 현재고 | Z3: 현재고 | AA3: 현재고 | AB3: 현재고 | AC3: 현재고 | AD3: 현재고 | AE3: 현재고 | AF3: 현재고 | AG3: 현재고 | AH3: 제조일자 | AJ3: 최종 구매일 | AK3: 구매단가 | AL3: 최종 판매일 | AM3: 비고 | AN3: 6월 처리방안 | AO3: 7월 처리방안 | AP3: 8월 처리방안 | AQ3: 9월 처리방안 | AR3: 10월 처리방안 | AS3: 11월 처리방안 | AT3: 12월 처리방안 | AU3: 1월 처리방안 | AV3: 2월 처리방안 | AW3: 3월 처리방안 | AX3: 4월 처리방안 | AY3: 5월 처리방안 | AZ3: 6월 처리방안 | BA3: 7월 처리방안 | BB3: 8월 처리방안 | BC3: 9월 처리방안 | BD3: 10월 처리방안 | BE3: 11월 처리방안 | BF3: 12월 처리방안 | BG3: 01월 처리방안 | BH3: 02월 처리방안 | BI3: 03월 처리방안 | BJ3: 04월 처리방안 | BK3: 05월 처리방안 | BL3: 06월 처리방안 | BM3: 07월 처리방안 | BN3: 08월 처리방안 | BO3: 09월 처리방안 | BP3: 10월 처리방안
B4: IL | C4: MOBIL SPARTAN EP 320 | D4: DM | E4: 37 | F4: 32 | G4: 28 | H4: 20 | I4: 4 | J4: 0 | K4: 0 | L4: 0 | M4: 0 | N4: 0 | O4: 0 | AH4: 6 | AI4: 2022.04.14 | AJ4: 2022.06.22 | AK4: 522000 | AL4: 2023.05.03 | AM4: 티센특가 인상전 재고 확보 | AN4: 기존 거래처 판매 우선 처리 | AO4: 기존 거래처 판매 우선 처리 | AP4: 기존 거래처 판매 우선 처리 | AQ4: 기존 거래처 판매 우선 처리 | AR4: 11월10일 해성티피씨 출고예정
AH5: 8 | AI5: 2022.04.25 | AN5: 포장용기 이상 제품-해성 구매요청 처리-김건우 | AO5: 포장용기 이상 제품-해성 구매요청 처리-김건우 | AP5: 포장용기 이상 제품-해성 구매요청 처리-김건우 | AQ5: 포장용기 이상 제품-해성 구매요청 처리-김건우
AH6: 5 | AI6: 2022.02.22 | AP6: 장기재고 발생 가능시- 해성 구매요청 처리-김건우 | AQ6: 장기재고 발생 가능시- 해성 구매요청 처리-김건우
AH7: 1 | AI7: 2021.01.19 | AN7: 장기재고 발생 가능시- 해성 구매요청 처리-김건우 | AO7: 장기재고 발생 가능시- 해성 구매요청 처리-김건우 | AQ7: 기존 거래처 판매 및 창원 이관후 판매
C8: MOBIL SPARTAN EP 460 | D8: DM | E8: =14-1 -> 13 | F8: 4 | G8: 3 | H8: 0 | AH8: =4-1 -> 3 | AI8: 2022.02.14 | AJ8: 2022.04.26 | AK8: 539000 | AL8: 2023.05.23 | AN8: 기존 거래처 판매 우선 처리 | AO8: 기존 거래처 판매 우선 처리 | AP8: 기존 거래처 판매 우선 처리 | AQ8: 기존 거래처 판매 완료 | AR8: 기존 거래처 판매 완료
AH9: 10 | AI9: 2022.04.26
C10: MOBILUX EP 3 | D10: PL | E10: =57 -> 57 | F10: 26 | G10: 16 | H10: 16 | I10: 6 | J10: 5 | K10: 5 | L10: 5 | M10: 5 | N10: 0 | O10: 0 | AH10: =58-1 -> 57 | AI10: 2021.01.02 | AJ10: 2021.04.13 | AK10: 62000 | AL10: 2023.05.03 | AS10: 판매중 | AT10: 판매중 | AU10: AJ 네트웍스판매 | AV10: AJ 네트웍스판매 | AW10: 3/12 AJ네트웍스 5말 판매완료 | AX10: 3/12 AJ네트웍스 5말 판매완료 | AY10: 3/12 AJ네트웍스 5말 판매완료 | AZ10: 3/12 AJ네트웍스 5말 판매완료 | BA10: 3/12 AJ네트웍스 5말 판매완료 | BB10: 3/12 AJ네트웍스 5말 판매완료 | BC10: 3/12 AJ네트웍스 5말 판매완료 | BD10: 3/12 AJ네트웍스 5말 판매완료 | BE10: 3/12 AJ네트웍스 5말 판매완료 | BF10: 3/12 AJ네트웍스 5말 판매완료 | BG10: 3/12 AJ네트웍스 5말 판매완료 | BH10: 3/12 AJ네트웍스 5말 판매완료 | BI10: 3/12 AJ네트웍스 5말 판매완료 | BJ10: 3/12 AJ네트웍스 5말 판매완료 | BK10: 3/12 AJ네트웍스 5말 판매완료 | BL10: 3/12 AJ네트웍스 5말 판매완료 | BM10: 3/12 AJ네트웍스 5말 판매완료 | BN10: 3/12 AJ네트웍스 5말 판매완료 | BO10: 3/12 AJ네트웍스 5말 판매완료 | BP10: 3/12 AJ네트웍스 5말 판매완료
C11: MOBIL SHC 525 | D11: PL | E11: 7 | F11: 0 | G11: 0 | AH11: 7 | AI11: 2021.12 | AJ11: 2022.07.13 | AK11: 249000 | AL11: 2023.05.22 | AO11: 7/21 출고완료
C12: MOBIL THERM 603 | D12: DM | E12: =16-4 -> 12 | F12: 2 | G12: 0 | AH12: 4 | AI12: 2022.04.05 | AJ12: 2022.06.30 | AK12: 560000 | AL12: 2023.05.10 | AM12: 제이케이머트리얼즈특가 잔량매입 | AP12: 판매완료 | AQ12: 판매완료 | AR12: 판매완료
AH13: 4 | AI13: 2022.05.20
AH14: 4 | AI14: 2022.06.15
C15: MOBIL GAR ARCTIC SHC 226 E | D15: PL | E15: 3 | F15: 0 | G15: 0 | AH15: 3 | AI15: 2021.04 | AJ15: 2022.03.31 | AK15: 273000 | AL15: 2022.11.04 | AO15: 6/14 부산사무소 이관 후 출고완료
C16: MOBIL GAR ARCTIC 300 | D16: DM | E16: 6 | F16: 6 | G16: 6 | H16: 6 | I16: 6 | J16: 6 | K16: 6 | L16: 6 | M16: 6 | N16: 6 | O16: 6 | P16: 6 | Q16: 6 | R16: 6 | S16: 6 | T16: 3 | U16: 3 | V16: 3 | W16: 3 | X16: 3 | Y16: 3 | Z16: 3 | AA16: 3 | AB16: 3 | AC16: 3 | AD16: 3 | AE16: 3 | AF16: 3 | AG16: 0 | AH16: 4 | AI16: 2021.12 | AJ16: 2022.04.25 | AK16: 1036000 | AL16: 2023.02.27 | AN16: 서브원 확인중 | AO16: 타 사업소 및 전략점 필요시 재고이관 예정 | AP16: 타 사업소 및 전략점 필요시 재고이관 예정 | AQ16: 타 사업소 및 전략점 필요시 재고이관 예정 | AR16: 타 사업소 및 전략점 필요시 재고이관 예정 | AS16: 타 사업소 및 전략점 필요시 재고이관 예정 | AT16: 타 사업소 및 전략점 필요시 재고이관 예정 | AU16: 타 사업소 및 전략점 필요시 재고이관 예정 | AV16: 타 사업소 및 전략점 필요시 재고이관 예정 | AW16: 타 사업소 및 전략점 필요시 재고이관 예정 | AX16: 타 사업소 및 전략점 필요시 재고이관 예정 | AY16: 타 사업소 및 전략점 필요시 재고이관 예정 | AZ16: 타 사업소 및 전략점 필요시 재고이관 예정 | BA16: 타 사업소 및 전략점 필요시 재고이관 예정 | BB16: 타 사업소 및 전략점 필요시 재고이관 예정 | BC16: 타 사업소 및 전략점 필요시 재고이관 예정 | BD16: 타 사업소 및 전략점 필요시 재고이관 예정 | BE16: 타 사업소 및 전략점 필요시 재고이관 예정 | BF16: 타 사업소 및 전략점 필요시 재고이관 예정 | BG16: 타 사업소 및 전략점 필요시 재고이관 예정 | BH16: 타 사업소 및 전략점 필요시 재고이관 예정 | BI16: 타 사업소 및 전략점 필요시 재고이관 예정 | BJ16: 타 사업소 및 전략점 필요시 재고이관 예정 | BK16: 타 사업소 및 전략점 필요시 재고이관 예정 | BL16: 타 사업소 및 전략점 필요시 재고이관 예정 | BM16: 타 사업소 및 전략점 필요시 재고이관 예정 | BN16: 타 사업소 및 전략점 필요시 재고이관 예정 | BO16: 타 사업소 및 전략점 필요시 재고이관 예정 | BP16: 9월 창원으로 이관
AH17: 2 | AI17: 2021.07 | BB17: 5월 서브원 3DM판매
C18: LUX EP 2 (15KG) | D18: PL | E18: 6 | F18: 6 | G18: 5 | H18: 5 | I18: 1 | J18: 1 | K18: 1 | L18: 1 | M18: 1 | N18: 1 | O18: 1 | P18: 1 | Q18: 1 | R18: 1 | S18: 1 | T18: 0 | U18: 0 | V18: 0 | W18: 0 | X18: 0 | Y18: 0 | Z18: 0 | AA18: 0 | AB18: 0 | AC18: 0 | AD18: 0 | AE18: 0 | AF18: 0 | AG18: 0 | AH18: 6 | AI18: 2020.09.23 | AJ18: 2020.10.06 | AK18: 46300 | AL18: 2023.04.03 | AM18: 화성구매 → 인천이관(20년12월) → 화성이관(23년1월) | AN18: 용량 변경으로 인한 재고 / 출하팀 선출고 지시로 처리 | AO18: 용량 변경으로 인한 재고 / 출하팀 선출고 지시로 처리 | AP18: 용량 변경으로 인한 재고 / 출하팀 선출고 지시로 처리 | AQ18: 용량 변경으로 인한 재고 / 출하팀 선출고 지시로 처리 | AR18: 용량 변경으로 인한 재고 / 출하팀 선출고 지시로 처리 | AS18: 용량 변경으로 인한 재고 / 출하팀 선출고 지시로 처리 | AT18: 용량 변경으로 인한 재고 / 출하팀 선출고 지시로 처리 | AU18: 용량 변경으로 인한 재고 / 출하팀 선출고 지시로 처리 | AV18: 용량 변경으로 인한 재고 / 출하팀 선출고 지시로 처리 | AW18: 용량 변경으로 인한 재고 / 출하팀 선출고 지시로 처리 | AX18: 용량 변경으로 인한 재고 / 출하팀 선출고 지시로 처리 | AY18: 용량 변경으로 인한 재고 / 출하팀 선출고 지시로 처리 | AZ18: 용량 변경으로 인한 재고 / 출하팀 선출고 지시로 처리 | BA18: 용량 변경으로 인한 재고 / 출하팀 선출고 지시로 처리 | BB18: 5월 엑스포상사 1PL판매
C19: LUX EP 023 (15KG) | D19: PL | E19: 6 | F19: 6 | G19: 3 | H19: 0 | AH19: 6 | AI19: 2020.02.11 | AJ19: 2020.09.21 | AK19: 55500 | AL19: 2022.12.27 | AN19: 재고 문의시 적극판매 유도 (주도 000) | AO19: 재고 문의시 적극판매 유도 (주도 000) | AP19: 재고 문의시 적극판매 유도 (주도 000) | AQ19: 기존 거래처 판매 완료 | AR19: 기존 거래처 판매 완료 | AS19: 기존 거래처 판매 완료 | AT19: 기존 거래처 판매 완료 | AU19: 기존 거래처 판매 완료 | AV19: 기존 거래처 판매 완료 | AW19: 대기유화 판매 추진-김기진 | AX19: 대기유화 판매 추진-김기진 | AY19: 대기유화 판매 추진-김기진 | AZ19: 대기유화 판매 추진-김기진 | BA19: 대기유화 판매 추진-김기진 | BB19: 대기유화 판매 추진-김기진 | BC19: 대기유화 판매 추진-김기진 | BD19: 대기유화 판매 추진-김기진 | BE19: 대기유화 판매 추진-김기진 | BF19: 대기유화 판매 추진-김기진 | BG19: 대기유화 판매 추진-김기진 | BH19: 대기유화 판매 추진-김기진 | BI19: 대기유화 판매 추진-김기진 | BJ19: 대기유화 판매 추진-김기진 | BK19: 대기유화 판매 추진-김기진 | BL19: 대기유화 판매 추진-김기진 | BM19: 대기유화 판매 추진-김기진 | BN19: 대기유화 판매 추진-김기진 | BO19: 대기유화 판매 추진-김기진 | BP19: 대기유화 판매 추진-김기진
C20: MOBIL VELOCITE HP 46 | D20: DM | E20: 2 | F20: 2 | G20: 2 | H20: 2 | I20: 1 | J20: 1 | K20: 1 | L20: 1 | M20: 1 | N20: 1 | O20: 1 | P20: 1 | Q20: 1 | R20: 1 | S20: 1 | T20: 1 | U20: 1 | V20: 1 | W20: 1 | X20: 1 | Y20: 1 | Z20: 1 | AA20: 1 | AB20: 1 | AC20: 1 | AD20: 1 | AE20: 1 | AF20: 1 | AG20: 1 | AH20: 2 | AI20: 2021.03.25 | AJ20: 2021.03.25 | AK20: 578000 | AL20: 2021.03.23 | AM20: 21.04월 10% 인상 전 재고 확보 | AN20: 대기유화 판매 추진-김기진 | AO20: 대기유화 판매 추진-김기진 | AP20: 대기유화 판매 추진-김기진 | AQ20: 대기유화 판매 추진-김기진 | AR20: 대기유화 판매 추진-김기진 | AS20: 대기유화 판매 추진-김기진 | AT20: 대기유화 판매 추진-김기진 | AU20: 대기유화 판매 추진-김기진 | AV20: 대기유화 판매 추진-김기진 | AW20: 롯데건설 청주, 대구 공급시 판매가능 | AX20: 대기유화 판매 추진-김기진 | AY20: 대기유화 판매 추진-김기진 | AZ20: 대기유화 판매 추진-김기진 | BA20: 대기유화 판매 추진-김기진 | BB20: 대기유화 판매 추진-김기진 | BC20: 대기유화 판매 추진-김기진 | BD20: 대기유화 판매 추진-김기진 | BE20: 대기유화 판매 추진-김기진 | BF20: 대기유화 판매 추진-김기진 | BG20: 대기유화 판매 추진-김기진 | BH20: 대기유화 판매 추진-김기진 | BI20: 대기유화 판매 추진-김기진 | BJ20: 대기유화 판매 추진-김기진 | BK20: 대기유화 판매 추진-김기진 | BL20: 대기유화 판매 추진-김기진 | BM20: 대기유화 판매 추진-김기진 | BN20: 대기유화 판매 추진-김기진 | BO20: 대기유화 판매 추진-김기진 | BP20: 대기유화 판매 추진-김기진
C21: MOBIL DTE 732 M | D21: DM | E21: 3 | F21: 3 | G21: 3 | H21: 3 | I21: 3 | J21: 3 | K21: 3 | L21: 3 | M21: 3 | N21: 3 | O21: 3 | P21: 3 | Q21: 3 | R21: 3 | S21: 3 | T21: 3 | U21: 0 | V21: 0 | W21: 0 | X21: 0 | Y21: 0 | Z21: 0 | AA21: 0 | AB21: 0 | AC21: 0 | AD21: 0 | AE21: 0 | AF21: 0 | AG21: 0 | AH21: 1 | AI21: 2020.12.16 | AJ21: 2021.05.04 | AK21: 325000 | AM21: 이테크건설특가 수출잔량분, 화성이관 | AN21: 롯데건설 청주, 대구 공급시 판매가능 | AO21: 롯데건설 청주, 대구 공급시 판매가능 | AP21: 롯데건설 청주, 대구 공급시 판매가능 | AQ21: 롯데건설 청주, 대구 공급시 판매가능 | AR21: 롯데건설 청주, 대구 공급시 판매가능 | AS21: 롯데건설 청주, 대구 공급시 판매가능 | AT21: 롯데건설 청주, 대구 공급시 판매가능 | AU21: 롯데건설 청주, 대구 공급시 판매가능 | AV21: 롯데건설 청주, 대구 공급시 판매가능 | AX21: 롯데건설 청주, 대구 공급시 판매가능 | AY21: 롯데건설 청주, 대구 공급시 판매가능 | AZ21: 롯데건설 청주, 대구 공급시 판매가능 | BA21: 롯데건설 청주, 대구 공급시 판매가능 | BB21: 롯데건설 청주, 대구 공급시 판매가능 | BC21: 롯데건설 청주, 대구 공급시 판매가능 | BD21: 판매완료 | BE21: 판매완료 | BF21: 판매완료 | BG21: 판매완료 | BH21: 판매완료 | BI21: 판매완료 | BJ21: 판매완료 | BK21: 판매완료 | BL21: 판매완료 | BM21: 판매완료 | BN21: 판매완료 | BO21: 판매완료 | BP21: 판매완료
AH22: 2 | AI22: 2021.03.31 | AW22: 현대자동차 forecast 확인(평안정공, 신평산업)
B23: AL | C23: DELVAC XHP ESP S 10W-40 | D23: DM | E23: 38 | F23: 38 | G23: 38 | H23: 34 | I23: 34 | J23: 34 | K23: 34 | L23: 34 | M23: 34 | N23: 34 | O23: 34 | P23: 34 | Q23: 34 | R23: 34 | S23: 34 | T23: 34 | U23: 34 | V23: 34 | W23: 34 | X23: 34 | Y23: 34 | Z23: 34 | AA23: 34 | AB23: 25 | AC23: 21 | AD23: 21 | AE23: 21 | AF23: 16 | AG23: 0 | AH23: 38 | AI23: 2022.04.29 | AJ23: 2022.05.02 | AK23: 573000 | AL23: 2022.08.01 | AM23: 단종 전, 트랜시스 공급분 재고확보 /현대자동차 발주없음 | AO23: 현대자동차 발주 없음, 현대자동차 forecast 확인(평안정공, 신평산업) | AP23: 현대자동차 forecast 확인(평안정공, 신평산업) | AQ23: 현대자동차 forecast 확인(평안정공, 신평산업) | AR23: 현대자동차 forecast 확인(평안정공, 신평산업) | AS23: 현대자동차 forecast 확인(평안정공, 신평산업) | AT23: 현대자동차 forecast 확인(평안정공, 신평산업) | AU23: 현대자동차 forecast 확인(평안정공, 신평산업) | AV23: 현대자동차 forecast 확인(평안정공, 신평산업) | AX23: 현대자동차 forecast 확인(평안정공, 신평산업) | AY23: 현대자동차 forecast 확인(평안정공, 신평산업) | AZ23: 현대자동차 forecast 확인(평안정공, 신평산업) | BA23: 현대자동차 forecast 확인(평안정공, 신평산업) | BB23: 현대자동차 forecast 확인(평안정공, 신평산업) | BC23: 현대자동차 forecast 확인(평안정공, 신평산업) | BD23: 현대자동차 forecast 확인(평안정공, 신평산업) | BE23: 현대자동차 forecast 확인(평안정공, 신평산업) | BF23: 현대자동차 forecast 확인(평안정공, 신평산업) | BG23: 현대자동차 forecast 확인(평안정공, 신평산업) | BH23: 현대자동차 forecast 확인(평안정공, 신평산업) | BI23: 현대자동차 forecast 확인(평안정공, 신평산업) | BJ23: 현대자동차 forecast 확인(평안정공, 신평산업) | BK23: 1월 서부지사 1DM / 5월 동부지사 8DM 판매 | BL23: 1월 서부지사 1DM / 6월 동부지사 4DM 판매 | BM23: 1월 서부지사 1DM / 6월 동부지사 4DM 판매 | BN23: 1월 서부지사 1DM / 6월 동부지사 4DM 판매 | BO23: 7월 동부지사 4DM, 월 서부지사 1드럼 판매 | BP23: 10월 동부지사 16드럼 판매
B24: AL | C24: DELVAC MX ADV CITY LOG 10W30 (6L*3) | D24: BOX | E24: 10 | F24: 10 | G24: 10 | H24: 10 | I24: 10 | J24: 10 | K24: 10 | L24: 10 | M24: 10 | N24: 10 | O24: 10 | P24: 10 | Q24: 10 | R24: 10 | S24: 10 | T24: 10 | U24: 10 | V24: 10 | W24: 10 | X24: 10 | Y24: 10 | Z24: 0 | AA24: 0 | AB24: 0 | AC24: 0 | AD24: 0 | AE24: 0 | AF24: 0 | AG24: 0 | AH24: 10 | AI24: 2021.03.25 | AJ24: 2021.12.07 | AK24: 51700 | AM24: 22년 1월 한유 반품(모빌코리아 반품요청 반려됨) | AW24: 화인프라텍 10EA 샘플지원 예정 | BF24: 만해모터스접대 | BI24: 1/31 만해모터스(접대) | BJ24: 1/31 만해모터스(접대) | BK24: 1/31 만해모터스(접대) | BL24: 1/31 만해모터스(접대) | BM24: 1/31 만해모터스(접대) | BN24: 1/31 만해모터스(접대) | BO24: 1/31 만해모터스(접대) | BP24: 1/31 만해모터스(접대)
B25: 기타 | C25: SUMIPLEX MP 700 (700g) (그리스) | D25: EA | E25: 28 | F25: 28 | G25: 28 | H25: 28 | I25: 28 | J25: 28 | K25: 28 | L25: 28 | M25: 28 | N25: 28 | O25: 28 | P25: 28 | Q25: 28 | R25: 28 | S25: 28 | T25: 28 | U25: 28 | V25: 28 | W25: 28 | X25: 28 | Y25: 28 | Z25: 0 | AA25: 0 | AB25: 0 | AC25: 0 | AD25: 0 | AE25: 0 | AF25: 0 | AG25: 0 | AJ25: 2013.03.13 | AK25: 29700 | AM25: 거래단절, 할인 판매 가능 확인 | AN25: 거래단절, 할인 판매 가능 확인 | AO25: 화인프라텍 10EA 샘플지원 예정 | AP25: 화인프라텍 10EA 샘플지원 예정 | AQ25: 화인프라텍 10EA 샘플지원 예정 | AR25: 화인프라텍 10EA 샘플지원 예정 | AS25: 화인프라텍 10EA 샘플지원 예정 | AT25: 화인프라텍 10EA 샘플지원 예정 | AU25: 화인프라텍 10EA 샘플지원 예정 | AV25: 화인프라텍 10EA 샘플지원 예정 | AW25: 소분판매 추진 / 유통기한 폐기 문제 | AX25: 화인프라텍 10EA 샘플지원 예정 | AY25: 화인프라텍 10EA 샘플지원 예정 | AZ25: 화인프라텍 10EA 샘플지원 예정 | BA25: 화인프라텍 10EA 샘플지원 예정 | BB25: 화인프라텍 10EA 샘플지원 예정 | BC25: 화인프라텍 10EA 샘플지원 예정 | BD25: 화인프라텍 10EA 샘플지원 예정 | BE25: 화인프라텍 10EA 샘플지원 예정 | BF25: 폐기처분 | BG25: 화인프라텍 10EA 샘플지원 예정 | BH25: 화인프라텍 10EA 샘플지원 예정 | BI25: 12/31 장기재고 폐기 | BJ25: 12/31 장기재고 폐기 | BK25: 12/31 장기재고 폐기 | BL25: 12/31 장기재고 폐기 | BM25: 12/31 장기재고 폐기 | BN25: 12/31 장기재고 폐기 | BO25: 12/31 장기재고 폐기 | BP25: 12/31 장기재고 폐기
B26: 기타 | C26: Renolit G7 FG1 | D26: DM | E26: 4 | F26: 4 | G26: 4 | H26: 4 | I26: 4 | J26: 4 | K26: 4 | L26: 4 | M26: 4 | N26: 4 | O26: 4 | P26: 4 | Q26: 4 | R26: 4 | S26: 4 | T26: 4 | U26: 4 | V26: 4 | W26: 4 | X26: 4 | Y26: 4 | Z26: 4 | AA26: 4 | AB26: 4 | AC26: 4 | AD26: 4 | AE26: 4 | AF26: 4 | AG26: 4 | AJ26: 2017.05.18 | AK26: 2920000 | AM26: 18년 7월 창원사무소 창고이관(김중경차장 수출관련분) | AN26: 소분판매 추진 / 유통기한 폐기 문제 | AO26: 소분판매 추진 / 유통기한 폐기 문제 | AP26: 소분판매 추진 / 유통기한 폐기 문제 | AQ26: 소분판매 추진 / 유통기한 폐기 문제 | AR26: 소분판매 추진 / 유통기한 폐기 문제 | AS26: 소분판매 추진 / 유통기한 폐기 문제 | AT26: 소분판매 추진 / 유통기한 폐기 문제 | AU26: 소분판매 추진 / 유통기한 폐기 문제 | AV26: 소분판매 추진 / 유통기한 폐기 문제 | AW26: 유통기한 폐기 문제 | AX26: 소분판매 추진 / 유통기한 폐기 문제 | AY26: 소분판매 추진 / 유통기한 폐기 문제 | AZ26: 소분판매 추진 / 유통기한 폐기 문제 | BA26: 소분판매 추진 / 유통기한 폐기 문제 | BB26: 소분판매 추진 / 유통기한 폐기 문제 | BC26: 소분판매 추진 / 유통기한 폐기 문제 | BD26: 소분판매 추진 / 유통기한 폐기 문제 | BE26: 소분판매 추진 / 유통기한 폐기 문제 | BF26: 소분판매 추진 / 유통기한 폐기 문제 | BG26: 소분판매 추진 / 유통기한 폐기 문제 | BH26: 소분판매 추진 / 유통기한 폐기 문제 | BI26: 소분판매 추진 / 유통기한 폐기 문제 | BJ26: 소분판매 추진 / 유통기한 폐기 문제 | BK26: 소분판매 추진 / 유통기한 폐기 문제 | BL26: 소분판매 추진 / 유통기한 폐기 문제 | BM26: 소분판매 추진 / 유통기한 폐기 문제 | BN26: 소분판매 추진 / 유통기한 폐기 문제 | BO26: 소분판매 추진 / 유통기한 폐기 문제 | BP26: 소분판매 추진 / 유통기한 폐기 문제
C27: Renolit G7 FG1 | D27: PL | E27: 6 | F27: 6 | G27: 6 | H27: 6 | I27: 6 | J27: 6 | K27: 6 | L27: 6 | M27: 6 | N27: 6 | O27: 6 | P27: 6 | Q27: 6 | R27: 6 | S27: 6 | T27: 6 | U27: 6 | V27: 6 | W27: 6 | X27: 6 | Y27: 6 | Z27: 6 | AA27: 6 | AB27: 6 | AC27: 6 | AD27: 6 | AE27: 6 | AF27: 6 | AG27: 6 | AJ27: 2017.05.18 | AK27: 342500 | AM27: 18년 7월 창원사무소 창고이관(김중경차장 수출관련분) | AN27: 유통기한 폐기 문제 | AO27: 유통기한 폐기 문제 | AP27: 유통기한 폐기 문제 | AQ27: 유통기한 폐기 문제 | AR27: 유통기한 폐기 문제 | AS27: 유통기한 폐기 문제 | AT27: 유통기한 폐기 문제 | AU27: 유통기한 폐기 문제 | AV27: 유통기한 폐기 문제 | AW27: 사용처 구매시점확인-판매추진-이승복 | AX27: 유통기한 폐기 문제 | AY27: 유통기한 폐기 문제 | AZ27: 유통기한 폐기 문제 | BA27: 유통기한 폐기 문제 | BB27: 유통기한 폐기 문제 | BC27: 유통기한 폐기 문제 | BD27: 유통기한 폐기 문제 | BE27: 유통기한 폐기 문제 | BF27: 유통기한 폐기 문제 | BG27: 유통기한 폐기 문제 | BH27: 유통기한 폐기 문제 | BI27: 유통기한 폐기 문제 | BJ27: 유통기한 폐기 문제 | BK27: 유통기한 폐기 문제 | BL27: 유통기한 폐기 문제 | BM27: 유통기한 폐기 문제 | BN27: 유통기한 폐기 문제 | BO27: 유통기한 폐기 문제 | BP27: 유통기한 폐기 문제
C28: CRC Food Grade Machine Oil-11oz [0.31/1] | D28: BOX | E28: 11 | F28: 11 | G28: 11 | H28: 11 | I28: 11 | J28: 11 | K28: 11 | L28: 11 | M28: 11 | N28: 11 | O28: 11 | P28: 11 | Q28: 11 | R28: 11 | S28: 11 | T28: 11 | U28: 11 | V28: 11 | W28: 11 | X28: 11 | Y28: 11 | Z28: 11 | AA28: 11 | AB28: 11 | AC28: 11 | AD28: 11 | AE28: 11 | AF28: 11 | AG28: 11 | AJ28: 2022.02.18 | AK28: 14000 | AM28: 동아제약(주) 천안공장 출고예정 | AN28: 사용처 구매시점확인-판매추진-이승복 | AO28: 사용처 구매시점확인-판매추진-이승복 | AP28: 사용처 구매시점확인-판매추진-이승복 | AQ28: 사용처 구매시점확인-판매추진-이승복 | AR28: 사용처 구매시점확인-판매추진-이승복 | AS28: 사용처 구매시점확인-판매추진-이승복 | AT28: 사용처 구매시점확인-판매추진-이승복 | AU28: 사용처 구매시점확인-판매추진-이승복 | AV28: 사용처 구매시점확인-판매추진-이승복 | AW28: 티스테이션석수점, 성우자동차정비 판매추진 | AX28: 사용처 구매시점확인-판매추진-이승복 | AY28: 사용처 구매시점확인-판매추진-이승복 | AZ28: 사용처 구매시점확인-판매추진-이승복 | BA28: 사용처 구매시점확인-판매추진-이승복 | BB28: 사용처 구매시점확인-판매추진-이승복 | BC28: 사용처 구매시점확인-판매추진-이승복 | BD28: 사용처 구매시점확인-판매추진-이승복 | BE28: 사용처 구매시점확인-판매추진-이승복 | BF28: 사용처 구매시점확인-판매추진-이승복 | BG28: 사용처 구매시점확인-판매추진-이승복 | BH28: 사용처 구매시점확인-판매추진-이승복 | BI28: 사용처 구매시점확인-판매추진-이승복 | BJ28: 사용처 구매시점확인-판매추진-이승복 | BK28: 사용처 구매시점확인-판매추진-이승복 | BL28: 사용처 구매시점확인-판매추진-이승복 | BM28: 사용처 구매시점확인-판매추진-이승복 | BN28: 사용처 구매시점확인-판매추진-이승복 | BO28: 사용처 구매시점확인-판매추진-이승복 | BP28: 사용처 구매시점확인-판매추진-이승복
C29: METAL CLEAN S | U29: 6 | V29: 6 | W29: 6 | X29: 6 | Y29: 6 | Z29: 6 | AA29: 6 | AB29: 6 | AC29: 6 | AD29: 6 | AE29: 6 | AF29: 6 | AG29: 6 | AM29: 진영정기 | BD29: 제조업체 세정제 판매예정 (김건우과장) | BE29: 제조업체 세정제 판매예정 (김건우과장) | BF29: 제조업체 세정제 판매예정 (김건우과장) | BG29: 제조업체 세정제 판매예정 (김건우과장) | BH29: 제조업체 세정제 판매예정 (김건우과장) | BI29: 제조업체 세정제 판매예정 (김건우과장) | BJ29: 제조업체 세정제 판매예정 (김건우과장) | BK29: 제조업체 세정제 판매예정 (김건우과장) | BL29: 제조업체 세정제 판매예정 (김건우과장) | BM29: 제조업체 세정제 판매예정 (김건우과장) | BN29: 제조업체 세정제 판매예정 (김건우과장) | BO29: 제조업체 세정제 판매예정 (김건우과장) | BP29: 제조업체 세정제 판매예정 (김건우과장)
E30: =SUM(E4:E29) -> 249 | F30: =SUM(F4:F29) -> 184 | G30: =SUM(G4:G29) -> 163 | H30: =SUM(H4:H29) -> 145 | I30: =SUM(I4:I29) -> 114 | J30: =SUM(J4:J29) -> 109 | K30: =SUM(K4:K29) -> 109 | L30: =SUM(L4:L29) -> 109 | ... AL30: =SUM(AL4:AL29) -> 0

Sheet 창원
E2: 6월 | F2: 7월 | G2: 8월 | H2: 9월 | I2: 10월 | J2: 11월 | K2: 12월 | L2: 1월 | M2: 2월 | N2: 3월 | O2: 4월 | P2: 5월 | Q2: 6월 | R2: 7월 | S2: 8월 | T2: 9월 | U2: 10월 | V2: 11월 | W2: 12월 | X2: 01월 | Y2: 02월 | Z2: 03월 | AA2: 04월 | AB2: 05월 | AC2: 06월 | AD2: 07월 | AE2: 08월 | AF2: 09월 | AG2: 10월 | BP2: 창원사업소
B3: 구분 | C3: 제품명 | D3: 규격 | E3: 전재고 | F3: 전재고 | G3: 전재고 | H3: 전재고 | I3: 전재고 | J3: 전재고 | K3: 전재고 | L3: 전재고 | M3: 전재고 | N3: 전재고 | O3: 전재고 | P3: 현재고 | Q3: 현재고 | R3: 현재고 | S3: 현재고 | T3: 현재고 | U3: 현재고 | V3: 현재고 | W3: 현재고 | X3: 현재고 | Y3: 현재고 | Z3: 현재고 | AA3: 현재고 | AB3: 현재고 | AC3: 현재고 | AD3: 현재고 | AE3: 현재고 | AF3: 현재고 | AG3: 현재고 | AH3: 제조일자 | AJ3: 최종 구매일 | AK3: 구매단가 | AL3: 최종 판매일 | AM3: 비고 | AN3: 6월 처리방안 | AO3: 7월 처리방안 | AP3: 8월 처리방안 | AQ3: 9월 처리방안 | AR3: 10월 처리방안 | AS3: 11월 처리방안 | AT3: 12월 처리방안 | AU3: 1월 처리방안 | AV3: 2월 처리방안 | AW3: 3월 처리방안 | AX3: 4월 처리방안 | AY3: 5월 처리방안 | AZ3: 6월 처리방안 | BA3: 7월 처리방안 | BB3: 8월 처리방안 | BC3: 9월 처리방안 | BD3: 10월 처리방안 | BE3: 11월 처리방안 | BF3: 12월 처리방안 | BG3: 01월 처리방안 | BH3: 02월 처리방안 | BI3: 03월 처리방안 | BJ3: 04월 처리방안 | BK3: 05월 처리방안 | BL3: 06월 처리방안 | BM3: 07월 처리방안 | BN3: 08월 처리방안 | BO3: 09월 처리방안 | BP3: 10월 처리방안
B4: IL | C4: MOBIL DTE 10 EXCEL 100 | D4: DM | E4: 27 | F4: 0 | AH4: 21 | AI4: 2022.05.26 | AJ4: 2022.06.29 | AK4: 506000 | AL4: 2023.04.21 | AM4: 무림페이퍼 특가 인상전 재고 확보 | AN4: 무림페이퍼 발주 시 출고 예정 | AO4: 출고 완료
AH5: 6 | AI5: 2022.06.23
C6: MOBIL HYDRAULIC AW 68 | D6: PL | E6: 56 | F6: 14 | G6: 0 | H6: 0 | I6: 0 | J6: 0 | K6: 0 | L6: 0 | M6: 0 | N6: 0 | O6: 0 | AH6: 42 | AI6: 2022.10.11 | AJ6: 2022.12.21 | AK6: 37600 | AL6: 2023.05.19 | AM6: 단가인상 우려로 다량매입 | AN6: 심팩 지속적으로 공급되는 제품 | AO6: 심팩 지속적으로 공급되는 제품 | AP6: 판매완료 | AQ6: 판매완료 | AR6: 판매완료 | AS6: 판매완료 | AT6: 판매완료 | AU6: 판매완료 | AV6: 판매완료 | AW6: 판매완료 | AX6: 판매완료 | AY6: 판매완료 | AZ6: 판매완료 | BA6: 판매완료 | BB6: 판매완료 | BC6: 판매완료 | BD6: 판매완료 | BE6: 판매완료 | BF6: 판매완료 | BG6: 판매완료 | BH6: 판매완료 | BI6: 판매완료 | BJ6: 판매완료 | BK6: 판매완료 | BL6: 판매완료 | BM6: 판매완료 | BN6: 판매완료 | BO6: 판매완료 | BP6: 판매완료
AH7: 14 | AI7: 2022.12.13
C8: MOBIL CUT 250 | D8: PL | E8: 8 | F8: 8 | G8: 8 | H8: 8 | I8: 8 | J8: 8 | K8: 8 | L8: 8 | M8: 8 | N8: 8 | O8: 8 | P8: 0 | Q8: 0 | R8: 0 | S8: 0 | T8: 0 | U8: 0 | V8: 0 | W8: 0 | X8: 0 | Y8: 0 | Z8: 0 | AA8: 0 | AB8: 0 | AC8: 0 | AD8: 0 | AE8: 0 | AF8: 0 | AG8: 0 | AH8: 1 | AI8: 2020.05.20 | AJ8: 2022.05.10 | AK8: 123726 | AL8: 2022.06.28 | AM8: 중앙 인수, 거래처 제품변경으로 판매중단 | AN8: 폐기 처분 | AO8: 폐기 처분 | AP8: 폐기 처분 | AQ8: 폐기 처분 | AR8: 폐기 처분 | AS8: 폐기 처분 | AT8: 폐기 처분 | AU8: 폐기 처분 | AV8: 폐기 처분 | AW8: 폐기 처분 | AX8: 폐기 처분 | AY8: 폐기 처분 | AZ8: 폐기 처분 | BA8: 5/31 불량 폐기처분 | BB8: 5/31 불량 폐기처분 | BC8: 5/31 불량 폐기처분 | BD8: 5/31 불량 폐기처분 | BE8: 5/31 불량 폐기처분 | BF8: 5/31 불량 폐기처분 | BG8: 5/31 불량 폐기처분 | BH8: 5/31 불량 폐기처분 | BI8: 5/31 불량 폐기처분 | BJ8: 5/31 불량 폐기처분 | BK8: 5/31 불량 폐기처분 | BL8: 5/31 불량 폐기처분 | BM8: 5/31 불량 폐기처분 | BN8: 5/31 불량 폐기처분 | BO8: 5/31 불량 폐기처분 | BP8: 5/31 불량 폐기처분
AH9: 7 | AI9: 2020.08.07 | AM9: (지속적인 틀밀림 현상으로 인해 제품 변경)
C10: MOBIL CENTAUR XHP 462 | D10: PL | E10: 1 | F10: 1 | G10: 1 | H10: 1 | I10: 1 | J10: 1 | K10: 1 | L10: 1 | M10: 1 | N10: 1 | O10: 1 | P10: 1 | Q10: 1 | R10: 1 | S10: 1 | T10: 1 | U10: 1 | V10: 1 | W10: 1 | X10: 1 | Y10: 1 | Z10: 1 | AA10: 0 | AB10: 0 | AC10: 0 | AD10: 0 | AE10: 0 | AF10: 0 | AG10: 0 | AH10: 1 | AI10: 2020.11.21 | AJ10: 2022.06.09 | AK10: 198000 | AL10: 2022.06.08 | AM10: 세아창원특수강 TEST 용도로 매입 | AN10: 세아창원특수강 TEST 용도로 매입 | AO10: 케이블카업체 판매 예정 | AP10: 케이블카업체 판매 예정 | AQ10: 케이블카업체 판매 예정 | AR10: 케이블카업체 판매 예정 | AS10: 케이블카업체 판매 예정 | AT10: 케이블카업체 판매 예정 | AU10: 케이블카업체 판매 예정 | AV10: 케이블카업체 판매 예정 | AW10: 케이블카업체 판매 예정 | AX10: 케이블카업체 판매 예정 | AY10: 케이블카업체 판매 예정 | AZ10: 케이블카업체 판매 예정 | BA10: 케이블카업체 판매 예정 | BB10: 케이블카업체 판매 예정 | BC10: 케이블카업체 판매 예정 | BD10: 케이블카업체 판매 예정 | BE10: 케이블카업체 판매 예정 | BF10: 케이블카업체 판매 예정 | BG10: 케이블카업체 판매 예정 | BH10: 케이블카업체 판매 예정 | BI10: 케이블카업체 판매 예정 | BJ10: 4/30 고려아연 카트리지로 판매 | BK10: 4/30 고려아연 카트리지로 판매 | BL10: 4/30 고려아연 카트리지로 판매 | BM10: 4/30 고려아연 카트리지로 판매 | BN10: 4/30 고려아연 카트리지로 판매 | BO10: 4/30 고려아연 카트리지로 판매 | BP10: 4/30 고려아연 카트리지로 판매
C11: MOBILUX EP 023 | D11: PL | E11: 28 | F11: 28 | G11: 25 | H11: 25 | I11: 25 | J11: 16 | K11: 15 | L11: 15 | M11: 13 | N11: 11 | O11: 11 | P11: 11 | Q11: 11 | R11: 8 | S11: 8 | T11: 6 | U11: 5 | V11: 5 | W11: 5 | X11: 3 | Y11: 3 | Z11: 0 | AA11: 0 | AB11: 0 | AC11: 0 | AD11: 0 | AE11: 0 | AF11: 0 | AG11: 0 | AH11: 28 | AI11: 2022.08.06 | AJ11: 2022.12.14 | AK11: 81000 | AL11: 2023.03.29 | AN11: 판매 중 | AO11: 판매 중(위아 사용예정) | AP11: 판매 중(위아 사용예정) | AQ11: 판매 중(위아 사용예정) | AR11: 판매 중(위아 사용예정) | AS11: 판매 중(위아 사용예정) | AT11: 판매 중(위아 사용예정) // 12/20 진주하우톤-1PL 납품 | AU11: 판매 중(위아 사용예정) | AV11: 2/29 제일윤활유 2말 납품완료 | AW11: 3/21 금세기 판매완료 | AX11: 판매 중(위아 사용예정) | AY11: 판매 중(위아 사용예정) | AZ11: 판매 중(위아 사용예정) | BA11: 판매 중(위아 사용예정) | BB11: 판매 중(위아 사용예정) | BC11: 판매 중(위아 사용예정) | BD11: 판매 중(위아 사용예정) | BE11: 판매 중(위아 사용예정) | BF11: 판매 중(위아 사용예정) | BG11: 판매 중(위아 사용예정), 1/26 제일윤활유상사 판매 | BH11: 판매 중(위아 사용예정) | BI11: 판매완료 | BJ11: 판매완료 | BK11: 판매완료 | BL11: 판매완료 | BM11: 판매완료 | BN11: 판매완료 | BO11: 판매완료 | BP11: 판매완료
C12: MOBIL SHC CIBUS 220 | D12: PL | E12: 1 | F12: 0 | AH12: 1 | AI12: 2021.02 | AJ12: 2022.05.10 | AK12: 288000 | AM12: 중앙 인수(삼성전기 판매제품) | AN12: 화성사무소 이동 예정 | AO12: 6/26 화성사무소 이관 후, 출고완료
C13: MOBIL VACUO 537 | D13: PL | E13: 1 | F13: 0 | AH13: 1 | AI13: 2021.07.27 | AJ13: 2022.06.09 | AK13: 89700 | AN13: 부산사업소 판매 예정 | AO13: 부산사무소 이관 후, 출고완료
C14: MOBILUX EP 0(15KG) | D14: PL | E14: 1 | F14: 0 | AH14: 1 | AI14: 2020.02.21 | AJ14: 2020.09.09 | AK14: 43900 | AL14: 2021.01.11 | AM14: 단종 후 16KG 변경 | AN14: 딜러 통해 판매예정 | AO14: 8/8 출고완료
C15: MOBILUX EP 1(15KG) | D15: PL | E15: 2 | F15: 0 | AH15: 2 | AI15: 2019.12.27 | AJ15: 2020.07.09 | AK15: 54600 | AL15: 2020.12.23 | AM15: 단종 후 16KG 변경 | AN15: 딜러 통해 판매예정 | AO15: 8/8 출고완료
C16: MOBIL PEGASUS 805 | D16: DM | E16: 7 | F16: 7 | G16: 7 | H16: 7 | I16: 7 | J16: 5 | K16: 1 | L16: 1 | M16: 1 | N16: 1 | O16: 0 | AH16: 6 | AI16: 2021.12.30 | AJ16: 2022.01.12 | AK16: 531000 | AL16: 2022.04.28 | AN16: 신일기술 판매예정 | AO16: 신일기술 판매예정-정현우부장 | AP16: 신일기술 판매예정-정현우부장 | AQ16: 신일기술 판매예정-정현우부장 | AR16: 신일기술 판매예정-정현우부장 | AS16: 신일기술 판매예정-정현우부장 | AT16: 신일기술 판매예정 // 12/15 신일기술-4DM 납품 | AU16: 신일기술 판매예정 | AV16: 신일기술 판매예정 | AW16: 신일기술 판매완료
AH17: 1 | AI17: 2021.03.03
B18: AL | C18: M DV LEGEND 1340 | D18: DM | E18: 4 | F18: 0 | AH18: 4 | AI18: 2021.09.13 | AJ18: 2021.09.15 | AK18: 512000 | AL18: 2021.09.17 | AO18: 출고 완료 | AP18: 출고 완료
B19: 기타 | C19: KIXX RD Z 32 | D19: PL | E19: 7 | F19: 5 | G19: 5 | H19: 5 | I19: 5 | J19: 5 | K19: 5 | L19: 5 | M19: 5 | N19: 5 | O19: 5 | P19: 5 | Q19: 5 | R19: 5 | S19: 5 | T19: 5 | U19: 5 | V19: 5 | W19: 5 | X19: 5 | Y19: 5 | Z19: 5 | AA19: 5 | AB19: 5 | AC19: 5 | AD19: 5 | AE19: 5 | AF19: 5 | AG19: 5 | AH19: 7 | AI19: 2022.04.20 | AJ19: 2022.10.17 | AK19: 71000 | AN19: 딜러 통해 판매예정 | AO19: 딜러 통해 판매예정 | AP19: 딜러 통해 판매예정 | AQ19: 딜러 통해 판매예정 | AR19: 딜러 통해 판매예정 | AS19: 딜러 통해 판매예정 | AT19: 딜러 통해 판매예정 | AU19: 딜러 통해 판매예정 | AV19: 딜러 통해 판매예정 | AW19: 딜러 통해 판매예정 | AX19: 딜러 통해 판매예정 | AY19: 딜러 통해 판매예정 | AZ19: 딜러 통해 판매예정 | BA19: 딜러 통해 판매예정 | BB19: 딜러 통해 판매예정 | BC19: 딜러 통해 판매예정 | BD19: 딜러 통해 판매예정 | BE19: 딜러 통해 판매예정 | BF19: 딜러 통해 판매예정 | BG19: 딜러 통해 판매예정 | BH19: 딜러 통해 판매예정 | BI19: 딜러 통해 판매예정 | BJ19: 딜러 통해 판매예정 | BK19: 딜러 통해 판매예정 | BL19: 딜러 통해 판매예정 | BM19: 딜러 통해 판매예정 | BN19: 딜러 통해 판매예정 | BO19: 딜러 통해 판매예정 | BP19: 딜러 통해 판매예정
C20: MOBIL HYJET V(5G)-sp [18.9] | D20: PL | AD20: 5 | AE20: 2 | AF20: 2 | AG20: 2 | AM20: 1PL은 유통기한(24.12)5년 | BN20: 화성이동 2PL, 폐기1PL / 25년 11월 피치항공 사용할수도 있음 | BO20: 25년 11월 피치항공 사용할수도 있음 | BP20: 25년 11월 피치항공 사용할수도 있음
C21: MOBIL NUTO H 68 [20] | D21: PL | AD21: 32 | AE21: 25 | AF21: 24 | AG21: 24 | BN21: 타영업소 협조 요청 (화성판매 7PL) | BO21: 타영업소 협조 요청 (화성판매 1PL) | BP21: 타영업소 협조 요청 (화성판매 1PL)
E22: =SUM(E4:E21) -> 143 | F22: =SUM(F4:F21) -> 63 | G22: =SUM(G6:G21) -> 46 | H22: =SUM(H6:H21) -> 46 | I22: =SUM(I6:I21) -> 46 | J22: =SUM(J6:J21) -> 35 | K22: =SUM(K6:K21) -> 30 | L22: =SUM(L6:L21) -> 30 | M22: =SUM(M6:M21) -> 28 | N22: =SUM(N6:N21) -> 26 | ... AG22: =SUM(AG6:AG21) -> 31 | AH22: =SUM(AH4:AH21) -> 143 | AI22: =SUM(AI4:AI21) -> 2021.02 | AJ22: =SUM(AJ4:AJ21) -> 0 | AK22: =SUM(AK4:AK21) -> 2536526 | AL22: =SUM(AL4:AL21) -> 0

Sheet 부산
E2: 6월 | F2: 7월 | G2: 8월 | P2: 부산사업소
B3: 구분 | C3: 제품명 | D3: 규격 | E3: 전재고 | F3: 전재고 | G3: 현재고 | H3: 제조일자 | J3: 최종 구매일 | K3: 구매단가 | L3: 최종 판매일 | M3: 비고 | N3: 6월 처리방안 | O3: 7월 처리방안 | P3: 8월 처리방안
B4: IL | C4: MOBILUX EP 3 | D4: PL | E4: 6 | F4: 0 | H4: 3 | I4: 2021.08.05 | J4: 2022.08.17 | K4: 81000 | L4: 2023.05.17 | N4: 간혹 창원 사업소에서 사용하니 필요시 창고이동 | O4: 창원으로 이관 후, 출고예정
H5: 3 | I5: 2021.06.02
C6: MOBIL NUTO H 68 | D6: DM | E6: 4 | F6: 0 | H6: 2 | I6: 2020.05.19 | J6: 2020.05.28 | K6: 305000 | L6: 2019.12.31 | M6: HYD AW 출시이후로 단가차이로 미출 | O6: 화성으로 이관 후, 이화다이케스팅 출고예정
H7: 2 | I7: 2020.01.30
C8: MOBIL HYDRAULIC AW 32 | D8: DM | E8: 3 | F8: 0 | H8: 2 | I8: 2021.01.18 | J8: 2022.06.21 | K8: 371000 | L8: 2023.05.22 | N8: 삼경O&T 출고시 처리 | O8: 창원으로 이관 후, 출고완료
H9: 1 | I9: 2021.10.18
C10: MOBIL GREASE XHP 222 SPECIAL | D10: PL | E10: 1 | F10: 0 | H10: 1 | I10: 2022.06.07 | J10: 2022.12.19 | K10: 180000 | L10: 2022.12.21 | M10: 대성윤활유에 보관중, 판매예정 | O10: 화성으로 이관 후, 출고완료
E11: =SUM(E4:E10) -> 14 | F11: =SUM(F4:F10) -> 0

Sheet 동부
E2: 6월 | F2: 7월 | G2: 8월 | H2: 9월 | I2: 10월 | J2: 11월 | K2: 12월 | L2: 1월 | M2: 2월 | N2: 3월 | O2: 4월 | P2: 5월 | Q2: 6월 | R2: 7월 | S2: 8월 | T2: 9월 | U2: 10월 | V2: 11월 | W2: 12월 | X2: 01월 | Y2: 02월 | Z2: 04월 | AA2: 03월 | AB2: 05월 | AC2: 06월 | AD2: 07월 | AE2: 08월 | AF2: 09월 | AG2: 10월 | AZ2: 동부사업소 | BO2: 동부사업소
B3: 구분 | C3: 제품명 | D3: 규격 | E3: 전재고 | F3: 전재고 | G3: 전재고 | H3: 전재고 | I3: 전재고 | J3: 전재고 | K3: 전재고 | L3: 전재고 | M3: 전재고 | N3: 전재고 | O3: 전재고 | P3: 현재고 | Q3: 현재고 | R3: 현재고 | S3: 현재고 | T3: 현재고 | U3: 현재고 | V3: 현재고 | W3: 현재고 | X3: 현재고 | Y3: 현재고 | Z3: 현재고 | AA3: 현재고 | AB3: 현재고 | AC3: 현재고 | AD3: 현재고 | AE3: 현재고 | AF3: 현재고 | AG3: 현재고 | AH3: 제조일자 | AJ3: 최종 구매일 | AK3: 구매단가 | AL3: 최종 판매일 | AM3: 비고 | AN3: 6월 처리방안 | AO3: 7월 처리방안 | AP3: 8월 처리방안 | AQ3: 9월 처리방안 | AR3: 10월 처리방안 | AS3: 11월 처리방안 | AT3: 12월 처리방안 | AU3: 1월 처리방안 | AV3: 2월 처리방안 | AW3: 3월 처리방안 | AX3: 5월 처리방안 | AY3: 6월 처리방안 | AZ3: 7월 처리방안 | BA3: 8월 처리방안 | BB3: 9월 처리방안 | BC3: 10월 처리방안 | BD3: 11월 처리방안 | BE3: 12월 처리방안 | BF3: 01월 처리방안 | BG3: 02월 처리방안 | BH3: 03월 처리방안 | BI3: 04월 처리방안 | BJ3: 05월 처리방안 | BK3: 06월 처리방안 | BL3: 07월 처리방안 | BM3: 08월 처리방안 | BN3: 09월 처리방안 | BO3: 10월 처리방안
B4: AL | C4: M DV ULTRA 5W-40 UP V1 | D4: PL | E4: 13 | F4: 13 | G4: 13 | H4: 8 | I4: 1 | J4: 1 | K4: 1 | L4: 1 | M4: 1 | N4: 1 | O4: 1 | P4: 1 | Q4: 1 | R4: 1 | S4: 1 | T4: 1 | U4: 1 | V4: 1 | W4: 1 | X4: 1 | Y4: 1 | Z4: 1 | AA4: 1 | AB4: 1 | AC4: 1 | AD4: 1 | AE4: 1 | AF4: 1 | AG4: 1 | AH4: 10 | AI4: 2021.07.16 | AJ4: 2022.06.20 | AK4: 165000 | AL4: 2022.12.05 | AM4: 화성이관->5PL/뉴명인모터스 1PL판매 | AN4: 경기오일 판매 예정 | AO4: 경기오일 판매 예정 | AP4: 경기오일 판매 예정 | AQ4: 경기오일 판매 예정 | AR4: 경기오일 판매 예정 | AS4: 경기오일 판매 예정 | AT4: 경기오일 판매 예정 | AU4: 경기오일 판매 예정 | AV4: 경기오일 판매 예정 | AW4: 경기오일 판매 예정 | AX4: 경기오일 판매 예정 | AY4: 경기오일 판매 예정 | AZ4: 경기오일 판매 예정 | BA4: 경기오일 판매 예정 | BB4: 경기오일 판매 예정 | BC4: 경기오일 판매 예정 | BD4: 경기오일 판매 예정 | BE4: 경기오일 판매 예정 | BF4: 경기오일 판매 예정 | BG4: 경기오일 판매 예정 | BH4: 경기오일 판매 예정 | BI4: 경기오일 판매 예정 | BJ4: 경기오일 판매 예정 | BK4: 경기오일 판매 예정 | BL4: 경기오일 판매 예정 | BM4: 경기오일 판매 예정 | BN4: 경기오일 판매 예정 | BO4: 경기오일 판매 예정
AH5: 3 | AI5: 2021.12.18 | AQ5: 동부 및 화성거래처 판매 | AR5: 화성이관->5PL/뉴명인모터스 2PL판매
C6: M Outboard Plus | D6: EA | E6: 8 | F6: 8 | G6: 8 | H6: 8 | I6: 8 | J6: 8 | K6: 8 | L6: 8 | M6: 8 | N6: 8 | O6: 8 | P6: 8 | Q6: 8 | R6: 8 | S6: 8 | T6: 8 | U6: 8 | V6: 8 | W6: 8 | X6: 8 | Y6: 8 | Z6: 8 | AA6: 8 | AB6: 8 | AC6: 8 | AD6: 8 | AE6: 8 | AF6: 8 | AG6: 8 | AH6: 8 | AI6: 2015.10.24 | AJ6: 2021.01.26 | AK6: =74300/24 -> 3095.8333 | AL6: 2022.12.31 | AM6: 소분판매 | AN6: 소매 판매 예정 | AO6: 소매 판매 예정 | AP6: 소매 판매 예정 | AU6: 소매 판매 예정 | AV6: 소매 판매 예정 | AW6: 소매 판매 예정 | AX6: 소매 판매 예정 | AY6: 소매 판매 예정 | AZ6: 소매 판매 예정 | BA6: 소매 판매 예정 | BB6: 소매 판매 예정 | BC6: 소매 판매 예정 | BD6: 소매 판매 예정 | BE6: 소매 판매 예정 | BF6: 소매 판매 예정 | BG6: 소매 판매 예정 | BH6: 소매 판매 예정 | BI6: 소매 판매 예정 | BJ6: 소매 판매 예정 | BK6: 소매 판매 예정 | BL6: 소매 판매 예정 | BM6: 소매 판매 예정 | BN6: 소매 판매 예정 | BO6: 소매 판매 예정
B7: IL | C7: MOBIL GREASE XHP 222 | D7: DM | E7: 5 | F7: 2 | G7: 2 | H7: 2 | I7: 2 | J7: 0 | K7: 0 | L7: 0 | M7: 0 | N7: 0 | O7: 0 | AH7: 2 | AI7: 2022.06.16 | AJ7: 2022.12.15 | AK7: 1303000 | AL7: 2022.12.27 | AN7: 49상사, 현대오일 사용 제품으로 가격 인상에 따른 재고 확보 | AO7: 49상사, 현대오일 사용 제품으로 가격 인상에 따른 재고 확보 | AP7: 49상사, 현대오일 사용 제품으로 가격 인상에 따른 재고 확보 | AQ7: 49상사, 현대오일 사용 제품으로 가격 인상에 따른 재고 확보 | AR7: 49상사, 현대오일 사용 제품으로 가격 인상에 따른 재고 확보 | AS7: 11/23 오일나라 -> 2드럼 | AT7: 11/23 오일나라 -> 2드럼 | AU7: 11/23 오일나라 -> 2드럼 | AV7: 11/23 오일나라 -> 2드럼 | AW7: 11/23 오일나라 -> 2드럼 | AX7: 11/23 오일나라 -> 2드럼 | AY7: 11/23 오일나라 -> 2드럼 | AZ7: 11/23 오일나라 -> 2드럼 | BA7: 11/23 오일나라 -> 2드럼 | BB7: 11/23 오일나라 -> 2드럼 | BC7: 11/23 오일나라 -> 2드럼 | BD7: 11/23 오일나라 -> 2드럼 | BE7: 11/23 오일나라 -> 2드럼 | BF7: 11/23 오일나라 -> 2드럼 | BG7: 11/23 오일나라 -> 2드럼 | BH7: 11/23 오일나라 -> 2드럼 | BI7: 11/23 오일나라 -> 2드럼 | BJ7: 11/23 오일나라 -> 2드럼 | BK7: 11/23 오일나라 -> 2드럼 | BL7: 11/23 오일나라 -> 2드럼 | BM7: 11/23 오일나라 -> 2드럼 | BN7: 11/23 오일나라 -> 2드럼 | BO7: 11/23 오일나라 -> 2드럼
AH8: 3 | AI8: 2022.11.03 | AO8: 3드럼 화성으로 이관 후, 출고중 | AP8: 3드럼 화성으로 이관 후, 출고중 | AQ8: 3드럼 화성으로 이관 후, 출고완료
B9: 기타 | C9: 극동 브레이크액 | D9: BOX | E9: 2 | F9: 2 | G9: 2 | H9: 2 | I9: 2 | J9: 2 | K9: 2 | L9: 2 | M9: 2 | N9: 2 | O9: 2 | P9: 0 | Q9: 0 | R9: 0 | S9: 0 | T9: 0 | U9: 0 | V9: 0 | W9: 0 | X9: 0 | Y9: 0 | Z9: 0 | AA9: 0 | AB9: 0 | AC9: 0 | AD9: 0 | AE9: 0 | AF9: 0 | AG9: 0 | AH9: 2 | AI9: 2021.02.19 | AJ9: 2021.04.07 | AK9: 43500 | AM9: 서부(인천) → 동부(남양주)이관 | AN9: 23년 9월 이전 판매 예정 | AO9: 23년 9월 이전 판매 예정 | AP9: 23년 9월 이전 판매 예정 | AQ9: 23년 11월 이전 판매 예정 | AR9: 23년 11월 이전 판매 예정 | AS9: 23년 11월 이전 판매 예정 | AT9: 24년 1월 이전 판매 예정 | AU9: 24년 상반기 판매 예정 | AV9: 24년 상반기 판매 예정 | AW9: 24년 상반기 판매 예정 | AX9: 24년 상반기 판매 예정 | AY9: 6/3 애니카오남점판매 - 2BOX | AZ9: 6/3 애니카오남점판매 - 2BOX | BA9: 6/3 애니카오남점판매 - 2BOX | BB9: 6/3 애니카오남점판매 - 2BOX | BC9: 6/3 애니카오남점판매 - 2BOX | BD9: 6/3 애니카오남점판매 - 2BOX | BE9: 6/3 애니카오남점판매 - 2BOX | BF9: 6/3 애니카오남점판매 - 2BOX | BG9: 6/3 애니카오남점판매 - 2BOX | BH9: 6/3 애니카오남점판매 - 2BOX | BI9: 6/3 애니카오남점판매 - 2BOX | BJ9: 6/3 애니카오남점판매 - 2BOX | BK9: 6/3 애니카오남점판매 - 2BOX | BL9: 6/3 애니카오남점판매 - 2BOX | BM9: 6/3 애니카오남점판매 - 2BOX | BN9: 6/3 애니카오남점판매 - 2BOX | BO9: 6/3 애니카오남점판매 - 2BOX
C10: 천미 HIREX EP No.2 | D10: PL | E10: 7 | F10: 6 | G10: 6 | H10: 1 | I10: 1 | J10: 1 | K10: 0 | L10: 0 | M10: 0 | N10: 0 | O10: 0 | AH10: 7 | AI10: 2022.03.16 | AJ10: 2022.07.05 | AK10: 60000 | AL10: 2022.11.08 | AN10: 23년말까지 판매 예정 | AO10: 23년말까지 판매 예정 | AP10: 23년말까지 판매 예정 | AQ10: 23년말까지 판매 예정 | AR10: 23년말까지 판매 예정 | AS10: 23년말까지 판매 예정 | AT10: 12/12 성심중기 판매-1PL | AU10: 12/12 성심중기 판매-1PL | AV10: 12/12 성심중기 판매-1PL | AW10: 12/12 성심중기 판매-1PL | AX10: 12/12 성심중기 판매-1PL | AY10: 12/12 성심중기 판매-1PL | AZ10: 12/12 성심중기 판매-1PL | BA10: 12/12 성심중기 판매-1PL | BB10: 12/12 성심중기 판매-1PL | BC10: 12/12 성심중기 판매-1PL | BD10: 12/12 성심중기 판매-1PL | BE10: 12/12 성심중기 판매-1PL | BF10: 12/12 성심중기 판매-1PL | BG10: 12/12 성심중기 판매-1PL | BH10: 12/12 성심중기 판매-1PL | BI10: 12/12 성심중기 판매-1PL | BJ10: 12/12 성심중기 판매-1PL | BK10: 12/12 성심중기 판매-1PL | BL10: 12/12 성심중기 판매-1PL | BM10: 12/12 성심중기 판매-1PL | BN10: 12/12 성심중기 판매-1PL | BO10: 12/12 성심중기 판매-1PL
C11: 천미 그리스 EP No.000 | D11: PL | E11: 3 | F11: 3 | G11: 3 | H11: 3 | I11: 3 | J11: 3 | K11: 0 | L11: 0 | M11: 0 | N11: 0 | O11: 0 | AH11: 3 | AI11: 2019.11.21 | AJ11: 2022.02.15 | AK11: 45000 | AL11: 2022.02.16 | AN11: 동절기용으로 23년말 판매 예정 | AO11: 동절기용으로 23년말 판매 예정 | AP11: 동절기용으로 23년말 판매 예정 | AQ11: 동절기용으로 23년말 판매 예정 | AR11: 동절기용으로 23년말 판매 예정 | AS11: 동절기용으로 23년말 판매 예정 | AT11: 12/22 광진케미칼에 반품-3PL | AU11: 12/22 광진케미칼에 반품-3PL | AV11: 12/22 광진케미칼에 반품-3PL | AW11: 12/22 광진케미칼에 반품-3PL | AX11: 12/22 광진케미칼에 반품-3PL | AY11: 12/22 광진케미칼에 반품-3PL | AZ11: 12/22 광진케미칼에 반품-3PL | BA11: 12/22 광진케미칼에 반품-3PL | BB11: 12/22 광진케미칼에 반품-3PL | BC11: 12/22 광진케미칼에 반품-3PL | BD11: 12/22 광진케미칼에 반품-3PL | BE11: 12/22 광진케미칼에 반품-3PL | BF11: 12/22 광진케미칼에 반품-3PL | BG11: 12/22 광진케미칼에 반품-3PL | BH11: 12/22 광진케미칼에 반품-3PL | BI11: 12/22 광진케미칼에 반품-3PL | BJ11: 12/22 광진케미칼에 반품-3PL | BK11: 12/22 광진케미칼에 반품-3PL | BL11: 12/22 광진케미칼에 반품-3PL | BM11: 12/22 광진케미칼에 반품-3PL | BN11: 12/22 광진케미칼에 반품-3PL | BO11: 12/22 광진케미칼에 반품-3PL
C12: 천미 그리스 EP No.00 | D12: PL | E12: 3 | F12: 3 | G12: 3 | H12: 3 | I12: 3 | J12: 3 | K12: 0 | L12: 0 | M12: 0 | N12: 0 | O12: 0 | AH12: 1 | AI12: 2020.01.28 | AJ12: 2022.12.14 | AK12: 60000 | AL12: 2022.12.21 | AN12: 동절기용으로 23년말 판매 예정 | AO12: 동절기용으로 23년말 판매 예정 | AP12: 동절기용으로 23년말 판매 예정 | AQ12: 동절기용으로 23년말 판매 예정 | AR12: 동절기용으로 23년말 판매 예정 | AS12: 동절기용으로 23년말 판매 예정 | AT12: 12/22 서이천모터스 판매-3PL | AU12: 12/22 서이천모터스 판매-3PL | AV12: 12/22 서이천모터스 판매-3PL | AW12: 12/22 서이천모터스 판매-3PL | AX12: 12/22 서이천모터스 판매-3PL | AY12: 12/22 서이천모터스 판매-3PL | AZ12: 12/22 서이천모터스 판매-3PL | BA12: 12/22 서이천모터스 판매-3PL | BB12: 12/22 서이천모터스 판매-3PL | BC12: 12/22 서이천모터스 판매-3PL | BD12: 12/22 서이천모터스 판매-3PL | BE12: 12/22 서이천모터스 판매-3PL | BF12: 12/22 서이천모터스 판매-3PL | BG12: 12/22 서이천모터스 판매-3PL | BH12: 12/22 서이천모터스 판매-3PL | BI12: 12/22 서이천모터스 판매-3PL | BJ12: 12/22 서이천모터스 판매-3PL | BK12: 12/22 서이천모터스 판매-3PL | BL12: 12/22 서이천모터스 판매-3PL | BM12: 12/22 서이천모터스 판매-3PL | BN12: 12/22 서이천모터스 판매-3PL | BO12: 12/22 서이천모터스 판매-3PL
AH13: 2 | AI13: 2021.03.29
C14: 현대 프리미엄 가솔린 5W20(05100-00121) | D14: BOX | E14: 15 | F14: 13 | G14: 13 | H14: 12 | I14: 11 | J14: 11 | K14: 11 | L14: 10 | M14: 10 | N14: 10 | O14: 10 | P14: 10 | Q14: 10 | R14: 10 | S14: 10 | T14: 10 | U14: 10 | V14: 7 | W14: 7 | X14: 7 | Y14: 7 | Z14: 7 | AA14: 7 | AB14: 7 | AC14: 7 | AD14: 7 | AE14: 7 | AF14: 7 | AG14: 7 | AH14: 1 | AI14: 2021.07.09 | AJ14: 2022.11.28 | AK14: 42078 | AL14: 2022.12.13 | AN14: 기아 일원점, 규석카 판매 예정 | AO14: 기아 일원점, 규석카 판매 예정 | AP14: 기아 일원점, 규석카 판매 예정 | AQ14: 기아 일원점, 규석카 판매 예정 | AR14: 기아 일원점, 규석카 판매 예정 | AS14: 기아 일원점, 규석카 판매 예정 | AT14: 기아 일원점, 규석카 판매 예정 | AU14: 기아 일원점, 규석카 판매 예정 | AV14: 기아 일원점, 규석카 판매 예정 | AW14: 기아 일원점, 규석카 판매 예정 | AX14: 기아 일원점, 규석카 판매 예정 | AY14: 기아 일원점, 규석카 판매 예정 | AZ14: 기아 일원점, 규석카 판매 예정 | BA14: 기아 일원점, 규석카 판매 예정 | BB14: 기아 일원점, 규석카 판매 예정 | BC14: 기아 일원점, 규석카 판매 예정 | BD14: 기아 일원점, 규석카 판매 예정 | BE14: 기아 일원점, 규석카 판매 예정 | BF14: 기아 일원점, 규석카 판매 예정 | BG14: 기아 일원점, 규석카 판매 예정 | BH14: 기아 일원점, 규석카 판매 예정 | BI14: 기아 일원점, 규석카 판매 예정 | BJ14: 기아 일원점, 규석카 판매 예정 | BK14: 기아 일원점, 규석카 판매 예정 | BL14: 기아 일원점, 규석카 판매 예정 | BM14: 기아 일원점, 규석카 판매 예정 | BN14: 기아 일원점, 규석카 판매 예정 | BO14: 기아 일원점, 규석카 판매 예정
AH15: 3 | AI15: 2021.09.15
AH16: 1 | AI16: 2022.04.20 | AM16: 기아일원점 → 1BOX 판매 | AN16: 기아 일원점, 규석카 판매 예정 | AO16: 기아 일원점, 규석카 판매 예정 | AP16: 기아 일원점, 규석카 판매 예정 | AQ16: 기아 일원점, 규석카 판매 예정 | AR16: 기아 일원점, 규석카 판매 예정 | AS16: 기아 일원점, 규석카 판매 예정 | AT16: 기아 일원점, 규석카 판매 예정 | AU16: 기아 일원점, 규석카 판매 예정 | AV16: 기아 일원점, 규석카 판매 예정 | AW16: 기아 일원점, 규석카 판매 예정 | AX16: 기아 일원점, 규석카 판매 예정 | AY16: 기아 일원점, 규석카 판매 예정 | AZ16: 기아 일원점, 규석카 판매 예정 | BA16: 기아 일원점, 규석카 판매 예정 | BB16: 기아 일원점, 규석카 판매 예정 | BC16: 기아 일원점, 규석카 판매 예정 | BD16: 기아 일원점, 규석카 판매 예정 | BE16: 기아 일원점, 규석카 판매 예정 | BF16: 기아 일원점, 규석카 판매 예정 | BG16: 기아 일원점, 규석카 판매 예정 | BH16: 기아 일원점, 규석카 판매 예정 | BI16: 기아 일원점, 규석카 판매 예정 | BJ16: 기아 일원점, 규석카 판매 예정 | BK16: 기아 일원점, 규석카 판매 예정 | BL16: 기아 일원점, 규석카 판매 예정 | BM16: 기아 일원점, 규석카 판매 예정 | BN16: 기아 일원점, 규석카 판매 예정 | BO16: 기아 일원점, 규석카 판매 예정
AH17: 1 | AI17: 2022.06.24 | AM17: 1/8 기아일원점판매 -1박스 | AR17: 기아일원점 -> 1BOX 판매 | AU17: 1/8 기아 일원점 1 BOX 판매
AH18: 2 | AI18: 2022.08.12 | AM18: 5/13 기아일원점 - 3박스
AH19: 7 | AI19: 2022.09.16
C20: 현대 LSD(02100-00100) | D20: BOX | E20: 4 | F20: 4 | G20: 4 | H20: 4 | I20: 4 | J20: 4 | K20: 4 | L20: 4 | M20: 4 | N20: 4 | O20: 4 | P20: 4 | Q20: 4 | R20: 4 | S20: 4 | T20: 4 | U20: 4 | V20: 4 | W20: 4 | X20: 4 | Y20: 4 | Z20: 4 | AA20: 4 | AB20: 4 | AC20: 4 | AD20: 4 | AE20: 4 | AF20: 4 | AG20: 4 | AH20: 1 | AI20: 2017.01.06 | AJ20: 2018.02.21 | AK20: 63554 | AL20: 2022.04.26 | AM20: 동부구매 → 중부(화성auto) → 동부(남양주)이관 | AN20: 기아 일원점, 규석카 판매 예정 | AO20: 기아 일원점, 규석카 판매 예정 | AP20: 기아 일원점, 규석카 판매 예정 | AQ20: 기아 일원점, 규석카 판매 예정 | AR20: 기아 일원점, 규석카 판매 예정 | AS20: 기아 일원점, 규석카 판매 예정 | AT20: 기아 일원점, 규석카 판매 예정 | AU20: 기아 일원점, 규석카 판매 예정 | AV20: 기아 일원점, 규석카 판매 예정 | AW20: 기아 일원점, 규석카 판매 예정 | AX20: 기아 일원점, 규석카 판매 예정 | AY20: 기아 일원점, 규석카 판매 예정 | AZ20: 기아 일원점, 규석카 판매 예정 | BA20: 기아 일원점, 규석카 판매 예정 | BB20: 기아 일원점, 규석카 판매 예정 | BC20: 기아 일원점, 규석카 판매 예정 | BD20: 기아 일원점, 규석카 판매 예정 | BE20: 기아 일원점, 규석카 판매 예정 | BF20: 기아 일원점, 규석카 판매 예정 | BG20: 기아 일원점, 규석카 판매 예정 | BH20: 기아 일원점, 규석카 판매 예정 | BI20: 기아 일원점, 규석카 판매 예정 | BJ20: 기아 일원점, 규석카 판매 예정 | BK20: 기아 일원점, 규석카 판매 예정 | BL20: 기아 일원점, 규석카 판매 예정 | BM20: 기아 일원점, 규석카 판매 예정 | BN20: 기아 일원점, 규석카 판매 예정 | BO20: 기아 일원점, 규석카 판매 예정
AH21: 1 | AI21: 2017.07.20
AH22: 2 | AI22: 2018.01.16
C23: 현대 초저점도 차세대플러스(05100-00191) | D23: BOX | E23: 4 | F23: 4 | G23: 4 | H23: 4 | I23: 4 | J23: 3 | K23: 3 | L23: 3 | M23: 3 | N23: 3 | O23: 3 | P23: 3 | Q23: 3 | R23: 3 | S23: 3 | T23: 3 | U23: 3 | V23: 3 | W23: 3 | X23: 3 | Y23: 3 | Z23: 3 | AA23: 3 | AB23: 3 | AC23: 3 | AD23: 3 | AE23: 3 | AF23: 3 | AG23: 3 | AH23: 2 | AI23: 2020.11.06 | AJ23: 2022.10.26 | AK23: 85531 | AL23: 2022.09.08 | AM23: 12/1 성수남부 -> 1박스 | AN23: 기아 일원점, 규석카 판매 예정 | AO23: 기아 일원점, 규석카 판매 예정 | AP23: 기아 일원점, 규석카 판매 예정 | AQ23: 기아 일원점, 규석카 판매 예정 | AR23: 기아 일원점, 규석카 판매 예정 | AS23: 기아 일원점, 규석카 판매 예정 | AT23: 기아 일원점, 규석카 판매 예정 | AU23: 기아 일원점, 규석카 판매 예정 | AV23: 기아 일원점, 규석카 판매 예정 | AW23: 기아 일원점, 규석카 판매 예정 | AX23: 기아 일원점, 규석카 판매 예정 | AY23: 기아 일원점, 규석카 판매 예정 | AZ23: 기아 일원점, 규석카 판매 예정 | BA23: 기아 일원점, 규석카 판매 예정 | BB23: 기아 일원점, 규석카 판매 예정 | BC23: 기아 일원점, 규석카 판매 예정 | BD23: 기아 일원점, 규석카 판매 예정 | BE23: 기아 일원점, 규석카 판매 예정 | BF23: 기아 일원점, 규석카 판매 예정 | BG23: 기아 일원점, 규석카 판매 예정 | BH23: 기아 일원점, 규석카 판매 예정 | BI23: 기아 일원점, 규석카 판매 예정 | BJ23: 기아 일원점, 규석카 판매 예정 | BK23: 기아 일원점, 규석카 판매 예정 | BL23: 기아 일원점, 규석카 판매 예정 | BM23: 기아 일원점, 규석카 판매 예정 | BN23: 기아 일원점, 규석카 판매 예정 | BO23: 기아 일원점, 규석카 판매 예정
AH24: 2 | AI24: 2020.12.11 | AS24: 12/1 성수남부 → 1박스
C25: 쌍용 부동액 | D25: BOX | E25: 3 | F25: 2 | G25: 2 | H25: 2 | I25: 2 | J25: 2 | K25: 0 | L25: 0 | M25: 0 | N25: 0 | O25: 0 | AH25: 1 | AI25: 2020.11.10 | AJ25: 2022.07.19 | AK25: 75000 | AL25: 2022.07.01 | AN25: 23년 9월 이전 판매 예정 | AO25: 23년 9월 이전 판매 예정 | AP25: 23년 9월 이전 판매 예정 | AQ25: 23년 11월 이전 판매 예정 | AR25: 23년 11월 이전 판매 예정 | AS25: 23년 11월 이전 판매 예정 | AT25: 12/29 삼정오토테크 판매-3박스 | AU25: 12/29 삼정오토테크 판매-3박스 | AV25: 12/29 삼정오토테크 판매-3박스 | AW25: 12/29 삼정오토테크 판매-3박스 | AX25: 12/29 삼정오토테크 판매-3박스 | AY25: 12/29 삼정오토테크 판매-3박스 | AZ25: 12/29 삼정오토테크 판매-3박스 | BA25: 12/29 삼정오토테크 판매-3박스 | BB25: 12/29 삼정오토테크 판매-3박스 | BC25: 12/29 삼정오토테크 판매-3박스 | BD25: 12/29 삼정오토테크 판매-3박스 | BE25: 12/29 삼정오토테크 판매-3박스 | BF25: 12/29 삼정오토테크 판매-3박스 | BG25: 12/29 삼정오토테크 판매-3박스 | BH25: 12/29 삼정오토테크 판매-3박스 | BI25: 12/29 삼정오토테크 판매-3박스 | BJ25: 12/29 삼정오토테크 판매-3박스 | BK25: 12/29 삼정오토테크 판매-3박스 | BL25: 12/29 삼정오토테크 판매-3박스 | BM25: 12/29 삼정오토테크 판매-3박스 | BN25: 12/29 삼정오토테크 판매-3박스 | BO25: 12/29 삼정오토테크 판매-3박스
AH26: 2 | AI26: 2022.02.10
E27: =SUM(E4:E26) -> 67 | F27: =SUM(F4:F25) -> 60 | G27: =SUM(G4:G26) -> 60 | H27: =SUM(H4:H26) -> 49 | I27: =SUM(I4:I26) -> 41 | J27: =SUM(J4:J26) -> 38 | K27: =SUM(K4:K26) -> 29 | L27: =SUM(L4:L26) -> 28 | M27: =SUM(M4:M26) -> 28 | N27: =SUM(N4:N26) -> 28 | ... AG27: =SUM(AG4:AG26) -> 23

Sheet 서부
E2: 6월 | F2: 7월 | G2: 8월 | H2: 9월 | I2: 10월 | J2: 11월 | K2: 12월 | L2: 1월 | M2: 2월 | N2: 3월 | O2: 4월 | P2: 5월 | Q2: 6월 | R2: 7월 | S2: 8월 | T2: 9월 | U2: 10월 | V2: 11월 | W2: 12월 | X2: 01월 | Y2: 02월 | Z2: 03월 | AA2: 04월 | AB2: 05월 | AC2: 06월 | AD2: 06월 | AE2: 08월 | AF2: 09월 | AG2: 09월 | BE2: 서부사업소 | BO2: 서부사업소
B3: 구분 | C3: 제품명 | D3: 규격 | E3: 전재고 | F3: 전재고 | G3: 전재고 | H3: 전재고 | I3: 전재고 | J3: 전재고 | K3: 전재고 | L3: 전재고 | M3: 전재고 | N3: 전재고 | O3: 전재고 | P3: 현재고 | Q3: 현재고 | R3: 현재고 | S3: 현재고 | T3: 현재고 | U3: 현재고 | V3: 현재고 | W3: 현재고 | X3: 현재고 | Y3: 현재고 | Z3: 현재고 | AA3: 현재고 | AB3: 현재고 | AC3: 현재고 | AD3: 현재고 | AE3: 현재고 | AF3: 현재고 | AG3: 현재고 | AH3: 제조일자 | AJ3: 최종 구매일 | AK3: 구매단가 | AL3: 최종 판매일 | AM3: 비고 | AN3: 6월 처리방안 | AO3: 7월 처리방안 | AP3: 8월 처리방안 | AQ3: 9월 처리방안 | AR3: 10월 처리방안 | AS3: 11월 처리방안 | AT3: 12월 처리방안 | AU3: 1월 처리방안 | AV3: 2월 처리방안 | AW3: 3월 처리방안 | AX3: 5월 처리방안 | AY3: 6월 처리방안 | AZ3: 7월 처리방안 | BA3: 8월 처리방안 | BB3: 9월 처리방안 | BC3: 10월 처리방안 | BD3: 11월 처리방안 | BE3: 12월 처리방안 | BF3: 01월 처리방안 | BG3: 02월 처리방안 | BH3: 03월 처리방안 | BI3: 04월 처리방안 | BJ3: 05월 처리방안 | BK3: 06월 처리방안 | BL3: 07월 처리방안 | BM3: 08월 처리방안 | BN3: 09월 처리방안 | BO3: 10월 처리방안
B4: AL | C4: MOBIL ATF 660-PL20L | D4: PL | E4: 3 | F4: 1 | G4: 1 | H4: 1 | I4: 1 | J4: 0 | K4: 0 | L4: 0 | M4: 0 | N4: 0 | O4: 0 | AH4: 3 | AJ4: 44656 | AK4: 59000 | AL4: 44960 | AM4: 자차사용 | AN4: 자차사용 | AO4: 자차사용 | AP4: 자차사용 | AQ4: 자차사용 | AR4: 자차사용 | AS4: 11/17 2450 자차사용
C5: M DELVAC MX 10W30-CT1L/12 | D5: BOX | E5: 10 | F5: 0 | G5: 0 | H5: 0 | AH5: 10 | AI5: =VLOOKUP(C5,[1]인천!$B:$E,4,0) -> 42297 | AJ5: 2015.11.12 | AK5: 44000 | AM5: [이동] 서부구매 → 화성auto보관 → 서부(인천) | AN5: 흥국상사 납품 예정 | AO5: 6/20 그린자동차 납품
C6: M Super 1000 XE Diesel 5W30-1LX12 | D6: BOX | E6: 5 | F6: 4 | G6: 4 | H6: 4 | I6: 4 | J6: 4 | K6: 4 | L6: 3 | M6: 3 | N6: 2 | O6: 2 | P6: 2 | Q6: 0 | R6: 0 | S6: 0 | T6: 0 | U6: 0 | V6: 0 | W6: 0 | X6: 0 | Y6: 0 | Z6: 0 | AA6: 0 | AB6: 0 | AC6: 0 | AD6: 0 | AE6: 0 | AF6: 0 | AG6: 0 | AH6: 5 | AI6: =VLOOKUP(C6,[1]인천!$B:$E,4,0) -> 43808 | AJ6: 2020.01.30 | AK6: 29970 | AL6: 44670 | AM6: 6/27 7048차량 3캔, 8651차량 7캔, 9313차량 7캔, 0797차량 7캔 | AN6: 흥국상사 납품 예정 | AO6: 1박스 자차사용/ 흥국상사 납품 예정 | AP6: 흥국상사 납품 예정 | AQ6: 흥국상사 납품 예정 | AR6: 흥국상사 납품 예정 | AS6: 흥국상사 납품 예정 | AT6: 흥국상사 납품 예정 | AU6: 자차사용 | AV6: 자차사용 | AW6: 자차사용 3/4 삼일자동차-7캔 지원, 2450차량-2캔, 7048차량-3캔 사용 | AX6: 자차사용 | AY6: 자차사용 | AZ6: 자차사용 | BA6: 자차사용 | BB6: 자차사용 | BC6: 자차사용 | BD6: 자차사용 | BE6: 자차사용 | BF6: 자차사용 | BG6: 자차사용 | BH6: 자차사용 | BI6: 자차사용 | BJ6: 자차사용 | BK6: 자차사용 | BL6: 자차사용 | BM6: 자차사용 | BN6: 자차사용 | BO6: 자차사용
C7: M-DEL MX CITY LOG 10W30-CT1LX12 | D7: BOX | E7: 4 | F7: 2 | G7: 2 | H7: 2 | I7: 2 | J7: 2 | K7: 2 | L7: 1 | M7: 1 | N7: 0 | O7: 0 | AH7: 4 | AI7: =VLOOKUP(C7,[1]인천!$B:$E,4,0) -> 42321 | AJ7: 42326 | AK7: 35200 | AL7: 43840 | AM7: 6/20 그린자동차 2박스 납품, 자차사용 | AN7: 흥국상사 협의 후 납품 | AO7: 6/20 그린자동차 2박스 납품/ 흥국상사 협의 후 납품 | AP7: 흥국상사 협의 후 납품 | AQ7: 흥국상사 협의 후 납품 | AR7: 흥국상사 협의 후 납품 | AS7: 흥국상사 협의 후 납품 | AT7: 흥국상사 협의 후 납품 | AU7: 자차사용 | AV7: 자차사용 | AW7: 자차사용 | AX7: 자차사용 | AY7: 자차사용 | AZ7: 자차사용 | BA7: 자차사용 | BB7: 자차사용 | BC7: 자차사용 | BD7: 자차사용 | BE7: 자차사용 | BF7: 자차사용 | BG7: 자차사용 | BH7: 자차사용 | BI7: 자차사용 | BJ7: 자차사용 | BK7: 자차사용 | BL7: 자차사용 | BM7: 자차사용 | BN7: 자차사용 | BO7: 자차사용
C8: M DELVAC MX ESP K 10W40-CT4LX4 | D8: BOX | E8: 5 | F8: 8 | G8: 8 | H8: 8 | I8: 8 | J8: 8 | K8: 9 | L8: 0 | M8: 0 | N8: 0 | O8: 0 | AH8: 5 | AI8: =VLOOKUP(C8,[1]인천!$B:$E,4,0) -> 44242 | AJ8: 44371 | AK8: 44000 | AL8: 44806 | AM8: 제주→인천으로 포장 발송 - 육지 판매 진행 계획-3BOX 재고 수량 조정, 1/12 성민유통 납품 | AN8: 이스즈 협의 후 납품 | AO8: 7/14 [이동] 제주 → 서부(인천)/ 이스즈 협의 후 납품 | AP8: 이스즈 협의 후 납품 | AQ8: 이스즈 협의 후 납품 | AR8: 이스즈 협의 후 납품 | AS8: 이스즈 협의 후 납품 | AT8: 성민유통 납품 예정 | AU8: 성민유통 납품 예정 | AV8: 성민유통 납품 예정 | AW8: 성민유통 납품 예정 | AX8: 업체 납품 중 | AY8: 업체 납품 중 | AZ8: 업체 납품 중 | BA8: 업체 납품 중 | BB8: 업체 납품 중 | BC8: 업체 납품 중 | BD8: 업체 납품 중 | BE8: 업체 납품 중 | BF8: 업체 납품 중 | BG8: 업체 납품 중 | BH8: 업체 납품 중 | BI8: 업체 납품 중 | BJ8: 업체 납품 중 | BK8: 업체 납품 중 | BL8: 업체 납품 중 | BM8: 업체 납품 중 | BN8: 업체 납품 중 | BO8: 업체 납품 중
C9: MOBIL DELVAC XHP ESP M 10W-40 CT4LX4 | D9: BOX | E9: 1 | F9: 1 | G9: 1 | H9: 1 | I9: 1 | J9: 1 | K9: 1 | L9: 1 | M9: 1 | N9: 1 | O9: 1 | P9: 1 | Q9: 1 | R9: 1 | S9: 1 | T9: 1 | U9: 1 | V9: 1 | W9: 1 | X9: 1 | Y9: 1 | Z9: 1 | AA9: 1 | AB9: 1 | AC9: 1 | AD9: 1 | AE9: 1 | AF9: 1 | AG9: 1 | AH9: 1 | AI9: =VLOOKUP(C9,[1]인천!$B:$E,4,0) -> 43336 | AJ9: 44091 | AK9: 66200 | AL9: 44657 | AN9: 이스즈 협의 후 납품 | AO9: 이스즈 협의 후 납품 | AP9: 이스즈 협의 후 납품 | AQ9: 이스즈 협의 후 납품 | AR9: 이스즈 협의 후 납품 | AS9: 이스즈 협의 후 납품 | AT9: 이스즈 협의 후 납품 | AU9: 자차사용 | AV9: 자차사용 | AW9: 자차사용 | AX9: 자차사용 | AY9: 자차사용 | AZ9: 자차사용 | BA9: 자차사용 | BB9: 자차사용 | BC9: 자차사용 | BD9: 자차사용 | BE9: 자차사용 | BF9: 자차사용 | BG9: 자차사용 | BH9: 자차사용 | BI9: 자차사용 | BJ9: 자차사용 | BK9: 자차사용 | BL9: 자차사용 | BM9: 자차사용 | BN9: 자차사용 | BO9: 자차사용
C10: M Delvac MX 10W30-CT4LX4 | D10: BOX | E10: 3 | F10: 0 | G10: 0 | H10: 0 | L10: #N/A | M10: #N/A | N10: #N/A | O10: #N/A | AH10: 3 | AI10: =VLOOKUP(C10,[1]인천!$B:$E,4,0) -> 43053 | AJ10: 2018.03.06 | AK10: 39500 | AL10: 43549 | AM10: [이동] 화성 → 서부(인천) | AN10: 자차사용 | AO10: 6/20 그린자동차 납품 | AX10: 강화상사 납품 예정 | AY10: 강화상사 납품 예정 | AZ10: 강화상사 납품 예정 | BA10: 강화상사 납품 예정 | BB10: 강화상사 납품 예정 | BC10: 강화상사 납품 예정 | BD10: 강화상사 납품 예정 | BE10: 강화상사 납품 예정 | BF10: 강화상사 납품 예정 | BG10: 강화상사 납품 예정 | BH10: 강화상사 납품 예정 | BI10: 강화상사 납품 예정 | BJ10: 강화상사 납품 예정 | BK10: 강화상사 납품 예정 | BL10: 강화상사 납품 예정 | BM10: 강화상사 납품 예정 | BN10: 강화상사 납품 예정 | BO10: 강화상사 납품 예정
C11: M-DEL MX ADV CITY LOG 5W40-CT6LX3 | D11: BOX | E11: 10 | F11: 0 | G11: 0 | H11: 0 | L11: #N/A | M11: #N/A | N11: #N/A | O11: #N/A | AJ11: 2021.10.14 | AK11: 54500 | AM11: 제주→인천으로 포장 발송 - 육지 판매 진행 계획 | AN11: 6월말 7월초 명성물류 화물 운송 재개시 인천으로 포장 발송 예정 | AO11: 제주→인천으로 포장 발송 - 육지 판매 진행 계획 | AX11: 거래처 납품 예정(안부장님 판매 예정) | AY11: 거래처 납품 예정(안부장님 판매 예정) | AZ11: 거래처 납품 예정(안부장님 판매 예정) | BA11: 거래처 납품 예정(안부장님 판매 예정) | BB11: 거래처 납품 예정(안부장님 판매 예정) | BC11: 거래처 납품 예정(안부장님 판매 예정) | BD11: 거래처 납품 예정(안부장님 판매 예정) | BE11: 거래처 납품 예정(안부장님 판매 예정) | BF11: 거래처 납품 예정(안부장님 판매 예정) | BG11: 거래처 납품 예정(안부장님 판매 예정) | BH11: 거래처 납품 예정(안부장님 판매 예정) | BI11: 거래처 납품 예정(안부장님 판매 예정) | BJ11: 거래처 납품 예정(안부장님 판매 예정) | BK11: 거래처 납품 예정(안부장님 판매 예정) | BL11: 거래처 납품 예정(안부장님 판매 예정) | BM11: 거래처 납품 예정(안부장님 판매 예정) | BN11: 거래처 납품 예정(안부장님 판매 예정) | BO11: 거래처 납품 예정(안부장님 판매 예정)
C12: M DELVAC MX ESP K 10W40-CT4LX4 | D12: BOX | E12: 3 | F12: 0 | G12: 0 | H12: 0 | L12: 0 | M12: 0 | N12: 0 | O12: 0 | AJ12: 2021.01.26 | AK12: 40100 | AL12: 2021.10.27 | AM12: 제주→인천으로 포장 발송 - 육지 판매 진행 계획 | AN12: 6월말 7월초 명성물류 화물 운송 재개시 인천으로 포장 발송 예정 | AO12: 제주→인천으로 포장 발송 - 육지 판매 진행 계획 | AX12: 자차사용 | AY12: 자차사용 | AZ12: 자차사용 | BA12: 자차사용 | BB12: 자차사용 | BC12: 자차사용 | BD12: 자차사용 | BE12: 자차사용 | BF12: 자차사용 | BG12: 자차사용 | BH12: 자차사용 | BI12: 자차사용 | BJ12: 자차사용 | BK12: 자차사용 | BL12: 자차사용 | BM12: 자차사용 | BN12: 자차사용 | BO12: 자차사용
C13: MOBIL SUPER MOTO 10W40 CT1LX12 | D13: BOX | E13: 0 | F13: 0 | G13: 0 | H13: 5 | I13: 5 | J13: 5 | K13: 5 | L13: 5 | M13: 5 | N13: 5 | O13: 5 | P13: 5 | Q13: 1 | R13: 0 | S13: 0 | T13: 0 | U13: 0 | V13: 0 | W13: 0 | X13: 0 | Y13: 0 | Z13: 0 | AA13: 0 | AB13: 0 | AC13: 0 | AD13: 0 | AE13: 0 | AF13: 0 | AG13: 0 | AJ13: 2021.07.29 | AK13: 46500 | AM13: 7/15 만수오일 | AN13: 6월말 7월초 명성물류 화물 운송 재개시 인천으로 포장 발송 예정 | AO13: 제주→인천으로 포장 발송 - 육지 판매 진행 계획 | AQ13: 업체 납품 중 | AR13: 업체 납품 중 | AS13: 업체 납품 중 | AT13: 업체 납품 중 | AU13: 업체 납품 중 | AV13: 업체 납품 중 | AW13: 업체 납품 중 | AX13: 업체 납품중 | AY13: 업체 납품중 | AZ13: 업체 납품중 | BA13: 업체 납품중 | BB13: 업체 납품중 | BC13: 업체 납품중 | BD13: 업체 납품중 | BE13: 업체 납품중 | BF13: 업체 납품중 | BG13: 업체 납품중 | BH13: 업체 납품중 | BI13: 업체 납품중 | BJ13: 업체 납품중 | BK13: 업체 납품중 | BL13: 업체 납품중 | BM13: 업체 납품중 | BN13: 업체 납품중 | BO13: 업체 납품중
C14: M DELVAC MX 15W40 (CI-4)-PL20L | D14: PL | H14: 0 | L14: #N/A | M14: #N/A | N14: #N/A | O14: #N/A | AJ14: 2020.02.18 | AK14: 43380 | AL14: 2021.12.06 | AM14: 제주→인천으로 포장 발송 - 육지 판매 진행 계획 | AN14: 6월말 7월초 명성물류 화물 운송 재개시 인천으로 포장 발송 예정 | AO14: 제주→인천으로 포장 발송 - 육지 판매 진행 계획 | AX14: 그린자동차 납품 예정 | AY14: 그린자동차 납품 예정 | AZ14: 그린자동차 납품 예정 | BA14: 그린자동차 납품 예정 | BB14: 그린자동차 납품 예정 | BC14: 그린자동차 납품 예정 | BD14: 그린자동차 납품 예정 | BE14: 그린자동차 납품 예정 | BF14: 그린자동차 납품 예정 | BG14: 그린자동차 납품 예정 | BH14: 그린자동차 납품 예정 | BI14: 그린자동차 납품 예정 | BJ14: 그린자동차 납품 예정 | BK14: 그린자동차 납품 예정 | BL14: 그린자동차 납품 예정 | BM14: 그린자동차 납품 예정 | BN14: 그린자동차 납품 예정 | BO14: 그린자동차 납품 예정
C15: MOBILUBE GX-A 80W-PL20L | D15: PL | E15: 0 | F15: 0 | G15: 0 | H15: 39 | I15: 39 | J15: 0 | K15: 0 | L15: #N/A | M15: #N/A | N15: #N/A | O15: #N/A | AJ15: 2019.04.30 | AK15: 66150 | AL15: 2019.03.25 | AM15: 제주→인천으로 포장 발송 - 육지 판매 진행 계획-39PL | AN15: 6월말 7월초 명성물류 화물 운송 재개시 인천으로 포장 발송 예정 | AO15: 제주→인천으로 포장 발송 - 육지 판매 진행 계획 | AQ15: 업체 납품 중 | AR15: 업체 납품 중 | AS15: 판매 및 8,11월 남양주 이관 : 33말(판매중), 11/20 오염으로 인한 사용 불가 폐기 : 2말
B16: 기타 | C16: 극동 브레이크액0.8／15 | D16: BOX | E16: 5 | F16: 3 | G16: 3 | H16: 3 | I16: 1 | J16: 1 | K16: 1 | L16: 0 | M16: 0 | N16: 0 | O16: 0 | AH16: 5 | AI16: =VLOOKUP(C16,[1]인천!$B:$E,4,0) -> 44246 | AJ16: 44392 | AK16: 43500 | AL16: 44698 | AM16: 10/6 큐로모터스 1박스, 10/17 한국공항리무진 1박스 납품, 1/24 한국공항리무진 1박스 납품 | AN16: 거래처 상의 후 납품 | AO16: 7/17 주식회사 공항리무진 2박스 납품/ 거래처 상의 후 납품 | AP16: 거래처 상의 후 납품 | AQ16: 거래처 상의 후 납품 | AR16: 10/6 큐로모터스 1박스, 10/17 한국공항리무진 1박스 납품/ 거래처 상의 후 납품 | AS16: 거래처 상의 후 납품 | AT16: 거래처 상의 후 납품 | AU16: 거래처 상의 후 납품 | AV16: 거래처 상의 후 납품 | AW16: 거래처 상의 후 납품 | AX16: 거래처 상의 후 납품 | AY16: 거래처 상의 후 납품 | AZ16: 거래처 상의 후 납품 | BA16: 거래처 상의 후 납품 | BB16: 거래처 상의 후 납품 | BC16: 거래처 상의 후 납품 | BD16: 거래처 상의 후 납품 | BE16: 거래처 상의 후 납품 | BF16: 거래처 상의 후 납품 | BG16: 거래처 상의 후 납품 | BH16: 거래처 상의 후 납품 | BI16: 거래처 상의 후 납품 | BJ16: 거래처 상의 후 납품 | BK16: 거래처 상의 후 납품 | BL16: 거래처 상의 후 납품 | BM16: 거래처 상의 후 납품 | BN16: 거래처 상의 후 납품 | BO16: 거래처 상의 후 납품
C17: 극동 EPG 4-1 | D17: PL | E17: 5 | F17: 5 | G17: 5 | H17: 5 | I17: 5 | J17: 5 | K17: 5 | L17: 0 | M17: 0 | N17: 0 | O17: 0 | AH17: 5 | AJ17: 43872 | AK17: 44000 | AL17: 44784 | AM17: 1/25 인천알앤씨 5박스 납품 | AN17: 거래처 상의 후 납품 | AO17: 거래처 상의 후 납품 | AP17: 거래처 상의 후 납품 | AQ17: 거래처 상의 후 납품 | AR17: 거래처 상의 후 납품 | AS17: 거래처 상의 후 납품 | AT17: 거래처 상의 후 납품 | AU17: 거래처 상의 후 납품 | AV17: 거래처 상의 후 납품 | AW17: 거래처 상의 후 납품 | AX17: 거래처 상의 후 납품 | AY17: 거래처 상의 후 납품 | AZ17: 거래처 상의 후 납품 | BA17: 거래처 상의 후 납품 | BB17: 거래처 상의 후 납품 | BC17: 거래처 상의 후 납품 | BD17: 거래처 상의 후 납품 | BE17: 거래처 상의 후 납품 | BF17: 거래처 상의 후 납품 | BG17: 거래처 상의 후 납품 | BH17: 거래처 상의 후 납품 | BI17: 거래처 상의 후 납품 | BJ17: 거래처 상의 후 납품 | BK17: 거래처 상의 후 납품 | BL17: 거래처 상의 후 납품 | BM17: 거래처 상의 후 납품 | BN17: 거래처 상의 후 납품 | BO17: 거래처 상의 후 납품
C18: 대우 순정 부동액(Red) 2／6 | D18: BOX | E18: 3 | F18: 3 | G18: 3 | H18: 3 | I18: 3 | J18: 3 | K18: 3 | L18: 0 | M18: 0 | N18: 0 | O18: 0 | AH18: 3 | AI18: =VLOOKUP(C18,[1]인천!$B:$E,4,0) -> 43467 | AJ18: 44175 | AK18: 63636.36 | AL18: 44442 | AM18: 1/25 오토존모터스 납품 | AN18: 오토존모터스 납품 예정 | AO18: 오토존모터스 납품 예정 | AP18: 오토존모터스 납품 예정 | AQ18: 오토존모터스 납품 예정 | AR18: 오토존모터스 납품 예정 | AS18: 오토존모터스 납품 예정 | AT18: 오토존모터스 납품 예정 | AU18: 오토존모터스 납품 예정 | AV18: 오토존모터스 납품 예정 | AW18: 오토존모터스 납품 예정 | AX18: 오토존모터스 납품 예정 | AY18: 오토존모터스 납품 예정 | AZ18: 오토존모터스 납품 예정 | BA18: 오토존모터스 납품 예정 | BB18: 오토존모터스 납품 예정 | BC18: 오토존모터스 납품 예정 | BD18: 오토존모터스 납품 예정 | BE18: 오토존모터스 납품 예정 | BF18: 오토존모터스 납품 예정 | BG18: 오토존모터스 납품 예정 | BH18: 오토존모터스 납품 예정 | BI18: 오토존모터스 납품 예정 | BJ18: 오토존모터스 납품 예정 | BK18: 오토존모터스 납품 예정 | BL18: 오토존모터스 납품 예정 | BM18: 오토존모터스 납품 예정 | BN18: 오토존모터스 납품 예정 | BO18: 오토존모터스 납품 예정
C19: 대우 순정 부동액(Blue) 2/6 | D19: BOX | E19: 4 | F19: 4 | G19: 4 | H19: 4 | I19: 4 | J19: 4 | K19: 4 | L19: 0 | M19: 0 | N19: 0 | O19: 0 | AH19: 4 | AI19: =VLOOKUP(C19,[1]인천!$B:$E,4,0) -> 44152 | AJ19: 44175 | AK19: 54545.45 | AL19: 44386 | AM19: 1/25 오토존모터스 납품 | AN19: 오토존모터스 납품 예정 | AO19: 오토존모터스 납품 예정 | AP19: 오토존모터스 납품 예정 | AQ19: 오토존모터스 납품 예정 | AR19: 오토존모터스 납품 예정 | AS19: 오토존모터스 납품 예정 | AT19: 오토존모터스 납품 예정 | AU19: 오토존모터스 납품 예정 | AV19: 오토존모터스 납품 예정 | AW19: 오토존모터스 납품 예정 | AX19: 오토존모터스 납품 예정 | AY19: 오토존모터스 납품 예정 | AZ19: 오토존모터스 납품 예정 | BA19: 오토존모터스 납품 예정 | BB19: 오토존모터스 납품 예정 | BC19: 오토존모터스 납품 예정 | BD19: 오토존모터스 납품 예정 | BE19: 오토존모터스 납품 예정 | BF19: 오토존모터스 납품 예정 | BG19: 오토존모터스 납품 예정 | BH19: 오토존모터스 납품 예정 | BI19: 오토존모터스 납품 예정 | BJ19: 오토존모터스 납품 예정 | BK19: 오토존모터스 납품 예정 | BL19: 오토존모터스 납품 예정 | BM19: 오토존모터스 납품 예정 | BN19: 오토존모터스 납품 예정 | BO19: 오토존모터스 납품 예정
C20: GULF Transyn MF-LV-Green 18L | D20: PL | E20: 2 | F20: 0 | G20: 0 | H20: 0 | L20: #N/A | M20: #N/A | N20: #N/A | O20: #N/A | AH20: 2 | AI20: =VLOOKUP(C20,[1]인천!$B:$E,4,0) -> 44393 | AJ20: 44508 | AK20: 110000 | AL20: 44509 | AN20: 거래처 납품 예정 | AO20: 8/7 신종합 납품
C21: 제니스 RHD 3 | D21: PL | E21: 2 | F21: 2 | G21: 1 | H21: 1 | I21: 1 | J21: 0 | K21: 0 | L21: #N/A | M21: #N/A | N21: #N/A | O21: #N/A | AH21: 2 | AI21: =VLOOKUP(C21,[1]인천!$B:$E,4,0) -> 42971 | AJ21: 43056 | AK21: 50000 | AL21: 43112 | AN21: 형제타이어 납품 예정 | AO21: 형제타이어 납품 예정 | AP21: 8/17 동신운수 1말납품, 형제타이어 납품 예정 | AQ21: 형제타이어 납품 예정 | AR21: 형제타이어 납품 예정 | AS21: 11/20 오염으로 인한 사용 불가 폐기 : 1말
C22: 극동EPG 000 | D22: PL | E22: 5 | F22: 4 | G22: 4 | H22: 4 | I22: 4 | J22: 4 | K22: 4 | L22: 2 | M22: 2 | N22: 2 | O22: 2 | P22: 2 | Q22: 2 | R22: 2 | S22: 2 | T22: 2 | U22: 2 | V22: 2 | W22: 2 | X22: 2 | Y22: 2 | Z22: 2 | AA22: 2 | AB22: 2 | AC22: 2 | AD22: 2 | AE22: 2 | AF22: 2 | AG22: 2 | AH22: 5 | AI22: =VLOOKUP(C22,[1]인천!$B:$E,4,0) -> 43393 | AJ22: 43440 | AK22: 38000 | AL22: 44166 | AN22: 거래처 상의 후 납품 | AO22: 7/18 대진자동차공업사 1말 납품/ 거래처 상의 후 납품 | AP22: 거래처 상의 후 납품 | AQ22: 거래처 상의 후 납품 | AR22: 거래처 상의 후 납품 | AS22: 거래처 상의 후 납품 | AT22: 거래처 상의 후 납품 | AU22: 거래처 상의 후 납품 | AV22: 거래처 상의 후 납품 | AW22: 거래처 상의 후 납품 | AX22: 거래처 상의 후 납품 | AY22: 거래처 상의 후 납품 | AZ22: 거래처 상의 후 납품 | BA22: 거래처 상의 후 납품 | BB22: 거래처 상의 후 납품 | BC22: 거래처 상의 후 납품 | BD22: 거래처 상의 후 납품 | BE22: 거래처 상의 후 납품 | BF22: 거래처 상의 후 납품 | BG22: 거래처 상의 후 납품 | BH22: 거래처 상의 후 납품 | BI22: 거래처 상의 후 납품 | BJ22: 거래처 상의 후 납품 | BK22: 거래처 상의 후 납품 | BL22: 거래처 상의 후 납품 | BM22: 거래처 상의 후 납품 | BN22: 거래처 상의 후 납품 | BO22: 거래처 상의 후 납품
C23: DEL. SYN GEAR LS 75W90 | D23: PL | E23: 6 | F23: 6 | G23: 6 | H23: 6 | I23: 6 | J23: 0 | K23: 0 | L23: #N/A | M23: #N/A | N23: #N/A | O23: #N/A | AH23: 6 | AM23: [이동] 화성auto보관 → 서부(인천)/ 12년~구매이력없음 | AN23: 폐기 | AO23: 폐기 | AP23: 폐기 | AQ23: 폐기 | AR23: 폐기 | AS23: 11/22 창원 이관 : 2말(자가사용완료), 11/23 인천차량 뒷대우 오일교환 : 4말
C24: VECTON 15W/40-20L | D24: PL | E24: 2 | F24: 2 | G24: 2 | H24: 2 | I24: 2 | J24: 0 | K24: 0 | L24: #N/A | M24: #N/A | N24: #N/A | O24: #N/A | AH24: 2 | AI24: =VLOOKUP(C24,[1]인천!$B:$E,4,0) -> 44340 | AJ24: 44599 | AK24: 60000 | AL24: 44587 | AN24: 강화상사 납품 예정 | AO24: 강화상사 납품 예정 | AP24: 강화상사 납품 예정 | AQ24: 강화상사 납품 예정 | AR24: 강화상사 납품 예정 | AS24: 11/29 강화상사 납품
C25: VECTON 15W/40-4LX3 | D25: BOX | E25: 1 | F25: 1 | G25: 1 | H25: 1 | I25: 1 | J25: 1 | K25: 1 | L25: 1 | M25: 1 | N25: 1 | O25: 1 | P25: 1 | Q25: 1 | R25: 1 | S25: 1 | T25: 1 | U25: 1 | V25: 1 | W25: 1 | X25: 1 | Y25: 1 | Z25: 1 | AA25: 1 | AB25: 1 | AC25: 1 | AD25: 1 | AE25: 1 | AF25: 1 | AG25: 1 | AH25: 1 | AI25: =VLOOKUP(C25,[1]인천!$B:$E,4,0) -> 44245 | AJ25: 44384 | AK25: 42000 | AN25: 강화상사 납품 예정 | AO25: 강화상사 납품 예정 | AP25: 강화상사 납품 예정 | AQ25: 강화상사 납품 예정 | AR25: 강화상사 납품 예정 | AS25: 강화상사 납품 예정 | AT25: 강화상사 납품 예정 | AU25: 강화상사 납품 예정 | AV25: 강화상사 납품 예정 | AW25: 강화상사 납품 예정 | AX25: 강화상사 납품 예정 | AY25: 강화상사 납품 예정 | AZ25: 강화상사 납품 예정 | BA25: 강화상사 납품 예정 | BB25: 강화상사 납품 예정 | BC25: 강화상사 납품 예정 | BD25: 강화상사 납품 예정 | BE25: 강화상사 납품 예정 | BF25: 강화상사 납품 예정 | BG25: 강화상사 납품 예정 | BH25: 강화상사 납품 예정 | BI25: 강화상사 납품 예정 | BJ25: 강화상사 납품 예정 | BK25: 강화상사 납품 예정 | BL25: 강화상사 납품 예정 | BM25: 강화상사 납품 예정 | BN25: 강화상사 납품 예정 | BO25: 강화상사 납품 예정
C26: FUCHS TITAN FFL-52529 (DCT)-PL20L | D26: PL | E26: 2 | F26: 2 | G26: 1 | H26: 1 | I26: 1 | J26: 1 | K26: 1 | L26: 1 | M26: 1 | N26: 1 | O26: 1 | P26: 0 | Q26: 0 | R26: 0 | S26: 0 | T26: 0 | U26: 0 | V26: 0 | W26: 0 | X26: 0 | Y26: 0 | Z26: 0 | AA26: 0 | AB26: 0 | AC26: 0 | AD26: 0 | AE26: 0 | AF26: 0 | AG26: 0 | AH26: 2 | AJ26: 44848 | AK26: 235454.55 | AL26: 44767 | AM26: 8/3 소닉모터스 1말 납품 | AN26: 거래처 납품 예정 | AO26: 거래처 납품 예정 | AP26: 8/3 소닉모터스 1말납품, 거래처 납품 예정 | AQ26: 거래처 납품 예정 | AR26: 거래처 납품 예정 | AS26: 거래처 납품 예정 | AT26: 거래처 납품 예정 | AU26: 거래처 납품 예정(안부장님 판매 예정) | AV26: 거래처 납품 예정(안부장님 판매 예정) | AW26: 거래처 납품 예정(안부장님 판매 예정) | AX26: 5/30 K모션 납품 | AY26: 5/30 K모션 납품 | AZ26: 5/30 K모션 납품 | BA26: 5/30 K모션 납품 | BB26: 5/30 K모션 납품 | BC26: 5/30 K모션 납품 | BD26: 5/30 K모션 납품 | BE26: 5/30 K모션 납품 | BF26: 5/30 K모션 납품 | BG26: 5/30 K모션 납품 | BH26: 5/30 K모션 납품 | BI26: 5/30 K모션 납품 | BJ26: 5/30 K모션 납품 | BK26: 5/30 K모션 납품 | BL26: 5/30 K모션 납품 | BM26: 5/30 K모션 납품 | BN26: 5/30 K모션 납품 | BO26: 5/30 K모션 납품
C27: GS ARLES 100 | D27: PL | E27: 1 | F27: 1 | G27: 1 | H27: 1 | I27: 1 | J27: 0 | K27: 0 | L27: #N/A | M27: #N/A | N27: #N/A | O27: #N/A | AH27: 1 | AI27: =VLOOKUP(C27,[1]인천!$B:$E,4,0) -> 40330 | AN27: 폐기 | AO27: 폐기 | AP27: 폐기 | AQ27: 폐기 | AR27: 폐기 | AS27: 11/20 오염으로 인한 사용 불가 폐기 : 1말
C28: Kixx ATF Multi Plus 20/1 | D28: PL | E28: 1 | F28: 1 | G28: 1 | H28: 1 | I28: 1 | J28: 1 | K28: 1 | L28: 1 | M28: 1 | N28: 1 | O28: 1 | P28: 1 | Q28: 1 | R28: 1 | S28: 1 | T28: 1 | U28: 1 | V28: 1 | W28: 1 | X28: 1 | Y28: 1 | Z28: 1 | AA28: 1 | AB28: 1 | AC28: 1 | AD28: 1 | AE28: 1 | AF28: 1 | AG28: 1 | AH28: 1 | AI28: =VLOOKUP(C28,[1]인천!$B:$E,4,0) -> 44286 | AJ28: 44397 | AK28: 60060 | AL28: 44397 | AN28: 자차사용 | AO28: 자차사용 | AP28: 자차사용 | AQ28: 자차사용 | AR28: 자차사용 | AS28: 자차사용 | AT28: 자차사용 | AU28: 자차사용 | AV28: 자차사용 | AW28: 자차사용 | AX28: 자차사용 | AY28: 자차사용 | AZ28: 자차사용 | BA28: 자차사용 | BB28: 자차사용 | BC28: 자차사용 | BD28: 자차사용 | BE28: 자차사용 | BF28: 자차사용 | BG28: 자차사용 | BH28: 자차사용 | BI28: 자차사용 | BJ28: 자차사용 | BK28: 자차사용 | BL28: 자차사용 | BM28: 자차사용 | BN28: 자차사용 | BO28: 자차사용
C29: 현대 뉴파워 스티어링오일(03100-00100) 1／12 | D29: BOX | E29: 18 | F29: 18 | G29: 18 | H29: 18 | I29: 18 | J29: 0 | K29: 0 | L29: #N/A | M29: #N/A | N29: #N/A | O29: #N/A | AH29: 18 | AI29: =VLOOKUP(C29,[1]인천!$B:$E,4,0) -> 43970 | AJ29: 43973 | AK29: 49236.36 | AL29: 44070 | AN29: 원창윤활유 상의 후 납품 | AO29: 원창윤활유 상의 후 납품 | AP29: 원창윤활유 상의 후 납품 | AQ29: 원창윤활유 상의 후 납품 | AR29: 원창윤활유 상의 후 납품 | AS29: 11/12 남양주 이관 : 12박스, 11/15 화성 이관 : 6박스(판매중)
C30: 현대 자동(04500-00400) | D30: BOX | E30: 2 | F30: 2 | G30: 2 | H30: 2 | I30: 2 | J30: 2 | K30: 2 | L30: 2 | M30: 2 | N30: 2 | O30: 2 | P30: 2 | Q30: 2 | R30: 2 | S30: 2 | T30: 2 | U30: 2 | V30: 2 | W30: 2 | X30: 2 | Y30: 2 | Z30: 2 | AA30: 2 | AB30: 2 | AC30: 2 | AD30: 2 | AE30: 2 | AF30: 2 | AG30: 2 | AH30: 2 | AI30: =VLOOKUP(C30,[1]인천!$B:$E,4,0) -> 44064 | AJ30: 44084 | AK30: 61482 | AL30: 43343 | AN30: 원창윤활유 상의 후 납품 | AO30: 원창윤활유 상의 후 납품 | AP30: 원창윤활유 상의 후 납품 | AQ30: 원창윤활유 상의 후 납품 | AR30: 원창윤활유 상의 후 납품 | AS30: 원창윤활유 상의 후 납품 | AT30: 원창윤활유 상의 후 납품 | AU30: 원창윤활유 상의 후 납품 | AV30: 원창윤활유 상의 후 납품 | AW30: 원창윤활유 상의 후 납품 | AX30: 원창윤활유 상의 후 납품 | AY30: 원창윤활유 상의 후 납품 | AZ30: 원창윤활유 상의 후 납품 | BA30: 원창윤활유 상의 후 납품 | BB30: 원창윤활유 상의 후 납품 | BC30: 원창윤활유 상의 후 납품 | BD30: 원창윤활유 상의 후 납품 | BE30: 원창윤활유 상의 후 납품 | BF30: 원창윤활유 상의 후 납품 | BG30: 원창윤활유 상의 후 납품 | BH30: 원창윤활유 상의 후 납품 | BI30: 원창윤활유 상의 후 납품 | BJ30: 원창윤활유 상의 후 납품 | BK30: 원창윤활유 상의 후 납품 | BL30: 원창윤활유 상의 후 납품 | BM30: 원창윤활유 상의 후 납품 | BN30: 원창윤활유 상의 후 납품 | BO30: 원창윤활유 상의 후 납품
C31: 현대 DPF 1／12 (05200-00120) | D31: BOX | E31: 5 | F31: 4 | G31: 4 | H31: 4 | I31: 4 | J31: 4 | K31: 4 | L31: 0 | M31: 0 | N31: 0 | O31: 0 | AH31: 5 | AJ31: 43973 | AK31: 39389.09 | AL31: 44651 | AM31: 6/27 선경기업 1박스 납품, 1/24 남양주로 창고 이관 | AN31: 원창윤활유 상의 후 납품 | AO31: 6/27 선경기업 1박스 납품/ 원창윤활유 상의 후 납품 | AP31: 원창윤활유 상의 후 납품 | AQ31: 원창윤활유 상의 후 납품 | AR31: 원창윤활유 상의 후 납품 | AS31: 원창윤활유 상의 후 납품 | AT31: 원창윤활유 상의 후 납품 | AU31: 원창윤활유 상의 후 납품 | AV31: 원창윤활유 상의 후 납품 | AW31: 원창윤활유 상의 후 납품 | AX31: 원창윤활유 상의 후 납품 | AY31: 원창윤활유 상의 후 납품 | AZ31: 원창윤활유 상의 후 납품 | BA31: 원창윤활유 상의 후 납품 | BB31: 원창윤활유 상의 후 납품 | BC31: 원창윤활유 상의 후 납품 | BD31: 원창윤활유 상의 후 납품 | BE31: 원창윤활유 상의 후 납품 | BF31: 원창윤활유 상의 후 납품 | BG31: 원창윤활유 상의 후 납품 | BH31: 원창윤활유 상의 후 납품 | BI31: 원창윤활유 상의 후 납품 | BJ31: 원창윤활유 상의 후 납품 | BK31: 원창윤활유 상의 후 납품 | BL31: 원창윤활유 상의 후 납품 | BM31: 원창윤활유 상의 후 납품 | BN31: 원창윤활유 상의 후 납품 | BO31: 원창윤활유 상의 후 납품
C32: 현대 저마찰형 1/12 (05100-00151) | D32: BOX | E32: 1 | F32: 1 | G32: 1 | H32: 1 | I32: 1 | J32: 0 | K32: 0 | L32: #N/A | M32: #N/A | N32: #N/A | O32: #N/A | AH32: 1 | AI32: =VLOOKUP(C32,[1]인천!$B:$E,4,0) -> 42703 | AJ32: 42978 | AK32: 40274 | AL32: 42990 | AM32: [이동] 동부(남양주) → 서부(인천) | AN32: 원창윤활유 상의 후 납품 | AO32: 원창윤활유 상의 후 납품 | AP32: 원창윤활유 상의 후 납품 | AQ32: 원창윤활유 상의 후 납품 | AR32: 원창윤활유 상의 후 납품 | AS32: 11/13 남양주 이관 : 1박스(판매완료)
C33: 현대 최고급 프리미엄 1／12 (05100-00141) | D33: BOX | E33: 1 | F33: 1 | G33: 1 | H33: 1 | I33: 1 | J33: 0 | K33: 0 | L33: #N/A | M33: #N/A | N33: #N/A | O33: #N/A | AH33: 1 | AI33: 2019.10.24 | AJ33: 43802 | AK33: 53530 | AN33: 원창윤활유 상의 후 납품 | AO33: 원창윤활유 상의 후 납품 | AP33: 원창윤활유 상의 후 납품 | AQ33: 원창윤활유 상의 후 납품 | AR33: 원창윤활유 상의 후 납품 | AS33: 11/13 남양주 이관 : 1박스(판매완료)
C34: 현대 중대형 디젤(05200-48BAO) 20/1 | D34: PL | E34: 1 | F34: 1 | G34: 1 | H34: 1 | I34: 1 | J34: 0 | K34: 0 | L34: #N/A | M34: #N/A | N34: #N/A | O34: #N/A | AH34: 1 | AI34: =VLOOKUP(C34,[1]인천!$B:$E,4,0) -> 44028 | AJ34: 44084 | AK34: 48648 | AL34: 42081 | AN34: 강화상사 납품 예정 | AO34: 강화상사 납품 예정 | AP34: 강화상사 납품 예정 | AQ34: 강화상사 납품 예정 | AR34: 강화상사 납품 예정 | AS34: 11/30 그린자동차 납품
