Workbook
Name Currency: #REF!
Name CVL_Syn_Vol_PYTD: #REF!
Name PVL_Vol_Plan: #REF!
Name PVL_Syn_Vol_PYTD: #REF!
Name IL_Vol_YTD_Plan: #REF!
Name PVL_Vol_YTD_Syn: #REF!
Name OperCube: #REF!
Name CVL_Vol_CM_Plan: #REF!
Name PVL_Syn_Vol_CM: #REF!
Name CVL_Real_YTD: #REF!
Name PVL_Vol_YTD: #REF!
Name BA_BS: #REF!
Name CVL_Vol_Plan: #REF!
Name PVL_Vol_CM_Plan: #REF!
Name CVL_Vol_Plan: #REF!
Name PVL_Syn_Vol_YTD: #REF!
Name BusArea: #REF!
Name PVL_Real_YTD: #REF!
Name CVL_Real_CM: #REF!
Name IL_Real_YTD: #REF!
Name Cycle: #REF!
Name CycleYear: #REF!
Name Month: #REF!
Name IL_Syn_Plan: #REF!
Name PVL_Syn_Plan: #REF!
Name cmtPC: #REF!
Name IL_Vol_CM_Plan: #REF!
Name YTDPlan: #REF!
Name BA_AS: #REF!
Name CVL_Syn_Vol_CM: #REF!
Name mhp: #REF!
Name BA_AM: #REF!
Name PVL_Real_PYTD: #REF!
Name ㅏㅏ: #REF!
Name GM: #REF!
Name Earnings: #REF!
Name Tab: #REF!
Name PVL_Syn_Plan: #REF!
Name BA_SP: #REF!
Name CVL_Syn_Vol_CM: #REF!
Name YTDPlan: #REF!
Name cmtBS: #REF!
Name class: #REF!
Name cmtSP: #REF!
Name CmtCube: #REF!
Name IL_Real_YTD_Plan: #REF!
Name CVL_Vol_YTD_Plan: #REF!
Name CVL_Real_Plan: #REF!
Name InflCube: #REF!
Name Opex_YTD: #REF!
Name PVL_Vol_PYTD: #REF!
Name IL_Syn_Vol_YTD: #REF!
Name ActualMonth: #REF!
Name YTDPlan: #REF!
Name CoreCube: #REF!
Name PVL_Vol_CM_Syn: #REF!
Name CVL_Real_YTD_Plan: #REF!
Name Date: #REF!
Name BA_AM: #REF!
Name BA_BS: #REF!

Sheet 사업소별
B2: AUTO 판매 실적 총괄
B3: 단위 : 리터
B4: 구 분 | C4: 2023년 실적 | D4: 2024년 실적 | E4: 2025년 계획 | F4: 증감율 | G4: 누적 | L4: 1월 | Q4: 2월 | V4: 3월 | AA4: 4월 | AF4: 5월 | AK4: 6월 | AP4: 7월 | AU4: 8월 | AZ4: 9월 | BE4: 10월 | BJ4: 11월 | BO4: 12월
G5: 2024년 | H5: 목표 | I5: 2025년 | J5: 달성율 | K5: 증감율 | L5: 2024년 | M5: 목표 | N5: 2025년 | O5: 달성율 | P5: 증감율 | Q5: 2024년 | R5: 목표 | S5: 2025년 | T5: 달성율 | U5: 증감율 | V5: 2024년 | W5: 목표 | X5: 2025년 | Y5: 달성율 | Z5: 증감율 | AA5: 2024년 | AB5: 목표 | AC5: 2025년 | AD5: 달성율 | AE5: 증감율 | AF5: 2024년 | AG5: 목표 | AH5: 2025년 | AI5: 달성율 | AJ5: 증감율 | AK5: 2024년 | AL5: 목표 | AM5: 2025년 | AN5: 달성율 | AO5: 증감율 | AP5: 2024년 | AQ5: 목표 | AR5: 2025년 | AS5: 달성율 | AT5: 증감율 | AU5: 2024년 | AV5: 목표 | AW5: 2025년 | AX5: 달성율 | AY5: 증감율 | AZ5: 2024년 | BA5: 목표 | BB5: 2025년 | BC5: 달성율 | BD5: 증감율 | BE5: 2024년 | BF5: 목표 | BG5: 2025년 | BH5: 달성율 | BI5: 증감율 | BJ5: 2024년 | BK5: 목표 | BL5: 2025년 | BM5: 달성율 | BN5: 증감율 | BO5: 2024년 | BP5: 목표 | BQ5: 2025년 | BR5: 달성율 | BS5: 증감율
B6: 합 계 | C6: =SUM(C7:C12) -> 4859570 | D6: =SUM(D7:D12) -> 5083200 | E6: =SUM(E7:E12) -> 5700000 | F6: =E6/D6-1 -> 0.12134089 | G6: =SUM(G7:G12) -> 4175664 | H6: =SUM(H7:H12) -> 4645500 | I6: =SUM(I7:I12) -> 4446794 | J6: =I6/H6 -> 0.95722613 | K6: =I6/G6-1 -> 0.064930991 | L6: =SUM(L7:L12) -> 328580 | M6: =SUM(M7:M12) -> 399000 | N6: =SUM(N7:N12) -> 346892 | O6: =N6/M6 -> 0.86940351 | P6: =N6/L6-1 -> 0.05573072 | Q6: =SUM(Q7:Q12) -> 346389 | R6: =SUM(R7:R12) -> 456000 | S6: =SUM(S7:S12) -> 429032 | T6: =S6/R6 -> 0.94085965 | U6: =S6/Q6-1 -> 0.23858437 | V6: =SUM(V7:V12) -> 464840 | W6: =SUM(W7:W12) -> 513000 | X6: =SUM(X7:X12) -> 406769 | Y6: =X6/W6 -> 0.79292203 | Z6: =X6/V6-1 -> -0.12492686 | AA6: =SUM(AA7:AA12) -> 455035 | AB6: =SUM(AB7:AB12) -> 456000 | AC6: =SUM(AC7:AC12) -> 471885 | AD6: =AC6/AB6 -> 1.0348355 | AE6: =AC6/AA6-1 -> 0.037030119 | AF6: =SUM(AF7:AF12) -> 396406 | AG6: =SUM(AG7:AG12) -> 456000 | AH6: =SUM(AH7:AH12) -> 485185 | AI6: =AH6/AG6 -> 1.0640022 | AJ6: =AH6/AF6-1 -> 0.22395978 | AK6: =SUM(AK7:AK12) -> 408513 | AL6: =SUM(AL7:AL12) -> 456000 | AM6: =SUM(AM7:AM12) -> 475756 | AN6: =AM6/AL6 -> 1.0433246 | AO6: =AM6/AK6-1 -> 0.16460431 | AP6: =SUM(AP7:AP12) -> 433130 | AQ6: =SUM(AQ7:AQ12) -> 456000 | AR6: =SUM(AR7:AR12) -> 426398 | AS6: =AR6/AQ6 -> 0.93508333 | AT6: =AR6/AP6-1 -> -0.015542678 | AU6: =SUM(AU7:AU12) -> 415086 | AV6: =SUM(AV7:AV12) -> 456000 | AW6: =SUM(AW7:AW12) -> 435464 | AX6: =AW6/AV6 -> 0.95496491 | AY6: =AW6/AU6-1 -> 0.049093441 | AZ6: =SUM(AZ7:AZ12) -> 383982 | BA6: =SUM(BA7:BA12) -> 456000 | BB6: =SUM(BB7:BB12) -> 484749 | BC6: =BB6/BA6 -> 1.0630461 | BD6: =BB6/AZ6-1 -> 0.26242636 | BE6: =SUM(BE7:BE12) -> 543703 | BF6: =SUM(BF7:BF12) -> 541500 | BG6: =SUM(BG7:BG12) -> 484664 | BH6: =BG6/BF6 -> 0.8950397 | BI6: =BG6/BE6-1 -> -0.10858686 | BJ6: =SUM(BJ7:BJ12) -> 0 | BK6: =SUM(BK7:BK12) -> 0 | BL6: =SUM(BL7:BL12) -> 0 | BM6: =BL6/BK6 -> #DIV/0! | BN6: =BL6/BJ6-1 -> #DIV/0! | BO6: =SUM(BO7:BO12) -> 0 | BP6: =SUM(BP7:BP12) -> 0 | BQ6: =SUM(BQ7:BQ12) -> 0 | BR6: =BQ6/BP6 -> #DIV/0! | BS6: =BQ6/BO6-1 -> #DIV/0!
B7: 동부사업소 | C7: =+'담당자별매출'!G24+'담당자별매출'!G31+'담당자별매출'!G79 -> 951869 | D7: =+'담당자별매출'!H24+'담당자별매출'!H31+'담당자별매출'!H79 -> 917387 | E7: =+'담당자별매출'!I24+'담당자별매출'!I31+'담당자별매출'!I79 -> 1070000 | F7: =E7/D7-1 -> 0.16635618 | G7: =+L7+Q7+V7+AA7+AF7+AK7+AP7+AU7+AZ7+BE7+BJ7+BO7 -> 739103 | H7: =+M7+R7+W7+AB7+AG7+AL7+AQ7+AV7+BA7+BF7+BK7+BP7 -> 872050 | I7: =+N7+S7+X7+AC7+AH7+AM7+AR7+AW7+BB7+BG7+BL7+BQ7 -> 786730 | J7: =I7/H7 -> 0.90216157 | K7: =I7/G7-1 -> 0.064438921 | L7: =+'담당자별매출'!P24+'담당자별매출'!P31+'담당자별매출'!P79 -> 62554 | M7: =+'담당자별매출'!Q24+'담당자별매출'!Q31+'담당자별매출'!Q79 -> 74900 | N7: =+'담당자별매출'!R24+'담당자별매출'!R31+'담당자별매출'!R79 -> 64927 | O7: =N7/M7 -> 0.86684913 | P7: =N7/L7-1 -> 0.037935224 | Q7: =+'담당자별매출'!U24+'담당자별매출'!U31+'담당자별매출'!U79 -> 54515 | R7: =+'담당자별매출'!V24+'담당자별매출'!V31+'담당자별매출'!V79 -> 85600 | S7: =+'담당자별매출'!W24+'담당자별매출'!W31+'담당자별매출'!W79 -> 73844 | T7: =S7/R7 -> 0.86266355 | U7: =S7/Q7-1 -> 0.35456296 | V7: =+'담당자별매출'!Z24+'담당자별매출'!Z31+'담당자별매출'!Z79 -> 72083 | W7: =+'담당자별매출'!AA24+'담당자별매출'!AA31+'담당자별매출'!AA79 -> 96300 | X7: =+'담당자별매출'!AB24+'담당자별매출'!AB31+'담당자별매출'!AB79 -> 75223 | Y7: =X7/W7 -> 0.78113188 | Z7: =X7/V7-1 -> 0.043560895 | AA7: =+'담당자별매출'!AE24+'담당자별매출'!AE31+'담당자별매출'!AE79 -> 76678 | AB7: =+'담당자별매출'!AF24+'담당자별매출'!AF31+'담당자별매출'!AF79 -> 85600 | AC7: =+'담당자별매출'!AG24+'담당자별매출'!AG31+'담당자별매출'!AG79 -> 89588 | AD7: =AC7/AB7 -> 1.0465888 | AE7: =AC7/AA7-1 -> 0.16836642 | AF7: =+'담당자별매출'!AJ24+'담당자별매출'!AJ31+'담당자별매출'!AJ79 -> 68103 | AG7: =+'담당자별매출'!AK24+'담당자별매출'!AK31+'담당자별매출'!AK79 -> 85600 | AH7: =+'담당자별매출'!AL24+'담당자별매출'!AL31+'담당자별매출'!AL79 -> 80915 | AI7: =AH7/AG7 -> 0.94526869 | AJ7: =AH7/AF7-1 -> 0.18812681 | AK7: =+'담당자별매출'!AO24+'담당자별매출'!AO31+'담당자별매출'!AO79 -> 71175 | AL7: =+'담당자별매출'!AP24+'담당자별매출'!AP31+'담당자별매출'!AP79 -> 85600 | AM7: =+'담당자별매출'!AQ24+'담당자별매출'!AQ31+'담당자별매출'!AQ79 -> 78297 | AN7: =AM7/AL7 -> 0.91468458 | AO7: =AM7/AK7-1 -> 0.10006322 | AP7: =+'담당자별매출'!AT24+'담당자별매출'!AT31+'담당자별매출'!AT79 -> 70886 | AQ7: =+'담당자별매출'!AU24+'담당자별매출'!AU31+'담당자별매출'!AU79 -> 85600 | AR7: =+'담당자별매출'!AV24+'담당자별매출'!AV31+'담당자별매출'!AV79 -> 82215 | AS7: =AR7/AQ7 -> 0.96045561 | AT7: =AR7/AP7-1 -> 0.15981999 | AU7: =+'담당자별매출'!AY24+'담당자별매출'!AY31+'담당자별매출'!AY79 -> 82313 | AV7: =+'담당자별매출'!AZ24+'담당자별매출'!AZ31+'담당자별매출'!AZ79 -> 85600 | AW7: =+'담당자별매출'!BA24+'담당자별매출'!BA31+'담당자별매출'!BA79 -> 74105 | AX7: =AW7/AV7 -> 0.86571262 | AY7: =AW7/AU7-1 -> -0.099716934 | AZ7: =+'담당자별매출'!BD24+'담당자별매출'!BD31+'담당자별매출'!BD79 -> 75786 | BA7: =+'담당자별매출'!BE24+'담당자별매출'!BE31+'담당자별매출'!BE79 -> 85600 | BB7: =+'담당자별매출'!BF24+'담당자별매출'!BF31+'담당자별매출'!BF79 -> 81391 | BC7: =BB7/BA7 -> 0.95082944 | BD7: =BB7/AZ7-1 -> 0.073958251 | BE7: =+'담당자별매출'!BI24+'담당자별매출'!BI31+'담당자별매출'!BI79 -> 105010 | BF7: =+'담당자별매출'!BJ24+'담당자별매출'!BJ31+'담당자별매출'!BJ79 -> 101650 | BG7: =+'담당자별매출'!BK24+'담당자별매출'!BK31+'담당자별매출'!BK79 -> 86225 | BH7: =BG7/BF7 -> 0.84825381 | BI7: =BG7/BE7-1 -> -0.17888772 | BJ7: =+'담당자별매출'!BN24+'담당자별매출'!BN31+'담당자별매출'!BN79 -> 0 | BK7: =+'담당자별매출'!BO24+'담당자별매출'!BO31+'담당자별매출'!BO79 -> 0 | BL7: =+'담당자별매출'!BP24+'담당자별매출'!BP31+'담당자별매출'!BP79 -> 0 | BM7: =BL7/BK7 -> #DIV/0! | BN7: =BL7/BJ7-1 -> #DIV/0! | BO7: =+'담당자별매출'!BS24+'담당자별매출'!BS31+'담당자별매출'!BS79 -> 0 | BP7: =+'담당자별매출'!BT24+'담당자별매출'!BT31+'담당자별매출'!BT79 -> 0 | BQ7: =+'담당자별매출'!BU24+'담당자별매출'!BU31+'담당자별매출'!BU79 -> 0 | BR7: =BQ7/BP7 -> #DIV/0! | BS7: =BQ7/BO7-1 -> #DIV/0!
B8: 서부사업소 | C8: =+'담당자별매출'!G41+'담당자별매출'!G48+'담당자별매출'!G55+'담당자별매출'!G80 -> 1803807 | D8: =+'담당자별매출'!H41+'담당자별매출'!H48+'담당자별매출'!H55+'담당자별매출'!H80 -> 1975922 | E8: =+'담당자별매출'!I41+'담당자별매출'!I48+'담당자별매출'!I55+'담당자별매출'!I80 -> 2138000 | F8: =E8/D8-1 -> 0.082026517 | G8: =+L8+Q8+V8+AA8+AF8+AK8+AP8+AU8+AZ8+BE8+BJ8+BO8 -> 1635742 | H8: =+M8+R8+W8+AB8+AG8+AL8+AQ8+AV8+BA8+BF8+BK8+BP8 -> 1742470 | I8: =+N8+S8+X8+AC8+AH8+AM8+AR8+AW8+BB8+BG8+BL8+BQ8 -> 1681660 | J8: =I8/H8 -> 0.96510126 | K8: =I8/G8-1 -> 0.028071664 | L8: =+'담당자별매출'!P41+'담당자별매출'!P48+'담당자별매출'!P55+'담당자별매출'!P80 -> 140523 | M8: =+'담당자별매출'!Q41+'담당자별매출'!Q48+'담당자별매출'!Q55+'담당자별매출'!Q80 -> 149660 | N8: =+'담당자별매출'!R41+'담당자별매출'!R48+'담당자별매출'!R55+'담당자별매출'!R80 -> 145603 | O8: =N8/M8 -> 0.97289189 | P8: =N8/L8-1 -> 0.036150666 | Q8: =+'담당자별매출'!U41+'담당자별매출'!U48+'담당자별매출'!U55+'담당자별매출'!U80 -> 125586 | R8: =+'담당자별매출'!V41+'담당자별매출'!V48+'담당자별매출'!V55+'담당자별매출'!V80 -> 171040 | S8: =+'담당자별매출'!W41+'담당자별매출'!W48+'담당자별매출'!W55+'담당자별매출'!W80 -> 162350 | T8: =S8/R8 -> 0.94919317 | U8: =S8/Q8-1 -> 0.29273964 | V8: =+'담당자별매출'!Z41+'담당자별매출'!Z48+'담당자별매출'!Z55+'담당자별매출'!Z80 -> 216352 | W8: =+'담당자별매출'!AA41+'담당자별매출'!AA48+'담당자별매출'!AA55+'담당자별매출'!AA80 -> 192420 | X8: =+'담당자별매출'!AB41+'담당자별매출'!AB48+'담당자별매출'!AB55+'담당자별매출'!AB80 -> 156055 | Y8: =X8/W8 -> 0.81101237 | Z8: =X8/V8-1 -> -0.2786986 | AA8: =+'담당자별매출'!AE41+'담당자별매출'!AE48+'담당자별매출'!AE55+'담당자별매출'!AE80 -> 170586 | AB8: =+'담당자별매출'!AF41+'담당자별매출'!AF48+'담당자별매출'!AF55+'담당자별매출'!AF80 -> 171040 | AC8: =+'담당자별매출'!AG41+'담당자별매출'!AG48+'담당자별매출'!AG55+'담당자별매출'!AG80 -> 177729 | AD8: =AC8/AB8 -> 1.0391078 | AE8: =AC8/AA8-1 -> 0.041873307 | AF8: =+'담당자별매출'!AJ41+'담당자별매출'!AJ48+'담당자별매출'!AJ55+'담당자별매출'!AJ80 -> 150023 | AG8: =+'담당자별매출'!AK41+'담당자별매출'!AK48+'담당자별매출'!AK55+'담당자별매출'!AK80 -> 171040 | AH8: =+'담당자별매출'!AL41+'담당자별매출'!AL48+'담당자별매출'!AL55+'담당자별매출'!AL80 -> 188749 | AI8: =AH8/AG8 -> 1.1035372 | AJ8: =AH8/AF8-1 -> 0.25813375 | AK8: =+'담당자별매출'!AO41+'담당자별매출'!AO48+'담당자별매출'!AO55+'담당자별매출'!AO80 -> 172741 | AL8: =+'담당자별매출'!AP41+'담당자별매출'!AP48+'담당자별매출'!AP55+'담당자별매출'!AP80 -> 171040 | AM8: =+'담당자별매출'!AQ41+'담당자별매출'!AQ48+'담당자별매출'!AQ55+'담당자별매출'!AQ80 -> 183872 | AN8: =AM8/AL8 -> 1.0750234 | AO8: =AM8/AK8-1 -> 0.06443751 | AP8: =+'담당자별매출'!AT41+'담당자별매출'!AT48+'담당자별매출'!AT55+'담당자별매출'!AT80 -> 164075 | AQ8: =+'담당자별매출'!AU41+'담당자별매출'!AU48+'담당자별매출'!AU55+'담당자별매출'!AU80 -> 171040 | AR8: =+'담당자별매출'!AV41+'담당자별매출'!AV48+'담당자별매출'!AV55+'담당자별매출'!AV80 -> 154301 | AS8: =AR8/AQ8 -> 0.902134 | AT8: =AR8/AP8-1 -> -0.059570318 | AU8: =+'담당자별매출'!AY41+'담당자별매출'!AY48+'담당자별매출'!AY55+'담당자별매출'!AY80 -> 156403 | AV8: =+'담당자별매출'!AZ41+'담당자별매출'!AZ48+'담당자별매출'!AZ55+'담당자별매출'!AZ80 -> 171040 | AW8: =+'담당자별매출'!BA41+'담당자별매출'!BA48+'담당자별매출'!BA55+'담당자별매출'!BA80 -> 162934 | AX8: =AW8/AV8 -> 0.95260758 | AY8: =AW8/AU8-1 -> 0.041757511 | AZ8: =+'담당자별매출'!BD41+'담당자별매출'!BD48+'담당자별매출'!BD55+'담당자별매출'!BD80 -> 145011 | BA8: =+'담당자별매출'!BE41+'담당자별매출'!BE48+'담당자별매출'!BE55+'담당자별매출'!BE80 -> 171040 | BB8: =+'담당자별매출'!BF41+'담당자별매출'!BF48+'담당자별매출'!BF55+'담당자별매출'!BF80 -> 182450 | BC8: =BB8/BA8 -> 1.0667095 | BD8: =BB8/AZ8-1 -> 0.25818041 | BE8: =+'담당자별매출'!BI41+'담당자별매출'!BI48+'담당자별매출'!BI55+'담당자별매출'!BI80 -> 194442 | BF8: =+'담당자별매출'!BJ41+'담당자별매출'!BJ48+'담당자별매출'!BJ55+'담당자별매출'!BJ80 -> 203110 | BG8: =+'담당자별매출'!BK41+'담당자별매출'!BK48+'담당자별매출'!BK55+'담당자별매출'!BK80 -> 167617 | BH8: =BG8/BF8 -> 0.82525233 | BI8: =BG8/BE8-1 -> -0.13795888 | BJ8: =+'담당자별매출'!BN41+'담당자별매출'!BN48+'담당자별매출'!BN55+'담당자별매출'!BN80 -> 0 | BK8: =+'담당자별매출'!BO41+'담당자별매출'!BO48+'담당자별매출'!BO55+'담당자별매출'!BO80 -> 0 | BL8: =+'담당자별매출'!BP41+'담당자별매출'!BP48+'담당자별매출'!BP55+'담당자별매출'!BP80 -> 0 | BM8: =BL8/BK8 -> #DIV/0! | BN8: =BL8/BJ8-1 -> #DIV/0! | BO8: =+'담당자별매출'!BS41+'담당자별매출'!BS48+'담당자별매출'!BS55+'담당자별매출'!BS80 -> 0 | BP8: =+'담당자별매출'!BT41+'담당자별매출'!BT48+'담당자별매출'!BT55+'담당자별매출'!BT80 -> 0 | BQ8: =+'담당자별매출'!BU41+'담당자별매출'!BU48+'담당자별매출'!BU55+'담당자별매출'!BU80 -> 0 | BR8: =BQ8/BP8 -> #DIV/0! | BS8: =BQ8/BO8-1 -> #DIV/0!
B9: 중부사업소 | C9: =+'담당자별매출'!G62+'담당자별매출'!G81 -> 580796 | D9: =+'담당자별매출'!H62+'담당자별매출'!H81 -> 659230 | E9: =+'담당자별매출'!I62+'담당자별매출'!I81 -> 742000 | F9: =E9/D9-1 -> 0.12555557 | G9: =+L9+Q9+V9+AA9+AF9+AK9+AP9+AU9+AZ9+BE9+BJ9+BO9 -> 548831 | H9: =+M9+R9+W9+AB9+AG9+AL9+AQ9+AV9+BA9+BF9+BK9+BP9 -> 604730 | I9: =+N9+S9+X9+AC9+AH9+AM9+AR9+AW9+BB9+BG9+BL9+BQ9 -> 589260 | J9: =I9/H9 -> 0.97441834 | K9: =I9/G9-1 -> 0.073663842 | L9: =+'담당자별매출'!P62+'담당자별매출'!P81 -> 44504 | M9: =+'담당자별매출'!Q62+'담당자별매출'!Q81 -> 51940 | N9: =+'담당자별매출'!R62+'담당자별매출'!R81 -> 37972 | O9: =N9/M9 -> 0.73107432 | P9: =N9/L9-1 -> -0.14677332 | Q9: =+'담당자별매출'!U62+'담당자별매출'!U81 -> 38822 | R9: =+'담당자별매출'!V62+'담당자별매출'!V81 -> 59360 | S9: =+'담당자별매출'!W62+'담당자별매출'!W81 -> 50646 | T9: =S9/R9 -> 0.85320081 | U9: =S9/Q9-1 -> 0.30456957 | V9: =+'담당자별매출'!Z62+'담당자별매출'!Z81 -> 52948 | W9: =+'담당자별매출'!AA62+'담당자별매출'!AA81 -> 66780 | X9: =+'담당자별매출'!AB62+'담당자별매출'!AB81 -> 57446 | Y9: =X9/W9 -> 0.86022761 | Z9: =X9/V9-1 -> 0.084951273 | AA9: =+'담당자별매출'!AE62+'담당자별매출'!AE81 -> 68242 | AB9: =+'담당자별매출'!AF62+'담당자별매출'!AF81 -> 59360 | AC9: =+'담당자별매출'!AG62+'담당자별매출'!AG81 -> 69236 | AD9: =AC9/AB9 -> 1.1663747 | AE9: =AC9/AA9-1 -> 0.01456581 | AF9: =+'담당자별매출'!AJ62+'담당자별매출'!AJ81 -> 48019 | AG9: =+'담당자별매출'!AK62+'담당자별매출'!AK81 -> 59360 | AH9: =+'담당자별매출'!AL62+'담당자별매출'!AL81 -> 71879 | AI9: =AH9/AG9 -> 1.2108996 | AJ9: =AH9/AF9-1 -> 0.49688665 | AK9: =+'담당자별매출'!AO62+'담당자별매출'!AO81 -> 51692 | AL9: =+'담당자별매출'!AP62+'담당자별매출'!AP81 -> 59360 | AM9: =+'담당자별매출'!AQ62+'담당자별매출'!AQ81 -> 53103 | AN9: =AM9/AL9 -> 0.89459232 | AO9: =AM9/AK9-1 -> 0.027296293 | AP9: =+'담당자별매출'!AT62+'담당자별매출'!AT81 -> 48326 | AQ9: =+'담당자별매출'!AU62+'담당자별매출'!AU81 -> 59360 | AR9: =+'담당자별매출'!AV62+'담당자별매출'!AV81 -> 55420 | AS9: =AR9/AQ9 -> 0.93362534 | AT9: =AR9/AP9-1 -> 0.14679469 | AU9: =+'담당자별매출'!AY62+'담당자별매출'!AY81 -> 56316 | AV9: =+'담당자별매출'!AZ62+'담당자별매출'!AZ81 -> 59360 | AW9: =+'담당자별매출'!BA62+'담당자별매출'!BA81 -> 49476 | AX9: =AW9/AV9 -> 0.83349057 | AY9: =AW9/AU9-1 -> -0.12145749 | AZ9: =+'담당자별매출'!BD62+'담당자별매출'!BD81 -> 55434 | BA9: =+'담당자별매출'!BE62+'담당자별매출'!BE81 -> 59360 | BB9: =+'담당자별매출'!BF62+'담당자별매출'!BF81 -> 67690 | BC9: =BB9/BA9 -> 1.1403302 | BD9: =BB9/AZ9-1 -> 0.22109175 | BE9: =+'담당자별매출'!BI62+'담당자별매출'!BI81 -> 84528 | BF9: =+'담당자별매출'!BJ62+'담당자별매출'!BJ81 -> 70490 | BG9: =+'담당자별매출'!BK62+'담당자별매출'!BK81 -> 76392 | BH9: =BG9/BF9 -> 1.0837282 | BI9: =BG9/BE9-1 -> -0.096252129 | BJ9: =+'담당자별매출'!BN62+'담당자별매출'!BN81 -> 0 | BK9: =+'담당자별매출'!BO62+'담당자별매출'!BO81 -> 0 | BL9: =+'담당자별매출'!BP62+'담당자별매출'!BP81 -> 0 | BM9: =BL9/BK9 -> #DIV/0! | BN9: =BL9/BJ9-1 -> #DIV/0! | BO9: =+'담당자별매출'!BS62+'담당자별매출'!BS81 -> 0 | BP9: =+'담당자별매출'!BT62+'담당자별매출'!BT81 -> 0 | BQ9: =+'담당자별매출'!BU62+'담당자별매출'!BU81 -> 0 | BR9: =BQ9/BP9 -> #DIV/0! | BS9: =BQ9/BO9-1 -> #DIV/0!
B10: 제주사업소 | C10: =+'담당자별매출'!G72 -> 79851 | D10: =+'담당자별매출'!H72 -> 84553 | E10: =+'담당자별매출'!I72 -> 100000 | F10: =E10/D10-1 -> 0.18269015 | G10: =+L10+Q10+V10+AA10+AF10+AK10+AP10+AU10+AZ10+BE10+BJ10+BO10 -> 68997 | H10: =+M10+R10+W10+AB10+AG10+AL10+AQ10+AV10+BA10+BF10+BK10+BP10 -> 81500 | I10: =+N10+S10+X10+AC10+AH10+AM10+AR10+AW10+BB10+BG10+BL10+BQ10 -> 79721 | J10: =I10/H10 -> 0.97817178 | K10: =I10/G10-1 -> 0.15542705 | L10: =+'담당자별매출'!P72 -> 6046 | M10: =+'담당자별매출'!Q72 -> 7000 | N10: =+'담당자별매출'!R72 -> 7984 | O10: =N10/M10 -> 1.1405714 | P10: =N10/L10-1 -> 0.32054251 | Q10: =+'담당자별매출'!U72 -> 6432 | R10: =+'담당자별매출'!V72 -> 8000 | S10: =+'담당자별매출'!W72 -> 8036 | T10: =S10/R10 -> 1.0045 | U10: =S10/Q10-1 -> 0.24937811 | V10: =+'담당자별매출'!Z72 -> 6184 | W10: =+'담당자별매출'!AA72 -> 9000 | X10: =+'담당자별매출'!AB72 -> 9066 | Y10: =X10/W10 -> 1.0073333 | Z10: =X10/V10-1 -> 0.4660414 | AA10: =+'담당자별매출'!AE72 -> 6456 | AB10: =+'담당자별매출'!AF72 -> 8000 | AC10: =+'담당자별매출'!AG72 -> 9488 | AD10: =AC10/AB10 -> 1.186 | AE10: =AC10/AA10-1 -> 0.46964064 | AF10: =+'담당자별매출'!AJ72 -> 6824 | AG10: =+'담당자별매출'!AK72 -> 8000 | AH10: =+'담당자별매출'!AL72 -> 6766 | AI10: =AH10/AG10 -> 0.84575 | AJ10: =AH10/AF10-1 -> -0.0084994138 | AK10: =+'담당자별매출'!AO72 -> 6668 | AL10: =+'담당자별매출'!AP72 -> 8000 | AM10: =+'담당자별매출'!AQ72 -> 7530 | AN10: =AM10/AL10 -> 0.94125 | AO10: =AM10/AK10-1 -> 0.12927415 | AP10: =+'담당자별매출'!AT72 -> 8026 | AQ10: =+'담당자별매출'!AU72 -> 8000 | AR10: =+'담당자별매출'!AV72 -> 7240 | AS10: =AR10/AQ10 -> 0.905 | AT10: =AR10/AP10-1 -> -0.097931722 | AU10: =+'담당자별매출'!AY72 -> 5699 | AV10: =+'담당자별매출'!AZ72 -> 8000 | AW10: =+'담당자별매출'!BA72 -> 7493 | AX10: =AW10/AV10 -> 0.936625 | AY10: =AW10/AU10-1 -> 0.31479207 | AZ10: =+'담당자별매출'!BD72 -> 6446 | BA10: =+'담당자별매출'!BE72 -> 8000 | BB10: =+'담당자별매출'!BF72 -> 7118 | BC10: =BB10/BA10 -> 0.88975 | BD10: =BB10/AZ10-1 -> 0.1042507 | BE10: =+'담당자별매출'!BI72 -> 10216 | BF10: =+'담당자별매출'!BJ72 -> 9500 | BG10: =+'담당자별매출'!BK72 -> 9000 | BH10: =BG10/BF10 -> 0.94736842 | BI10: =BG10/BE10-1 -> -0.11902897 | BJ10: =+'담당자별매출'!BN72 | BK10: =+'담당자별매출'!BO72 | BL10: =+'담당자별매출'!BP72 | BM10: =BL10/BK10 -> #DIV/0! | BN10: =BL10/BJ10-1 -> #DIV/0! | BO10: =+'담당자별매출'!BS72 | BP10: =+'담당자별매출'!BT72 | BQ10: =+'담당자별매출'!BU72 | BR10: =BQ10/BP10 -> #DIV/0! | BS10: =BQ10/BO10-1 -> #DIV/0!
B11: 남부지사 | C11: =+'담당자별매출'!G10 -> 610171 | D11: =+'담당자별매출'!H10 -> 557613 | E11: =+'담당자별매출'!I10 -> 650000 | F11: =E11/D11-1 -> 0.16568301 | G11: =+L11+Q11+V11+AA11+AF11+AK11+AP11+AU11+AZ11+BE11+BJ11+BO11 -> 450121 | H11: =+M11+R11+W11+AB11+AG11+AL11+AQ11+AV11+BA11+BF11+BK11+BP11 -> 529750 | I11: =+N11+S11+X11+AC11+AH11+AM11+AR11+AW11+BB11+BG11+BL11+BQ11 -> 479396 | J11: =I11/H11 -> 0.90494762 | K11: =I11/G11-1 -> 0.065038068 | L11: =+'담당자별매출'!P10 -> 21880 | M11: =+'담당자별매출'!Q10 -> 45500 | N11: =+'담당자별매출'!R10 -> 35432 | O11: =N11/M11 -> 0.77872527 | P11: =N11/L11-1 -> 0.61937843 | Q11: =+'담당자별매출'!U10 -> 44547 | R11: =+'담당자별매출'!V10 -> 52000 | S11: =+'담당자별매출'!W10 -> 47352 | T11: =S11/R11 -> 0.91061538 | U11: =S11/Q11-1 -> 0.062967203 | V11: =+'담당자별매출'!Z10 -> 46817 | W11: =+'담당자별매출'!AA10 -> 58500 | X11: =+'담당자별매출'!AB10 -> 50988 | Y11: =X11/W11 -> 0.87158974 | Z11: =X11/V11-1 -> 0.089091569 | AA11: =+'담당자별매출'!AE10 -> 52212 | AB11: =+'담당자별매출'!AF10 -> 52000 | AC11: =+'담당자별매출'!AG10 -> 51164 | AD11: =AC11/AB11 -> 0.98392308 | AE11: =AC11/AA11-1 -> -0.020072014 | AF11: =+'담당자별매출'!AJ10 -> 45220 | AG11: =+'담당자별매출'!AK10 -> 52000 | AH11: =+'담당자별매출'!AL10 -> 45652 | AI11: =AH11/AG11 -> 0.87792308 | AJ11: =AH11/AF11-1 -> 0.009553295 | AK11: =+'담당자별매출'!AO10 -> 40278 | AL11: =+'담당자별매출'!AP10 -> 52000 | AM11: =+'담당자별매출'!AQ10 -> 61776 | AN11: =AM11/AL11 -> 1.188 | AO11: =AM11/AK11-1 -> 0.5337405 | AP11: =+'담당자별매출'!AT10 -> 60084 | AQ11: =+'담당자별매출'!AU10 -> 52000 | AR11: =+'담당자별매출'!AV10 -> 47720 | AS11: =AR11/AQ11 -> 0.91769231 | AT11: =AR11/AP11-1 -> -0.20577858 | AU11: =+'담당자별매출'!AY10 -> 34006 | AV11: =+'담당자별매출'!AZ10 -> 52000 | AW11: =+'담당자별매출'!BA10 -> 42798 | AX11: =AW11/AV11 -> 0.82303846 | AY11: =AW11/AU11-1 -> 0.25854261 | AZ11: =+'담당자별매출'!BD10 -> 40544 | BA11: =+'담당자별매출'!BE10 -> 52000 | BB11: =+'담당자별매출'!BF10 -> 51776 | BC11: =BB11/BA11 -> 0.99569231 | BD11: =BB11/AZ11-1 -> 0.27703236 | BE11: =+'담당자별매출'!BI10 -> 64533 | BF11: =+'담당자별매출'!BJ10 -> 61750 | BG11: =+'담당자별매출'!BK10 -> 44738 | BH11: =BG11/BF11 -> 0.72450202 | BI11: =BG11/BE11-1 -> -0.30674229 | BJ11: =+'담당자별매출'!BN10 | BK11: =+'담당자별매출'!BO10 | BL11: =+'담당자별매출'!BP10 | BM11: =BL11/BK11 -> #DIV/0! | BN11: =BL11/BJ11-1 -> #DIV/0! | BO11: =+'담당자별매출'!BS10 | BP11: =+'담당자별매출'!BT10 | BQ11: =+'담당자별매출'!BU10 | BR11: =BQ11/BP11 -> #DIV/0! | BS11: =BQ11/BO11-1 -> #DIV/0!
B12: B2B본부 | C12: =+'담당자별매출'!G11 -> 833076 | D12: =+'담당자별매출'!H11 -> 888495 | E12: =+'담당자별매출'!I11 -> 1000000 | F12: =E12/D12-1 -> 0.12549874 | G12: =+L12+Q12+V12+AA12+AF12+AK12+AP12+AU12+AZ12+BE12+BJ12+BO12 -> 732870 | H12: =+M12+R12+W12+AB12+AG12+AL12+AQ12+AV12+BA12+BF12+BK12+BP12 -> 815000 | I12: =+N12+S12+X12+AC12+AH12+AM12+AR12+AW12+BB12+BG12+BL12+BQ12 -> 830027 | J12: =I12/H12 -> 1.018438 | K12: =I12/G12-1 -> 0.13257058 | L12: =+'담당자별매출'!P11 -> 53073 | M12: =+'담당자별매출'!Q11 -> 70000 | N12: =+'담당자별매출'!R11 -> 54974 | O12: =N12/M12 -> 0.78534286 | P12: =N12/L12-1 -> 0.035818589 | Q12: =+'담당자별매출'!U11 -> 76487 | R12: =+'담당자별매출'!V11 -> 80000 | S12: =+'담당자별매출'!W11 -> 86804 | T12: =S12/R12 -> 1.08505 | U12: =S12/Q12-1 -> 0.13488567 | V12: =+'담당자별매출'!Z11 -> 70456 | W12: =+'담당자별매출'!AA11 -> 90000 | X12: =+'담당자별매출'!AB11 -> 57991 | Y12: =X12/W12 -> 0.64434444 | Z12: =X12/V12-1 -> -0.17691893 | AA12: =+'담당자별매출'!AE11 -> 80861 | AB12: =+'담당자별매출'!AF11 -> 80000 | AC12: =+'담당자별매출'!AG11 -> 74680 | AD12: =AC12/AB12 -> 0.9335 | AE12: =AC12/AA12-1 -> -0.076439816 | AF12: =+'담당자별매출'!AJ11 -> 78217 | AG12: =+'담당자별매출'!AK11 -> 80000 | AH12: =+'담당자별매출'!AL11 -> 91224 | AI12: =AH12/AG12 -> 1.1403 | AJ12: =AH12/AF12-1 -> 0.16629377 | AK12: =+'담당자별매출'!AO11 -> 65959 | AL12: =+'담당자별매출'!AP11 -> 80000 | AM12: =+'담당자별매출'!AQ11 -> 91178 | AN12: =AM12/AL12 -> 1.139725 | AO12: =AM12/AK12-1 -> 0.38234358 | AP12: =+'담당자별매출'!AT11 -> 81733 | AQ12: =+'담당자별매출'!AU11 -> 80000 | AR12: =+'담당자별매출'!AV11 -> 79502 | AS12: =AR12/AQ12 -> 0.993775 | AT12: =AR12/AP12-1 -> -0.027296196 | AU12: =+'담당자별매출'!AY11 -> 80349 | AV12: =+'담당자별매출'!AZ11 -> 80000 | AW12: =+'담당자별매출'!BA11 -> 98658 | AX12: =AW12/AV12 -> 1.233225 | AY12: =AW12/AU12-1 -> 0.22786842 | AZ12: =+'담당자별매출'!BD11 -> 60761 | BA12: =+'담당자별매출'!BE11 -> 80000 | BB12: =+'담당자별매출'!BF11 -> 94324 | BC12: =BB12/BA12 -> 1.17905 | BD12: =BB12/AZ12-1 -> 0.55237735 | BE12: =+'담당자별매출'!BI11 -> 84974 | BF12: =+'담당자별매출'!BJ11 -> 95000 | BG12: =+'담당자별매출'!BK11 -> 100692 | BH12: =BG12/BF12 -> 1.0599158 | BI12: =BG12/BE12-1 -> 0.18497423 | BJ12: =+'담당자별매출'!BN11 | BK12: =+'담당자별매출'!BO11 | BL12: =+'담당자별매출'!BP11 | BM12: =BL12/BK12 -> #DIV/0! | BN12: =BL12/BJ12-1 -> #DIV/0! | BO12: =+'담당자별매출'!BS11 | BP12: =+'담당자별매출'!BT11 | BQ12: =+'담당자별매출'!BU11 | BR12: =BQ12/BP12 -> #DIV/0! | BS12: =BQ12/BO12-1 -> #DIV/0!
BQ16: `

Sheet 담당자별매출
E1: 사무실은 전부 딜러로 함. | J1: 개인의 기타부분은 lcc로 분류
B2: 단위 : 리터
B3: 구 분 (PVL, CVL) | E3: 전체 거래처수 | F3: 거래처수 | G3: 2023년 실적 | H3: 2024년 실적 | I3: 2025년 계획 | J3: 증감율 | K3: 누적실적 | P3: 1월 | U3: 2월 | Z3: 3월 | AE3: 4월 | AJ3: 5월 | AO3: 6월 | AT3: 7월 | AY3: 8월 | BD3: 9월 | BI3: 10월
K4: 2024년 | L4: 목표 | M4: 2025년 | N4: 달성율 | O4: 증감율 | P4: 2024년 | Q4: 목표 | R4: 2025년 | S4: 달성율 | T4: 증감율 | U4: 2024년 | V4: 목표 | W4: 2025년 | X4: 달성율 | Y4: 증감율 | Z4: 2024년 | AA4: 목표 | AB4: 2025년 | AC4: 달성율 | AD4: 증감율 | AE4: 2024년 | AF4: 목표 | AG4: 2025년 | AH4: 달성율 | AI4: 증감율 | AJ4: 2024년 | AK4: 목표 | AL4: 2025년 | AM4: 달성율 | AN4: 증감율 | AO4: 2024년 | AP4: 목표 | AQ4: 2025년 | AR4: 달성율 | AS4: 증감율 | AT4: 2024년 | AU4: 목표 | AV4: 2025년 | AW4: 달성율 | AX4: 증감율 | AY4: 2024년 | AZ4: 목표 | BA4: 2025년 | BB4: 달성율 | BC4: 증감율 | BD4: 2024년 | BE4: 목표 | BF4: 2025년 | BG4: 달성율 | BH4: 증감율 | BI4: 2024년 | BJ4: 목표 | BK4: 2025년 | BL4: 달성율 | BM4: 증감율
B5: AUTO | C5: 합계 | E5: =E6+E11 -> 1273 | F5: =F6+F11 -> 1222 | G5: =G6+G11 -> 4859570 | H5: =H6+H11 -> 5083200 | I5: =I6+I11 -> 5700000 | J5: =I5/H5-1 -> 0.12134089 | K5: =K6+K11 -> 4175664 | L5: =L6+L11 -> 4645500 | M5: =M6+M11 -> 4446794 | N5: =M5/L5 -> 0.95722613 | O5: =M5/K5-1 -> 0.064930991 | P5: =P6+P11 -> 328580 | Q5: =Q6+Q11 -> 399000 | R5: =R6+R11 -> 346892 | S5: =R5/Q5 -> 0.86940351 | T5: =R5/P5-1 -> 0.05573072 | U5: =U6+U11 -> 346389 | V5: =V6+V11 -> 456000 | W5: =W6+W11 -> 429032 | X5: =W5/V5 -> 0.94085965 | Y5: =W5/U5-1 -> 0.23858437 | Z5: =Z6+Z11 -> 464840 | AA5: =AA6+AA11 -> 513000 | AB5: =AB6+AB11 -> 406769 | AC5: =AB5/AA5 -> 0.79292203 | AD5: =AB5/Z5-1 -> -0.12492686 | AE5: =AE6+AE11 -> 455035 | AF5: =AF6+AF11 -> 456000 | AG5: =AG6+AG11 -> 471885 | AH5: =AG5/AF5 -> 1.0348355 | AI5: =AG5/AE5-1 -> 0.037030119 | AJ5: =AJ6+AJ11 -> 396406 | AK5: =AK6+AK11 -> 456000 | AL5: =AL6+AL11 -> 485185 | AM5: =AL5/AK5 -> 1.0640022 | AN5: =AL5/AJ5-1 -> 0.22395978 | AO5: =AO6+AO11 -> 408513 | AP5: =AP6+AP11 -> 456000 | AQ5: =AQ6+AQ11 -> 475756 | AR5: =AQ5/AP5 -> 1.0433246 | AS5: =AQ5/AO5-1 -> 0.16460431 | AT5: =AT6+AT11 -> 433130 | AU5: =AU6+AU11 -> 456000 | AV5: =AV6+AV11 -> 426398 | AW5: =AV5/AU5 -> 0.93508333 | AX5: =AV5/AT5-1 -> -0.015542678 | AY5: =AY6+AY11 -> 415086 | AZ5: =AZ6+AZ11 -> 456000 | BA5: =BA6+BA11 -> 435464 | BB5: =BA5/AZ5 -> 0.95496491 | BC5: =BA5/AY5-1 -> 0.049093441 | BD5: =BD6+BD11 -> 383982 | BE5: =BE6+BE11 -> 456000 | BF5: =BF6+BF11 -> 484749 | BG5: =BF5/BE5 -> 1.0630461 | BH5: =BF5/BD5-1 -> 0.26242636 | BI5: =BI6+BI11 -> 543703 | BJ5: =BJ6+BJ11 -> 541500 | BK5: =BK6+BK11 -> 484664 | BL5: =BK5/BJ5 -> 0.8950397 | BM5: =BK5/BI5-1 -> -0.10858686
C6: B2C AUTO | D6: 소계 | E6: =SUM(E7:E10) -> 1273 | F6: =SUM(F7:F10) -> 1222 | G6: =SUM(G7:G10) -> 4026494 | H6: =SUM(H7:H10) -> 4194705 | I6: =SUM(I7:I10) -> 4700000 | J6: =I6/H6-1 -> 0.1204602 | K6: =SUM(K7:K10) -> 3442794 | L6: =SUM(L7:L10) -> 3830500 | M6: =SUM(M7:M10) -> 3616767 | N6: =M6/L6 -> 0.94420232 | O6: =M6/K6-1 -> 0.050532504 | P6: =SUM(P7:P10) -> 275507 | Q6: =SUM(Q7:Q10) -> 329000 | R6: =SUM(R7:R10) -> 291918 | S6: =R6/Q6 -> 0.88728875 | T6: =R6/P6-1 -> 0.059566545 | U6: =SUM(U7:U10) -> 269902 | V6: =SUM(V7:V10) -> 376000 | W6: =SUM(W7:W10) -> 342228 | X6: =W6/V6 -> 0.91018085 | Y6: =W6/U6-1 -> 0.26797134 | Z6: =SUM(Z7:Z10) -> 394384 | AA6: =SUM(AA7:AA10) -> 423000 | AB6: =SUM(AB7:AB10) -> 348778 | AC6: =AB6/AA6 -> 0.82453428 | AD6: =AB6/Z6-1 -> -0.11563857 | AE6: =SUM(AE7:AE10) -> 374174 | AF6: =SUM(AF7:AF10) -> 376000 | AG6: =SUM(AG7:AG10) -> 397205 | AH6: =AG6/AF6 -> 1.0563963 | AI6: =AG6/AE6-1 -> 0.061551578 | AJ6: =SUM(AJ7:AJ10) -> 318189 | AK6: =SUM(AK7:AK10) -> 376000 | AL6: =SUM(AL7:AL10) -> 393961 | AM6: =AL6/AK6 -> 1.0477686 | AN6: =AL6/AJ6-1 -> 0.2381352 | AO6: =SUM(AO7:AO10) -> 342554 | AP6: =SUM(AP7:AP10) -> 376000 | AQ6: =SUM(AQ7:AQ10) -> 384578 | AR6: =AQ6/AP6 -> 1.0228138 | AS6: =AQ6/AO6-1 -> 0.12267847 | AT6: =SUM(AT7:AT10) -> 351397 | AU6: =SUM(AU7:AU10) -> 376000 | AV6: =SUM(AV7:AV10) -> 346896 | AW6: =AV6/AU6 -> 0.92259574 | AX6: =AV6/AT6-1 -> -0.012808874 | AY6: =SUM(AY7:AY10) -> 334737 | AZ6: =SUM(AZ7:AZ10) -> 376000 | BA6: =SUM(BA7:BA10) -> 336806 | BB6: =BA6/AZ6 -> 0.89576064 | BC6: =BA6/AY6-1 -> 0.0061809719 | BD6: =SUM(BD7:BD10) -> 323221 | BE6: =SUM(BE7:BE10) -> 376000 | BF6: =SUM(BF7:BF10) -> 390425 | BG6: =BF6/BE6 -> 1.0383644 | BH6: =BF6/BD6-1 -> 0.20791966 | BI6: =SUM(BI7:BI10) -> 458729 | BJ6: =SUM(BJ7:BJ10) -> 446500 | BK6: =SUM(BK7:BK10) -> 383972 | BL6: =BK6/BJ6 -> 0.85995969 | BM6: =BK6/BI6-1 -> -0.1629655
D7: Fleet | E7: =+E26+E29+E33+E36+E39+E43+E46+E50+E53+E57+E60+E64+E67+E70+E74 -> 180 | F7: =+F26+F29+F33+F36+F39+F43+F46+F50+F53+F57+F60+F64+F67+F70+F74 -> 174 | G7: =+G26+G29+G33+G36+G39+G43+G46+G50+G53+G57+G60+G64+G67+G70+G74 -> 388427 | H7: =+H26+H29+H33+H36+H39+H43+H46+H50+H53+H57+H60+H64+H67+H70+H74 -> 414329 | I7: =+I26+I29+I33+I36+I39+I43+I46+I50+I53+I57+I60+I64+I67+I70+I74 -> 457900 | J7: =I7/H7-1 -> 0.10516039 | K7: =P7+U7+Z7+AE7+AJ7+AO7+AT7+AY7+BD7+BI7+BN7+BS7 -> 344987 | L7: =Q7+V7+AA7+AF7+AK7+AP7+AU7+AZ7+BE7+BJ7+BO7+BT7 -> 373188.5 | M7: =R7+W7+AB7+AG7+AL7+AQ7+AV7+BA7+BF7+BK7+BP7+BU7 -> 350111 | N7: =M7/L7 -> 0.93816128 | O7: =M7/K7-1 -> 0.014852734 | P7: =+P26+P29+P33+P36+P39+P43+P46+P50+P53+P57+P60+P64+P67+P70+P74 -> 34738 | Q7: =+Q26+Q29+Q33+Q36+Q39+Q43+Q46+Q50+Q53+Q57+Q60+Q64+Q67+Q70+Q74 -> 32053 | R7: =+R26+R29+R33+R36+R39+R43+R46+R50+R53+R57+R60+R64+R67+R70+R74 -> 29708 | S7: =R7/Q7 -> 0.92683992 | T7: =R7/P7-1 -> -0.1447982 | U7: =+U26+U29+U33+U36+U39+U43+U46+U50+U53+U57+U60+U64+U67+U70+U74 -> 28470 | V7: =+V26+V29+V33+V36+V39+V43+V46+V50+V53+V57+V60+V64+V67+V70+V74 -> 36632 | W7: =+W26+W29+W33+W36+W39+W43+W46+W50+W53+W57+W60+W64+W67+W70+W74 -> 29631 | X7: =W7/V7 -> 0.80888294 | Y7: =W7/U7-1 -> 0.040779768 | Z7: =+Z26+Z29+Z33+Z36+Z39+Z43+Z46+Z50+Z53+Z57+Z60+Z64+Z67+Z70+Z74 -> 94196 | AA7: =+AA26+AA29+AA33+AA36+AA39+AA43+AA46+AA50+AA53+AA57+AA60+AA64+AA67+AA70+AA74 -> 41211 | AB7: =+AB26+AB29+AB33+AB36+AB39+AB43+AB46+AB50+AB53+AB57+AB60+AB64+AB67+AB70+AB74 -> 38426 | AC7: =AB7/AA7 -> 0.93242096 | AD7: =AB7/Z7-1 -> -0.59206336 | AE7: =+AE26+AE29+AE33+AE36+AE39+AE43+AE46+AE50+AE53+AE57+AE60+AE64+AE67+AE70+AE74 -> 18988 | AF7: =+AF26+AF29+AF33+AF36+AF39+AF43+AF46+AF50+AF53+AF57+AF60+AF64+AF67+AF70+AF74 -> 36632 | AG7: =+AG26+AG29+AG33+AG36+AG39+AG43+AG46+AG50+AG53+AG57+AG60+AG64+AG67+AG70+AG74 -> 38916 | AH7: =AG7/AF7 -> 1.0623499 | AI7: =AG7/AE7-1 -> 1.0495049 | AJ7: =+AJ26+AJ29+AJ33+AJ36+AJ39+AJ43+AJ46+AJ50+AJ53+AJ57+AJ60+AJ64+AJ67+AJ70+AJ74 -> 22380 | AK7: =+AK26+AK29+AK33+AK36+AK39+AK43+AK46+AK50+AK53+AK57+AK60+AK64+AK67+AK70+AK74 -> 36632 | AL7: =+AL26+AL29+AL33+AL36+AL39+AL43+AL46+AL50+AL53+AL57+AL60+AL64+AL67+AL70+AL74 -> 34800 | AM7: =AL7/AK7 -> 0.94998908 | AN7: =AL7/AJ7-1 -> 0.55495979 | AO7: =+AO26+AO29+AO33+AO36+AO39+AO43+AO46+AO50+AO53+AO57+AO60+AO64+AO67+AO70+AO74 -> 33406 | AP7: =+AP26+AP29+AP33+AP36+AP39+AP43+AP46+AP50+AP53+AP57+AP60+AP64+AP67+AP70+AP74 -> 36632 | AQ7: =+AQ26+AQ29+AQ33+AQ36+AQ39+AQ43+AQ46+AQ50+AQ53+AQ57+AQ60+AQ64+AQ67+AQ70+AQ74 -> 50672 | AR7: =AQ7/AP7 -> 1.3832715 | AS7: =AQ7/AO7-1 -> 0.51685326 | AT7: =+AT26+AT29+AT33+AT36+AT39+AT43+AT46+AT50+AT53+AT57+AT60+AT64+AT67+AT70+AT74 -> 25398 | AU7: =+AU26+AU29+AU33+AU36+AU39+AU43+AU46+AU50+AU53+AU57+AU60+AU64+AU67+AU70+AU74 -> 36632 | AV7: =+AV26+AV29+AV33+AV36+AV39+AV43+AV46+AV50+AV53+AV57+AV60+AV64+AV67+AV70+AV74 -> 31690 | AW7: =AV7/AU7 -> 0.86509063 | AX7: =AV7/AT7-1 -> 0.24773604 | AY7: =+AY26+AY29+AY33+AY36+AY39+AY43+AY46+AY50+AY53+AY57+AY60+AY64+AY67+AY70+AY74 -> 28876 | AZ7: =+AZ26+AZ29+AZ33+AZ36+AZ39+AZ43+AZ46+AZ50+AZ53+AZ57+AZ60+AZ64+AZ67+AZ70+AZ74 -> 36632 | BA7: =+BA26+BA29+BA33+BA36+BA39+BA43+BA46+BA50+BA53+BA57+BA60+BA64+BA67+BA70+BA74 -> 30574 | BB7: =BA7/AZ7 -> 0.83462546 | BC7: =BA7/AY7-1 -> 0.058803158 | BD7: =+BD26+BD29+BD33+BD36+BD39+BD43+BD46+BD50+BD53+BD57+BD60+BD64+BD67+BD70+BD74 -> 27014 | BE7: =+BE26+BE29+BE33+BE36+BE39+BE43+BE46+BE50+BE53+BE57+BE60+BE64+BE67+BE70+BE74 -> 36632 | BF7: =+BF26+BF29+BF33+BF36+BF39+BF43+BF46+BF50+BF53+BF57+BF60+BF64+BF67+BF70+BF74 -> 35304 | BG7: =BF7/BE7 -> 0.96374754 | BH7: =BF7/BD7-1 -> 0.30687792 | BI7: =+BI26+BI29+BI33+BI36+BI39+BI43+BI46+BI50+BI53+BI57+BI60+BI64+BI67+BI70+BI74 -> 31521 | BJ7: =+BJ26+BJ29+BJ33+BJ36+BJ39+BJ43+BJ46+BJ50+BJ53+BJ57+BJ60+BJ64+BJ67+BJ70+BJ74 -> 43500.5 | BK7: =+BK26+BK29+BK33+BK36+BK39+BK43+BK46+BK50+BK53+BK57+BK60+BK64+BK67+BK70+BK74 -> 30390 | BL7: =BK7/BJ7 -> 0.69861266 | BM7: =BK7/BI7-1 -> -0.035880841
D8: LCC | E8: =+E27+E30+E34+E37+E40+E44+E47+E51+E54+E58+E61+E65+E68+E71+E75 -> 1010 | F8: =+F27+F30+F34+F37+F40+F44+F47+F51+F54+F58+F61+F65+F68+F71+F75 -> 972 | G8: =+G27+G30+G34+G37+G40+G44+G47+G51+G54+G58+G61+G65+G68+G71+G75 -> 2129404 | H8: =+H27+H30+H34+H37+H40+H44+H47+H51+H54+H58+H61+H65+H68+H71+H75 -> 2338098 | I8: =+I27+I30+I34+I37+I40+I44+I47+I51+I54+I58+I61+I65+I68+I71+I75 -> 2685000 | J8: =I8/H8-1 -> 0.14836932 | K8: =P8+U8+Z8+AE8+AJ8+AO8+AT8+AY8+BD8+BI8+BN8+BS8 -> 1934208 | L8: =Q8+V8+AA8+AF8+AK8+AP8+AU8+AZ8+BE8+BJ8+BO8+BT8 -> 2188275 | M8: =R8+W8+AB8+AG8+AL8+AQ8+AV8+BA8+BF8+BK8+BP8+BU8 -> 2041493 | N8: =M8/L8 -> 0.93292342 | O8: =M8/K8-1 -> 0.055467147 | P8: =+P27+P30+P34+P37+P40+P44+P47+P51+P54+P58+P61+P65+P68+P71+P75 -> 161980 | Q8: =+Q27+Q30+Q34+Q37+Q40+Q44+Q47+Q51+Q54+Q58+Q61+Q65+Q68+Q71+Q75 -> 187950 | R8: =+R27+R30+R34+R37+R40+R44+R47+R51+R54+R58+R61+R65+R68+R71+R75 -> 153801 | S8: =R8/Q8 -> 0.81830806 | T8: =R8/P8-1 -> -0.050493888 | U8: =+U27+U30+U34+U37+U40+U44+U47+U51+U54+U58+U61+U65+U68+U71+U75 -> 147223 | V8: =+V27+V30+V34+V37+V40+V44+V47+V51+V54+V58+V61+V65+V68+V71+V75 -> 214800 | W8: =+W27+W30+W34+W37+W40+W44+W47+W51+W54+W58+W61+W65+W68+W71+W75 -> 183533 | X8: =W8/V8 -> 0.85443669 | Y8: =W8/U8-1 -> 0.24663266 | Z8: =+Z27+Z30+Z34+Z37+Z40+Z44+Z47+Z51+Z54+Z58+Z61+Z65+Z68+Z71+Z75 -> 184869 | AA8: =+AA27+AA30+AA34+AA37+AA40+AA44+AA47+AA51+AA54+AA58+AA61+AA65+AA68+AA71+AA75 -> 241650 | AB8: =+AB27+AB30+AB34+AB37+AB40+AB44+AB47+AB51+AB54+AB58+AB61+AB65+AB68+AB71+AB75 -> 196996 | AC8: =AB8/AA8 -> 0.81521208 | AD8: =AB8/Z8-1 -> 0.065597802 | AE8: =+AE27+AE30+AE34+AE37+AE40+AE44+AE47+AE51+AE54+AE58+AE61+AE65+AE68+AE71+AE75 -> 218926 | AF8: =+AF27+AF30+AF34+AF37+AF40+AF44+AF47+AF51+AF54+AF58+AF61+AF65+AF68+AF71+AF75 -> 214800 | AG8: =+AG27+AG30+AG34+AG37+AG40+AG44+AG47+AG51+AG54+AG58+AG61+AG65+AG68+AG71+AG75 -> 224451 | AH8: =AG8/AF8 -> 1.0449302 | AI8: =AG8/AE8-1 -> 0.025236838 | AJ8: =+AJ27+AJ30+AJ34+AJ37+AJ40+AJ44+AJ47+AJ51+AJ54+AJ58+AJ61+AJ65+AJ68+AJ71+AJ75 -> 179561 | AK8: =+AK27+AK30+AK34+AK37+AK40+AK44+AK47+AK51+AK54+AK58+AK61+AK65+AK68+AK71+AK75 -> 214800 | AL8: =+AL27+AL30+AL34+AL37+AL40+AL44+AL47+AL51+AL54+AL58+AL61+AL65+AL68+AL71+AL75 -> 248446 | AM8: =AL8/AK8 -> 1.1566387 | AN8: =AL8/AJ8-1 -> 0.38363008 | AO8: =+AO27+AO30+AO34+AO37+AO40+AO44+AO47+AO51+AO54+AO58+AO61+AO65+AO68+AO71+AO75 -> 186368 | AP8: =+AP27+AP30+AP34+AP37+AP40+AP44+AP47+AP51+AP54+AP58+AP61+AP65+AP68+AP71+AP75 -> 214800 | AQ8: =+AQ27+AQ30+AQ34+AQ37+AQ40+AQ44+AQ47+AQ51+AQ54+AQ58+AQ61+AQ65+AQ68+AQ71+AQ75 -> 196924 | AR8: =AQ8/AP8 -> 0.9167784 | AS8: =AQ8/AO8-1 -> 0.056640625 | AT8: =+AT27+AT30+AT34+AT37+AT40+AT44+AT47+AT51+AT54+AT58+AT61+AT65+AT68+AT71+AT75 -> 186811 | AU8: =+AU27+AU30+AU34+AU37+AU40+AU44+AU47+AU51+AU54+AU58+AU61+AU65+AU68+AU71+AU75 -> 214800 | AV8: =+AV27+AV30+AV34+AV37+AV40+AV44+AV47+AV51+AV54+AV58+AV61+AV65+AV68+AV71+AV75 -> 195868 | AW8: =AV8/AU8 -> 0.9118622 | AX8: =AV8/AT8-1 -> 0.048482156 | AY8: =+AY27+AY30+AY34+AY37+AY40+AY44+AY47+AY51+AY54+AY58+AY61+AY65+AY68+AY71+AY75 -> 192529 | AZ8: =+AZ27+AZ30+AZ34+AZ37+AZ40+AZ44+AZ47+AZ51+AZ54+AZ58+AZ61+AZ65+AZ68+AZ71+AZ75 -> 214800 | BA8: =+BA27+BA30+BA34+BA37+BA40+BA44+BA47+BA51+BA54+BA58+BA61+BA65+BA68+BA71+BA75 -> 182105 | BB8: =BA8/AZ8 -> 0.84778864 | BC8: =BA8/AY8-1 -> -0.054142493 | BD8: =+BD27+BD30+BD34+BD37+BD40+BD44+BD47+BD51+BD54+BD58+BD61+BD65+BD68+BD71+BD75 -> 185236 | BE8: =+BE27+BE30+BE34+BE37+BE40+BE44+BE47+BE51+BE54+BE58+BE61+BE65+BE68+BE71+BE75 -> 214800 | BF8: =+BF27+BF30+BF34+BF37+BF40+BF44+BF47+BF51+BF54+BF58+BF61+BF65+BF68+BF71+BF75 -> 222904 | BG8: =BF8/BE8 -> 1.0377281 | BH8: =BF8/BD8-1 -> 0.2033514 | BI8: =+BI27+BI30+BI34+BI37+BI40+BI44+BI47+BI51+BI54+BI58+BI61+BI65+BI68+BI71+BI75 -> 290705 | BJ8: =+BJ27+BJ30+BJ34+BJ37+BJ40+BJ44+BJ47+BJ51+BJ54+BJ58+BJ61+BJ65+BJ68+BJ71+BJ75 -> 255075 | BK8: =+BK27+BK30+BK34+BK37+BK40+BK44+BK47+BK51+BK54+BK58+BK61+BK65+BK68+BK71+BK75 -> 236465 | BL8: =BK8/BJ8 -> 0.92704107 | BM8: =BK8/BI8-1 -> -0.1865809
D9: 사무실 | E9: =E76+E79+E80+E81 -> 83 | F9: =F76+F79+F80+F81 -> 76 | G9: =G76+G79+G80+G81 -> 898492 | H9: =H76+H79+H80+H81 -> 884665 | I9: =I76+I79+I80+I81 -> 907100 | J9: =I9/H9-1 -> 0.025359882 | K9: =P9+U9+Z9+AE9+AJ9+AO9+AT9+AY9+BD9+BI9+BN9+BS9 -> 713478 | L9: =Q9+V9+AA9+AF9+AK9+AP9+AU9+AZ9+BE9+BJ9+BO9+BT9 -> 739286.5 | M9: =R9+W9+AB9+AG9+AL9+AQ9+AV9+BA9+BF9+BK9+BP9+BU9 -> 745767 | N9: =M9/L9 -> 1.0087659 | O9: =M9/K9-1 -> 0.045255775 | P9: =P76+P79+P80+P81 -> 56909 | Q9: =Q76+Q79+Q80+Q81 -> 63497 | R9: =R76+R79+R80+R81 -> 72977 | S9: =R9/Q9 -> 1.1492984 | T9: =R9/P9-1 -> 0.2823455 | U9: =U76+U79+U80+U81 -> 49662 | V9: =V76+V79+V80+V81 -> 72568 | W9: =W76+W79+W80+W81 -> 81712 | X9: =W9/V9 -> 1.126006 | Y9: =W9/U9-1 -> 0.64536265 | Z9: =Z76+Z79+Z80+Z81 -> 68502 | AA9: =AA76+AA79+AA80+AA81 -> 81639 | AB9: =AB76+AB79+AB80+AB81 -> 62368 | AC9: =AB9/AA9 -> 0.7639486 | AD9: =AB9/Z9-1 -> -0.089544831 | AE9: =AE76+AE79+AE80+AE81 -> 84048 | AF9: =AF76+AF79+AF80+AF81 -> 72568 | AG9: =AG76+AG79+AG80+AG81 -> 82674 | AH9: =AG9/AF9 -> 1.1392625 | AI9: =AG9/AE9-1 -> -0.016347801 | AJ9: =AJ76+AJ79+AJ80+AJ81 -> 71028 | AK9: =AK76+AK79+AK80+AK81 -> 72568 | AL9: =AL76+AL79+AL80+AL81 -> 65063 | AM9: =AL9/AK9 -> 0.89657976 | AN9: =AL9/AJ9-1 -> -0.083980965 | AO9: =AO76+AO79+AO80+AO81 -> 82502 | AP9: =AP76+AP79+AP80+AP81 -> 72568 | AQ9: =AQ76+AQ79+AQ80+AQ81 -> 75206 | AR9: =AQ9/AP9 -> 1.0363521 | AS9: =AQ9/AO9-1 -> -0.08843422 | AT9: =AT76+AT79+AT80+AT81 -> 79104 | AU9: =AU76+AU79+AU80+AU81 -> 72568 | AV9: =AV76+AV79+AV80+AV81 -> 71618 | AW9: =AV9/AU9 -> 0.98690883 | AX9: =AV9/AT9-1 -> -0.094634911 | AY9: =AY76+AY79+AY80+AY81 -> 79326 | AZ9: =AZ76+AZ79+AZ80+AZ81 -> 72568 | BA9: =BA76+BA79+BA80+BA81 -> 81329 | BB9: =BA9/AZ9 -> 1.1207281 | BC9: =BA9/AY9-1 -> 0.025250233 | BD9: =BD76+BD79+BD80+BD81 -> 70427 | BE9: =BE76+BE79+BE80+BE81 -> 72568 | BF9: =BF76+BF79+BF80+BF81 -> 80441 | BG9: =BF9/BE9 -> 1.1084913 | BH9: =BF9/BD9-1 -> 0.14218979 | BI9: =BI76+BI79+BI80+BI81 -> 71970 | BJ9: =BJ76+BJ79+BJ80+BJ81 -> 86174.5 | BK9: =BK76+BK79+BK80+BK81 -> 72379 | BL9: =BK9/BJ9 -> 0.83991204 | BM9: =BK9/BI9-1 -> 0.0056829234
D10: 남부지사 | G10: 610171 | H10: 557613 | I10: 650000 | J10: =I10/H10-1 -> 0.16568301 | K10: =P10+U10+Z10+AE10+AJ10+AO10+AT10+AY10+BD10+BI10+BN10+BS10 -> 450121 | L10: =Q10+V10+AA10+AF10+AK10+AP10+AU10+AZ10+BE10+BJ10+BO10+BT10 -> 529750 | M10: =R10+W10+AB10+AG10+AL10+AQ10+AV10+BA10+BF10+BK10+BP10+BU10 -> 479396 | N10: =M10/L10 -> 0.90494762 | O10: =M10/K10-1 -> 0.065038068 | P10: 21880 | Q10: 45500 | R10: 35432 | S10: =R10/Q10 -> 0.77872527 | T10: =R10/P10-1 -> 0.61937843 | U10: 44547 | V10: 52000 | W10: 47352 | X10: =W10/V10 -> 0.91061538 | Y10: =W10/U10-1 -> 0.062967203 | Z10: 46817 | AA10: 58500 | AB10: 50988 | AC10: =AB10/AA10 -> 0.87158974 | AD10: =AB10/Z10-1 -> 0.089091569 | AE10: 52212 | AF10: 52000 | AG10: 51164 | AH10: =AG10/AF10 -> 0.98392308 | AI10: =AG10/AE10-1 -> -0.020072014 | AJ10: 45220 | AK10: 52000 | AL10: 45652 | AM10: =AL10/AK10 -> 0.87792308 | AN10: =AL10/AJ10-1 -> 0.009553295 | AO10: 40278 | AP10: 52000 | AQ10: 61776 | AR10: =AQ10/AP10 -> 1.188 | AS10: =AQ10/AO10-1 -> 0.5337405 | AT10: 60084 | AU10: 52000 | AV10: 47720 | AW10: =AV10/AU10 -> 0.91769231 | AX10: =AV10/AT10-1 -> -0.20577858 | AY10: 34006 | AZ10: 52000 | BA10: 42798 | BB10: =BA10/AZ10 -> 0.82303846 | BC10: =BA10/AY10-1 -> 0.25854261 | BD10: 40544 | BE10: 52000 | BF10: 51776 | BG10: =BF10/BE10 -> 0.99569231 | BH10: =BF10/BD10-1 -> 0.27703236 | BI10: 64533 | BJ10: 61750 | BK10: 44738 | BL10: =BK10/BJ10 -> 0.72450202 | BM10: =BK10/BI10-1 -> -0.30674229
C11: B2B AUTO | D11: 소계 | E11: =SUM(E12:E13) -> 0 | F11: =SUM(F12:F13) -> 0 | G11: =SUM(G12:G13) -> 833076 | H11: =SUM(H12:H13) -> 888495 | I11: =SUM(I12:I13) -> 1000000 | J11: =I11/H11-1 -> 0.12549874 | K11: =SUM(K12:K13) -> 732870 | L11: =SUM(L12:L13) -> 815000 | M11: =SUM(M12:M13) -> 830027 | N11: =M11/L11 -> 1.018438 | O11: =M11/K11-1 -> 0.13257058 | P11: =SUM(P12:P13) -> 53073 | Q11: =SUM(Q12:Q13) -> 70000 | R11: =SUM(R12:R13) -> 54974 | S11: =R11/Q11 -> 0.78534286 | T11: =R11/P11-1 -> 0.035818589 | U11: =SUM(U12:U13) -> 76487 | V11: =SUM(V12:V13) -> 80000 | W11: =SUM(W12:W13) -> 86804 | X11: =W11/V11 -> 1.08505 | Y11: =W11/U11-1 -> 0.13488567 | Z11: =SUM(Z12:Z13) -> 70456 | AA11: =SUM(AA12:AA13) -> 90000 | AB11: =SUM(AB12:AB13) -> 57991 | AC11: =AB11/AA11 -> 0.64434444 | AD11: =AB11/Z11-1 -> -0.17691893 | AE11: =SUM(AE12:AE13) -> 80861 | AF11: =SUM(AF12:AF13) -> 80000 | AG11: =SUM(AG12:AG13) -> 74680 | AH11: =AG11/AF11 -> 0.9335 | AI11: =AG11/AE11-1 -> -0.076439816 | AJ11: =SUM(AJ12:AJ13) -> 78217 | AK11: =SUM(AK12:AK13) -> 80000 | AL11: =SUM(AL12:AL13) -> 91224 | AM11: =AL11/AK11 -> 1.1403 | AN11: =AL11/AJ11-1 -> 0.16629377 | AO11: =SUM(AO12:AO13) -> 65959 | AP11: =SUM(AP12:AP13) -> 80000 | AQ11: =SUM(AQ12:AQ13) -> 91178 | AR11: =AQ11/AP11 -> 1.139725 | AS11: =AQ11/AO11-1 -> 0.38234358 | AT11: =SUM(AT12:AT13) -> 81733 | AU11: =SUM(AU12:AU13) -> 80000 | AV11: =SUM(AV12:AV13) -> 79502 | AW11: =AV11/AU11 -> 0.993775 | AX11: =AV11/AT11-1 -> -0.027296196 | AY11: =SUM(AY12:AY13) -> 80349 | AZ11: =SUM(AZ12:AZ13) -> 80000 | BA11: =SUM(BA12:BA13) -> 98658 | BB11: =BA11/AZ11 -> 1.233225 | BC11: =BA11/AY11-1 -> 0.22786842 | BD11: =SUM(BD12:BD13) -> 60761 | BE11: =SUM(BE12:BE13) -> 80000 | BF11: =SUM(BF12:BF13) -> 94324 | BG11: =BF11/BE11 -> 1.17905 | BH11: =BF11/BD11-1 -> 0.55237735 | BI11: =SUM(BI12:BI13) -> 84974 | BJ11: =SUM(BJ12:BJ13) -> 95000 | BK11: =SUM(BK12:BK13) -> 100692 | BL11: =BK11/BJ11 -> 1.0599158 | BM11: =BK11/BI11-1 -> 0.18497423
D12: b2b | G12: 532515 | H12: 636298 | I12: 690000 | J12: =I12/H12-1 -> 0.084397562 | K12: =P12+U12+Z12+AE12+AJ12+AO12+AT12+AY12+BD12+BI12+BN12+BS12 -> 529040 | L12: =Q12+V12+AA12+AF12+AK12+AP12+AU12+AZ12+BE12+BJ12+BO12+BT12 -> 562350 | M12: =R12+W12+AB12+AG12+AL12+AQ12+AV12+BA12+BF12+BK12+BP12+BU12 -> 461086 | N12: =M12/L12 -> 0.81992709 | O12: =M12/K12-1 -> -0.12844775 | P12: 41782 | Q12: 48300 | R12: 36219 | S12: =R12/Q12 -> 0.74987578 | T12: =R12/P12-1 -> -0.13314346 | U12: 59747 | V12: 55200 | W12: 52741 | X12: =W12/V12 -> 0.9554529 | Y12: =W12/U12-1 -> -0.11726112 | Z12: 50095 | AA12: 62100 | AB12: 35671 | AC12: =AB12/AA12 -> 0.57441224 | AD12: =AB12/Z12-1 -> -0.28793293 | AE12: 58269 | AF12: 55200 | AG12: 44992 | AH12: =AG12/AF12 -> 0.81507246 | AI12: =AG12/AE12-1 -> -0.22785701 | AJ12: 57645 | AK12: 55200 | AL12: 52528 | AM12: =AL12/AK12 -> 0.9515942 | AN12: =AL12/AJ12-1 -> -0.088767456 | AO12: 50348 | AP12: 55200 | AQ12: 39438 | AR12: =AQ12/AP12 -> 0.71445652 | AS12: =AQ12/AO12-1 -> -0.21669182 | AT12: 52167 | AU12: 55200 | AV12: 42531 | AW12: =AV12/AU12 -> 0.77048913 | AX12: =AV12/AT12-1 -> -0.18471447 | AY12: 57230 | AZ12: 55200 | BA12: 46422 | BB12: =BA12/AZ12 -> 0.84097826 | BC12: =BA12/AY12-1 -> -0.188852 | BD12: 38571 | BE12: 55200 | BF12: 45604 | BG12: =BF12/BE12 -> 0.82615942 | BH12: =BF12/BD12-1 -> 0.18233906 | BI12: 63186 | BJ12: 65550 | BK12: 64940 | BL12: =BK12/BJ12 -> 0.99069413 | BM12: =BK12/BI12-1 -> 0.027759314
D13: 기타 | G13: 300561 | H13: 252197 | I13: 310000 | J13: =I13/H13-1 -> 0.22919781 | K13: =P13+U13+Z13+AE13+AJ13+AO13+AT13+AY13+BD13+BI13+BN13+BS13 -> 203830 | L13: =Q13+V13+AA13+AF13+AK13+AP13+AU13+AZ13+BE13+BJ13+BO13+BT13 -> 252650 | M13: =R13+W13+AB13+AG13+AL13+AQ13+AV13+BA13+BF13+BK13+BP13+BU13 -> 368941 | N13: =M13/L13 -> 1.460285 | O13: =M13/K13-1 -> 0.81004268 | P13: 11291 | Q13: 21700 | R13: 18755 | S13: =R13/Q13 -> 0.86428571 | T13: =R13/P13-1 -> 0.66105748 | U13: 16740 | V13: 24800 | W13: 34063 | X13: =W13/V13 -> 1.3735081 | Y13: =W13/U13-1 -> 1.0348268 | Z13: 20361 | AA13: 27900 | AB13: 22320 | AC13: =AB13/AA13 -> 0.8 | AD13: =AB13/Z13-1 -> 0.096213349 | AE13: 22592 | AF13: 24800 | AG13: 29688 | AH13: =AG13/AF13 -> 1.1970968 | AI13: =AG13/AE13-1 -> 0.31409348 | AJ13: 20572 | AK13: 24800 | AL13: 38696 | AM13: =AL13/AK13 -> 1.5603226 | AN13: =AL13/AJ13-1 -> 0.88100331 | AO13: 15611 | AP13: 24800 | AQ13: 51740 | AR13: =AQ13/AP13 -> 2.0862903 | AS13: =AQ13/AO13-1 -> 2.3143296 | AT13: 29566 | AU13: 24800 | AV13: 36971 | AW13: =AV13/AU13 -> 1.4907661 | AX13: =AV13/AT13-1 -> 0.25045661 | AY13: 23119 | AZ13: 24800 | BA13: 52236 | BB13: =BA13/AZ13 -> 2.1062903 | BC13: =BA13/AY13-1 -> 1.2594403 | BD13: 22190 | BE13: 24800 | BF13: 48720 | BG13: =BF13/BE13 -> 1.9645161 | BH13: =BF13/BD13-1 -> 1.1955836 | BI13: 21788 | BJ13: 29450 | BK13: 35752 | BL13: =BK13/BJ13 -> 1.2139898 | BM13: =BK13/BI13-1 -> 0.64090325
G14: =G6-G23-G10 -> 0 | H14: =H6-H23-H10 -> 0
G15: =G6-G10 -> 3416323 | H15: =H6-H10 -> 3637092 | I15: b2b-5% | K15: =K6-K10 -> 2992673 | L15: =L6-L10 -> 3300750 | M15: =M6-M10 -> 3137371 | P15: =P6-P10 -> 253627 | Q15: =Q6-Q10 -> 283500 | R15: =R6-R10 -> 256486 | U15: =U6-U10 -> 225355 | V15: =V6-V10 -> 324000 | W15: =W6-W10 -> 294876 | Z15: =Z6-Z10 -> 347567 | AA15: =AA6-AA10 -> 364500 | AB15: =AB6-AB10 -> 297790 | AE15: =AE6-AE10 -> 321962 | AF15: =AF6-AF10 -> 324000 | AG15: =AG6-AG10 -> 346041 | AJ15: =AJ6-AJ10 -> 272969 | AK15: =AK6-AK10 -> 324000 | AL15: =AL6-AL10 -> 348309 | AO15: =AO6-AO10 -> 302276 | AP15: =AP6-AP10 -> 324000 | AQ15: =AQ6-AQ10 -> 322802 | AT15: =AT6-AT10 -> 291313 | AU15: =AU6-AU10 -> 324000 | AV15: =AV6-AV10 -> 299176 | AY15: =AY6-AY10 -> 300731 | AZ15: =AZ6-AZ10 -> 324000 | BA15: =BA6-BA10 -> 294008 | BD15: =BD6-BD10 -> 282677 | BE15: =BE6-BE10 -> 324000 | BF15: =BF6-BF10 -> 338649 | BI15: =BI6-BI10 -> 394196 | BJ15: =BJ6-BJ10 -> 384750 | BK15: =BK6-BK10 -> 339234
I16: 남부-10%
R17: =R6-#REF! -> #REF! | W17: =W6-#REF! -> #REF! | AB17: =AB6-#REF! -> #REF! | AG17: =AG6-#REF! -> #REF! | AL17: =AL6-#REF! -> #REF! | AQ17: =AQ6-#REF! -> #REF! | AV17: =AV6-#REF! -> #REF! | BA17: =BA6-#REF! -> #REF! | BF17: =BF6-#REF! -> #REF! | BK17: =BK6-#REF! -> #REF!
D18: Fleet | F18: 480
D19: LCC | F19: 31784 | G19: =+G7+G8+G9+G10-E18-E19 -> 4026494 | H19: =+H7+H8+H9+H10-F18-F19 -> 4162441 | I19: =I6-I10 -> 4050000 | K19: =K6-K10 -> 2992673 | L19: =L6-L10 -> 3300750 | M19: =M6-M10 -> 3137371 | P19: =P6-P10 -> 253627 | Q19: =Q6-Q10 -> 283500 | R19: =R6-R10 -> 256486 | U19: =U6-U10 -> 225355 | V19: =V6-V10 -> 324000 | W19: =W6-W10 -> 294876 | Z19: =Z6-Z10 -> 347567 | AA19: =AA6-AA10 -> 364500 | AB19: =AB6-AB10 -> 297790 | AE19: =AE6-AE10 -> 321962 | AF19: =AF6-AF10 -> 324000 | AG19: =AG6-AG10 -> 346041 | AJ19: =AJ6-AJ10 -> 272969 | AK19: =AK6-AK10 -> 324000 | AL19: =AL6-AL10 -> 348309 | AO19: =AO6-AO10 -> 302276 | AP19: =AP6-AP10 -> 324000 | AQ19: =AQ6-AQ10 -> 322802 | AT19: =AT6-AT10 -> 291313 | AU19: =AU6-AU10 -> 324000 | AV19: =AV6-AV10 -> 299176 | AY19: =AY6-AY10 -> 300731 | AZ19: =AZ6-AZ10 -> 324000 | BA19: =BA6-BA10 -> 294008 | BD19: =BD6-BD10 -> 282677 | BE19: =BE6-BE10 -> 324000 | BF19: =BF6-BF10 -> 338649 | BI19: =BI6-BI10 -> 394196 | BJ19: =BJ6-BJ10 -> 384750 | BK19: =BK6-BK10 -> 339234
B21: 구 분 (PVL, CVL) | E21: 전체 거래처수 | F21: 거래처수 | G21: 2023년 실적 | H21: 2024년 실적 | I21: 2025년 계획 | J21: 증감율 | K21: 누적실적 | P21: 1월 | U21: 2월 | Z21: 3월 | AE21: 4월 | AJ21: 5월 | AO21: 6월 | AT21: 7월 | AY21: 8월 | BD21: 9월 | BI21: 10월
K22: 2024년 | L22: 목표 | M22: 2025년 | N22: 달성율 | O22: 증감율 | P22: 2024년 | Q22: 목표 | R22: 2025년 | S22: 달성율 | T22: 증감율 | U22: 2024년 | V22: 목표 | W22: 2025년 | X22: 달성율 | Y22: 증감율 | Z22: 2024년 | AA22: 목표 | AB22: 2025년 | AC22: 달성율 | AD22: 증감율 | AE22: 2024년 | AF22: 목표 | AG22: 2025년 | AH22: 달성율 | AI22: 증감율 | AJ22: 2024년 | AK22: 목표 | AL22: 2025년 | AM22: 달성율 | AN22: 증감율 | AO22: 2024년 | AP22: 목표 | AQ22: 2025년 | AR22: 달성율 | AS22: 증감율 | AT22: 2024년 | AU22: 목표 | AV22: 2025년 | AW22: 달성율 | AX22: 증감율 | AY22: 2024년 | AZ22: 목표 | BA22: 2025년 | BB22: 달성율 | BC22: 증감율 | BD22: 2024년 | BE22: 목표 | BF22: 2025년 | BG22: 달성율 | BH22: 증감율 | BI22: 2024년 | BJ22: 목표 | BK22: 2025년 | BL22: 달성율 | BM22: 증감율
B23: B2C 총 계 | E23: =+E24+E31+E41+E48+E55+E62+E72+E77 -> 1273 | F23: =+F24+F31+F41+F48+F55+F62+F72+F77 -> 1222 | G23: =+G24+G31+G41+G48+G55+G62+G72+G77 -> 3416323 | H23: =+H24+H31+H41+H48+H55+H62+H72+H77 -> 3637092 | I23: =+I24+I31+I41+I48+I55+I62+I72+I77 -> 4050000 | J23: =I23/H23-1 -> 0.11352696 | K23: =+K24+K31+K41+K48+K55+K62+K72+K77 -> 2992673 | L23: =+L24+L31+L41+L48+L55+L62+L72+L77 -> 3300750 | M23: =+M24+M31+M41+M48+M55+M62+M72+M77 -> 3137371 | N23: =M23/L23 -> 0.95050246 | O23: =M23/K23-1 -> 0.048350755 | P23: =+P24+P31+P41+P48+P55+P62+P72+P77 -> 253627 | Q23: =+Q24+Q31+Q41+Q48+Q55+Q62+Q72+Q77 -> 283500 | R23: =+R24+R31+R41+R48+R55+R62+R72+R77 -> 256486 | S23: =R23/Q23 -> 0.90471252 | T23: =R23/P23-1 -> 0.011272459 | U23: =+U24+U31+U41+U48+U55+U62+U72+U77 -> 225355 | V23: =+V24+V31+V41+V48+V55+V62+V72+V77 -> 324000 | W23: =+W24+W31+W41+W48+W55+W62+W72+W77 -> 294876 | X23: =W23/V23 -> 0.91011111 | Y23: =W23/U23-1 -> 0.30849548 | Z23: =+Z24+Z31+Z41+Z48+Z55+Z62+Z72+Z77 -> 347567 | AA23: =+AA24+AA31+AA41+AA48+AA55+AA62+AA72+AA77 -> 364500 | AB23: =+AB24+AB31+AB41+AB48+AB55+AB62+AB72+AB77 -> 297790 | AC23: =AB23/AA23 -> 0.81698217 | AD23: =AB23/Z23-1 -> -0.14321555 | AE23: =+AE24+AE31+AE41+AE48+AE55+AE62+AE72+AE77 -> 321962 | AF23: =+AF24+AF31+AF41+AF48+AF55+AF62+AF72+AF77 -> 324000 | AG23: =+AG24+AG31+AG41+AG48+AG55+AG62+AG72+AG77 -> 346041 | AH23: =AG23/AF23 -> 1.0680278 | AI23: =AG23/AE23-1 -> 0.074788329 | AJ23: =+AJ24+AJ31+AJ41+AJ48+AJ55+AJ62+AJ72+AJ77 -> 272969 | AK23: =+AK24+AK31+AK41+AK48+AK55+AK62+AK72+AK77 -> 324000 | AL23: =+AL24+AL31+AL41+AL48+AL55+AL62+AL72+AL77 -> 348309 | AM23: =AL23/AK23 -> 1.0750278 | AN23: =AL23/AJ23-1 -> 0.27600204 | AO23: =+AO24+AO31+AO41+AO48+AO55+AO62+AO72+AO77 -> 302276 | AP23: =+AP24+AP31+AP41+AP48+AP55+AP62+AP72+AP77 -> 324000 | AQ23: =+AQ24+AQ31+AQ41+AQ48+AQ55+AQ62+AQ72+AQ77 -> 322802 | AR23: =AQ23/AP23 -> 0.99630247 | AS23: =AQ23/AO23-1 -> 0.067904829 | AT23: =+AT24+AT31+AT41+AT48+AT55+AT62+AT72+AT77 -> 291313 | AU23: =+AU24+AU31+AU41+AU48+AU55+AU62+AU72+AU77 -> 324000 | AV23: =+AV24+AV31+AV41+AV48+AV55+AV62+AV72+AV77 -> 299176 | AW23: =AV23/AU23 -> 0.92338272 | AX23: =AV23/AT23-1 -> 0.026991586 | AY23: =+AY24+AY31+AY41+AY48+AY55+AY62+AY72+AY77 -> 300731 | AZ23: =+AZ24+AZ31+AZ41+AZ48+AZ55+AZ62+AZ72+AZ77 -> 324000 | BA23: =+BA24+BA31+BA41+BA48+BA55+BA62+BA72+BA77 -> 294008 | BB23: =BA23/AZ23 -> 0.9074321 | BC23: =BA23/AY23-1 -> -0.022355527 | BD23: =+BD24+BD31+BD41+BD48+BD55+BD62+BD72+BD77 -> 282677 | BE23: =+BE24+BE31+BE41+BE48+BE55+BE62+BE72+BE77 -> 324000 | BF23: =+BF24+BF31+BF41+BF48+BF55+BF62+BF72+BF77 -> 338649 | BG23: =BF23/BE23 -> 1.045213 | BH23: =BF23/BD23-1 -> 0.19800691 | BI23: =+BI24+BI31+BI41+BI48+BI55+BI62+BI72+BI77 -> 394196 | BJ23: =+BJ24+BJ31+BJ41+BJ48+BJ55+BJ62+BJ72+BJ77 -> 384750 | BK23: =+BK24+BK31+BK41+BK48+BK55+BK62+BK72+BK77 -> 339234 | BL23: =BK23/BJ23 -> 0.88169981 | BM23: =BK23/BI23-1 -> -0.1394281
B24: 맥심팀 | C24: 합계 | E24: =E25+E28 -> 219 | F24: =F25+F28 -> 215 | G24: =G25+G28 -> 321951 | H24: =H25+H28 -> 326900 | I24: =I25+I28 -> 380000 | J24: =I24/H24-1 -> 0.162435 | K24: =K25+K28 -> 266619 | L24: =L25+L28 -> 309700 | M24: =M25+M28 -> 261116 | N24: =M24/L24 -> 0.84312561 | O24: =M24/K24-1 -> -0.020639939 | P24: =P25+P28 -> 25459 | Q24: =Q25+Q28 -> 26600 | R24: =R25+R28 -> 23074 | S24: =R24/Q24 -> 0.86744361 | T24: =R24/P24-1 -> -0.093680035 | U24: =U25+U28 -> 23473 | V24: =V25+V28 -> 30400 | W24: =W25+W28 -> 27234 | X24: =W24/V24 -> 0.89585526 | Y24: =W24/U24-1 -> 0.16022664 | Z24: =Z25+Z28 -> 29112 | AA24: =AA25+AA28 -> 34200 | AB24: =AB25+AB28 -> 24427 | AC24: =AB24/AA24 -> 0.71423977 | AD24: =AB24/Z24-1 -> -0.1609302 | AE24: =AE25+AE28 -> 26255 | AF24: =AF25+AF28 -> 30400 | AG24: =AG25+AG28 -> 28476 | AH24: =AG24/AF24 -> 0.93671053 | AI24: =AG24/AE24-1 -> 0.084593411 | AJ24: =AJ25+AJ28 -> 25884 | AK24: =AK25+AK28 -> 30400 | AL24: =AL25+AL28 -> 24269 | AM24: =AL24/AK24 -> 0.79832237 | AN24: =AL24/AJ24-1 -> -0.062393757 | AO24: =AO25+AO28 -> 25094 | AP24: =AP25+AP28 -> 30400 | AQ24: =AQ25+AQ28 -> 28653 | AR24: =AQ24/AP24 -> 0.94253289 | AS24: =AQ24/AO24-1 -> 0.14182673 | AT24: =AT25+AT28 -> 27682 | AU24: =AU25+AU28 -> 30400 | AV24: =AV25+AV28 -> 26218 | AW24: =AV24/AU24 -> 0.86243421 | AX24: =AV24/AT24-1 -> -0.052886352 | AY24: =AY25+AY28 -> 30232 | AZ24: =AZ25+AZ28 -> 30400 | BA24: =BA25+BA28 -> 22603 | BB24: =BA24/AZ24 -> 0.74351974 | BC24: =BA24/AY24-1 -> -0.2523485 | BD24: =BD25+BD28 -> 25176 | BE24: =BE25+BE28 -> 30400 | BF24: =BF25+BF28 -> 30270 | BG24: =BF24/BE24 -> 0.99572368 | BH24: =BF24/BD24-1 -> 0.20233556 | BI24: =BI25+BI28 -> 28252 | BJ24: =BJ25+BJ28 -> 36100 | BK24: =BK25+BK28 -> 25892 | BL24: =BK24/BJ24 -> 0.71722992 | BM24: =BK24/BI24-1 -> -0.083533909
C25: 심경섭 | D25: 소계 | E25: =SUM(E26:E27) -> 121 | F25: =SUM(F26:F27) -> 118 | G25: =SUM(G26:G27) -> 159117 | H25: =SUM(H26:H27) -> 167460 | I25: =SUM(I26:I27) -> 195000 | J25: =I25/H25-1 -> 0.16445718 | K25: =SUM(K26:K27) -> 136046 | L25: =SUM(L26:L27) -> 158925 | M25: =SUM(M26:M27) -> 129026 | N25: =M25/L25 -> 0.81186723 | O25: =M25/K25-1 -> -0.051600194 | P25: =SUM(P26:P27) -> 13407 | Q25: =SUM(Q26:Q27) -> 13650 | R25: =SUM(R26:R27) -> 11026 | S25: =R25/Q25 -> 0.80776557 | T25: =R25/P25-1 -> -0.17759379 | U25: =SUM(U26:U27) -> 10671 | V25: =SUM(V26:V27) -> 15600 | W25: =SUM(W26:W27) -> 12810 | X25: =W25/V25 -> 0.82115385 | Y25: =W25/U25-1 -> 0.20044982 | Z25: =SUM(Z26:Z27) -> 13216 | AA25: =SUM(AA26:AA27) -> 17550 | AB25: =SUM(AB26:AB27) -> 13611 | AC25: =AB25/AA25 -> 0.77555556 | AD25: =AB25/Z25-1 -> 0.029888015 | AE25: =SUM(AE26:AE27) -> 14207 | AF25: =SUM(AF26:AF27) -> 15600 | AG25: =SUM(AG26:AG27) -> 14122 | AH25: =AG25/AF25 -> 0.90525641 | AI25: =AG25/AE25-1 -> -0.0059829661 | AJ25: =SUM(AJ26:AJ27) -> 13712 | AK25: =SUM(AK26:AK27) -> 15600 | AL25: =SUM(AL26:AL27) -> 12675 | AM25: =AL25/AK25 -> 0.8125 | AN25: =AL25/AJ25-1 -> -0.075627188 | AO25: =SUM(AO26:AO27) -> 12397 | AP25: =SUM(AP26:AP27) -> 15600 | AQ25: =SUM(AQ26:AQ27) -> 14034 | AR25: =AQ25/AP25 -> 0.89961538 | AS25: =AQ25/AO25-1 -> 0.13204808 | AT25: =SUM(AT26:AT27) -> 15198 | AU25: =SUM(AU26:AU27) -> 15600 | AV25: =SUM(AV26:AV27) -> 12640 | AW25: =AV25/AU25 -> 0.81025641 | AX25: =AV25/AT25-1 -> -0.16831162 | AY25: =SUM(AY26:AY27) -> 15530 | AZ25: =SUM(AZ26:AZ27) -> 15600 | BA25: =SUM(BA26:BA27) -> 11837 | BB25: =BA25/AZ25 -> 0.75878205 | BC25: =BA25/AY25-1 -> -0.23779781 | BD25: =SUM(BD26:BD27) -> 12802 | BE25: =SUM(BE26:BE27) -> 15600 | BF25: =SUM(BF26:BF27) -> 14460 | BG25: =BF25/BE25 -> 0.92692308 | BH25: =BF25/BD25-1 -> 0.12951101 | BI25: =SUM(BI26:BI27) -> 14906 | BJ25: =SUM(BJ26:BJ27) -> 18525 | BK25: =SUM(BK26:BK27) -> 11811 | BL25: =BK25/BJ25 -> 0.63757085 | BM25: =BK25/BI25-1 -> -0.20763451
D26: Fleet | E26: 1 | F26: 1 | H26: 800 | J26: =I26/H26-1 -> -1 | K26: =P26+U26+Z26+AE26+AJ26+AO26+AT26+AY26+BD26+BI26+BN26+BS26 -> 800 | L26: =Q26+V26+AA26+AF26+AK26+AP26+AU26+AZ26+BE26+BJ26+BO26+BT26 -> 0 | M26: =R26+W26+AB26+AG26+AL26+AQ26+AV26+BA26+BF26+BK26+BP26+BU26 -> 600 | N26: =M26/L26 -> #DIV/0! | O26: =M26/K26-1 -> -0.25 | S26: =R26/Q26 -> #DIV/0! | T26: =R26/P26-1 -> #DIV/0! | X26: =W26/V26 -> #DIV/0! | Y26: =W26/U26-1 -> #DIV/0! | AC26: =AB26/AA26 -> #DIV/0! | AD26: =AB26/Z26-1 -> #DIV/0! | AG26: 600 | AH26: =AG26/AF26 -> #DIV/0! | AI26: =AG26/AE26-1 -> #DIV/0! | AM26: =AL26/AK26 -> #DIV/0! | AN26: =AL26/AJ26-1 -> #DIV/0! | AR26: =AQ26/AP26 -> #DIV/0! | AS26: =AQ26/AO26-1 -> #DIV/0! | AT26: 800 | AW26: =AV26/AU26 -> #DIV/0! | AX26: =AV26/AT26-1 -> -1 | BB26: =BA26/AZ26 -> #DIV/0! | BC26: =BA26/AY26-1 -> #DIV/0! | BG26: =BF26/BE26 -> #DIV/0! | BH26: =BF26/BD26-1 -> #DIV/0! | BL26: =BK26/BJ26 -> #DIV/0! | BM26: =BK26/BI26-1 -> #DIV/0!
D27: LCC | E27: 120 | F27: 117 | G27: 159117 | H27: 166660 | I27: 195000 | J27: =I27/H27-1 -> 0.1700468 | K27: =P27+U27+Z27+AE27+AJ27+AO27+AT27+AY27+BD27+BI27+BN27+BS27 -> 135246 | L27: =Q27+V27+AA27+AF27+AK27+AP27+AU27+AZ27+BE27+BJ27+BO27+BT27 -> 158925 | M27: =R27+W27+AB27+AG27+AL27+AQ27+AV27+BA27+BF27+BK27+BP27+BU27 -> 128426 | N27: =M27/L27 -> 0.80809187 | O27: =M27/K27-1 -> -0.05042663 | P27: 13407 | Q27: 13650 | R27: 11026 | S27: =R27/Q27 -> 0.80776557 | T27: =R27/P27-1 -> -0.17759379 | U27: 10671 | V27: 15600 | W27: 12810 | X27: =W27/V27 -> 0.82115385 | Y27: =W27/U27-1 -> 0.20044982 | Z27: 13216 | AA27: 17550 | AB27: 13611 | AC27: =AB27/AA27 -> 0.77555556 | AD27: =AB27/Z27-1 -> 0.029888015 | AE27: 14207 | AF27: 15600 | AG27: 13522 | AH27: =AG27/AF27 -> 0.86679487 | AI27: =AG27/AE27-1 -> -0.048215668 | AJ27: 13712 | AK27: 15600 | AL27: 12675 | AM27: =AL27/AK27 -> 0.8125 | AN27: =AL27/AJ27-1 -> -0.075627188 | AO27: 12397 | AP27: 15600 | AQ27: 14034 | AR27: =AQ27/AP27 -> 0.89961538 | AS27: =AQ27/AO27-1 -> 0.13204808 | AT27: 14398 | AU27: 15600 | AV27: 12640 | AW27: =AV27/AU27 -> 0.81025641 | AX27: =AV27/AT27-1 -> -0.12210029 | AY27: 15530 | AZ27: 15600 | BA27: 11837 | BB27: =BA27/AZ27 -> 0.75878205 | BC27: =BA27/AY27-1 -> -0.23779781 | BD27: 12802 | BE27: 15600 | BF27: 14460 | BG27: =BF27/BE27 -> 0.92692308 | BH27: =BF27/BD27-1 -> 0.12951101 | BI27: 14906 | BJ27: 18525 | BK27: 11811 | BL27: =BK27/BJ27 -> 0.63757085 | BM27: =BK27/BI27-1 -> -0.20763451
C28: 이상욱 | D28: 소계 | E28: =SUM(E29:E30) -> 98 | F28: =SUM(F29:F30) -> 97 | G28: =SUM(G29:G30) -> 162834 | H28: =SUM(H29:H30) -> 159440 | I28: =SUM(I29:I30) -> 185000 | J28: =I28/H28-1 -> 0.16031109 | K28: =SUM(K29:K30) -> 130573 | L28: =SUM(L29:L30) -> 150775 | M28: =SUM(M29:M30) -> 132090 | N28: =M28/L28 -> 0.87607362 | O28: =M28/K28-1 -> 0.011618022 | P28: =SUM(P29:P30) -> 12052 | Q28: =SUM(Q29:Q30) -> 12950 | R28: =SUM(R29:R30) -> 12048 | S28: =R28/Q28 -> 0.93034749 | T28: =R28/P28-1 -> -0.00033189512 | U28: =SUM(U29:U30) -> 12802 | V28: =SUM(V29:V30) -> 14800 | W28: =SUM(W29:W30) -> 14424 | X28: =W28/V28 -> 0.97459459 | Y28: =W28/U28-1 -> 0.12669895 | Z28: =SUM(Z29:Z30) -> 15896 | AA28: =SUM(AA29:AA30) -> 16650 | AB28: =SUM(AB29:AB30) -> 10816 | AC28: =AB28/AA28 -> 0.64960961 | AD28: =AB28/Z28-1 -> -0.31957725 | AE28: =SUM(AE29:AE30) -> 12048 | AF28: =SUM(AF29:AF30) -> 14800 | AG28: =SUM(AG29:AG30) -> 14354 | AH28: =AG28/AF28 -> 0.96986486 | AI28: =AG28/AE28-1 -> 0.19140106 | AJ28: =SUM(AJ29:AJ30) -> 12172 | AK28: =SUM(AK29:AK30) -> 14800 | AL28: =SUM(AL29:AL30) -> 11594 | AM28: =AL28/AK28 -> 0.78337838 | AN28: =AL28/AJ28-1 -> -0.047486034 | AO28: =SUM(AO29:AO30) -> 12697 | AP28: =SUM(AP29:AP30) -> 14800 | AQ28: =SUM(AQ29:AQ30) -> 14619 | AR28: =AQ28/AP28 -> 0.98777027 | AS28: =AQ28/AO28-1 -> 0.15137434 | AT28: =SUM(AT29:AT30) -> 12484 | AU28: =SUM(AU29:AU30) -> 14800 | AV28: =SUM(AV29:AV30) -> 13578 | AW28: =AV28/AU28 -> 0.91743243 | AX28: =AV28/AT28-1 -> 0.087632169 | AY28: =SUM(AY29:AY30) -> 14702 | AZ28: =SUM(AZ29:AZ30) -> 14800 | BA28: =SUM(BA29:BA30) -> 10766 | BB28: =BA28/AZ28 -> 0.72743243 | BC28: =BA28/AY28-1 -> -0.26771868 | BD28: =SUM(BD29:BD30) -> 12374 | BE28: =SUM(BE29:BE30) -> 14800 | BF28: =SUM(BF29:BF30) -> 15810 | BG28: =BF28/BE28 -> 1.0682432 | BH28: =BF28/BD28-1 -> 0.277679 | BI28: =SUM(BI29:BI30) -> 13346 | BJ28: =SUM(BJ29:BJ30) -> 17575 | BK28: =SUM(BK29:BK30) -> 14081 | BL28: =BK28/BJ28 -> 0.80119488 | BM28: =BK28/BI28-1 -> 0.055072681
D29: Fleet | E29: 14 | F29: 14 | G29: 16716 | H29: 20028 | I29: 23000 | J29: =I29/H29-1 -> 0.14839225 | K29: =P29+U29+Z29+AE29+AJ29+AO29+AT29+AY29+BD29+BI29+BN29+BS29 -> 17016 | L29: =Q29+V29+AA29+AF29+AK29+AP29+AU29+AZ29+BE29+BJ29+BO29+BT29 -> 18745 | M29: =R29+W29+AB29+AG29+AL29+AQ29+AV29+BA29+BF29+BK29+BP29+BU29 -> 16692 | N29: =M29/L29 -> 0.89047746 | O29: =M29/K29-1 -> -0.019040903 | P29: 2064 | Q29: 1610 | R29: 1600 | S29: =R29/Q29 -> 0.99378882 | T29: =R29/P29-1 -> -0.2248062 | U29: 1200 | V29: 1840 | W29: 2580 | X29: =W29/V29 -> 1.4021739 | Y29: =W29/U29-1 -> 1.15 | Z29: 4200 | AA29: 2070 | AB29: 1200 | AC29: =AB29/AA29 -> 0.57971014 | AD29: =AB29/Z29-1 -> -0.71428571 | AE29: 600 | AF29: 1840 | AG29: 1900 | AH29: =AG29/AF29 -> 1.0326087 | AI29: =AG29/AE29-1 -> 2.1666667 | AJ29: 1680 | AK29: 1840 | AL29: 1400 | AM29: =AL29/AK29 -> 0.76086957 | AN29: =AL29/AJ29-1 -> -0.16666667 | AO29: 1000 | AP29: 1840 | AQ29: 2400 | AR29: =AQ29/AP29 -> 1.3043478 | AS29: =AQ29/AO29-1 -> 1.4 | AT29: 1800 | AU29: 1840 | AV29: 1000 | AW29: =AV29/AU29 -> 0.54347826 | AX29: =AV29/AT29-1 -> -0.44444444 | AY29: 1740 | AZ29: 1840 | BA29: 1600 | BB29: =BA29/AZ29 -> 0.86956522 | BC29: =BA29/AY29-1 -> -0.08045977 | BD29: 1320 | BE29: 1840 | BF29: 1412 | BG29: =BF29/BE29 -> 0.7673913 | BH29: =BF29/BD29-1 -> 0.06969697 | BI29: 1412 | BJ29: 2185 | BK29: 1600 | BL29: =BK29/BJ29 -> 0.73226545 | BM29: =BK29/BI29-1 -> 0.13314448
D30: LCC | E30: 84 | F30: 83 | G30: 146118 | H30: 139412 | I30: 162000 | J30: =I30/H30-1 -> 0.16202336 | K30: =P30+U30+Z30+AE30+AJ30+AO30+AT30+AY30+BD30+BI30+BN30+BS30 -> 113557 | L30: =Q30+V30+AA30+AF30+AK30+AP30+AU30+AZ30+BE30+BJ30+BO30+BT30 -> 132030 | M30: =R30+W30+AB30+AG30+AL30+AQ30+AV30+BA30+BF30+BK30+BP30+BU30 -> 115398 | N30: =M30/L30 -> 0.87402863 | O30: =M30/K30-1 -> 0.016212123 | P30: 9988 | Q30: 11340 | R30: 10448 | S30: =R30/Q30 -> 0.92134039 | T30: =R30/P30-1 -> 0.046055266 | U30: 11602 | V30: 12960 | W30: 11844 | X30: =W30/V30 -> 0.91388889 | Y30: =W30/U30-1 -> 0.020858473 | Z30: 11696 | AA30: 14580 | AB30: 9616 | AC30: =AB30/AA30 -> 0.65953361 | AD30: =AB30/Z30-1 -> -0.17783858 | AE30: 11448 | AF30: 12960 | AG30: 12454 | AH30: =AG30/AF30 -> 0.96095679 | AI30: =AG30/AE30-1 -> 0.087875611 | AJ30: 10492 | AK30: 12960 | AL30: 10194 | AM30: =AL30/AK30 -> 0.78657407 | AN30: =AL30/AJ30-1 -> -0.028402592 | AO30: 11697 | AP30: 12960 | AQ30: 12219 | AR30: =AQ30/AP30 -> 0.94282407 | AS30: =AQ30/AO30-1 -> 0.044626827 | AT30: 10684 | AU30: 12960 | AV30: 12578 | AW30: =AV30/AU30 -> 0.97052469 | AX30: =AV30/AT30-1 -> 0.17727443 | AY30: 12962 | AZ30: 12960 | BA30: 9166 | BB30: =BA30/AZ30 -> 0.70725309 | BC30: =BA30/AY30-1 -> -0.29285604 | BD30: 11054 | BE30: 12960 | BF30: 14398 | BG30: =BF30/BE30 -> 1.1109568 | BH30: =BF30/BD30-1 -> 0.30251493 | BI30: 11934 | BJ30: 15390 | BK30: 12481 | BL30: =BK30/BJ30 -> 0.81098116 | BM30: =BK30/BI30-1 -> 0.045835428
