Workbook

Sheet 미출
A1: Sales_Document | B1: Name_1 | C1: Ship-to | D1: Material | E1: Description | F1: Open_orders_quantity | G1: Created_On | H1: Requested_delivdate | I1: Remark
A2: 2102721484 | B2: YOUNGIL O & C-GP | C2: YOUNGIL O&C-DP | D2: 142288 | E2: M-PYROTEC HFD 46B DRUM-R 230KG | F2: 20 | G2: 45399 | H2: 45497 | I2: 수입일정확인
A3: 2102721484 | B3: YOUNGIL O & C-GP | C3: YOUNGIL O&C-DP | D3: 140259 | E3: MOBILUX EP 023 DRUM 180KG:SG | F3: 7 | G3: 45399 | H3: 45497 | I3: 수입일정확인
A4: 2102718592 | B4: YOUNGIL O & C-GP | C4: YOUNGIL O&C-DP | D4: 134997 | E4: MOBILTEMP SHC 32,35LB PAIL | F4: 7 | G4: 45393 | H4: 45491 | I4: 수입일정확인
A5: 2102713865 | B5: YOUNGIL O & C-GP | C5: YOUNGIL O&C-DP | D5: 134997 | E5: MOBILTEMP SHC 32,35LB PAIL | F5: 3 | G5: 45384 | H5: 45483 | I5: 수입일정확인
A6: 2102725749 | B6: YOUNGIL O & C-GP | C6: YOUNGIL O&C-DP | D6: 123336 | E6: MOBIL VELOCITE NO 3 PAIL 20L | F6: 28 | G6: 45406 | H6: 45411 | I6: re-packing예정
A7: 2102724847 | B7: YOUNGIL O & C-GP | C7: YOUNGIL O&C-DP | D7: 139041 | E7: MOBIL DTE 732 PAIL 20L:KR | F7: 2 | G7: 45405 | H7: 45408 | I7: re-packing예정
A8: 2102724847 | B8: YOUNGIL O & C-GP | C8: YOUNGIL O&C-DP | D8: 135542 | E8: MOBIL VACUO 533-PL20L | F8: 10 | G8: 45405 | H8: 45408 | I8: re-packing예정
A9: 2102724068 | B9: YOUNGIL O & C-GP | C9: YOUNGIL O&C-DP | D9: 140200 | E9: MOBILITH SHC 100 PAIL 16KG:SG | F9: 11 | G9: 45404 | H9: 45407 | I9: 수입일정확인
A10: 2102722228 | B10: YOUNGIL O & C-GP | C10: YOUNGIL O&C-DP | D10: 141741 | E10: MOBIL DTE 24 ULTRA PAIL 20L:KR | F10: 28 | G10: 45400 | H10: 45405 | I10: 04/25(목)생산예상
A11: 2102721485 | B11: YOUNGIL O & C-GP | C11: YOUNGIL O&C-DP | D11: 135016 | E11: MOBIL GLYGOYLE 460, 20LT PAIL | F11: 4 | G11: 45399 | H11: 45404 | I11: 수입일정확인
A12: 2102721485 | B12: YOUNGIL O & C-GP | C12: YOUNGIL O&C-DP | D12: 122837 | E12: MOBIL RARUS 424 PAIL 20L | F12: 28 | G12: 45399 | H12: 45404 | I12: 생산대기
A13: 2102721485 | B13: YOUNGIL O & C-GP | C13: YOUNGIL O&C-DP | D13: 139070 | E13: MOBIL GLYGOYLE 30 PAIL 20L:KR | F13: 5 | G13: 45399 | H13: 45404 | I13: re-packing예정
... A20: 2102709230 | B20: YOUNGIL O & C-GP | C20: YOUNGIL O&C-DP | D20: 135016 | E20: MOBIL GLYGOYLE 460, 20LT PAIL | F20: 3 | G20: 45376 | H20: 45379 | I20: 수입일정확인
A22: 2102725749 | B22: YOUNGIL O & C-GP | C22: YOUNGIL O&C-DP | D22: 123330 | E22: VACUUM PUMP OIL, 20LT, PAIL | F22: 14 | G22: 24.04.2024 | H22: 29.04.2024 | I22: HW20240424
A23: 2102685012 | B23: YOUNGIL O & C-GP | C23: YOUNGIL O&C-DP | D23: 135152 | E23: MOBIL SHC CIBUS 220, 20LT PAIL | F23: 1 | G23: 13.02.2024 | H23: 22.05.2024 | I23: HW20240213

Sheet 양식
B2: 발 주 서 | M2: 발주 접수처 (엑슨모빌 중국 상하이 고객지원팀)
M3: · 부서메일주소 : koreadcp@exxonmobil.com
M4: · 수신부담팩스 : 00798 8521 8501
M5: · 수신부담전화 : 00798 8521 8503
B7: 대리점명 | D7: (주)영일오엔씨 | F7: 대리점코드 | G7: 모빌(194637) | K7: 발주일 | L7: =TODAY() -> 45981 | N7: 납기일 | O7: =TODAY()+1 -> 45982
B8: 전화번호 | D8: 02-2693-5189 | F8: 팩스번호 | G8: 02-2693-5902 | K8: 담당자 | L8: 조윤석 팀장 | N8: 연락처 | O8: 031-8059-5151
B9: 주소 | K9: 납 지 | L9: 영일-화성 | M9: =IF($L9<>0,VLOOKUP($L9,$G$54:$K$76,2,FALSE),"") -> 경기도 화성시 향남읍 구문천1길 43-9
B11: 순번 (No.) | C11: 발주처 | D11: 거래처명 (Ship to) | E11: 코드번호 (Child Code) | F11: 제품코드 (P-Code) | G11: 제품명 (Product Name) | J11: 규격 (Package) | K11: 제품군 (Lob) | L11: 수량 (Quanty) | M11: 물량/리터 (Volume) | N11: 단가 (Unit Price) | O11: 금액(별도) (Amounts) | P11: 오더번호 | R11: 발주단위 | U11: 금액(포함) | V11: 미출수량 | W11: 중복 | X11: 전일발주수량 | Y11: 단가 | Z11: 확인
B12: 1 | D12: 화성창고-일반가 | E12: =IF($D12<>0,VLOOKUP($D12,$D$54:$E$77,2,FALSE),"") -> 194667 | G12: =IF($F12<>0,VLOOKUP($F12,$E$79:$M$535,2,FALSE),"") | J12: =IF($F12<>0,VLOOKUP($F12,$E$79:$M$535,7,FALSE),"") | K12: =IF($F12<>0,VLOOKUP($F12,$E$79:$M$535,8,FALSE),"") | M12: =IF($L12<>0,VLOOKUP($F12,$E$79:$M$535,9,FALSE)*$L12,"") | N12: =IF($F12<>0,VLOOKUP($F12,$E$62:$L$543,5,FALSE),"") | O12: =IF(L12<>0,$L12*$N12,"") | R12: =VLOOKUP(F12,'파레트 제품 리스트'!$B:$F,4,0) -> #N/A | S12: =VLOOKUP(F12,'파레트 제품 리스트'!$B:$F,5,0) -> #N/A | U12: =O12*1.1 -> #VALUE! | V12: =VLOOKUP(F12,미출!$D:$F,3,0) -> #N/A | W12: =COUNTIF($F$11:$F$13,F12) -> 0 | X12: =VLOOKUP(F12,#REF!,7,0) -> #REF! | Z12: =N12=Y12 -> TRUE
B13: 2 | D13: 화성창고-일반가 | E13: =IF($D13<>0,VLOOKUP($D13,$D$54:$E$77,2,FALSE),"") -> 194667 | G13: =IF($F13<>0,VLOOKUP($F13,$E$79:$M$535,2,FALSE),"") | J13: =IF($F13<>0,VLOOKUP($F13,$E$79:$M$535,7,FALSE),"") | K13: =IF($F13<>0,VLOOKUP($F13,$E$79:$M$535,8,FALSE),"") | M13: =IF($L13<>0,VLOOKUP($F13,$E$79:$M$535,9,FALSE)*$L13,"") | N13: =IF($F13<>0,VLOOKUP($F13,$E$62:$L$543,5,FALSE),"") | O13: =IF(L13<>0,$L13*$N13,"") | R13: =VLOOKUP(F13,'파레트 제품 리스트'!$B:$F,4,0) -> #N/A | S13: =VLOOKUP(F13,'파레트 제품 리스트'!$B:$F,5,0) -> #N/A | U13: =O13*1.1 -> #VALUE! | V13: =VLOOKUP(F13,미출!$D:$F,3,0) -> #N/A | W13: =COUNTIF($F$11:$F$13,F13) -> 0 | X13: =VLOOKUP(F13,#REF!,7,0) -> #REF! | Z13: =N13=Y13 -> TRUE
B14: 3 | D14: 화성창고-일반가 | E14: =IF($D14<>0,VLOOKUP($D14,$D$54:$E$77,2,FALSE),"") -> 194667 | G14: =IF($F14<>0,VLOOKUP($F14,$E$79:$M$535,2,FALSE),"") | J14: =IF($F14<>0,VLOOKUP($F14,$E$79:$M$535,7,FALSE),"") | K14: =IF($F14<>0,VLOOKUP($F14,$E$79:$M$535,8,FALSE),"") | M14: =IF($L14<>0,VLOOKUP($F14,$E$79:$M$535,9,FALSE)*$L14,"") | N14: =IF($F14<>0,VLOOKUP($F14,$E$62:$L$543,5,FALSE),"") | O14: =IF(L14<>0,$L14*$N14,"") | R14: =VLOOKUP(F14,'파레트 제품 리스트'!$B:$F,4,0) -> #N/A | S14: =VLOOKUP(F14,'파레트 제품 리스트'!$B:$F,5,0) -> #N/A | U14: =O14*1.1 -> #VALUE! | V14: =VLOOKUP(F14,미출!$D:$F,3,0) -> #N/A | W14: =COUNTIF($F$11:$F$13,F14) -> 0 | X14: =VLOOKUP(F14,#REF!,7,0) -> #REF! | Z14: =N14=Y14 -> TRUE
B15: 4 | D15: 화성창고-일반가 | E15: =IF($D15<>0,VLOOKUP($D15,$D$54:$E$77,2,FALSE),"") -> 194667 | G15: =IF($F15<>0,VLOOKUP($F15,$E$79:$M$535,2,FALSE),"") | J15: =IF($F15<>0,VLOOKUP($F15,$E$79:$M$535,7,FALSE),"") | K15: =IF($F15<>0,VLOOKUP($F15,$E$79:$M$535,8,FALSE),"") | M15: =IF($L15<>0,VLOOKUP($F15,$E$79:$M$535,9,FALSE)*$L15,"") | N15: =IF($F15<>0,VLOOKUP($F15,$E$62:$L$543,5,FALSE),"") | O15: =IF(L15<>0,$L15*$N15,"") | R15: =VLOOKUP(F15,'파레트 제품 리스트'!$B:$F,4,0) -> #N/A | S15: =VLOOKUP(F15,'파레트 제품 리스트'!$B:$F,5,0) -> #N/A | U15: =O15*1.1 -> #VALUE! | V15: =VLOOKUP(F15,미출!$D:$F,3,0) -> #N/A | W15: =COUNTIF($F$11:$F$13,F15) -> 0 | X15: =VLOOKUP(F15,#REF!,7,0) -> #REF! | Z15: =N15=Y15 -> TRUE
B16: 5 | D16: 화성창고-일반가 | E16: =IF($D16<>0,VLOOKUP($D16,$D$54:$E$77,2,FALSE),"") -> 194667 | G16: =IF($F16<>0,VLOOKUP($F16,$E$79:$M$535,2,FALSE),"") | J16: =IF($F16<>0,VLOOKUP($F16,$E$79:$M$535,7,FALSE),"") | K16: =IF($F16<>0,VLOOKUP($F16,$E$79:$M$535,8,FALSE),"") | M16: =IF($L16<>0,VLOOKUP($F16,$E$79:$M$535,9,FALSE)*$L16,"") | N16: =IF($F16<>0,VLOOKUP($F16,$E$62:$L$543,5,FALSE),"") | O16: =IF(L16<>0,$L16*$N16,"") | R16: =VLOOKUP(F16,'파레트 제품 리스트'!$B:$F,4,0) -> #N/A | S16: =VLOOKUP(F16,'파레트 제품 리스트'!$B:$F,5,0) -> #N/A | U16: =O16*1.1 -> #VALUE! | V16: =VLOOKUP(F16,미출!$D:$F,3,0) -> #N/A | W16: =COUNTIF($F$11:$F$13,F16) -> 0 | X16: =VLOOKUP(F16,#REF!,7,0) -> #REF! | Z16: =N16=Y16 -> TRUE
B17: 6 | D17: 화성창고-일반가 | E17: =IF($D17<>0,VLOOKUP($D17,$D$54:$E$77,2,FALSE),"") -> 194667 | G17: =IF($F17<>0,VLOOKUP($F17,$E$79:$M$535,2,FALSE),"") | J17: =IF($F17<>0,VLOOKUP($F17,$E$79:$M$535,7,FALSE),"") | K17: =IF($F17<>0,VLOOKUP($F17,$E$79:$M$535,8,FALSE),"") | M17: =IF($L17<>0,VLOOKUP($F17,$E$79:$M$535,9,FALSE)*$L17,"") | N17: =IF($F17<>0,VLOOKUP($F17,$E$62:$L$543,5,FALSE),"") | O17: =IF(L17<>0,$L17*$N17,"") | R17: =VLOOKUP(F17,'파레트 제품 리스트'!$B:$F,4,0) -> #N/A | S17: =VLOOKUP(F17,'파레트 제품 리스트'!$B:$F,5,0) -> #N/A | U17: =O17*1.1 -> #VALUE! | V17: =VLOOKUP(F17,미출!$D:$F,3,0) -> #N/A | W17: =COUNTIF($F$11:$F$13,F17) -> 0 | X17: =VLOOKUP(F17,#REF!,7,0) -> #REF! | Z17: =N17=Y17 -> TRUE
B18: 7 | D18: 화성창고-일반가 | E18: =IF($D18<>0,VLOOKUP($D18,$D$54:$E$77,2,FALSE),"") -> 194667 | G18: =IF($F18<>0,VLOOKUP($F18,$E$79:$M$535,2,FALSE),"") | J18: =IF($F18<>0,VLOOKUP($F18,$E$79:$M$535,7,FALSE),"") | K18: =IF($F18<>0,VLOOKUP($F18,$E$79:$M$535,8,FALSE),"") | M18: =IF($L18<>0,VLOOKUP($F18,$E$79:$M$535,9,FALSE)*$L18,"") | N18: =IF($F18<>0,VLOOKUP($F18,$E$62:$L$543,5,FALSE),"") | O18: =IF(L18<>0,$L18*$N18,"") | R18: =VLOOKUP(F18,'파레트 제품 리스트'!$B:$F,4,0) -> #N/A | S18: =VLOOKUP(F18,'파레트 제품 리스트'!$B:$F,5,0) -> #N/A | U18: =O18*1.1 -> #VALUE! | V18: =VLOOKUP(F18,미출!$D:$F,3,0) -> #N/A | W18: =COUNTIF($F$11:$F$13,F18) -> 0 | X18: =VLOOKUP(F18,#REF!,7,0) -> #REF! | Z18: =N18=Y18 -> TRUE
B19: 8 | D19: 화성창고-일반가 | E19: =IF($D19<>0,VLOOKUP($D19,$D$54:$E$77,2,FALSE),"") -> 194667 | F19: 139137 | G19: =IF($F19<>0,VLOOKUP($F19,$E$79:$M$535,2,FALSE),"") -> MOBILGEAR 600 XP 320 PAIL 20L:KR | J19: =IF($F19<>0,VLOOKUP($F19,$E$79:$M$535,7,FALSE),"") -> PAIL | K19: =IF($F19<>0,VLOOKUP($F19,$E$79:$M$535,8,FALSE),"") -> IND | L19: 28 | M19: =IF($L19<>0,VLOOKUP($F19,$E$79:$M$535,9,FALSE)*$L19,"") -> 560 | N19: =IF($F19<>0,VLOOKUP($F19,$E$62:$L$543,5,FALSE),"") -> 80900 | O19: =IF(L19<>0,$L19*$N19,"") -> 2265200 | R19: =VLOOKUP(F19,'파레트 제품 리스트'!$B:$F,4,0) -> MIX (28) | S19: =VLOOKUP(F19,'파레트 제품 리스트'!$B:$F,5,0) -> 1 | U19: =O19*1.1 -> 2491720 | V19: =VLOOKUP(F19,미출!$D:$F,3,0) -> #N/A | W19: =COUNTIF($F$11:$F$13,F19) -> 0 | X19: =VLOOKUP(F19,#REF!,7,0) -> #REF! | Z19: =N19=Y19 -> FALSE
B20: 9 | D20: 화성창고-일반가 | E20: =IF($D20<>0,VLOOKUP($D20,$D$54:$E$77,2,FALSE),"") -> 194667 | F20: 140141 | G20: =IF($F20<>0,VLOOKUP($F20,$E$79:$M$535,2,FALSE),"") -> MOBILGREASE XHP 222 SPECIAL PAIL 16KG:SG | J20: =IF($F20<>0,VLOOKUP($F20,$E$79:$M$535,7,FALSE),"") -> PAIL | K20: =IF($F20<>0,VLOOKUP($F20,$E$79:$M$535,8,FALSE),"") -> IND | L20: 14 | M20: =IF($L20<>0,VLOOKUP($F20,$E$79:$M$535,9,FALSE)*$L20,"") -> 224 | N20: =IF($F20<>0,VLOOKUP($F20,$E$62:$L$543,5,FALSE),"") -> 188000 | O20: =IF(L20<>0,$L20*$N20,"") -> 2632000 | P20: 26 | R20: =VLOOKUP(F20,'파레트 제품 리스트'!$B:$F,4,0) -> MIX (28) | S20: =VLOOKUP(F20,'파레트 제품 리스트'!$B:$F,5,0) -> 1 | U20: =O20*1.1 -> 2895200 | V20: =VLOOKUP(F20,미출!$D:$F,3,0) -> #N/A | W20: =COUNTIF($F$11:$F$13,F20) -> 0 | X20: =VLOOKUP(F20,#REF!,7,0) -> #REF! | Z20: =N20=Y20 -> FALSE
B21: 10 | D21: 화성창고-일반가 | E21: =IF($D21<>0,VLOOKUP($D21,$D$54:$E$77,2,FALSE),"") -> 194667 | F21: 139143 | G21: =IF($F21<>0,VLOOKUP($F21,$E$79:$M$535,2,FALSE),"") -> NUTO H 32 PAIL 20L:KR | J21: =IF($F21<>0,VLOOKUP($F21,$E$79:$M$535,7,FALSE),"") -> PAIL | K21: =IF($F21<>0,VLOOKUP($F21,$E$79:$M$535,8,FALSE),"") -> IND | L21: 14 | M21: =IF($L21<>0,VLOOKUP($F21,$E$79:$M$535,9,FALSE)*$L21,"") -> 280 | N21: =IF($F21<>0,VLOOKUP($F21,$E$62:$L$543,5,FALSE),"") -> 44000 | O21: =IF(L21<>0,$L21*$N21,"") -> 616000 | P21: 22 | R21: =VLOOKUP(F21,'파레트 제품 리스트'!$B:$F,4,0) -> MIX (28) | S21: =VLOOKUP(F21,'파레트 제품 리스트'!$B:$F,5,0) -> 1 | U21: =O21*1.1 -> 677600 | V21: =VLOOKUP(F21,미출!$D:$F,3,0) -> #N/A | W21: =COUNTIF($F$11:$F$13,F21) -> 0 | X21: =VLOOKUP(F21,#REF!,7,0) -> #REF! | Z21: =N21=Y21 -> FALSE
B22: 11 | D22: 화성창고-일반가 | E22: =IF($D22<>0,VLOOKUP($D22,$D$54:$E$77,2,FALSE),"") -> 194667 | F22: 139145 | G22: =IF($F22<>0,VLOOKUP($F22,$E$79:$M$535,2,FALSE),"") -> NUTO H 46 PAIL 20L:KR | J22: =IF($F22<>0,VLOOKUP($F22,$E$79:$M$535,7,FALSE),"") -> PAIL | K22: =IF($F22<>0,VLOOKUP($F22,$E$79:$M$535,8,FALSE),"") -> IND | L22: 42 | M22: =IF($L22<>0,VLOOKUP($F22,$E$79:$M$535,9,FALSE)*$L22,"") -> 840 | N22: =IF($F22<>0,VLOOKUP($F22,$E$62:$L$543,5,FALSE),"") -> 44000 | O22: =IF(L22<>0,$L22*$N22,"") -> 1848000 | P22: 124 | R22: =VLOOKUP(F22,'파레트 제품 리스트'!$B:$F,4,0) -> Full | S22: =VLOOKUP(F22,'파레트 제품 리스트'!$B:$F,5,0) -> 42 | U22: =O22*1.1 -> 2032800 | V22: =VLOOKUP(F22,미출!$D:$F,3,0) -> #N/A | W22: =COUNTIF($F$11:$F$13,F22) -> 0 | X22: =VLOOKUP(F22,#REF!,7,0) -> #REF! | Z22: =N22=Y22 -> FALSE
B23: 12 | D23: 화성창고-일반가 | E23: =IF($D23<>0,VLOOKUP($D23,$D$54:$E$77,2,FALSE),"") -> 194667 | F23: 140854 | G23: =IF($F23<>0,VLOOKUP($F23,$E$79:$M$535,2,FALSE),"") -> MOBIL SHC 630 PAIL 20L:SG | J23: =IF($F23<>0,VLOOKUP($F23,$E$79:$M$535,7,FALSE),"") -> PAIL | K23: =IF($F23<>0,VLOOKUP($F23,$E$79:$M$535,8,FALSE),"") -> IND | L23: 28 | M23: =IF($L23<>0,VLOOKUP($F23,$E$79:$M$535,9,FALSE)*$L23,"") -> 560 | N23: =IF($F23<>0,VLOOKUP($F23,$E$62:$L$543,5,FALSE),"") -> 287000 | O23: =IF(L23<>0,$L23*$N23,"") -> 8036000 | P23: 425 | R23: =VLOOKUP(F23,'파레트 제품 리스트'!$B:$F,4,0) -> MIX (28) | S23: =VLOOKUP(F23,'파레트 제품 리스트'!$B:$F,5,0) -> 1 | U23: =O23*1.1 -> 8839600 | V23: =VLOOKUP(F23,미출!$D:$F,3,0) -> #N/A | W23: =COUNTIF($F$11:$F$13,F23) -> 0 | X23: =VLOOKUP(F23,#REF!,7,0) -> #REF! | Z23: =N23=Y23 -> FALSE
B24: 13 | D24: 화성창고-일반가 | E24: =IF($D24<>0,VLOOKUP($D24,양식0!$D$44:$E$92,2,FALSE),"") -> 194667 | F24: 139152 | G24: =IF($F24<>0,VLOOKUP($F24,양식0!$E$74:$M$539,2,FALSE),"") -> SPARTAN EP 220 PAIL 20L:KR | J24: =IF($F24<>0,VLOOKUP($F24,양식0!$E$74:$M$539,7,FALSE),"") -> PAIL | K24: =IF($F24<>0,VLOOKUP($F24,양식0!$E$74:$M$539,8,FALSE),"") -> IND | L24: 28 | M24: =IF($L24<>0,VLOOKUP($F24,양식0!$E$74:$M$539,9,FALSE)*$L24,"") -> 560 | N24: =IF($F24<>0,VLOOKUP($F24,양식0!$E$53:$L$547,5,FALSE),"") -> 56700 | O24: =IF(L24<>0,$L24*$N24,"") -> 1587600 | P24: 100 | R24: =VLOOKUP(F24,'파레트 제품 리스트'!$B:$F,4,0) -> MIX (28) | S24: =VLOOKUP(F24,'파레트 제품 리스트'!$B:$F,5,0) -> 1 | U24: =O24*1.1 -> 1746360 | W24: =COUNTIF($F$24:$F$26,F24) -> 1
B25: 2 | D25: 화성창고-일반가 | E25: =IF($D25<>0,VLOOKUP($D25,양식0!$D$44:$E$92,2,FALSE),"") -> 194667 | F25: 139156 | G25: =IF($F25<>0,VLOOKUP($F25,양식0!$E$74:$M$539,2,FALSE),"") -> SPARTAN EP 460 PAIL 20L:KR | J25: =IF($F25<>0,VLOOKUP($F25,양식0!$E$74:$M$539,7,FALSE),"") -> PAIL | K25: =IF($F25<>0,VLOOKUP($F25,양식0!$E$74:$M$539,8,FALSE),"") -> IND | L25: 28 | M25: =IF($L25<>0,VLOOKUP($F25,양식0!$E$74:$M$539,9,FALSE)*$L25,"") -> 560 | N25: =IF($F25<>0,VLOOKUP($F25,양식0!$E$53:$L$547,5,FALSE),"") -> 64600 | O25: =IF(L25<>0,$L25*$N25,"") -> 1808800 | P25: 0 | R25: =VLOOKUP(F25,'파레트 제품 리스트'!$B:$F,4,0) -> MIX (28) | S25: =VLOOKUP(F25,'파레트 제품 리스트'!$B:$F,5,0) -> 1 | U25: =O25*1.1 -> 1989680 | W25: =COUNTIF($F$24:$F$26,F25) -> 1
B26: 3 | D26: 화성창고-일반가 | E26: =IF($D26<>0,VLOOKUP($D26,양식0!$D$44:$E$92,2,FALSE),"") -> 194667 | F26: 148688 | G26: =IF($F26<>0,VLOOKUP($F26,양식0!$E$74:$M$539,2,FALSE),"") -> MOBIL VACUO 533-PL20L | J26: =IF($F26<>0,VLOOKUP($F26,양식0!$E$74:$M$539,7,FALSE),"") -> PAIL | K26: =IF($F26<>0,VLOOKUP($F26,양식0!$E$74:$M$539,8,FALSE),"") -> IND | L26: 28 | M26: =IF($L26<>0,VLOOKUP($F26,양식0!$E$74:$M$539,9,FALSE)*$L26,"") -> 560 | N26: =IF($F26<>0,VLOOKUP($F26,양식0!$E$53:$L$547,5,FALSE),"") -> 69500 | O26: =IF(L26<>0,$L26*$N26,"") -> 1946000 | P26: 125 | R26: =VLOOKUP(F26,'파레트 제품 리스트'!$B:$F,4,0) -> MIX (28) | S26: =VLOOKUP(F26,'파레트 제품 리스트'!$B:$F,5,0) -> 1 | U26: =O26*1.1 -> 2140600 | V26: =VLOOKUP(F26,미출!$D:$F,3,0) -> #N/A | W26: =COUNTIF($F$24:$F$26,F26) -> 1 | X26: =VLOOKUP(F26,#REF!,7,0) -> #REF! | Z26: =N26=Y26 -> FALSE
B27: 4 | D27: 화성창고-일반가 | E27: =IF($D27<>0,VLOOKUP($D27,양식0!$D$44:$E$92,2,FALSE),"") -> 194667 | F27: 148661 | G27: =IF($F27<>0,VLOOKUP($F27,양식0!$E$74:$M$539,2,FALSE),"") -> MOBIL VELOCITE NO 3 PAIL 20L | J27: =IF($F27<>0,VLOOKUP($F27,양식0!$E$74:$M$539,7,FALSE),"") -> PAIL | K27: =IF($F27<>0,VLOOKUP($F27,양식0!$E$74:$M$539,8,FALSE),"") -> IND | L27: 42 | M27: =IF($L27<>0,VLOOKUP($F27,양식0!$E$74:$M$539,9,FALSE)*$L27,"") -> 840 | N27: =IF($F27<>0,VLOOKUP($F27,양식0!$E$53:$L$547,5,FALSE),"") -> 63400 | O27: =IF(L27<>0,$L27*$N27,"") -> 2662800 | P27: 0 | R27: =VLOOKUP(F27,'파레트 제품 리스트'!$B:$F,4,0) -> Full | S27: =VLOOKUP(F27,'파레트 제품 리스트'!$B:$F,5,0) -> 42 | U27: =O27*1.1 -> 2929080 | W27: =COUNTIF($F$24:$F$26,F27) -> 0
B28: 5 | D28: 화성창고-일반가 | E28: =IF($D28<>0,VLOOKUP($D28,양식0!$D$44:$E$92,2,FALSE),"") -> 194667 | F28: 148662 | G28: =IF($F28<>0,VLOOKUP($F28,양식0!$E$74:$M$539,2,FALSE),"") -> MOBIL VELOCITE 6, 20LT, PAIL | J28: =IF($F28<>0,VLOOKUP($F28,양식0!$E$74:$M$539,7,FALSE),"") -> PAIL | K28: =IF($F28<>0,VLOOKUP($F28,양식0!$E$74:$M$539,8,FALSE),"") -> IND | L28: 42 | M28: =IF($L28<>0,VLOOKUP($F28,양식0!$E$74:$M$539,9,FALSE)*$L28,"") -> 840 | N28: =IF($F28<>0,VLOOKUP($F28,양식0!$E$53:$L$547,5,FALSE),"") -> 55400 | O28: =IF(L28<>0,$L28*$N28,"") -> 2326800 | P28: 0 | R28: =VLOOKUP(F28,'파레트 제품 리스트'!$B:$F,4,0) -> Full | S28: =VLOOKUP(F28,'파레트 제품 리스트'!$B:$F,5,0) -> 42 | U28: =O28*1.1 -> 2559480 | W28: =COUNTIF($F$24:$F$26,F28) -> 0
B29: 6 | D29: 화성창고-일반가 | E29: =IF($D29<>0,VLOOKUP($D29,양식0!$D$44:$E$92,2,FALSE),"") -> 194667 | F29: 140252 | G29: =IF($F29<>0,VLOOKUP($F29,양식0!$E$74:$M$539,2,FALSE),"") -> MOBILUX EP 0 PAIL 16KG:SG | J29: =IF($F29<>0,VLOOKUP($F29,양식0!$E$74:$M$539,7,FALSE),"") -> PAIL | K29: =IF($F29<>0,VLOOKUP($F29,양식0!$E$74:$M$539,8,FALSE),"") -> IND | L29: 28 | M29: =IF($L29<>0,VLOOKUP($F29,양식0!$E$74:$M$539,9,FALSE)*$L29,"") -> 448 | N29: =IF($F29<>0,VLOOKUP($F29,양식0!$E$53:$L$547,5,FALSE),"") -> 81000 | O29: =IF(L29<>0,$L29*$N29,"") -> 2268000 | P29: 78 | R29: =VLOOKUP(F29,'파레트 제품 리스트'!$B:$F,4,0) -> MIX (28) | S29: =VLOOKUP(F29,'파레트 제품 리스트'!$B:$F,5,0) -> 1 | U29: =O29*1.1 -> 2494800 | W29: =COUNTIF($F$24:$F$26,F29) -> 0
B30: 7 | D30: 화성창고-일반가 | E30: =IF($D30<>0,VLOOKUP($D30,양식0!$D$44:$E$92,2,FALSE),"") -> 194667 | F30: 140255 | G30: =IF($F30<>0,VLOOKUP($F30,양식0!$E$74:$M$539,2,FALSE),"") -> MOBILUX EP 1 PAIL 16KG:SG | J30: =IF($F30<>0,VLOOKUP($F30,양식0!$E$74:$M$539,7,FALSE),"") -> PAIL | K30: =IF($F30<>0,VLOOKUP($F30,양식0!$E$74:$M$539,8,FALSE),"") -> IND | L30: 28 | M30: =IF($L30<>0,VLOOKUP($F30,양식0!$E$74:$M$539,9,FALSE)*$L30,"") -> 448 | N30: =IF($F30<>0,VLOOKUP($F30,양식0!$E$53:$L$547,5,FALSE),"") -> 81000 | O30: =IF(L30<>0,$L30*$N30,"") -> 2268000 | P30: 71 | R30: =VLOOKUP(F30,'파레트 제품 리스트'!$B:$F,4,0) -> MIX (28) | S30: =VLOOKUP(F30,'파레트 제품 리스트'!$B:$F,5,0) -> 1 | U30: =O30*1.1 -> 2494800 | V30: =VLOOKUP(F30,미출!$D:$F,3,0) -> #N/A | W30: =COUNTIF($F$24:$F$26,F30) -> 0 | X30: =VLOOKUP(F30,#REF!,7,0) -> #REF! | Z30: =N30=Y30 -> FALSE
B31: 8 | D31: 화성창고-일반가 | E31: =IF($D31<>0,VLOOKUP($D31,양식0!$D$44:$E$92,2,FALSE),"") -> 194667 | F31: 140263 | G31: =IF($F31<>0,VLOOKUP($F31,양식0!$E$74:$M$539,2,FALSE),"") -> MOBILUX EP 2 PAIL 16KG:SG | J31: =IF($F31<>0,VLOOKUP($F31,양식0!$E$74:$M$539,7,FALSE),"") -> PAIL | K31: =IF($F31<>0,VLOOKUP($F31,양식0!$E$74:$M$539,8,FALSE),"") -> IND | L31: 56 | M31: =IF($L31<>0,VLOOKUP($F31,양식0!$E$74:$M$539,9,FALSE)*$L31,"") -> 896 | N31: =IF($F31<>0,VLOOKUP($F31,양식0!$E$53:$L$547,5,FALSE),"") -> 81000 | O31: =IF(L31<>0,$L31*$N31,"") -> 4536000 | P31: 576 | R31: =VLOOKUP(F31,'파레트 제품 리스트'!$B:$F,4,0) -> MIX (28) | S31: =VLOOKUP(F31,'파레트 제품 리스트'!$B:$F,5,0) -> 1 | U31: =O31*1.1 -> 4989600 | W31: =COUNTIF($F$24:$F$26,F31) -> 0
B32: 9 | D32: 화성창고-일반가 | E32: =IF($D32<>0,VLOOKUP($D32,양식0!$D$44:$E$92,2,FALSE),"") -> 194667 | F32: 140256 | G32: =IF($F32<>0,VLOOKUP($F32,양식0!$E$74:$M$539,2,FALSE),"") -> MOBILUX EP 3 PAIL 16KG:SG | J32: =IF($F32<>0,VLOOKUP($F32,양식0!$E$74:$M$539,7,FALSE),"") -> PAIL | K32: =IF($F32<>0,VLOOKUP($F32,양식0!$E$74:$M$539,8,FALSE),"") -> IND | L32: 28 | M32: =IF($L32<>0,VLOOKUP($F32,양식0!$E$74:$M$539,9,FALSE)*$L32,"") -> 448 | N32: =IF($F32<>0,VLOOKUP($F32,양식0!$E$53:$L$547,5,FALSE),"") -> 81000 | O32: =IF(L32<>0,$L32*$N32,"") -> 2268000 | P32: 43 | R32: =VLOOKUP(F32,'파레트 제품 리스트'!$B:$F,4,0) -> MIX (28) | S32: =VLOOKUP(F32,'파레트 제품 리스트'!$B:$F,5,0) -> 1 | U32: =O32*1.1 -> 2494800 | W32: =COUNTIF($F$24:$F$26,F32) -> 0
B33: 13 | D33: 화성창고-일반가 | E33: =IF($D33<>0,VLOOKUP($D33,양식0!$D$44:$E$92,2,FALSE),"") -> 194667 | F33: 144277 | G33: =IF($F33<>0,VLOOKUP($F33,양식0!$E$74:$M$539,2,FALSE),"") -> MOBIL VACUOLINE 1409 PAIL 20L | J33: =IF($F33<>0,VLOOKUP($F33,양식0!$E$74:$M$539,7,FALSE),"") -> PAIL | K33: =IF($F33<>0,VLOOKUP($F33,양식0!$E$74:$M$539,8,FALSE),"") -> IND | L33: 42 | M33: =IF($L33<>0,VLOOKUP($F33,양식0!$E$74:$M$539,9,FALSE)*$L33,"") -> 840 | N33: =IF($F33<>0,VLOOKUP($F33,양식0!$E$53:$L$547,5,FALSE),"") -> 46600 | O33: =IF(L33<>0,$L33*$N33,"") -> 1957200 | W33: =COUNTIF($F$24:$F$26,F33) -> 0
B34: 14 | E34: =IF($D34<>0,VLOOKUP($D34,양식0!$D$44:$E$92,2,FALSE),"") | G34: =IF($F34<>0,VLOOKUP($F34,양식0!$E$74:$M$539,2,FALSE),"") | J34: =IF($F34<>0,VLOOKUP($F34,양식0!$E$74:$M$539,7,FALSE),"") | K34: =IF($F34<>0,VLOOKUP($F34,양식0!$E$74:$M$539,8,FALSE),"") | M34: =IF($L34<>0,VLOOKUP($F34,양식0!$E$74:$M$539,9,FALSE)*$L34,"") | N34: =IF($F34<>0,VLOOKUP($F34,양식0!$E$53:$L$547,5,FALSE),"") | O34: =IF(L34<>0,$L34*$N34,"") | R34: =VLOOKUP(F34,'파레트 제품 리스트'!$B:$F,4,0) -> #N/A | S34: =VLOOKUP(F34,'파레트 제품 리스트'!$B:$F,5,0) -> #N/A | U34: =O34*1.1 -> #VALUE! | V34: =VLOOKUP(F34,미출!$D:$F,3,0) -> #N/A | W34: =COUNTIF($F$11:$F$13,F34) -> 0 | X34: =VLOOKUP(F34,#REF!,7,0) -> #REF! | Z34: =N34=Y34 -> TRUE
B35: 15 | E35: =IF($D35<>0,VLOOKUP($D35,$D$54:$E$76,2,FALSE),"") | G35: =IF($F35<>0,VLOOKUP($F35,$E$79:$M$544,2,FALSE),"") | J35: =IF($F35<>0,VLOOKUP($F35,$E$79:$M$544,7,FALSE),"") | K35: =IF($F35<>0,VLOOKUP($F35,$E$79:$M$544,8,FALSE),"") | M35: =IF($L35<>0,VLOOKUP($F35,$E$79:$M$527,9,FALSE)*$L35,"") | N35: =IF($F35<>0,VLOOKUP($F35,$E$62:$L$543,5,FALSE),"") | O35: =IF(L35<>0,$L35*$N35,"") | R35: =VLOOKUP(F35,'파레트 제품 리스트'!$B:$F,4,0) -> #N/A | S35: =VLOOKUP(F35,'파레트 제품 리스트'!$B:$F,5,0) -> #N/A | U35: =O35*1.1 -> #VALUE! | V35: =VLOOKUP(F35,미출!$D:$F,3,0) -> #N/A | W35: =COUNTIF($F$11:$F$13,F35) -> 0 | X35: =VLOOKUP(F35,#REF!,7,0) -> #REF! | Z35: =N35=Y35 -> TRUE
J36: =IF($F36<>0,VLOOKUP($F36,$E$88:$M$457,7,FALSE),"") | K36: =IF($F36<>0,VLOOKUP($F36,$E$88:$M$457,8,FALSE),"") | M36: =IF($L36<>0,VLOOKUP($F36,$E$88:$M$457,9,FALSE)*$L36,"") | N36: =IF($F36<>0,VLOOKUP($F36,$E$88:$M$457,5,FALSE),"") | O36: =IF(L36<>0,$L36*$N36,"")
I37: 발주물량 | J37: 리터(Liter) | K37: =SUM(M12:M35) -> 8904 | M37: 발주 금액 | N37: 부가세별도 | O37: =SUM(O12:O35) -> 39026400
J38: 드럼(Drum) | K38: =$K$37/200 -> 44.52 | N38: 부가세포함 | O38: =O37*1.1 -> 42929040
L41: =#REF!+#REF!+#REF!+#REF! -> #REF!
L42: =+#REF!+#REF!+#REF!+#REF! -> #REF!
L43: =L42-L41 -> #REF!
B50: 발주서 기초자료
D53: 거래처명 | E53: 거래처코드 | G53: 배송지 | H53: 주소 | M53: 담당자 | N53: 연락처
...

Sheet 양식0
B2: 발 주 서 | F2: 파레트요청 | M2: 발주 접수처 (엑슨모빌 중국 상하이 고객지원팀)
M3: · 부서메일주소 : koreadcp@exxonmobil.com
M4: · 수신부담팩스 : 00798 8521 8501
M5: · 수신부담전화 : 00798 8521 8503
B7: 대리점명 | D7: (주)영일오엔씨 | F7: 대리점코드 | G7: 모빌(194637) | K7: 발주일 | L7: =TODAY() -> 45981 | N7: 납기일
B8: 전화번호 | D8: 02-2693-5189 | F8: 팩스번호 | G8: 02-2693-5902 | K8: 담당자 | L8: 조윤석 팀장 | N8: 연락처 | O8: 031-8059-5151
B9: 주소 | K9: 납 지 | L9: 영일-화성 | M9: =IF($L9<>0,VLOOKUP($L9,$G$45:$K$70,2,FALSE),"") -> 경기도 화성시 향남읍 구문천1길 43-9
B11: 순번 (No.) | C11: 발주처 | D11: 거래처명 (Ship to) | E11: 코드번호 (Child Code) | F11: 제품코드 (P-Code) | G11: 제품명 (Product Name) | J11: 규격 (Package) | K11: 제품군 (Lob) | L11: 수량 (Quanty) | M11: 물량/리터 (Volume) | N11: 단가 (Unit Price) | O11: 금액(별도) (Amounts) | P11: 오더번호 | R11: 발주단위 | U11: 금액(포함) | V11: 미출수량 | W11: 중복 | X11: 전일발주수량 | Y11: 단가 | Z11: 확인
B12: 1 | C12: 소분 | D12: 화성창고-티센 | E12: =IF($D12<>0,VLOOKUP($D12,$D$45:$E$72,2,FALSE),"") -> 194638 | F12: 132835 | G12: =IF($F12<>0,VLOOKUP($F12,$E$74:$M$539,2,FALSE),"") -> MOBIL GLYGOYLE 460, 208LT DRUM | J12: =IF($F12<>0,VLOOKUP($F12,$E$74:$M$539,7,FALSE),"") -> DRUM | K12: =IF($F12<>0,VLOOKUP($F12,$E$74:$M$539,8,FALSE),"") -> IND | L12: 5 | M12: =IF($L12<>0,VLOOKUP($F12,$E$74:$M$539,9,FALSE)*$L12,"") -> 1040 | N12: 1755000 | O12: =IF(L12<>0,$L12*$N12,"") -> 8775000 | P12: 101 | R12: =VLOOKUP(F12,'파레트 제품 리스트'!$B:$F,4,0) -> DRUM | S12: =VLOOKUP(F12,'파레트 제품 리스트'!$B:$F,5,0) -> 1 | U12: =O12*1.1 -> 9652500 | V12: =VLOOKUP(F12,미출!$D:$F,3,0) -> #N/A | W12: =COUNTIF($F$11:$F$11,F12) -> 0 | X12: =VLOOKUP(F12,#REF!,7,0) -> #REF! | Z12: =N12=Y12 -> FALSE
B13: 2 | C13: 석문에너지 | D13: 화성창고-일반가 | E13: =IF($D13<>0,VLOOKUP($D13,$D$45:$E$72,2,FALSE),"") -> 194667 | F13: 139040 | G13: =IF($F13<>0,VLOOKUP($F13,$E$74:$M$539,2,FALSE),"") -> MOBIL DTE 732 DRUM 200L:KR | J13: =IF($F13<>0,VLOOKUP($F13,$E$74:$M$539,7,FALSE),"") -> DRUM | K13: =IF($F13<>0,VLOOKUP($F13,$E$74:$M$539,8,FALSE),"") -> IND | L13: 4 | M13: =IF($L13<>0,VLOOKUP($F13,$E$74:$M$539,9,FALSE)*$L13,"") -> 800 | N13: =IF($F13<>0,VLOOKUP($F13,$E$53:$L$546,5,FALSE),"") -> 575000 | O13: =IF(L13<>0,$L13*$N13,"") -> 2300000 | P13: 0 | R13: =VLOOKUP(F13,'파레트 제품 리스트'!$B:$F,4,0) -> DRUM | S13: =VLOOKUP(F13,'파레트 제품 리스트'!$B:$F,5,0) -> 1 | U13: =O13*1.1 -> 2530000 | V13: =VLOOKUP(F13,미출!$D:$F,3,0) -> #N/A | W13: =COUNTIF($F$11:$F$11,F13) -> 0 | X13: =VLOOKUP(F13,#REF!,7,0) -> #REF! | Z13: =N13=Y13 -> FALSE
B14: 3 | C14: 극동오일 | D14: 화성창고-일반가 | E14: =IF($D14<>0,VLOOKUP($D14,$D$45:$E$72,2,FALSE),"") -> 194667 | F14: 139059 | G14: =IF($F14<>0,VLOOKUP($F14,$E$74:$M$539,2,FALSE),"") -> MOBIL DTE OIL HEAVY MEDIUM DRUM 200L:KR | J14: =IF($F14<>0,VLOOKUP($F14,$E$74:$M$539,7,FALSE),"") -> DRUM | K14: =IF($F14<>0,VLOOKUP($F14,$E$74:$M$539,8,FALSE),"") -> IND | L14: 1 | M14: =IF($L14<>0,VLOOKUP($F14,$E$74:$M$539,9,FALSE)*$L14,"") -> 200 | N14: =IF($F14<>0,VLOOKUP($F14,$E$53:$L$546,5,FALSE),"") -> 691000 | O14: =IF(L14<>0,$L14*$N14,"") -> 691000 | P14: 50 | R14: =VLOOKUP(F14,'파레트 제품 리스트'!$B:$F,4,0) -> DRUM | S14: =VLOOKUP(F14,'파레트 제품 리스트'!$B:$F,5,0) -> 1 | U14: =O14*1.1 -> 760100 | V14: =VLOOKUP(F14,미출!$D:$F,3,0) -> #N/A | W14: =COUNTIF($F$11:$F$11,F14) -> 0 | X14: =VLOOKUP(F14,#REF!,7,0) -> #REF! | Z14: =N14=Y14 -> FALSE
B15: 4 | D15: 화성창고-일반가 | E15: =IF($D15<>0,VLOOKUP($D15,$D$45:$E$72,2,FALSE),"") -> 194667 | F15: 144167 | G15: =IF($F15<>0,VLOOKUP($F15,$E$74:$M$539,2,FALSE),"") -> MOBIL HYDRAULIC AW 46 PAIL 20L:KR | J15: =IF($F15<>0,VLOOKUP($F15,$E$74:$M$539,7,FALSE),"") -> PAIL | K15: =IF($F15<>0,VLOOKUP($F15,$E$74:$M$539,8,FALSE),"") -> IND | L15: 42 | M15: =IF($L15<>0,VLOOKUP($F15,$E$74:$M$539,9,FALSE)*$L15,"") -> 840 | N15: =IF($F15<>0,VLOOKUP($F15,$E$53:$L$546,5,FALSE),"") -> 31200 | O15: =IF(L15<>0,$L15*$N15,"") -> 1310400 | P15: 577 | R15: =VLOOKUP(F15,'파레트 제품 리스트'!$B:$F,4,0) -> Full | S15: =VLOOKUP(F15,'파레트 제품 리스트'!$B:$F,5,0) -> 42 | U15: =O15*1.1 -> 1441440 | V15: =VLOOKUP(F15,미출!$D:$F,3,0) -> #N/A | W15: =COUNTIF($F$11:$F$11,F15) -> 0 | X15: =VLOOKUP(F15,#REF!,7,0) -> #REF! | Z15: =N15=Y15 -> FALSE
B16: 5 | D16: 화성창고-일반가 | E16: =IF($D16<>0,VLOOKUP($D16,$D$45:$E$72,2,FALSE),"") -> 194667 | F16: 144170 | G16: =IF($F16<>0,VLOOKUP($F16,$E$74:$M$539,2,FALSE),"") -> MOBIL HYDRAULIC AW 68 DRUM 200L:KR | J16: =IF($F16<>0,VLOOKUP($F16,$E$74:$M$539,7,FALSE),"") -> DRUM | K16: =IF($F16<>0,VLOOKUP($F16,$E$74:$M$539,8,FALSE),"") -> IND | L16: 2 | M16: =IF($L16<>0,VLOOKUP($F16,$E$74:$M$539,9,FALSE)*$L16,"") -> 400 | N16: =IF($F16<>0,VLOOKUP($F16,$E$53:$L$546,5,FALSE),"") -> 314000 | O16: =IF(L16<>0,$L16*$N16,"") -> 628000 | P16: 309 | R16: =VLOOKUP(F16,'파레트 제품 리스트'!$B:$F,4,0) -> #N/A | S16: =VLOOKUP(F16,'파레트 제품 리스트'!$B:$F,5,0) -> #N/A | U16: =O16*1.1 -> 690800 | V16: =VLOOKUP(F16,미출!$D:$F,3,0) -> #N/A | W16: =COUNTIF($F$11:$F$11,F16) -> 0 | X16: =VLOOKUP(F16,#REF!,7,0) -> #REF! | Z16: =N16=Y16 -> FALSE
B17: 6 | D17: 화성창고-일반가 | E17: =IF($D17<>0,VLOOKUP($D17,$D$45:$E$72,2,FALSE),"") -> 194667 | F17: 139144 | G17: =IF($F17<>0,VLOOKUP($F17,$E$74:$M$539,2,FALSE),"") -> NUTO H 46 DRUM 200L:KR | J17: =IF($F17<>0,VLOOKUP($F17,$E$74:$M$539,7,FALSE),"") -> DRUM | K17: =IF($F17<>0,VLOOKUP($F17,$E$74:$M$539,8,FALSE),"") -> IND | L17: 4 | M17: =IF($L17<>0,VLOOKUP($F17,$E$74:$M$539,9,FALSE)*$L17,"") -> 800 | N17: =IF($F17<>0,VLOOKUP($F17,$E$53:$L$546,5,FALSE),"") -> 423000 | O17: =IF(L17<>0,$L17*$N17,"") -> 1692000 | P17: 49 | R17: =VLOOKUP(F17,'파레트 제품 리스트'!$B:$F,4,0) -> DRUM | S17: =VLOOKUP(F17,'파레트 제품 리스트'!$B:$F,5,0) -> 1 | U17: =O17*1.1 -> 1861200 | V17: =VLOOKUP(F17,미출!$D:$F,3,0) -> #N/A | W17: =COUNTIF($F$11:$F$11,F17) -> 0 | X17: =VLOOKUP(F17,#REF!,7,0) -> #REF! | Z17: =N17=Y17 -> FALSE
B18: 7 | D18: 화성창고-일반가 | E18: =IF($D18<>0,VLOOKUP($D18,$D$45:$E$72,2,FALSE),"") -> 194667 | F18: 139145 | G18: =IF($F18<>0,VLOOKUP($F18,$E$74:$M$539,2,FALSE),"") -> NUTO H 46 PAIL 20L:KR | J18: =IF($F18<>0,VLOOKUP($F18,$E$74:$M$539,7,FALSE),"") -> PAIL | K18: =IF($F18<>0,VLOOKUP($F18,$E$74:$M$539,8,FALSE),"") -> IND | L18: 42 | M18: =IF($L18<>0,VLOOKUP($F18,$E$74:$M$539,9,FALSE)*$L18,"") -> 840 | N18: =IF($F18<>0,VLOOKUP($F18,$E$53:$L$546,5,FALSE),"") -> 44000 | O18: =IF(L18<>0,$L18*$N18,"") -> 1848000 | P18: 231 | R18: =VLOOKUP(F18,'파레트 제품 리스트'!$B:$F,4,0) -> Full | S18: =VLOOKUP(F18,'파레트 제품 리스트'!$B:$F,5,0) -> 42 | U18: =O18*1.1 -> 2032800 | V18: =VLOOKUP(F18,미출!$D:$F,3,0) -> #N/A | W18: =COUNTIF($F$11:$F$11,F18) -> 0 | X18: =VLOOKUP(F18,#REF!,7,0) -> #REF! | Z18: =N18=Y18 -> FALSE
B19: 8 | D19: 화성창고-일반가 | E19: =IF($D19<>0,VLOOKUP($D19,$D$45:$E$72,2,FALSE),"") -> 194667 | F19: 148662 | G19: =IF($F19<>0,VLOOKUP($F19,$E$74:$M$539,2,FALSE),"") -> MOBIL VELOCITE 6, 20LT, PAIL | J19: =IF($F19<>0,VLOOKUP($F19,$E$74:$M$539,7,FALSE),"") -> PAIL | K19: =IF($F19<>0,VLOOKUP($F19,$E$74:$M$539,8,FALSE),"") -> IND | L19: 42 | M19: =IF($L19<>0,VLOOKUP($F19,$E$74:$M$539,9,FALSE)*$L19,"") -> 840 | N19: =IF($F19<>0,VLOOKUP($F19,$E$53:$L$546,5,FALSE),"") -> 55400 | O19: =IF(L19<>0,$L19*$N19,"") -> 2326800 | P19: 309 | R19: =VLOOKUP(F19,'파레트 제품 리스트'!$B:$F,4,0) -> Full | S19: =VLOOKUP(F19,'파레트 제품 리스트'!$B:$F,5,0) -> 42 | U19: =O19*1.1 -> 2559480 | V19: =VLOOKUP(F19,미출!$D:$F,3,0) -> #N/A | W19: =COUNTIF($F$11:$F$11,F19) -> 0 | X19: =VLOOKUP(F19,#REF!,7,0) -> #REF! | Z19: =N19=Y19 -> FALSE
B20: 9 | C20: 아이마켓 | D20: 화성창고-일반가 | E20: =IF($D20<>0,VLOOKUP($D20,$D$45:$E$72,2,FALSE),"") -> 194667 | F20: 132528 | G20: =IF($F20<>0,VLOOKUP($F20,$E$74:$M$539,2,FALSE),"") -> MOBILGREASE FM 222, 16KG/35.2LB | J20: =IF($F20<>0,VLOOKUP($F20,$E$74:$M$539,7,FALSE),"") -> PAIL | K20: =IF($F20<>0,VLOOKUP($F20,$E$74:$M$539,8,FALSE),"") -> IND | L20: 10 | M20: =IF($L20<>0,VLOOKUP($F20,$E$74:$M$539,9,FALSE)*$L20,"") -> 160 | N20: =IF($F20<>0,VLOOKUP($F20,$E$53:$L$546,5,FALSE),"") -> 269000 | O20: =IF(L20<>0,$L20*$N20,"") -> 2690000 | P20: 0 | R20: =VLOOKUP(F20,'파레트 제품 리스트'!$B:$F,4,0) -> MIX (28) | S20: =VLOOKUP(F20,'파레트 제품 리스트'!$B:$F,5,0) -> 1 | U20: =O20*1.1 -> 2959000 | V20: =VLOOKUP(F20,미출!$D:$F,3,0) -> #N/A | W20: =COUNTIF($F$11:$F$11,F20) -> 0 | X20: =VLOOKUP(F20,#REF!,7,0) -> #REF! | Z20: =N20=Y20 -> FALSE
B21: 10 | D21: 화성창고-하이스코 | E21: =IF($D21<>0,VLOOKUP($D21,$D$45:$E$72,2,FALSE),"") -> 194729 | F21: 139135 | G21: =IF($F21<>0,VLOOKUP($F21,$E$74:$M$539,2,FALSE),"") -> MOBILGEAR 600 XP 320 DRUM 200L:KR | J21: =IF($F21<>0,VLOOKUP($F21,$E$74:$M$539,7,FALSE),"") -> DRUM | K21: =IF($F21<>0,VLOOKUP($F21,$E$74:$M$539,8,FALSE),"") -> IND | L21: 8 | M21: =IF($L21<>0,VLOOKUP($F21,$E$74:$M$539,9,FALSE)*$L21,"") -> 1600 | N21: 502920 | O21: =IF(L21<>0,$L21*$N21,"") -> 4023360 | P21: 33 | R21: =VLOOKUP(F21,'파레트 제품 리스트'!$B:$F,4,0) -> DRUM | S21: =VLOOKUP(F21,'파레트 제품 리스트'!$B:$F,5,0) -> 1 | U21: =O21*1.1 -> 4425696 | V21: =VLOOKUP(F21,미출!$D:$F,3,0) -> #N/A | W21: =COUNTIF($F$11:$F$11,F21) -> 0 | X21: =VLOOKUP(F21,#REF!,7,0) -> #REF! | Z21: =N21=Y21 -> FALSE
B22: 11 | D22: 화성창고-화성에너지 | E22: =IF($D22<>0,VLOOKUP($D22,$D$45:$E$72,2,FALSE),"") -> 200584 | F22: 141746 | G22: =IF($F22<>0,VLOOKUP($F22,$E$74:$M$539,2,FALSE),"") -> MOBIL DTE 25 ULTRA DRUM 200L:KR | J22: =IF($F22<>0,VLOOKUP($F22,$E$74:$M$539,7,FALSE),"") -> DRUM | K22: =IF($F22<>0,VLOOKUP($F22,$E$74:$M$539,8,FALSE),"") -> IND | L22: 12 | M22: =IF($L22<>0,VLOOKUP($F22,$E$74:$M$539,9,FALSE)*$L22,"") -> 2400 | N22: 433000 | O22: =IF(L22<>0,$L22*$N22,"") -> 5196000 | P22: 300 | R22: =VLOOKUP(F22,'파레트 제품 리스트'!$B:$F,4,0) -> DRUM | S22: =VLOOKUP(F22,'파레트 제품 리스트'!$B:$F,5,0) -> 1 | U22: =O22*1.1 -> 5715600 | V22: =VLOOKUP(F22,미출!$D:$F,3,0) -> #N/A | W22: =COUNTIF($F$11:$F$11,F22) -> 0 | X22: =VLOOKUP(F22,#REF!,7,0) -> #REF! | Z22: =N22=Y22 -> FALSE
B23: 12 | D23: 화성창고-화성에너지 | E23: =IF($D23<>0,VLOOKUP($D23,$D$45:$E$72,2,FALSE),"") -> 200584 | F23: 139134 | G23: =IF($F23<>0,VLOOKUP($F23,$E$74:$M$539,2,FALSE),"") -> MOBILGEAR 600 XP 220 PAIL 20L:KR | J23: =IF($F23<>0,VLOOKUP($F23,$E$74:$M$539,7,FALSE),"") -> PAIL | K23: =IF($F23<>0,VLOOKUP($F23,$E$74:$M$539,8,FALSE),"") -> IND | L23: 42 | M23: =IF($L23<>0,VLOOKUP($F23,$E$74:$M$539,9,FALSE)*$L23,"") -> 840 | N23: 70500 | O23: =IF(L23<>0,$L23*$N23,"") -> 2961000 | P23: 52 | R23: =VLOOKUP(F23,'파레트 제품 리스트'!$B:$F,4,0) -> Full | S23: =VLOOKUP(F23,'파레트 제품 리스트'!$B:$F,5,0) -> 42 | U23: =O23*1.1 -> 3257100 | V23: =VLOOKUP(F23,미출!$D:$F,3,0) -> #N/A | W23: =COUNTIF($F$11:$F$11,F23) -> 0 | X23: =VLOOKUP(F23,#REF!,7,0) -> #REF! | Z23: =N23=Y23 -> FALSE
B24: 13 | D24: 화성창고-화성에너지 | E24: =IF($D24<>0,VLOOKUP($D24,$D$45:$E$72,2,FALSE),"") -> 200584 | F24: 140263 | G24: =IF($F24<>0,VLOOKUP($F24,$E$74:$M$539,2,FALSE),"") -> MOBILUX EP 2 PAIL 16KG:SG | J24: =IF($F24<>0,VLOOKUP($F24,$E$74:$M$539,7,FALSE),"") -> PAIL | K24: =IF($F24<>0,VLOOKUP($F24,$E$74:$M$539,8,FALSE),"") -> IND | L24: 42 | M24: =IF($L24<>0,VLOOKUP($F24,$E$74:$M$539,9,FALSE)*$L24,"") -> 672 | N24: 71800 | O24: =IF(L24<>0,$L24*$N24,"") -> 3015600 | P24: 483 | R24: =VLOOKUP(F24,'파레트 제품 리스트'!$B:$F,4,0) -> MIX (28) | S24: =VLOOKUP(F24,'파레트 제품 리스트'!$B:$F,5,0) -> 1 | U24: =O24*1.1 -> 3317160 | V24: =VLOOKUP(F24,미출!$D:$F,3,0) -> #N/A | W24: =COUNTIF($F$11:$F$11,F24) -> 0 | X24: =VLOOKUP(F24,#REF!,7,0) -> #REF! | Z24: =N24=Y24 -> FALSE
B25: 14 | D25: 화성창고-일반가 | E25: =IF($D25<>0,VLOOKUP($D25,$D$45:$E$72,2,FALSE),"") -> 194667 | F25: 144169 | G25: =IF($F25<>0,VLOOKUP($F25,$E$74:$M$539,2,FALSE),"") -> MOBIL HYDRAULIC AW 68 PAIL 20L:KR | J25: =IF($F25<>0,VLOOKUP($F25,$E$74:$M$539,7,FALSE),"") -> PAIL | K25: =IF($F25<>0,VLOOKUP($F25,$E$74:$M$539,8,FALSE),"") -> IND | L25: 28 | M25: =IF($L25<>0,VLOOKUP($F25,$E$74:$M$539,9,FALSE)*$L25,"") -> 560 | N25: =IF($F25<>0,VLOOKUP($F25,$E$53:$L$546,5,FALSE),"") -> 33900 | O25: =IF(L25<>0,$L25*$N25,"") -> 949200 | R25: =VLOOKUP(F25,'파레트 제품 리스트'!$B:$F,4,0) -> #N/A | S25: =VLOOKUP(F25,'파레트 제품 리스트'!$B:$F,5,0) -> #N/A | U25: =O25*1.1 -> 1044120 | V25: =VLOOKUP(F25,미출!$D:$F,3,0) -> #N/A | W25: =COUNTIF($F$11:$F$11,F25) -> 0 | X25: =VLOOKUP(F25,#REF!,7,0) -> #REF! | Z25: =N25=Y25 -> FALSE
B26: 15 | E26: =IF($D26<>0,VLOOKUP($D26,$D$44:$E$92,2,FALSE),"") | G26: =IF($F26<>0,VLOOKUP($F26,$E$74:$M$539,2,FALSE),"") | J26: =IF($F26<>0,VLOOKUP($F26,$E$74:$M$539,7,FALSE),"") | K26: =IF($F26<>0,VLOOKUP($F26,$E$74:$M$539,8,FALSE),"") | M26: =IF($L26<>0,VLOOKUP($F26,$E$74:$M$539,9,FALSE)*$L26,"") | O26: =IF(L26<>0,$L26*$N26,"") | R26: =VLOOKUP(F26,'파레트 제품 리스트'!$B:$F,4,0) -> #N/A | S26: =VLOOKUP(F26,'파레트 제품 리스트'!$B:$F,5,0) -> #N/A | U26: =O26*1.1 -> #VALUE! | V26: =VLOOKUP(F26,미출!$D:$F,3,0) -> #N/A | W26: =COUNTIF($F$11:$F$11,F26) -> 0 | X26: =VLOOKUP(F26,#REF!,7,0) -> #REF! | Z26: =N26=Y26 -> TRUE
J27: =IF($F27<>0,VLOOKUP($F27,$E$91:$M$460,7,FALSE),"") | K27: =IF($F27<>0,VLOOKUP($F27,$E$91:$M$460,8,FALSE),"") | M27: =IF($L27<>0,VLOOKUP($F27,$E$91:$M$460,9,FALSE)*$L27,"") | N27: =IF($F27<>0,VLOOKUP($F27,$E$91:$M$460,5,FALSE),"") | O27: =IF(L27<>0,$L27*$N27,"")
I28: 발주물량 | J28: 리터(Liter) | K28: =SUM(M12:M26) -> 11992 | M28: 발주 금액 | N28: 부가세별도 | O28: =SUM(O12:O26) -> 38406360
J29: 드럼(Drum) | K29: =$K$28/200 -> 59.96 | N29: 부가세포함 | O29: =O28*1.1 -> 42246996
L32: =#REF!+#REF!+#REF!+#REF! -> #REF!
L33: =+#REF!+#REF!+#REF!+#REF! -> #REF!
L34: =L33-L32 -> #REF!
B41: 발주서 기초자료
D44: 거래처명 | E44: 거래처코드 | G44: 배송지 | H44: 주소 | M44: 담당자 | N44: 연락처
D45: 화성창고-일반가 | E45: 194667 | G45: 영일-화성 | H45: 경기도 화성시 향남읍 구문천1길 43-9
D46: 화성창고-화성에너지 | E46: 200584 | G46: 영일 - 화성(에너지) | H46: 경기도 화성시 향남읍 구문천1길 43-9
D47: 화성창고-하이스코 | E47: 194729 | G47: 영일-현대제철(화성창고) | H47: 경기도 화성시 향남읍 구문천1길 43-9
D48: 화성창고-티센 | E48: 194638 | G48: 티센크루프엘리베이터코리아(주) | H48: 경기도 화성시 향남읍 구문천1길 43-9
D49: 화성창고-아주지오텍 | E49: 202724 | G49: 영일 - 아주지오텍(화성창고) | H49: 경기도 화성시 향남읍 구문천1길 43-9
D50: 화성창고-위아 | E50: 203805 | G50: 영일 - 위아(화성창고) | H50: 경기도 화성시 향남읍 구문천1길 43-9
D51: 화성창고-SEW | E51: 215691 | G51: 영일-SEW-화성창고 | H51: 경기도 화성시 향남읍 구문천1길 43-9
D52: 화성창고-SHILLA | E52: 208008 | G52: 영일-신라정밀-화성창고 | H52: 경기도 화성시 향남읍 구문천1길 43-9
D53: 화성창고-KORAIL-iL | E53: 207998 | G53: 영일-코레일-화성창고 | H53: 경기도 화성시 향남읍 구문천1길 43-9 | R53: `
...

Sheet 양식1 (2)
B2: 발 주 서 | M2: 발주 접수처 (엑슨모빌 중국 상하이 고객지원팀)
M3: · 부서메일주소 : koreadcp@exxonmobil.com
M4: · 수신부담팩스 : 00798 8521 8501
M5: · 수신부담전화 : 00798 8521 8503
B7: 대리점명 | D7: (주)영일오엔씨 | F7: 대리점코드 | G7: 모빌(194637) | K7: 발주일 | L7: =TODAY() -> 45981 | N7: 납기일 | O7: =TODAY()+1 -> 45982
B8: 전화번호 | D8: 02-2693-5189 | F8: 팩스번호 | G8: 02-2693-5902 | K8: 담당자 | L8: 조윤석 팀장 | N8: 연락처 | O8: 031-8059-5151
B9: 주소 | K9: 납 지 | L9: 영일-화성 | M9: =IF($L9<>0,VLOOKUP($L9,$G$45:$K$70,2,FALSE),"") -> 경기도 화성시 향남읍 구문천1길 43-9
B11: 순번 (No.) | C11: 발주처 | D11: 거래처명 (Ship to) | E11: 코드번호 (Child Code) | F11: 제품코드 (P-Code) | G11: 제품명 (Product Name) | J11: 규격 (Package) | K11: 제품군 (Lob) | L11: 수량 (Quanty) | M11: 물량/리터 (Volume) | N11: 단가 (Unit Price) | O11: 금액(별도) (Amounts) | P11: 오더번호 | R11: 발주단위 | U11: 금액(포함) | V11: 미출수량 | W11: 중복 | X11: 전일발주수량 | Y11: 단가 | Z11: 확인
B12: 1 | C12: 조성호 | D12: 화성창고-일반가 | E12: =IF($D12<>0,VLOOKUP($D12,$D$45:$E$71,2,FALSE),"") -> 194667 | F12: 140677 | G12: =IF($F12<>0,VLOOKUP($F12,$E$73:$M$535,2,FALSE),"") -> MOBIL RARUS 68 EXCEL 20LT:KR | J12: =IF($F12<>0,VLOOKUP($F12,$E$73:$M$535,7,FALSE),"") -> PAIL | K12: =IF($F12<>0,VLOOKUP($F12,$E$73:$M$535,8,FALSE),"") -> IND | L12: 20 | M12: =IF($L12<>0,VLOOKUP($F12,$E$73:$M$535,9,FALSE)*$L12,"") -> 400 | N12: =IF($F12<>0,VLOOKUP($F12,$E$53:$L$543,5,FALSE),"") -> 79200 | O12: =IF(L12<>0,$L12*$N12,"") -> 1584000 | R12: =VLOOKUP(F12,'파레트 제품 리스트'!$B:$F,4,0) -> MIX (28) | S12: =VLOOKUP(F12,'파레트 제품 리스트'!$B:$F,5,0) -> 1 | U12: =O12*1.1 -> 1742400
B13: 2 | D13: 화성창고-일반가 | E13: =IF($D13<>0,VLOOKUP($D13,$D$45:$E$71,2,FALSE),"") -> 194667 | G13: =IF($F13<>0,VLOOKUP($F13,$E$73:$M$535,2,FALSE),"") | J13: =IF($F13<>0,VLOOKUP($F13,$E$73:$M$535,7,FALSE),"") | K13: =IF($F13<>0,VLOOKUP($F13,$E$73:$M$535,8,FALSE),"") | M13: =IF($L13<>0,VLOOKUP($F13,$E$73:$M$535,9,FALSE)*$L13,"") | N13: =IF($F13<>0,VLOOKUP($F13,$E$53:$L$543,5,FALSE),"") | O13: =IF(L13<>0,$L13*$N13,"") | R13: =VLOOKUP(F13,'파레트 제품 리스트'!$B:$F,4,0) -> #N/A | S13: =VLOOKUP(F13,'파레트 제품 리스트'!$B:$F,5,0) -> #N/A | U13: =O13*1.1 -> #VALUE!
B14: 3 | D14: 화성창고-일반가 | E14: =IF($D14<>0,VLOOKUP($D14,$D$45:$E$71,2,FALSE),"") -> 194667 | G14: =IF($F14<>0,VLOOKUP($F14,$E$73:$M$535,2,FALSE),"") | J14: =IF($F14<>0,VLOOKUP($F14,$E$73:$M$535,7,FALSE),"") | K14: =IF($F14<>0,VLOOKUP($F14,$E$73:$M$535,8,FALSE),"") | M14: =IF($L14<>0,VLOOKUP($F14,$E$73:$M$535,9,FALSE)*$L14,"") | N14: =IF($F14<>0,VLOOKUP($F14,$E$53:$L$543,5,FALSE),"") | O14: =IF(L14<>0,$L14*$N14,"") | R14: =VLOOKUP(F14,'파레트 제품 리스트'!$B:$F,4,0) -> #N/A | S14: =VLOOKUP(F14,'파레트 제품 리스트'!$B:$F,5,0) -> #N/A | U14: =O14*1.1 -> #VALUE!
B15: 4 | D15: 화성창고-일반가 | E15: =IF($D15<>0,VLOOKUP($D15,$D$45:$E$71,2,FALSE),"") -> 194667 | G15: =IF($F15<>0,VLOOKUP($F15,$E$73:$M$535,2,FALSE),"") | J15: =IF($F15<>0,VLOOKUP($F15,$E$73:$M$535,7,FALSE),"") | K15: =IF($F15<>0,VLOOKUP($F15,$E$73:$M$535,8,FALSE),"") | M15: =IF($L15<>0,VLOOKUP($F15,$E$73:$M$535,9,FALSE)*$L15,"") | N15: =IF($F15<>0,VLOOKUP($F15,$E$53:$L$543,5,FALSE),"") | O15: =IF(L15<>0,$L15*$N15,"") | R15: =VLOOKUP(F15,'파레트 제품 리스트'!$B:$F,4,0) -> #N/A | S15: =VLOOKUP(F15,'파레트 제품 리스트'!$B:$F,5,0) -> #N/A | U15: =O15*1.1 -> #VALUE!
B16: 5 | D16: 화성창고-일반가 | E16: =IF($D16<>0,VLOOKUP($D16,$D$45:$E$71,2,FALSE),"") -> 194667 | G16: =IF($F16<>0,VLOOKUP($F16,$E$73:$M$535,2,FALSE),"") | J16: =IF($F16<>0,VLOOKUP($F16,$E$73:$M$535,7,FALSE),"") | K16: =IF($F16<>0,VLOOKUP($F16,$E$73:$M$535,8,FALSE),"") | M16: =IF($L16<>0,VLOOKUP($F16,$E$73:$M$535,9,FALSE)*$L16,"") | N16: =IF($F16<>0,VLOOKUP($F16,$E$53:$L$543,5,FALSE),"") | O16: =IF(L16<>0,$L16*$N16,"") | R16: =VLOOKUP(F16,'파레트 제품 리스트'!$B:$F,4,0) -> #N/A | S16: =VLOOKUP(F16,'파레트 제품 리스트'!$B:$F,5,0) -> #N/A | U16: =O16*1.1 -> #VALUE!
B17: 6 | D17: 화성창고-일반가 | E17: =IF($D17<>0,VLOOKUP($D17,$D$45:$E$71,2,FALSE),"") -> 194667 | G17: =IF($F17<>0,VLOOKUP($F17,$E$73:$M$535,2,FALSE),"") | J17: =IF($F17<>0,VLOOKUP($F17,$E$73:$M$535,7,FALSE),"") | K17: =IF($F17<>0,VLOOKUP($F17,$E$73:$M$535,8,FALSE),"") | M17: =IF($L17<>0,VLOOKUP($F17,$E$73:$M$535,9,FALSE)*$L17,"") | N17: =IF($F17<>0,VLOOKUP($F17,$E$53:$L$543,5,FALSE),"") | O17: =IF(L17<>0,$L17*$N17,"") | R17: =VLOOKUP(F17,'파레트 제품 리스트'!$B:$F,4,0) -> #N/A | S17: =VLOOKUP(F17,'파레트 제품 리스트'!$B:$F,5,0) -> #N/A | U17: =O17*1.1 -> #VALUE!
B18: 7 | D18: 화성창고-일반가 | E18: =IF($D18<>0,VLOOKUP($D18,$D$45:$E$71,2,FALSE),"") -> 194667 | G18: =IF($F18<>0,VLOOKUP($F18,$E$73:$M$535,2,FALSE),"") | J18: =IF($F18<>0,VLOOKUP($F18,$E$73:$M$535,7,FALSE),"") | K18: =IF($F18<>0,VLOOKUP($F18,$E$73:$M$535,8,FALSE),"") | M18: =IF($L18<>0,VLOOKUP($F18,$E$73:$M$535,9,FALSE)*$L18,"") | N18: =IF($F18<>0,VLOOKUP($F18,$E$53:$L$543,5,FALSE),"") | O18: =IF(L18<>0,$L18*$N18,"") | R18: =VLOOKUP(F18,'파레트 제품 리스트'!$B:$F,4,0) -> #N/A | S18: =VLOOKUP(F18,'파레트 제품 리스트'!$B:$F,5,0) -> #N/A | U18: =O18*1.1 -> #VALUE!
B19: 8 | D19: 화성창고-일반가 | E19: =IF($D19<>0,VLOOKUP($D19,$D$45:$E$71,2,FALSE),"") -> 194667 | G19: =IF($F19<>0,VLOOKUP($F19,$E$73:$M$535,2,FALSE),"") | J19: =IF($F19<>0,VLOOKUP($F19,$E$73:$M$535,7,FALSE),"") | K19: =IF($F19<>0,VLOOKUP($F19,$E$73:$M$535,8,FALSE),"") | M19: =IF($L19<>0,VLOOKUP($F19,$E$73:$M$535,9,FALSE)*$L19,"") | N19: =IF($F19<>0,VLOOKUP($F19,$E$53:$L$543,5,FALSE),"") | O19: =IF(L19<>0,$L19*$N19,"") | R19: =VLOOKUP(F19,'파레트 제품 리스트'!$B:$F,4,0) -> #N/A | S19: =VLOOKUP(F19,'파레트 제품 리스트'!$B:$F,5,0) -> #N/A | U19: =O19*1.1 -> #VALUE!
B20: 9 | D20: 화성창고-일반가 | E20: =IF($D20<>0,VLOOKUP($D20,$D$45:$E$71,2,FALSE),"") -> 194667 | G20: =IF($F20<>0,VLOOKUP($F20,$E$73:$M$535,2,FALSE),"") | J20: =IF($F20<>0,VLOOKUP($F20,$E$73:$M$535,7,FALSE),"") | K20: =IF($F20<>0,VLOOKUP($F20,$E$73:$M$535,8,FALSE),"") | M20: =IF($L20<>0,VLOOKUP($F20,$E$73:$M$535,9,FALSE)*$L20,"") | N20: =IF($F20<>0,VLOOKUP($F20,$E$53:$L$543,5,FALSE),"") | O20: =IF(L20<>0,$L20*$N20,"") | R20: =VLOOKUP(F20,'파레트 제품 리스트'!$B:$F,4,0) -> #N/A | S20: =VLOOKUP(F20,'파레트 제품 리스트'!$B:$F,5,0) -> #N/A | U20: =O20*1.1 -> #VALUE!
B21: 10 | D21: 화성창고-일반가 | E21: =IF($D21<>0,VLOOKUP($D21,$D$45:$E$71,2,FALSE),"") -> 194667 | G21: =IF($F21<>0,VLOOKUP($F21,$E$73:$M$535,2,FALSE),"") | J21: =IF($F21<>0,VLOOKUP($F21,$E$73:$M$535,7,FALSE),"") | K21: =IF($F21<>0,VLOOKUP($F21,$E$73:$M$535,8,FALSE),"") | M21: =IF($L21<>0,VLOOKUP($F21,$E$73:$M$535,9,FALSE)*$L21,"") | N21: =IF($F21<>0,VLOOKUP($F21,$E$53:$L$543,5,FALSE),"") | O21: =IF(L21<>0,$L21*$N21,"") | R21: =VLOOKUP(F21,'파레트 제품 리스트'!$B:$F,4,0) -> #N/A | S21: =VLOOKUP(F21,'파레트 제품 리스트'!$B:$F,5,0) -> #N/A | U21: =O21*1.1 -> #VALUE!
B22: 11 | D22: 화성창고-일반가 | E22: =IF($D22<>0,VLOOKUP($D22,$D$45:$E$71,2,FALSE),"") -> 194667 | G22: =IF($F22<>0,VLOOKUP($F22,$E$73:$M$535,2,FALSE),"") | J22: =IF($F22<>0,VLOOKUP($F22,$E$73:$M$535,7,FALSE),"") | K22: =IF($F22<>0,VLOOKUP($F22,$E$73:$M$535,8,FALSE),"") | M22: =IF($L22<>0,VLOOKUP($F22,$E$73:$M$535,9,FALSE)*$L22,"") | N22: =IF($F22<>0,VLOOKUP($F22,$E$53:$L$543,5,FALSE),"") | O22: =IF(L22<>0,$L22*$N22,"") | R22: =VLOOKUP(F22,'파레트 제품 리스트'!$B:$F,4,0) -> #N/A | S22: =VLOOKUP(F22,'파레트 제품 리스트'!$B:$F,5,0) -> #N/A | U22: =O22*1.1 -> #VALUE!
B23: 12 | D23: 화성창고-일반가 | E23: =IF($D23<>0,VLOOKUP($D23,$D$45:$E$71,2,FALSE),"") -> 194667 | G23: =IF($F23<>0,VLOOKUP($F23,$E$73:$M$535,2,FALSE),"") | J23: =IF($F23<>0,VLOOKUP($F23,$E$73:$M$535,7,FALSE),"") | K23: =IF($F23<>0,VLOOKUP($F23,$E$73:$M$535,8,FALSE),"") | M23: =IF($L23<>0,VLOOKUP($F23,$E$73:$M$535,9,FALSE)*$L23,"") | N23: =IF($F23<>0,VLOOKUP($F23,$E$53:$L$543,5,FALSE),"") | O23: =IF(L23<>0,$L23*$N23,"") | R23: =VLOOKUP(F23,'파레트 제품 리스트'!$B:$F,4,0) -> #N/A | S23: =VLOOKUP(F23,'파레트 제품 리스트'!$B:$F,5,0) -> #N/A | U23: =O23*1.1 -> #VALUE!
B24: 13 | D24: 화성창고-일반가 | E24: =IF($D24<>0,VLOOKUP($D24,$D$45:$E$71,2,FALSE),"") -> 194667 | G24: =IF($F24<>0,VLOOKUP($F24,$E$73:$M$535,2,FALSE),"") | J24: =IF($F24<>0,VLOOKUP($F24,$E$73:$M$535,7,FALSE),"") | K24: =IF($F24<>0,VLOOKUP($F24,$E$73:$M$535,8,FALSE),"") | M24: =IF($L24<>0,VLOOKUP($F24,$E$73:$M$535,9,FALSE)*$L24,"") | N24: =IF($F24<>0,VLOOKUP($F24,$E$53:$L$543,5,FALSE),"") | O24: =IF(L24<>0,$L24*$N24,"") | R24: =VLOOKUP(F24,'파레트 제품 리스트'!$B:$F,4,0) -> #N/A | S24: =VLOOKUP(F24,'파레트 제품 리스트'!$B:$F,5,0) -> #N/A | U24: =O24*1.1 -> #VALUE!
B25: 14 | D25: 화성창고-일반가 | E25: =IF($D25<>0,VLOOKUP($D25,$D$45:$E$71,2,FALSE),"") -> 194667 | G25: =IF($F25<>0,VLOOKUP($F25,$E$73:$M$535,2,FALSE),"") | J25: =IF($F25<>0,VLOOKUP($F25,$E$73:$M$535,7,FALSE),"") | K25: =IF($F25<>0,VLOOKUP($F25,$E$73:$M$535,8,FALSE),"") | M25: =IF($L25<>0,VLOOKUP($F25,$E$73:$M$535,9,FALSE)*$L25,"") | N25: =IF($F25<>0,VLOOKUP($F25,$E$53:$L$543,5,FALSE),"") | O25: =IF(L25<>0,$L25*$N25,"") | R25: =VLOOKUP(F25,'파레트 제품 리스트'!$B:$F,4,0) -> #N/A | S25: =VLOOKUP(F25,'파레트 제품 리스트'!$B:$F,5,0) -> #N/A | U25: =O25*1.1 -> #VALUE!
B26: 15 | G26: =IF($F26<>0,VLOOKUP($F26,$E$73:$M$535,2,FALSE),"") | J26: =IF($F26<>0,VLOOKUP($F26,$E$73:$M$535,7,FALSE),"") | K26: =IF($F26<>0,VLOOKUP($F26,$E$73:$M$535,8,FALSE),"") | M26: =IF($L26<>0,VLOOKUP($F26,$E$73:$M$535,9,FALSE)*$L26,"") | N26: =IF($F26<>0,VLOOKUP($F26,$E$53:$L$543,5,FALSE),"") | O26: =IF(L26<>0,$L26*$N26,"") | U26: =O26*1.1 -> #VALUE!
J27: =IF($F27<>0,VLOOKUP($F27,$E$88:$M$457,7,FALSE),"") | K27: =IF($F27<>0,VLOOKUP($F27,$E$88:$M$457,8,FALSE),"") | M27: =IF($L27<>0,VLOOKUP($F27,$E$88:$M$457,9,FALSE)*$L27,"") | N27: =IF($F27<>0,VLOOKUP($F27,$E$88:$M$457,5,FALSE),"") | O27: =IF(L27<>0,$L27*$N27,"")
I28: 발주물량 | J28: 리터(Liter) | K28: =SUM(M12:M26) -> 400 | M28: 발주 금액 | N28: 부가세별도 | O28: =SUM(O12:O27) -> 1584000
J29: 드럼(Drum) | K29: =$K$28/200 -> 2 | N29: 부가세포함 | O29: =O28*1.1 -> 1742400
L32: =#REF!+#REF!+#REF!+#REF! -> #REF!
L33: =+#REF!+#REF!+#REF!+#REF! -> #REF!
L34: =L33-L32 -> #REF!
B41: 발주서 기초자료
D44: 거래처명 | E44: 거래처코드 | G44: 배송지 | H44: 주소 | M44: 담당자 | N44: 연락처
D45: 화성창고-일반가 | E45: 194667 | G45: 영일-화성 | H45: 경기도 화성시 향남읍 구문천1길 43-9
D46: 화성창고-화성에너지 | E46: 200584 | G46: 영일 - 화성(에너지) | H46: 경기도 화성시 향남읍 구문천1길 43-9
D47: 화성창고-하이스코 | E47: 194729 | G47: 영일-현대제철(화성창고) | H47: 경기도 화성시 향남읍 구문천1길 43-9
D48: 화성창고-티센 | E48: 194638 | G48: 티센크루프엘리베이터코리아(주) | H48: 경기도 화성시 향남읍 구문천1길 43-9
D49: 화성창고-아주지오텍 | E49: 202724 | G49: 영일 - 아주지오텍(화성창고) | H49: 경기도 화성시 향남읍 구문천1길 43-9
D50: 화성창고-위아 | E50: 203805 | G50: 영일 - 위아(화성창고) | H50: 경기도 화성시 향남읍 구문천1길 43-9
D51: 화성창고-SEW | E51: 215691 | G51: 영일-SEW-화성창고 | H51: 경기도 화성시 향남읍 구문천1길 43-9
D52: 화성창고-SHILLA | E52: 208008 | G52: 영일-신라정밀-화성창고 | H52: 경기도 화성시 향남읍 구문천1길 43-9
D53: 화성창고-KORAIL-iL | E53: 207998 | G53: 영일-코레일-화성창고 | H53: 경기도 화성시 향남읍 구문천1길 43-9 | R53: `
...

Sheet 양식1
B2: 발 주 서 | M2: 발주 접수처 (엑슨모빌 중국 상하이 고객지원팀)
M3: · 부서메일주소 : koreadcp@exxonmobil.com
M4: · 수신부담팩스 : 00798 8521 8501
M5: · 수신부담전화 : 00798 8521 8503
B7: 대리점명 | D7: (주)영일오엔씨 | F7: 대리점코드 | G7: 모빌(194637) | K7: 발주일 | L7: =TODAY() -> 45981 | N7: 납기일 | O7: =TODAY()+1 -> 45982
B8: 전화번호 | D8: 02-2693-5189 | F8: 팩스번호 | G8: 02-2693-5902 | K8: 담당자 | L8: 조윤석 팀장 | N8: 연락처 | O8: 031-8059-5151
B9: 주소 | K9: 납 지 | L9: 영일-화성 | M9: =IF($L9<>0,VLOOKUP($L9,$G$45:$K$70,2,FALSE),"") -> 경기도 화성시 향남읍 구문천1길 43-9
B11: 순번 (No.) | C11: 발주처 | D11: 거래처명 (Ship to) | E11: 코드번호 (Child Code) | F11: 제품코드 (P-Code) | G11: 제품명 (Product Name) | J11: 규격 (Package) | K11: 제품군 (Lob) | L11: 수량 (Quanty) | M11: 물량/리터 (Volume) | N11: 단가 (Unit Price) | O11: 금액(별도) (Amounts) | P11: 오더번호 | R11: 발주단위 | U11: 금액(포함) | V11: 미출수량 | W11: 중복 | X11: 전일발주수량 | Y11: 단가 | Z11: 확인
B12: 1 | C12: 한화토탈에너지 | D12: 화성창고-일반가 | E12: =IF($D12<>0,VLOOKUP($D12,$D$45:$E$71,2,FALSE),"") -> 194667 | F12: 139600 | G12: =IF($F12<>0,VLOOKUP($F12,$E$73:$M$535,2,FALSE),"") -> MOBIL SHC GEAR 320 WT PAIL 20L:KR | J12: =IF($F12<>0,VLOOKUP($F12,$E$73:$M$535,7,FALSE),"") -> PAIL | K12: =IF($F12<>0,VLOOKUP($F12,$E$73:$M$535,8,FALSE),"") -> IND | L12: 6 | M12: =IF($L12<>0,VLOOKUP($F12,$E$73:$M$535,9,FALSE)*$L12,"") -> 120 | N12: =IF($F12<>0,VLOOKUP($F12,$E$53:$L$543,5,FALSE),"") -> 482000 | O12: =IF(L12<>0,$L12*$N12,"") -> 2892000 | P12: 0 | R12: =VLOOKUP(F12,'파레트 제품 리스트'!$B:$F,4,0) -> MIX (28) | S12: =VLOOKUP(F12,'파레트 제품 리스트'!$B:$F,5,0) -> 1 | U12: =O12*1.1 -> 3181200
B13: 2 | C13: 빠라베에사 | D13: 화성창고-일반가 | E13: =IF($D13<>0,VLOOKUP($D13,$D$45:$E$71,2,FALSE),"") -> 194667 | F13: 143985 | G13: =IF($F13<>0,VLOOKUP($F13,$E$73:$M$535,2,FALSE),"") -> MOBIL SHC 630 DRUM 208L:SG | J13: =IF($F13<>0,VLOOKUP($F13,$E$73:$M$535,7,FALSE),"") -> DRUM | K13: =IF($F13<>0,VLOOKUP($F13,$E$73:$M$535,8,FALSE),"") -> IND | L13: 1 | M13: =IF($L13<>0,VLOOKUP($F13,$E$73:$M$535,9,FALSE)*$L13,"") -> 208 | N13: =IF($F13<>0,VLOOKUP($F13,$E$53:$L$543,5,FALSE),"") -> 2763000 | O13: =IF(L13<>0,$L13*$N13,"") -> 2763000 | P13: 0 | R13: =VLOOKUP(F13,'파레트 제품 리스트'!$B:$F,4,0) -> #N/A | S13: =VLOOKUP(F13,'파레트 제품 리스트'!$B:$F,5,0) -> #N/A | U13: =O13*1.1 -> 3039300
B14: 3 | C14: 서부산업 | D14: 화성창고-일반가 | E14: =IF($D14<>0,VLOOKUP($D14,$D$45:$E$71,2,FALSE),"") -> 194667 | F14: 135836 | G14: =IF($F14<>0,VLOOKUP($F14,$E$73:$M$535,2,FALSE),"") -> MOBIL GARGOYLE ARCTIC SHC 230 DRUM 208L | J14: =IF($F14<>0,VLOOKUP($F14,$E$73:$M$535,7,FALSE),"") -> DRUM | K14: =IF($F14<>0,VLOOKUP($F14,$E$73:$M$535,8,FALSE),"") -> IND | L14: 1 | M14: =IF($L14<>0,VLOOKUP($F14,$E$73:$M$535,9,FALSE)*$L14,"") -> 208 | N14: =IF($F14<>0,VLOOKUP($F14,$E$53:$L$543,5,FALSE),"") -> 3321000 | O14: =IF(L14<>0,$L14*$N14,"") -> 3321000 | P14: 0 | R14: =VLOOKUP(F14,'파레트 제품 리스트'!$B:$F,4,0) -> DRUM | S14: =VLOOKUP(F14,'파레트 제품 리스트'!$B:$F,5,0) -> 1 | U14: =O14*1.1 -> 3653100
B15: 2 | D15: 화성창고-일반가 | E15: =IF($D15<>0,VLOOKUP($D15,$D$45:$E$71,2,FALSE),"") -> 194667 | F15: 139105 | G15: =IF($F15<>0,VLOOKUP($F15,$E$73:$M$535,2,FALSE),"") -> MOBILTHERM 603 DRUM 200L:KR | J15: =IF($F15<>0,VLOOKUP($F15,$E$73:$M$535,7,FALSE),"") -> DRUM | K15: =IF($F15<>0,VLOOKUP($F15,$E$73:$M$535,8,FALSE),"") -> IND | L15: 2 | M15: =IF($L15<>0,VLOOKUP($F15,$E$73:$M$535,9,FALSE)*$L15,"") -> 400 | N15: =IF($F15<>0,VLOOKUP($F15,$E$53:$L$543,5,FALSE),"") -> 628000 | O15: =IF(L15<>0,$L15*$N15,"") -> 1256000 | P15: 16 | R15: =VLOOKUP(F15,'파레트 제품 리스트'!$B:$F,4,0) -> DRUM | S15: =VLOOKUP(F15,'파레트 제품 리스트'!$B:$F,5,0) -> 1 | U15: =O15*1.1 -> 1381600
B16: 3 | D16: 화성창고-일반가 | E16: =IF($D16<>0,VLOOKUP($D16,$D$45:$E$71,2,FALSE),"") -> 194667 | F16: 144277 | G16: =IF($F16<>0,VLOOKUP($F16,$E$73:$M$535,2,FALSE),"") -> MOBIL VACUOLINE 1409 PAIL 20L | J16: =IF($F16<>0,VLOOKUP($F16,$E$73:$M$535,7,FALSE),"") -> PAIL | K16: =IF($F16<>0,VLOOKUP($F16,$E$73:$M$535,8,FALSE),"") -> IND | L16: 42 | M16: =IF($L16<>0,VLOOKUP($F16,$E$73:$M$535,9,FALSE)*$L16,"") -> 840 | N16: =IF($F16<>0,VLOOKUP($F16,$E$53:$L$543,5,FALSE),"") -> 46600 | O16: =IF(L16<>0,$L16*$N16,"") -> 1957200 | P16: 251 | R16: =VLOOKUP(F16,'파레트 제품 리스트'!$B:$F,4,0) -> Full | S16: =VLOOKUP(F16,'파레트 제품 리스트'!$B:$F,5,0) -> 42 | U16: =O16*1.1 -> 2152920
B17: 4 | D17: 화성창고-일반가 | E17: =IF($D17<>0,VLOOKUP($D17,$D$45:$E$71,2,FALSE),"") -> 194667 | F17: 148688 | G17: =IF($F17<>0,VLOOKUP($F17,$E$73:$M$535,2,FALSE),"") -> MOBIL VACUO 533-PL20L | J17: =IF($F17<>0,VLOOKUP($F17,$E$73:$M$535,7,FALSE),"") -> PAIL | K17: =IF($F17<>0,VLOOKUP($F17,$E$73:$M$535,8,FALSE),"") -> IND | L17: 14 | M17: =IF($L17<>0,VLOOKUP($F17,$E$73:$M$535,9,FALSE)*$L17,"") -> 280 | N17: =IF($F17<>0,VLOOKUP($F17,$E$53:$L$543,5,FALSE),"") -> 69500 | O17: =IF(L17<>0,$L17*$N17,"") -> 973000 | P17: 23 | R17: =VLOOKUP(F17,'파레트 제품 리스트'!$B:$F,4,0) -> MIX (28) | S17: =VLOOKUP(F17,'파레트 제품 리스트'!$B:$F,5,0) -> 1 | U17: =O17*1.1 -> 1070300
B18: 5 | D18: 화성창고-위아 | E18: =IF($D18<>0,VLOOKUP($D18,$D$45:$E$71,2,FALSE),"") -> 203805 | F18: 139101 | G18: =IF($F18<>0,VLOOKUP($F18,$E$73:$M$535,2,FALSE),"") -> MOBIL VELOCITE NO 3 DRUM 200L:KR | J18: =IF($F18<>0,VLOOKUP($F18,$E$73:$M$535,7,FALSE),"") -> DRUM | K18: =IF($F18<>0,VLOOKUP($F18,$E$73:$M$535,8,FALSE),"") -> IND | L18: 2 | M18: =IF($L18<>0,VLOOKUP($F18,$E$73:$M$535,9,FALSE)*$L18,"") -> 400 | N18: 490000 | O18: =IF(L18<>0,$L18*$N18,"") -> 980000 | P18: 22 | R18: =VLOOKUP(F18,'파레트 제품 리스트'!$B:$F,4,0) -> DRUM | S18: =VLOOKUP(F18,'파레트 제품 리스트'!$B:$F,5,0) -> 1 | U18: =O18*1.1 -> 1078000
B19: 6 | D19: 화성창고-일반가 | E19: =IF($D19<>0,VLOOKUP($D19,$D$45:$E$71,2,FALSE),"") -> 194667 | F19: 140202 | G19: =IF($F19<>0,VLOOKUP($F19,$E$73:$M$535,2,FALSE),"") -> MOBILITH SHC 220 PAIL 16KG:SG | J19: =IF($F19<>0,VLOOKUP($F19,$E$73:$M$535,7,FALSE),"") -> PAIL | K19: =IF($F19<>0,VLOOKUP($F19,$E$73:$M$535,8,FALSE),"") -> IND | L19: 8 | M19: =IF($L19<>0,VLOOKUP($F19,$E$73:$M$535,9,FALSE)*$L19,"") -> 128 | N19: =IF($F19<>0,VLOOKUP($F19,$E$53:$L$543,5,FALSE),"") -> 352000 | O19: =IF(L19<>0,$L19*$N19,"") -> 2816000 | P19: 72 | R19: =VLOOKUP(F19,'파레트 제품 리스트'!$B:$F,4,0) -> MIX (28) | S19: =VLOOKUP(F19,'파레트 제품 리스트'!$B:$F,5,0) -> 1 | U19: =O19*1.1 -> 3097600
B20: 9 | D20: 화성창고-일반가 | E20: =IF($D20<>0,VLOOKUP($D20,$D$45:$E$71,2,FALSE),"") -> 194667 | F20: 139107 | G20: =IF($F20<>0,VLOOKUP($F20,$E$73:$M$535,2,FALSE),"") -> MOBIL PEGASUS 610 DRUM 200L:KR | J20: =IF($F20<>0,VLOOKUP($F20,$E$73:$M$535,7,FALSE),"") -> DRUM | K20: =IF($F20<>0,VLOOKUP($F20,$E$73:$M$535,8,FALSE),"") -> IND | L20: 8 | M20: =IF($L20<>0,VLOOKUP($F20,$E$73:$M$535,9,FALSE)*$L20,"") -> 1600 | N20: =IF($F20<>0,VLOOKUP($F20,$E$53:$L$543,5,FALSE),"") -> 630000 | O20: =IF(L20<>0,$L20*$N20,"") -> 5040000 | P20: 40 | R20: =VLOOKUP(F20,'파레트 제품 리스트'!$B:$F,4,0) -> DRUM | S20: =VLOOKUP(F20,'파레트 제품 리스트'!$B:$F,5,0) -> 1 | U20: =O20*1.1 -> 5544000
B21: 10 | E21: =IF($D21<>0,VLOOKUP($D21,$D$45:$E$71,2,FALSE),"") | G21: =IF($F21<>0,VLOOKUP($F21,$E$73:$M$535,2,FALSE),"") | J21: =IF($F21<>0,VLOOKUP($F21,$E$73:$M$535,7,FALSE),"") | K21: =IF($F21<>0,VLOOKUP($F21,$E$73:$M$535,8,FALSE),"") | M21: =IF($L21<>0,VLOOKUP($F21,$E$73:$M$535,9,FALSE)*$L21,"") | N21: =IF($F21<>0,VLOOKUP($F21,$E$53:$L$543,5,FALSE),"") | O21: =IF(L21<>0,$L21*$N21,"") | R21: =VLOOKUP(F21,'파레트 제품 리스트'!$B:$F,4,0) -> #N/A | S21: =VLOOKUP(F21,'파레트 제품 리스트'!$B:$F,5,0) -> #N/A | U21: =O21*1.1 -> #VALUE!
B22: 11 | E22: =IF($D22<>0,VLOOKUP($D22,$D$45:$E$71,2,FALSE),"") | G22: =IF($F22<>0,VLOOKUP($F22,$E$73:$M$535,2,FALSE),"") | J22: =IF($F22<>0,VLOOKUP($F22,$E$73:$M$535,7,FALSE),"") | K22: =IF($F22<>0,VLOOKUP($F22,$E$73:$M$535,8,FALSE),"") | M22: =IF($L22<>0,VLOOKUP($F22,$E$73:$M$535,9,FALSE)*$L22,"") | N22: =IF($F22<>0,VLOOKUP($F22,$E$53:$L$543,5,FALSE),"") | O22: =IF(L22<>0,$L22*$N22,"") | R22: =VLOOKUP(F22,'파레트 제품 리스트'!$B:$F,4,0) -> #N/A | S22: =VLOOKUP(F22,'파레트 제품 리스트'!$B:$F,5,0) -> #N/A | U22: =O22*1.1 -> #VALUE!
B23: 12 | E23: =IF($D23<>0,VLOOKUP($D23,$D$45:$E$71,2,FALSE),"") | G23: =IF($F23<>0,VLOOKUP($F23,$E$73:$M$535,2,FALSE),"") | J23: =IF($F23<>0,VLOOKUP($F23,$E$73:$M$535,7,FALSE),"") | K23: =IF($F23<>0,VLOOKUP($F23,$E$73:$M$535,8,FALSE),"") | M23: =IF($L23<>0,VLOOKUP($F23,$E$73:$M$535,9,FALSE)*$L23,"") | N23: =IF($F23<>0,VLOOKUP($F23,$E$53:$L$543,5,FALSE),"") | O23: =IF(L23<>0,$L23*$N23,"") | R23: =VLOOKUP(F23,'파레트 제품 리스트'!$B:$F,4,0) -> #N/A | S23: =VLOOKUP(F23,'파레트 제품 리스트'!$B:$F,5,0) -> #N/A | U23: =O23*1.1 -> #VALUE!
B24: 13 | E24: =IF($D24<>0,VLOOKUP($D24,$D$45:$E$71,2,FALSE),"") | G24: =IF($F24<>0,VLOOKUP($F24,$E$73:$M$535,2,FALSE),"") | J24: =IF($F24<>0,VLOOKUP($F24,$E$73:$M$535,7,FALSE),"") | K24: =IF($F24<>0,VLOOKUP($F24,$E$73:$M$535,8,FALSE),"") | M24: =IF($L24<>0,VLOOKUP($F24,$E$73:$M$535,9,FALSE)*$L24,"") | N24: =IF($F24<>0,VLOOKUP($F24,$E$53:$L$543,5,FALSE),"") | O24: =IF(L24<>0,$L24*$N24,"") | R24: =VLOOKUP(F24,'파레트 제품 리스트'!$B:$F,4,0) -> #N/A | S24: =VLOOKUP(F24,'파레트 제품 리스트'!$B:$F,5,0) -> #N/A | U24: =O24*1.1 -> #VALUE!
B25: 14 | E25: =IF($D25<>0,VLOOKUP($D25,$D$45:$E$71,2,FALSE),"") | G25: =IF($F25<>0,VLOOKUP($F25,$E$73:$M$535,2,FALSE),"") | J25: =IF($F25<>0,VLOOKUP($F25,$E$73:$M$535,7,FALSE),"") | K25: =IF($F25<>0,VLOOKUP($F25,$E$73:$M$535,8,FALSE),"") | M25: =IF($L25<>0,VLOOKUP($F25,$E$73:$M$535,9,FALSE)*$L25,"") | N25: =IF($F25<>0,VLOOKUP($F25,$E$53:$L$543,5,FALSE),"") | O25: =IF(L25<>0,$L25*$N25,"") | R25: =VLOOKUP(F25,'파레트 제품 리스트'!$B:$F,4,0) -> #N/A | S25: =VLOOKUP(F25,'파레트 제품 리스트'!$B:$F,5,0) -> #N/A | U25: =O25*1.1 -> #VALUE!
B26: 15 | G26: =IF($F26<>0,VLOOKUP($F26,$E$73:$M$535,2,FALSE),"") | J26: =IF($F26<>0,VLOOKUP($F26,$E$73:$M$535,7,FALSE),"") | K26: =IF($F26<>0,VLOOKUP($F26,$E$73:$M$535,8,FALSE),"") | M26: =IF($L26<>0,VLOOKUP($F26,$E$73:$M$535,9,FALSE)*$L26,"") | N26: =IF($F26<>0,VLOOKUP($F26,$E$53:$L$543,5,FALSE),"") | O26: =IF(L26<>0,$L26*$N26,"") | U26: =O26*1.1 -> #VALUE!
J27: =IF($F27<>0,VLOOKUP($F27,$E$88:$M$457,7,FALSE),"") | K27: =IF($F27<>0,VLOOKUP($F27,$E$88:$M$457,8,FALSE),"") | M27: =IF($L27<>0,VLOOKUP($F27,$E$88:$M$457,9,FALSE)*$L27,"") | N27: =IF($F27<>0,VLOOKUP($F27,$E$88:$M$457,5,FALSE),"") | O27: =IF(L27<>0,$L27*$N27,"")
I28: 발주물량 | J28: 리터(Liter) | K28: =SUM(M12:M26) -> 4184 | M28: 발주 금액 | N28: 부가세별도 | O28: =SUM(O12:O27) -> 21998200
J29: 드럼(Drum) | K29: =$K$28/200 -> 20.92 | N29: 부가세포함 | O29: =O28*1.1 -> 24198020
L32: =#REF!+#REF!+#REF!+#REF! -> #REF!
L33: =+#REF!+#REF!+#REF!+#REF! -> #REF!
L34: =L33-L32 -> #REF!
B41: 발주서 기초자료
D44: 거래처명 | E44: 거래처코드 | G44: 배송지 | H44: 주소 | M44: 담당자 | N44: 연락처
D45: 화성창고-일반가 | E45: 194667 | G45: 영일-화성 | H45: 경기도 화성시 향남읍 구문천1길 43-9
D46: 화성창고-화성에너지 | E46: 200584 | G46: 영일 - 화성(에너지) | H46: 경기도 화성시 향남읍 구문천1길 43-9
D47: 화성창고-하이스코 | E47: 194729 | G47: 영일-현대제철(화성창고) | H47: 경기도 화성시 향남읍 구문천1길 43-9
D48: 화성창고-티센 | E48: 194638 | G48: 티센크루프엘리베이터코리아(주) | H48: 경기도 화성시 향남읍 구문천1길 43-9
D49: 화성창고-아주지오텍 | E49: 202724 | G49: 영일 - 아주지오텍(화성창고) | H49: 경기도 화성시 향남읍 구문천1길 43-9
D50: 화성창고-위아 | E50: 203805 | G50: 영일 - 위아(화성창고) | H50: 경기도 화성시 향남읍 구문천1길 43-9
D51: 화성창고-SEW | E51: 215691 | G51: 영일-SEW-화성창고 | H51: 경기도 화성시 향남읍 구문천1길 43-9
D52: 화성창고-SHILLA | E52: 208008 | G52: 영일-신라정밀-화성창고 | H52: 경기도 화성시 향남읍 구문천1길 43-9
D53: 화성창고-KORAIL-iL | E53: 207998 | G53: 영일-코레일-화성창고 | H53: 경기도 화성시 향남읍 구문천1길 43-9 | R53: `
...

Sheet 양식2
B2: 발 주 서 | M2: 발주 접수처 (엑슨모빌 중국 상하이 고객지원팀)
M3: · 부서메일주소 : koreadcp@exxonmobil.com
M4: · 수신부담팩스 : 00798 8521 8501
M5: · 수신부담전화 : 00798 8521 8503
B7: 대리점명 | D7: (주)영일오엔씨 | F7: 대리점코드 | G7: 모빌(194637) | K7: 발주일 | L7: =TODAY() -> 45981 | N7: 납기일 | O7: =TODAY()+1 -> 45982
B8: 전화번호 | D8: 02-2693-5189 | F8: 팩스번호 | G8: 02-2693-5902 | K8: 담당자 | L8: 조윤석 팀장 | N8: 연락처 | O8: 031-8059-5151
B9: 주소 | K9: 납 지 | L9: 영일-화성 | M9: =IF($L9<>0,VLOOKUP($L9,$G$45:$K$68,2,FALSE),"") -> 경기도 화성시 향남읍 구문천1길 43-9
B11: 순번 (No.) | C11: 발주처 | D11: 거래처명 (Ship to) | E11: 코드번호 (Child Code) | F11: 제품코드 (P-Code) | G11: 제품명 (Product Name) | J11: 규격 (Package) | K11: 제품군 (Lob) | L11: 수량 (Quanty) | M11: 물량/리터 (Volume) | N11: 단가 (Unit Price) | O11: 금액(별도) (Amounts) | P11: 오더번호 | R11: 발주단위 | U11: 금액(포함) | V11: 미출수량 | W11: 중복 | X11: 전일발주수량 | Y11: 단가 | Z11: 확인
B12: 1 | C12: 남부지사 | D12: 화성창고-일반가 | E12: =IF($D12<>0,VLOOKUP($D12,$D$45:$E$73,2,FALSE),"") -> 194667 | F12: 141742 | G12: =IF($F12<>0,VLOOKUP($F12,$E$81:$M$537,2,FALSE),"") -> MOBIL DTE 24 ULTRA DRUM 200L:KR | J12: =IF($F12<>0,VLOOKUP($F12,$E$81:$M$537,7,FALSE),"") -> DRUM | K12: =IF($F12<>0,VLOOKUP($F12,$E$81:$M$537,8,FALSE),"") -> IND | L12: 20 | M12: =IF($L12<>0,VLOOKUP($F12,$E$81:$M$537,9,FALSE)*$L12,"") -> 4000 | N12: =IF($F12<>0,VLOOKUP($F12,$E$53:$L$545,5,FALSE),"") -> 492000 | O12: =IF(L12<>0,$L12*$N12,"") -> 9840000 | P12: 15 | R12: =VLOOKUP(F12,'파레트 제품 리스트'!$B:$F,4,0) -> DRUM | S12: =VLOOKUP(F12,'파레트 제품 리스트'!$B:$F,5,0) -> 1 | U12: =O12*1.1 -> 10824000
B13: 2 | C13: 동부상사 | D13: 화성창고-일반가 | E13: =IF($D13<>0,VLOOKUP($D13,$D$45:$E$73,2,FALSE),"") -> 194667 | F13: 139125 | G13: =IF($F13<>0,VLOOKUP($F13,$E$81:$M$537,2,FALSE),"") -> MOBILGEAR 600 XP 68 DRUM 200L:KR | J13: =IF($F13<>0,VLOOKUP($F13,$E$81:$M$537,7,FALSE),"") -> DRUM | K13: =IF($F13<>0,VLOOKUP($F13,$E$81:$M$537,8,FALSE),"") -> IND | L13: 5 | M13: =IF($L13<>0,VLOOKUP($F13,$E$81:$M$537,9,FALSE)*$L13,"") -> 1000 | N13: =IF($F13<>0,VLOOKUP($F13,$E$53:$L$545,5,FALSE),"") -> 618000 | O13: =IF(L13<>0,$L13*$N13,"") -> 3090000 | P13: 21 | R13: =VLOOKUP(F13,'파레트 제품 리스트'!$B:$F,4,0) -> DRUM | S13: =VLOOKUP(F13,'파레트 제품 리스트'!$B:$F,5,0) -> 1 | U13: =O13*1.1 -> 3399000
B14: 3 | D14: 화성창고-일반가 | E14: =IF($D14<>0,VLOOKUP($D14,$D$45:$E$73,2,FALSE),"") -> 194667 | F14: 139137 | G14: =IF($F14<>0,VLOOKUP($F14,$E$81:$M$537,2,FALSE),"") -> MOBILGEAR 600 XP 320 PAIL 20L:KR | J14: =IF($F14<>0,VLOOKUP($F14,$E$81:$M$537,7,FALSE),"") -> PAIL | K14: =IF($F14<>0,VLOOKUP($F14,$E$81:$M$537,8,FALSE),"") -> IND | L14: 14 | M14: =IF($L14<>0,VLOOKUP($F14,$E$81:$M$537,9,FALSE)*$L14,"") -> 280 | N14: =IF($F14<>0,VLOOKUP($F14,$E$53:$L$545,5,FALSE),"") -> 80900 | O14: =IF(L14<>0,$L14*$N14,"") -> 1132600 | P14: 41 | R14: =VLOOKUP(F14,'파레트 제품 리스트'!$B:$F,4,0) -> MIX (28) | S14: =VLOOKUP(F14,'파레트 제품 리스트'!$B:$F,5,0) -> 1 | U14: =O14*1.1 -> 1245860
