Workbook

Sheet 2025년
BW1: 10 | BZ1: =BW1/12 -> 0.83333333
B2: 구분 | F2: 2023년 실적 | G2: 2024년 실적 | H2: 2025년(P) | I2: 증감율 | J2: 누적 | O2: 1월 | T2: 2월 | Y2: 3월 | AD2: 4월 | AI2: 5월 | AN2: 6월 | AS2: 7월 | AX2: 8월 | BC2: 9월 | BH2: 10월 | BM2: 11월 | BR2: 12월
J3: 2024년 | K3: 목표 | L3: 2025년 | M3: 달성율 | N3: 전년대비 | O3: =J3 -> 2024년 | P3: =K3 -> 목표 | Q3: =L3 -> 2025년 | R3: =M3 -> 달성율 | S3: =N3 -> 전년대비 | T3: =O3 -> 2024년 | U3: =P3 -> 목표 | V3: =Q3 -> 2025년 | ... BV3: =BQ3 -> 전년대비
B4: Auto+IL | D4: 판매량 | F4: ='2024년 실적'!G4 -> 10656512 | G4: ='2024년 실적'!L4 -> 10517294 | H4: =H9+H29 -> 11825000 | I4: =H4/G4-1 -> 0.12433864 | J4: =J9+J29 -> 8489461 | K4: =K9+K29 -> 9654680 | L4: =L9+L29 -> 8826715 | M4: =L4/K4-1 -> -0.085757892 | N4: =L4/J4-1 -> 0.039726197 | O4: =O9+O29 -> 750995 | P4: =P9+P29 -> 909418 | Q4: =Q9+Q29 -> 729749 | R4: =Q4/P4-1 -> -0.19756482 | S4: =Q4/O4-1 -> -0.028290468 | T4: =T9+T29 -> 731815 | U4: =U9+U29 -> 966418 | V4: =V9+V29 -> 885251 | W4: =V4/U4-1 -> -0.083987467 | X4: =V4/T4-1 -> 0.20966501 | Y4: =Y9+Y29 -> 940726 | Z4: =Z9+Z29 -> 1023418 | AA4: =AA9+AA29 -> 833839 | AB4: =AA4/Z4-1 -> -0.18524103 | AC4: =AA4/Y4-1 -> -0.11362182 | AD4: =AD9+AD29 -> 899518 | AE4: =AE9+AE29 -> 966418 | AF4: =AF9+AF29 -> 986877 | AG4: =AF4/AE4-1 -> 0.021169929 | AH4: =AF4/AD4-1 -> 0.097117567 | AI4: =AI9+AI29 -> 888999 | AJ4: =AJ9+AJ29 -> 966418 | AK4: =AK9+AK29 -> 949364 | AL4: =AK4/AJ4-1 -> -0.017646608 | AM4: =AK4/AI4-1 -> 0.067902214 | AN4: =AN9+AN29 -> 810468 | AO4: =AO9+AO29 -> 966418 | AP4: =AP9+AP29 -> 967394 | AQ4: =AP4/AO4-1 -> 0.001009915 | AR4: =AP4/AN4-1 -> 0.19362393 | AS4: =AS9+AS29 -> 917440 | AT4: =AT9+AT29 -> 966418 | AU4: =AU9+AU29 -> 851003 | AV4: =AU4/AT4-1 -> -0.11942555 | AW4: =AU4/AS4-1 -> -0.072415635 | AX4: =AX9+AX29 -> 839998 | AY4: =AY9+AY29 -> 966418 | AZ4: =AZ9+AZ29 -> 879550 | BA4: =AZ4/AY4-1 -> -0.089886571 | BB4: =AZ4/AX4-1 -> 0.047085826 | BC4: =BC9+BC29 -> 762755 | BD4: =BD9+BD29 -> 966418 | BE4: =BE9+BE29 -> 981485 | BF4: =BE4/BD4-1 -> 0.015590562 | BG4: =BE4/BC4-1 -> 0.28676312 | BH4: =BH9+BH29 -> 1032921 | BI4: =BI9+BI29 -> 1051918 | BJ4: =BJ9+BJ29 -> 859631 | BK4: =BJ4/BI4-1 -> -0.18279657 | BL4: =BJ4/BH4-1 -> -0.16776694 | BM4: =BM9+BM29 -> 970781 | BN4: =BN9+BN29 -> 1051918 | BO4: =BO9+BO29 -> 0 | BP4: =BO4/BN4-1 -> -1 | BQ4: =BO4/BM4-1 -> -1 | BR4: =BR9+BR29 -> 970878 | BS4: =BS9+BS29 -> 1023418 | BT4: =BT9+BT29 -> 0 | BU4: =BT4/BS4-1 -> -1 | BV4: =BT4/BR4-1 -> -1 | BX4: =L4-J4 -> 337254
D5: sell-in | F5: ='2024년 실적'!G5 -> 10654645 | G5: ='2024년 실적'!L5 -> 10432495 | H5: =H8+H28 -> 11825000 | I5: =H5/G5-1 -> 0.13347766 | J5: =J8+J28 -> 8551937 | K5: =K8+K28 -> 9736680 | L5: =L8+L28 -> 8912487 | M5: =L5/K5-1 -> -0.084648258 | N5: =L5/J5-1 -> 0.042160039 | O5: =O8+O28 -> 638533 | P5: =P8+P28 -> 909418 | Q5: =Q8+Q28 -> 664936 | R5: =Q5/P5-1 -> -0.26883347 | S5: =Q5/O5-1 -> 0.041349468 | T5: =T8+T28 -> 719427 | U5: =U8+U28 -> 966418 | V5: =V8+V28 -> 950172 | W5: =V5/U5-1 -> -0.016810531 | X5: =V5/T5-1 -> 0.32073442 | Y5: =Y8+Y28 -> 924619 | Z5: =Z8+Z28 -> 1023418 | AA5: =AA8+AA28 -> 879459 | AB5: =AA5/Z5-1 -> -0.14066491 | AC5: =AA5/Y5-1 -> -0.048841739 | AD5: =AD8+AD28 -> 938664 | AE5: =AE8+AE28 -> 966418 | AF5: =AF8+AF28 -> 994782 | AG5: =AF5/AE5-1 -> 0.029349619 | AH5: =AF5/AD5-1 -> 0.059784971 | AI5: =AI8+AI28 -> 978656 | AJ5: =AJ8+AJ28 -> 953418 | AK5: =AK8+AK28 -> 905373 | AL5: =AK5/AJ5-1 -> -0.050392378 | AM5: =AK5/AI5-1 -> -0.074881266 | AN5: =AN8+AN28 -> 833917 | AO5: =AO8+AO28 -> 966418 | AP5: =AP8+AP28 -> 1019715 | AQ5: =AP5/AO5-1 -> 0.055149014 | AR5: =AP5/AN5-1 -> 0.22280155 | AS5: =AS8+AS28 -> 825476 | AT5: =AT8+AT28 -> 966418 | AU5: =AU8+AU28 -> 885158 | AV5: =AU5/AT5-1 -> -0.084083699 | AW5: =AU5/AS5-1 -> 0.072300103 | AX5: =AX8+AX28 -> 851637 | AY5: =AY8+AY28 -> 966418 | AZ5: =AZ8+AZ28 -> 828054 | BA5: =AZ5/AY5-1 -> -0.143172 | BB5: =AZ5/AX5-1 -> -0.027691376 | BC5: =BC8+BC28 -> 720078 | BD5: =BD8+BD28 -> 966418 | BE5: =BE8+BE28 -> 1060818 | BF5: =BE5/BD5-1 -> 0.0976803 | BG5: =BE5/BC5-1 -> 0.47319874 | BH5: =BH8+BH28 -> 1120930 | BI5: =BI8+BI28 -> 1051918 | BJ5: =BJ8+BJ28 -> 724020 | BK5: =BJ5/BI5-1 -> -0.31171441 | BL5: =BJ5/BH5-1 -> -0.35408991 | BM5: =BM8+BM28 -> 945381 | BN5: =BN8+BN28 -> 1051918 | BO5: =BO8+BO28 -> 0 | BP5: =BO5/BN5-1 -> -1 | BQ5: =BO5/BM5-1 -> -1 | BR5: =BR8+BR28 -> 935177 | BS5: =BS8+BS28 -> 1023418 | BT5: =BT8+BT28 -> 0 | BU5: =BT5/BS5-1 -> -1 | BV5: =BT5/BR5-1 -> -1 | BX5: =L5-J5 -> 360550
D6: 재고 | F6: ='2024년 실적'!G6 -> 753757 | G6: ='2024년 실적'!L6 -> 668998 | H6: =H7+H27 -> 492708 | I6: =H6/G6-1 -> -0.26351349 | J6: =J7+J27 -> 740283 | K6: =K7+K27 -> 525959 | L6: =L7+L27 -> 648940 | M6: =L6/K6-1 -> 0.23382241 | N6: =L6/J6-1 -> -0.1233893 | O6: =O7+O27 -> 639609 | P6: =P7+P27 -> 454709 | Q6: =Q7+Q27 -> 601684 | R6: =Q6/P6-1 -> 0.3232287 | S6: =Q6/O6-1 -> -0.059294037 | T6: =T7+T27 -> 563024 | U6: =U7+U27 -> 476709 | V6: =V7+V27 -> 662331 | W6: =V6/U6-1 -> 0.3893822 | X6: =V6/T6-1 -> 0.17638147 | Y6: =Y7+Y27 -> 476578 | Z6: =Z7+Z27 -> 511709 | AA6: =AA7+AA27 -> 705672 | AB6: =AA6/Z6-1 -> 0.37904942 | AC6: =AA6/Y6-1 -> 0.4807062 | AD6: =AD7+AD27 -> 483429 | AE6: =AE7+AE27 -> 483209 | AF6: =AF7+AF27 -> 721498 | AG6: =AF6/AE6-1 -> 0.49313858 | AH6: =AF6/AD6-1 -> 0.49245908 | AI6: =AI7+AI27 -> 749888 | AJ6: =AJ7+AJ27 -> 476709 | AK6: =AK7+AK27 -> 676501 | AL6: =AK6/AJ6-1 -> 0.41910683 | AM6: =AK6/AI6-1 -> -0.097863948 | AN6: =AN7+AN27 -> 771620 | AO6: =AO7+AO27 -> 483209 | AP6: =AP7+AP27 -> 627682 | AQ6: =AP6/AO6-1 -> 0.29898657 | AR6: =AP6/AN6-1 -> -0.18654001 | AS6: =AS7+AS27 -> 449939 | AT6: =AT7+AT27 -> 483209 | AU6: =AU7+AU27 -> 760061 | AV6: =AU6/AT6-1 -> 0.57294463 | AW6: =AU6/AS6-1 -> 0.68925343 | AX6: =AX7+AX27 -> 614643 | AY6: =AY7+AY27 -> 483209 | AZ6: =AZ7+AZ27 -> 707639 | BA6: =AZ6/AY6-1 -> 0.46445741 | BB6: =AZ6/AX6-1 -> 0.15130084 | BC6: =BC7+BC27 -> 651732 | BD6: =BD7+BD27 -> 483209 | BE6: =BE7+BE27 -> 785543 | BF6: =BE6/BD6-1 -> 0.62567957 | BG6: =BE6/BC6-1 -> 0.20531599 | BH6: =BH7+BH27 -> 740283 | BI6: =BI7+BI27 -> 525959 | BJ6: =BJ7+BJ27 -> 648940 | BK6: =BJ6/BI6-1 -> 0.23382241 | BL6: =BJ6/BH6-1 -> -0.1233893 | BM6: =BM7+BM27 -> 705251 | BN6: =BN7+BN27 -> 525959 | BO6: =BO7+BO27 -> 0 | BP6: =BO6/BN6-1 -> -1 | BQ6: =BO6/BM6-1 -> -1 | BR6: =BR7+BR27 -> 668998 | BS6: =BS7+BS27 -> 511709 | BT6: =BT7+BT27 -> 0 | BU6: =BT6/BS6-1 -> -1 | BV6: =BT6/BR6-1 -> -1 | BX6: =L6-G6 -> -20058
B7: B2C | C7: Auto | D7: 재고 | F7: ='2024년 실적'!G7 -> 343119 | G7: ='2024년 실적'!L7 -> 309009 | H7: =ROUND(H8/24,0) -> 237500 | I7: =H7/G7-1 -> -0.23141397 | J7: =BH7 -> 356671 | K7: =BI7 -> 270750 | L7: =BJ7 -> 332935 | M7: =L7/K7-1 -> 0.22967682 | N7: =L7/J7-1 -> -0.066548724 | O7: ='2024년 실적'!Q7 -> 309841 | P7: =ROUND(P9/2,2) -> 199500 | Q7: =169559+129032 -> 298591 | R7: =Q7/P7-1 -> 0.49669674 | S7: =Q7/O7-1 -> -0.036308946 | T7: ='2024년 실적'!V7 -> 284901 | U7: 221500 | V7: 334118 | W7: =V7/U7-1 -> 0.50843341 | X7: =V7/T7-1 -> 0.17275124 | Y7: ='2024년 실적'!AA7 -> 135478 | Z7: =Z8/2 -> 256500 | AA7: =207878+155999 -> 363877 | AB7: =AA7/Z7-1 -> 0.41862378 | AC7: =AA7/Y7-1 -> 1.6858752 | AD7: ='2024년 실적'!AF7 -> 152494 | AE7: =AE8/2 -> 228000 | AF7: 349398 | AG7: =AF7/AE7-1 -> 0.53244737 | AH7: =AF7/AD7-1 -> 1.2912246 | AI7: ='2024년 실적'!AK7 -> 343961 | AJ7: =AJ8/2 -> 221500 | AK7: 332385 | AL7: =AK7/AJ7-1 -> 0.50060948 | AM7: =AK7/AI7-1 -> -0.033654978 | AN7: ='2024년 실적'!AP7 -> 352267 | AO7: =AO8/2 -> 228000 | AP7: 338603 | AQ7: =AP7/AO7-1 -> 0.48510088 | AR7: =AP7/AN7-1 -> -0.03878876 | AS7: ='2024년 실적'!AU7 -> 158232 | AT7: =AT8/2 -> 228000 | AU7: 387894 | AV7: =AU7/AT7-1 -> 0.70128947 | AW7: =AU7/AS7-1 -> 1.4514258 | AX7: ='2024년 실적'!AZ7 -> 337471 | AY7: =AY9/2 -> 228000 | AZ7: 370048 | BA7: =AZ7/AY7-1 -> 0.62301754 | BB7: =AZ7/AX7-1 -> 0.096532739 | BC7: ='2024년 실적'!BE7 -> 336907 | BD7: =BD9/2 -> 228000 | BE7: 404138 | BF7: =BE7/BD7-1 -> 0.77253509 | BG7: =BE7/BC7-1 -> 0.19955359 | BH7: ='2024년 실적'!BJ7 -> 356671 | BI7: =BI8/2 -> 270750 | BJ7: 332935 | BK7: =BJ7/BI7-1 -> 0.22967682 | BL7: =BJ7/BH7-1 -> -0.066548724 | BM7: ='2024년 실적'!BO7 -> 330282 | BN7: =BN8/2 -> 270750 | BP7: =BO7/BN7-1 -> -1 | BQ7: =BO7/BM7-1 -> -1 | BR7: ='2024년 실적'!BT7 -> 309009 | BS7: =BS9/2 -> 256500 | BU7: =BT7/BS7-1 -> -1 | BV7: =BT7/BR7-1 -> -1
D8: sell-in | F8: ='2024년 실적'!G8 -> 4950552 | G8: ='2024년 실적'!L8 -> 5050656 | H8: =H9 -> 5700000 | I8: =H8/G8-1 -> 0.12856627 | J8: =O8+T8+Y8+AD8+AI8+AN8+AS8+AX8+BC8+BH8 -> 4188376 | K8: =P8+U8+Z8+AE8+AJ8+AO8+AT8+AY8+BD8+BI8 -> 4632500 | L8: =Q8+V8+AA8+AF8+AK8+AP8+AU8+AZ8+BE8+BJ8 -> 4469546 | M8: =L8/K8-1 -> -0.035176255 | N8: =L8/J8-1 -> 0.067131031 | O8: ='2024년 실적'!Q8 -> 297287 | P8: =P9 -> 399000 | Q8: 337645 | R8: =Q8/P8-1 -> -0.15377193 | S8: =Q8/O8-1 -> 0.13575434 | T8: ='2024년 실적'!V8 -> 322387 | U8: =U9 -> 456000 | V8: 465225 | W8: =V8/U8-1 -> 0.020230263 | X8: =V8/T8-1 -> 0.44306377 | Y8: ='2024년 실적'!AA8 -> 456333 | Z8: =Z9 -> 513000 | AA8: =276187+166804 -> 442991 | AB8: =AA8/Z8-1 -> -0.13646979 | AC8: =AA8/Y8-1 -> -0.029237421 | AD8: ='2024년 실적'!AF8 -> 491302 | AE8: =AE9 -> 456000 | AF8: 446722 | AG8: =AF8/AE8-1 -> -0.020346491 | AH8: =AF8/AD8-1 -> -0.090738487 | AI8: ='2024년 실적'!AK8 -> 427552 | AJ8: 443000 | AK8: 468535 | AL8: =AK8/AJ8-1 -> 0.057641084 | AM8: =AK8/AI8-1 -> 0.095855007 | AN8: ='2024년 실적'!AP8 -> 417231 | AO8: =AO9 -> 456000 | AP8: 546396 | AQ8: =AP8/AO8-1 -> 0.19823684 | AR8: =AP8/AN8-1 -> 0.30957671 | AS8: ='2024년 실적'!AU8 -> 425307 | AT8: =AT9 -> 456000 | AU8: 412989 | AV8: =AU8/AT8-1 -> -0.094322368 | AW8: =AU8/AS8-1 -> -0.028962608 | AX8: ='2024년 실적'!AZ8 -> 410717 | AY8: =AY9 -> 456000 | AZ8: 418512 | BA8: =AZ8/AY8-1 -> -0.082210526 | BB8: =AZ8/AX8-1 -> 0.018979005 | BC8: ='2024년 실적'!BE8 -> 377030 | BD8: =BD9 -> 456000 | BE8: 519753 | BF8: =BE8/BD8-1 -> 0.13980921 | BG8: =BE8/BC8-1 -> 0.37854547 | BH8: ='2024년 실적'!BJ8 -> 563230 | BI8: =BI9 -> 541500 | BJ8: 410778 | BK8: =BJ8/BI8-1 -> -0.2414072 | BL8: =BJ8/BH8-1 -> -0.2706745 | BM8: ='2024년 실적'!BO8 -> 444511 | BN8: =BN9 -> 541500 | BP8: =BO8/BN8-1 -> -1 | BQ8: =BO8/BM8-1 -> -1 | BR8: ='2024년 실적'!BT8 -> 417769 | BS8: =BS9 -> 513000 | BU8: =BT8/BS8-1 -> -1 | BV8: =BT8/BR8-1 -> -1 | BX8: =L8-J8 -> 281170 | BZ8: 목표대비
D9: AUTO 합계 | F9: ='2024년 실적'!G9 -> 4859570 | G9: ='2024년 실적'!L9 -> 5083802 | H9: =H10+H26 -> 5700000 | I9: =H9/G9-1 -> 0.1212081 | J9: =J10+J26 -> 4089810 | K9: =K10+K26 -> 4550500 | L9: =L10+L26 -> 4346066 | M9: =L9/K9-1 -> -0.044925613 | N9: =L9/J9-1 -> 0.062657189 | O9: =O10+O26 -> 328580 | P9: =P10+P26 -> 399000 | Q9: =Q10+Q26 -> 346892 | R9: =Q9/P9-1 -> -0.13059649 | S9: =Q9/O9-1 -> 0.05573072 | T9: =T10+T26 -> 346389 | U9: =U10+U26 -> 456000 | V9: =V10+V26 -> 428944 | W9: =V9/U9-1 -> -0.059333333 | X9: =V9/T9-1 -> 0.23833032 | Y9: =Y10+Y26 -> 464840 | Z9: =Z10+Z26 -> 513000 | AA9: =AA10+AA26 -> 406769 | AB9: =AA9/Z9-1 -> -0.20707797 | AC9: =AA9/Y9-1 -> -0.12492686 | AD9: =AD10+AD26 -> 455471 | AE9: =AE10+AE26 -> 456000 | AF9: =AF10+AF26 -> 471885 | AG9: =AF9/AE9-1 -> 0.034835526 | AH9: =AF9/AD9-1 -> 0.036037421 | AI9: =AI10+AI26 -> 396406 | AJ9: =AJ10+AJ26 -> 456000 | AK9: =AK10+AK26 -> 485185 | AL9: =AK9/AJ9-1 -> 0.064002193 | AM9: =AK9/AI9-1 -> 0.22395978 | AN9: =AN10+AN26 -> 408513 | AO9: =AO10+AO26 -> 456000 | AP9: =AP10+AP26 -> 475620 | AQ9: =AP9/AO9-1 -> 0.043026316 | AR9: =AP9/AN9-1 -> 0.16427139 | AS9: =AS10+AS26 -> 432986 | AT9: =AT10+AT26 -> 456000 | AU9: =AU10+AU26 -> 426398 | AV9: =AU9/AT9-1 -> -0.064916667 | AW9: =AU9/AS9-1 -> -0.015215273 | AX9: =AX10+AX26 -> 415086 | AY9: =AY10+AY26 -> 456000 | AZ9: =AZ10+AZ26 -> 435464 | BA9: =AZ9/AY9-1 -> -0.045035088 | BB9: =AZ9/AX9-1 -> 0.049093441 | BC9: =BC10+BC26 -> 384010 | BD9: =BD10+BD26 -> 456000 | BE9: =BE10+BE26 -> 484749 | BF9: =BE9/BD9-1 -> 0.063046053 | BG9: =BE9/BC9-1 -> 0.26233431 | BH9: =BH10+BH26 -> 543703 | BI9: =BI10+BI26 -> 541500 | BJ9: =BJ10+BJ26 -> 481588 | BK9: =BJ9/BI9-1 -> -0.11064081 | BL9: =BJ9/BH9-1 -> -0.11424436 | BM9: =BM10+BM26 -> 469271 | BN9: =BN10+BN26 -> 541500 | BO9: =BO10+BO26 -> 0 | BP9: =BO9/BN9-1 -> -1 | BQ9: =BO9/BM9-1 -> -1 | BR9: =BR10+BR26 -> 438547 | BS9: =BS10+BS26 -> 513000 | BT9: =BT10+BT26 -> 0 | BU9: =BT9/BS9-1 -> -1 | BV9: =BT9/BR9-1 -> -1 | BW9: =L9/$BW$1*12 -> 5215279.2 | BX9: =L9-J9 -> 256256 | BZ9: =L9/H9 -> 0.76246772
D10: B2C 소계 | F10: ='2024년 실적'!G10 -> 4024174 | G10: ='2024년 실적'!L10 -> 4179787 | H10: =H15+H20+H23+H24+H25 -> 4700000 | I10: =H10/G10-1 -> 0.12445921 | J10: =J15+J20+J23+J24+J25 -> 3430314 | K10: =K15+K20+K23+K24+K25 -> 3830500 | L10: =L15+L20+L23+L24+L25 -> 3608431 | M10: =L10/K10-1 -> -0.057973894 | N10: =L10/J10-1 -> 0.051924401 | O10: =O15+O20+O23+O24+O25 -> 274687 | P10: =P15+P20+P23+P24+P25 -> 329000 | Q10: =Q15+Q20+Q23+Q24+Q25 -> 291318 | R10: =Q10/P10-1 -> -0.11453495 | S10: =Q10/O10-1 -> 0.060545275 | T10: =T15+T20+T23+T24+T25 -> 268242 | U10: =U15+U20+U23+U24+U25 -> 376000 | V10: =V15+V20+V23+V24+V25 -> 341292 | W10: =V10/U10-1 -> -0.092308511 | X10: =V10/T10-1 -> 0.27232872 | Y10: =Y15+Y20+Y23+Y24+Y25 -> 393184 | Z10: =Z15+Z20+Z23+Z24+Z25 -> 423000 | AA10: =AA15+AA20+AA23+AA24+AA25 -> 347446 | AB10: =AA10/Z10-1 -> -0.17861466 | AC10: =AA10/Y10-1 -> -0.11632722 | AD10: =AD15+AD20+AD23+AD24+AD25 -> 372658 | AE10: =AE15+AE20+AE23+AE24+AE25 -> 376000 | AF10: =AF15+AF20+AF23+AF24+AF25 -> 396605 | AG10: =AF10/AE10-1 -> 0.054800532 | AH10: =AF10/AD10-1 -> 0.064259992 | AI10: =AI15+AI20+AI23+AI24+AI25 -> 317789 | AJ10: =AJ15+AJ20+AJ23+AJ24+AJ25 -> 376000 | AK10: =AK15+AK20+AK23+AK24+AK25 -> 393541 | AL10: =AK10/AJ10-1 -> 0.046651596 | AM10: =AK10/AI10-1 -> 0.238372 | AN10: =AN15+AN20+AN23+AN24+AN25 -> 341134 | AO10: =AO15+AO20+AO23+AO24+AO25 -> 376000 | AP10: =AP15+AP20+AP23+AP24+AP25 -> 383622 | AQ10: =AP10/AO10-1 -> 0.020271277 | AR10: =AP10/AN10-1 -> 0.1245493 | AS10: =AS15+AS20+AS23+AS24+AS25 -> 349793 | AT10: =AT15+AT20+AT23+AT24+AT25 -> 376000 | AU10: =AU15+AU20+AU23+AU24+AU25 -> 345784 | AV10: =AU10/AT10-1 -> -0.080361702 | AW10: =AU10/AS10-1 -> -0.011461064 | AX10: =AX15+AX20+AX23+AX24+AX25 -> 333757 | AY10: =AY15+AY20+AY23+AY24+AY25 -> 376000 | AZ10: =AZ15+AZ20+AZ23+AZ24+AZ25 -> 335646 | BA10: =AZ10/AY10-1 -> -0.10732447 | BB10: =AZ10/AX10-1 -> 0.0056598064 | BC10: =BC15+BC20+BC23+BC24+BC25 -> 321541 | BD10: =BD15+BD20+BD23+BD24+BD25 -> 376000 | BE10: =BE15+BE20+BE23+BE24+BE25 -> 389017 | BF10: =BE10/BD10-1 -> 0.034619681 | BG10: =BE10/BC10-1 -> 0.20985193 | BH10: =BH15+BH20+BH23+BH24+BH25 -> 457529 | BI10: =BI15+BI20+BI23+BI24+BI25 -> 446500 | BJ10: =BJ15+BJ20+BJ23+BJ24+BJ25 -> 384160 | BK10: =BJ10/BI10-1 -> -0.13961926 | BL10: =BJ10/BH10-1 -> -0.16035923 | BM10: =BM15+BM20+BM23+BM24+BM25 -> 381403 | BN10: =BN15+BN20+BN23+BN24+BN25 -> 446500 | BO10: =BO15+BO20+BO23+BO24+BO25 -> 0 | BP10: =BO10/BN10-1 -> -1 | BQ10: =BO10/BM10-1 -> -1 | BR10: =BR15+BR20+BR23+BR24+BR25 -> 368070 | BS10: =BS15+BS20+BS23+BS24+BS25 -> 423000 | BT10: =BT15+BT20+BT23+BT24+BT25 -> 0 | BU10: =BT10/BS10-1 -> -1 | BV10: =BT10/BR10-1 -> -1 | BW10: =L10/$BW$1*12 -> 4330117.2 | BX10: =L10-J10 -> 178117 | BZ10: =L10/H10 -> 0.76775128
D11: B2C 팀 소계 | F11: ='2024년 실적'!G11 -> 2526417 | G11: ='2024년 실적'!L11 -> 2758457 | H11: =H12+H13+H16+H17+H18+H21+H24 -> 3150000 | I11: =H11/G11-1 -> 0.14194276 | J11: =J12+J13+J16+J17+J18+J21+J24 -> 2284225 | K11: =K12+K13+K16+K17+K18+K21+K24 -> 2567250 | L11: =L12+L13+L16+L17+L18+L21+L24 -> 2401694 | M11: =L11/K11-1 -> -0.064487681 | N11: =L11/J11-1 -> 0.051426195 | O11: =O12+O13+O16+O17+O18+O21+O24 -> 196934 | P11: =P12+P13+P16+P17+P18+P21+P24 -> 220500 | Q11: =Q12+Q13+Q16+Q17+Q18+Q21+Q24 -> 183957 | R11: =Q11/P11-1 -> -0.16572789 | S11: =Q11/O11-1 -> -0.065895173 | T11: =T12+T13+T16+T17+T18+T21+T24 -> 175693 | U11: =U12+U13+U16+U17+U18+U21+U24 -> 252000 | V11: =V12+V13+V16+V17+V18+V21+V24 -> 214388 | W11: =V11/U11-1 -> -0.14925397 | X11: =V11/T11-1 -> 0.22024213 | Y11: =Y12+Y13+Y16+Y17+Y18+Y21+Y24 -> 279353 | Z11: =Z12+Z13+Z16+Z17+Z18+Z21+Z24 -> 283500 | AA11: =AA12+AA13+AA16+AA17+AA18+AA21+AA24 -> 235602 | AB11: =AA11/Z11-1 -> -0.16895238 | AC11: =AA11/Y11-1 -> -0.15661547 | AD11: =AD12+AD13+AD16+AD17+AD18+AD21+AD24 -> 238174 | AE11: =AE12+AE13+AE16+AE17+AE18+AE21+AE24 -> 252000 | AF11: =AF12+AF13+AF16+AF17+AF18+AF21+AF24 -> 265555 | AG11: =AF11/AE11-1 -> 0.053789683 | AH11: =AF11/AD11-1 -> 0.11496217 | AI11: =AI12+AI13+AI16+AI17+AI18+AI21+AI24 -> 202277 | AJ11: =AJ12+AJ13+AJ16+AJ17+AJ18+AJ21+AJ24 -> 252000 | AK11: =AK12+AK13+AK16+AK17+AK18+AK21+AK24 -> 283486 | AL11: =AK11/AJ11-1 -> 0.12494444 | AM11: =AK11/AI11-1 -> 0.40147422 | AN11: =AN12+AN13+AN16+AN17+AN18+AN21+AN24 -> 220110 | AO11: =AO12+AO13+AO16+AO17+AO18+AO21+AO24 -> 252000 | AP11: =AP12+AP13+AP16+AP17+AP18+AP21+AP24 -> 248318 | AQ11: =AP11/AO11-1 -> -0.014611111 | AR11: =AP11/AN11-1 -> 0.1281541 | AS11: =AS12+AS13+AS16+AS17+AS18+AS21+AS24 -> 213751 | AT11: =AT12+AT13+AT16+AT17+AT18+AT21+AT24 -> 252000 | AU11: =AU12+AU13+AU16+AU17+AU18+AU21+AU24 -> 227858 | AV11: =AU11/AT11-1 -> -0.095801587 | AW11: =AU11/AS11-1 -> 0.065997352 | AX11: =AX12+AX13+AX16+AX17+AX18+AX21+AX24 -> 221691 | AY11: =AY12+AY13+AY16+AY17+AY18+AY21+AY24 -> 252000 | AZ11: =AZ12+AZ13+AZ16+AZ17+AZ18+AZ21+AZ24 -> 213759 | BA11: =AZ11/AY11-1 -> -0.15175 | BB11: =AZ11/AX11-1 -> -0.035779531 | BC11: =BC12+BC13+BC16+BC17+BC18+BC21+BC24 -> 212618 | BD11: =BD12+BD13+BD16+BD17+BD18+BD21+BD24 -> 252000 | BE11: =BE12+BE13+BE16+BE17+BE18+BE21+BE24 -> 259684 | BF11: =BE11/BD11-1 -> 0.030492063 | BG11: =BE11/BC11-1 -> 0.22136414 | BH11: =BH12+BH13+BH16+BH17+BH18+BH21+BH24 -> 323624 | BI11: =BI12+BI13+BI16+BI17+BI18+BI21+BI24 -> 299250 | BJ11: =BJ12+BJ13+BJ16+BJ17+BJ18+BJ21+BJ24 -> 269087 | BK11: =BJ11/BI11-1 -> -0.10079532 | BL11: =BJ11/BH11-1 -> -0.16851964 | BM11: =BM12+BM13+BM16+BM17+BM18+BM21+BM24 -> 238215 | BN11: =BN12+BN13+BN16+BN17+BN18+BN21+BN24 -> 299250 | BO11: =BO12+BO13+BO16+BO17+BO18+BO21+BO24 -> 0 | BP11: =BO11/BN11-1 -> -1 | BQ11: =BO11/BM11-1 -> -1 | BR11: =BR12+BR13+BR16+BR17+BR18+BR21+BR24 -> 236017 | BS11: =BS12+BS13+BS16+BS17+BS18+BS21+BS24 -> 283500 | BT11: =BT12+BT13+BT16+BT17+BT18+BT21+BT24 -> 0 | BU11: =BT11/BS11-1 -> -1 | BV11: =BT11/BR11-1 -> -1 | BW11: =L11/$BW$1*12 -> 2882032.8 | BX11: =L11-J11 -> 117469 | BZ11: =L11/H11 -> 0.76244254
D12: 동부지사 | E12: 맥심팀 | F12: ='2024년 실적'!G12 -> 321951 | G12: ='2024년 실적'!L12 -> 326920 | H12: 380000 | I12: =H12/G12-1 -> 0.16236388 | J12: =O12+T12+Y12+AD12+AI12+AN12+AS12+AX12+BC12+BH12 -> 266639 | K12: =P12+U12+Z12+AE12+AJ12+AO12+AT12+AY12+BD12+BI12 -> 309700 | L12: =Q12+V12+AA12+AF12+AK12+AP12+AU12+AZ12+BE12+BJ12 -> 261116 | M12: =L12/K12-1 -> -0.15687439 | N12: =L12/J12-1 -> -0.020713399 | O12: ='2024년 실적'!Q12 -> 25459 | P12: 26600 | Q12: 23074 | R12: =Q12/P12-1 -> -0.13255639 | S12: =Q12/O12-1 -> -0.093680035 | T12: ='2024년 실적'!V12 -> 23473 | U12: 30400 | V12: 27234 | W12: =V12/U12-1 -> -0.10414474 | X12: =V12/T12-1 -> 0.16022664 | Y12: ='2024년 실적'!AA12 -> 29112 | Z12: 34200 | AA12: 24427 | AB12: =AA12/Z12-1 -> -0.28576023 | AC12: =AA12/Y12-1 -> -0.1609302 | AD12: ='2024년 실적'!AF12 -> 26275 | AE12: 30400 | AF12: 28476 | AG12: =AF12/AE12-1 -> -0.063289474 | AH12: =AF12/AD12-1 -> 0.08376784 | AI12: ='2024년 실적'!AK12 -> 25884 | AJ12: 30400 | AK12: 24269 | AL12: =AK12/AJ12-1 -> -0.20167763 | AM12: =AK12/AI12-1 -> -0.062393757 | AN12: ='2024년 실적'!AP12 -> 25094 | AO12: 30400 | AP12: 28653 | AQ12: =AP12/AO12-1 -> -0.057467105 | AR12: =AP12/AN12-1 -> 0.14182673 | AS12: ='2024년 실적'!AU12 -> 27682 | AT12: 30400 | AU12: 26218 | AV12: =AU12/AT12-1 -> -0.13756579 | AW12: =AU12/AS12-1 -> -0.052886352 | AX12: ='2024년 실적'!AZ12 -> 30232 | AY12: 30400 | AZ12: 22603 | BA12: =AZ12/AY12-1 -> -0.25648026 | BB12: =AZ12/AX12-1 -> -0.2523485 | BC12: ='2024년 실적'!BE12 -> 25176 | BD12: 30400 | BE12: 30270 | BF12: =BE12/BD12-1 -> -0.0042763158 | BG12: =BE12/BC12-1 -> 0.20233556 | BH12: ='2024년 실적'!BJ12 -> 28252 | BI12: 36100 | BJ12: 25892 | BK12: =BJ12/BI12-1 -> -0.28277008 | BL12: =BJ12/BH12-1 -> -0.083533909 | BM12: ='2024년 실적'!BO12 -> 31261 | BN12: 36100 | BP12: =BO12/BN12-1 -> -1 | BQ12: =BO12/BM12-1 -> -1 | BR12: ='2024년 실적'!BT12 -> 29020 | BS12: 34200 | BU12: =BT12/BS12-1 -> -1 | BV12: =BT12/BR12-1 -> -1 | BW12: =L12/$BW$1*12 -> 313339.2 | BX12: =L12-J12 -> -5523 | BZ12: =L12/H12 -> 0.68714737
E13: 솔개팀 | F13: ='2024년 실적'!G13 -> 419768 | G13: ='2024년 실적'!L13 -> 408254 | H13: 500000 | I13: =H13/G13-1 -> 0.22472774 | J13: =O13+T13+Y13+AD13+AI13+AN13+AS13+AX13+BC13+BH13 -> 332891 | K13: =P13+U13+Z13+AE13+AJ13+AO13+AT13+AY13+BD13+BI13 -> 407500 | L13: =Q13+V13+AA13+AF13+AK13+AP13+AU13+AZ13+BE13+BJ13 -> 358318 | M13: =L13/K13-1 -> -0.12069202 | N13: =L13/J13-1 -> 0.076382359 | O13: ='2024년 실적'!Q13 -> 23114 | P13: 35000 | Q13: 27115 | R13: =Q13/P13-1 -> -0.22528571 | S13: =Q13/O13-1 -> 0.17309855 | T13: ='2024년 실적'!V13 -> 23040 | U13: 40000 | V13: 31498 | W13: =V13/U13-1 -> -0.21255 | X13: =V13/T13-1 -> 0.36710069 | Y13: ='2024년 실적'!AA13 -> 32253 | Z13: 45000 | AA13: 35556 | AB13: =AA13/Z13-1 -> -0.20986667 | AC13: =AA13/Y13-1 -> 0.10240908 | AD13: ='2024년 실적'!AF13 -> 38343 | AE13: 40000 | AF13: 36548 | AG13: =AF13/AE13-1 -> -0.0863 | AH13: =AF13/AD13-1 -> -0.046814282 | AI13: ='2024년 실적'!AK13 -> 27107 | AJ13: 40000 | AK13: 43328 | AL13: =AK13/AJ13-1 -> 0.0832 | AM13: =AK13/AI13-1 -> 0.59840632 | AN13: ='2024년 실적'!AP13 -> 31256 | AO13: 40000 | AP13: 33610 | AQ13: =AP13/AO13-1 -> -0.15975 | AR13: =AP13/AN13-1 -> 0.07531354 | AS13: ='2024년 실적'!AU13 -> 31416 | AT13: 40000 | AU13: 38936 | AV13: =AU13/AT13-1 -> -0.0266 | AW13: =AU13/AS13-1 -> 0.23936847 | AX13: ='2024년 실적'!AZ13 -> 30542 | AY13: 40000 | AZ13: 33474 | BA13: =AZ13/AY13-1 -> -0.16315 | BB13: =AZ13/AX13-1 -> 0.095998952 | BC13: ='2024년 실적'!BE13 -> 32278 | BD13: 40000 | BE13: 37534 | BF13: =BE13/BD13-1 -> -0.06165 | BG13: =BE13/BC13-1 -> 0.16283537 | BH13: ='2024년 실적'!BJ13 -> 63542 | BI13: 47500 | BJ13: 40719 | BK13: =BJ13/BI13-1 -> -0.14275789 | BL13: =BJ13/BH13-1 -> -0.35917976 | BM13: ='2024년 실적'!BO13 -> 36878 | BN13: 47500 | BP13: =BO13/BN13-1 -> -1 | BQ13: =BO13/BM13-1 -> -1 | BR13: ='2024년 실적'!BT13 -> 38485 | BS13: 45000 | BU13: =BT13/BS13-1 -> -1 | BV13: =BT13/BR13-1 -> -1 | BW13: =L13/$BW$1*12 -> 429981.6 | BX13: =L13-J13 -> 25427 | BZ13: =L13/H13 -> 0.716636
E14: 사무실 | F14: ='2024년 실적'!G14 -> 207830 | G14: ='2024년 실적'!L14 -> 182489 | H14: 190000 | I14: =H14/G14-1 -> 0.041158645 | J14: =O14+T14+Y14+AD14+AI14+AN14+AS14+AX14+BC14+BH14 -> 139593 | K14: =P14+U14+Z14+AE14+AJ14+AO14+AT14+AY14+BD14+BI14 -> 154850 | L14: =Q14+V14+AA14+AF14+AK14+AP14+AU14+AZ14+BE14+BJ14 -> 167446 | M14: =L14/K14-1 -> 0.081343235 | N14: =L14/J14-1 -> 0.19953006 | O14: ='2024년 실적'!Q14 -> 13981 | P14: 13300 | Q14: 14738 | R14: =Q14/P14-1 -> 0.1081203 | S14: =Q14/O14-1 -> 0.054144911 | T14: ='2024년 실적'!V14 -> 8002 | U14: 15200 | V14: 15112 | W14: =V14/U14-1 -> -0.0057894737 | X14: =V14/T14-1 -> 0.88852787 | Y14: ='2024년 실적'!AA14 -> 10718 | Z14: 17100 | AA14: 15240 | AB14: =AA14/Z14-1 -> -0.10877193 | AC14: =AA14/Y14-1 -> 0.42190707 | AD14: ='2024년 실적'!AF14 -> 12080 | AE14: 15200 | AF14: 24564 | AG14: =AF14/AE14-1 -> 0.61605263 | AH14: =AF14/AD14-1 -> 1.0334437 | AI14: ='2024년 실적'!AK14 -> 15112 | AJ14: 15200 | AK14: 13318 | AL14: =AK14/AJ14-1 -> -0.12381579 | AM14: =AK14/AI14-1 -> -0.11871361 | AN14: ='2024년 실적'!AP14 -> 14825 | AO14: 15200 | AP14: 16034 | AQ14: =AP14/AO14-1 -> 0.054868421 | AR14: =AP14/AN14-1 -> 0.081551433 | AS14: ='2024년 실적'!AU14 -> 11788 | AT14: 15200 | AU14: 17061 | AV14: =AU14/AT14-1 -> 0.12243421 | AW14: =AU14/AS14-1 -> 0.44731931 | AX14: ='2024년 실적'!AZ14 -> 21539 | AY14: 15200 | AZ14: 18028 | BA14: =AZ14/AY14-1 -> 0.18605263 | BB14: =AZ14/AX14-1 -> -0.16300664 | BC14: ='2024년 실적'!BE14 -> 18332 | BD14: 15200 | BE14: 13587 | BF14: =BE14/BD14-1 -> -0.10611842 | BG14: =BE14/BC14-1 -> -0.25883701 | BH14: ='2024년 실적'!BJ14 -> 13216 | BI14: 18050 | BJ14: 19764 | BK14: =BJ14/BI14-1 -> 0.094958449 | BL14: =BJ14/BH14-1 -> 0.49546005 | BM14: ='2024년 실적'!BO14 -> 21416 | BN14: 18050 | BP14: =BO14/BN14-1 -> -1 | BQ14: =BO14/BM14-1 -> -1 | BR14: ='2024년 실적'!BT14 -> 21480 | BS14: 17100 | BU14: =BT14/BS14-1 -> -1 | BV14: =BT14/BR14-1 -> -1 | BW14: =L14/$BW$1*12 -> 200935.2 | BX14: =L14-J14 -> 27853 | BZ14: =L14/H14 -> 0.88129474
E15: 소계 | F15: ='2024년 실적'!G15 -> 949549 | G15: ='2024년 실적'!L15 -> 917663 | H15: =SUM(H12:H14) -> 1070000 | I15: =H15/G15-1 -> 0.16600539 | J15: =SUM(J12:J14) -> 739123 | K15: =SUM(K12:K14) -> 872050 | L15: =SUM(L12:L14) -> 786880 | M15: =L15/K15-1 -> -0.097666418 | N15: =L15/J15-1 -> 0.064613062 | O15: =SUM(O12:O14) -> 62554 | P15: =SUM(P12:P14) -> 74900 | Q15: =SUM(Q12:Q14) -> 64927 | R15: =Q15/P15-1 -> -0.13315087 | S15: =Q15/O15-1 -> 0.037935224 | T15: =SUM(T12:T14) -> 54515 | U15: =SUM(U12:U14) -> 85600 | V15: =SUM(V12:V14) -> 73844 | W15: =V15/U15-1 -> -0.13733645 | X15: =V15/T15-1 -> 0.35456296 | Y15: =SUM(Y12:Y14) -> 72083 | Z15: =SUM(Z12:Z14) -> 96300 | AA15: =SUM(AA12:AA14) -> 75223 | AB15: =AA15/Z15-1 -> -0.21886812 | AC15: =AA15/Y15-1 -> 0.043560895 | AD15: =SUM(AD12:AD14) -> 76698 | AE15: =SUM(AE12:AE14) -> 85600 | AF15: =SUM(AF12:AF14) -> 89588 | AG15: =AF15/AE15-1 -> 0.046588785 | AH15: =AF15/AD15-1 -> 0.16806175 | AI15: =SUM(AI12:AI14) -> 68103 | AJ15: =SUM(AJ12:AJ14) -> 85600 | AK15: =SUM(AK12:AK14) -> 80915 | AL15: =AK15/AJ15-1 -> -0.054731308 | AM15: =AK15/AI15-1 -> 0.18812681 | AN15: =SUM(AN12:AN14) -> 71175 | AO15: =SUM(AO12:AO14) -> 85600 | AP15: =SUM(AP12:AP14) -> 78297 | AQ15: =AP15/AO15-1 -> -0.085315421 | AR15: =AP15/AN15-1 -> 0.10006322 | AS15: =SUM(AS12:AS14) -> 70886 | AT15: =SUM(AT12:AT14) -> 85600 | AU15: =SUM(AU12:AU14) -> 82215 | AV15: =AU15/AT15-1 -> -0.039544393 | AW15: =AU15/AS15-1 -> 0.15981999 | AX15: =SUM(AX12:AX14) -> 82313 | AY15: =SUM(AY12:AY14) -> 85600 | AZ15: =SUM(AZ12:AZ14) -> 74105 | BA15: =AZ15/AY15-1 -> -0.13428738 | BB15: =AZ15/AX15-1 -> -0.099716934 | BC15: =SUM(BC12:BC14) -> 75786 | BD15: =SUM(BD12:BD14) -> 85600 | BE15: =SUM(BE12:BE14) -> 81391 | BF15: =BE15/BD15-1 -> -0.049170561 | BG15: =BE15/BC15-1 -> 0.073958251 | BH15: =SUM(BH12:BH14) -> 105010 | BI15: =SUM(BI12:BI14) -> 101650 | BJ15: =SUM(BJ12:BJ14) -> 86375 | BK15: =BJ15/BI15-1 -> -0.15027054 | BL15: =BJ15/BH15-1 -> -0.17745929 | BM15: =SUM(BM12:BM14) -> 89555 | BN15: =SUM(BN12:BN14) -> 101650 | BO15: =SUM(BO12:BO14) -> 0 | BP15: =BO15/BN15-1 -> -1 | BQ15: =BO15/BM15-1 -> -1 | BR15: =SUM(BR12:BR14) -> 88985 | BS15: =SUM(BS12:BS14) -> 96300 | BT15: =SUM(BT12:BT14) -> 0 | BU15: =BT15/BS15-1 -> -1 | BV15: =BT15/BR15-1 -> -1 | BW15: =L15/$BW$1*12 -> 944256 | BX15: =L15-J15 -> 47757 | BZ15: =L15/H15 -> 0.73540187
D16: 서부지사 | E16: 아리안팀 | F16: ='2024년 실적'!G16 -> 265892 | G16: ='2024년 실적'!L16 -> 345199 | H16: 390000 | I16: =H16/G16-1 -> 0.12978311 | J16: =O16+T16+Y16+AD16+AI16+AN16+AS16+AX16+BC16+BH16 -> 282919 | K16: =P16+U16+Z16+AE16+AJ16+AO16+AT16+AY16+BD16+BI16 -> 317850 | L16: =Q16+V16+AA16+AF16+AK16+AP16+AU16+AZ16+BE16+BJ16 -> 295693 | M16: =L16/K16-1 -> -0.069708982 | N16: =L16/J16-1 -> 0.045150732 | O16: ='2024년 실적'!Q16 -> 24956 | P16: 27300 | Q16: 27472 | R16: =Q16/P16-1 -> 0.0063003663 | S16: =Q16/O16-1 -> 0.10081744 | T16: ='2024년 실적'!V16 -> 22654 | U16: 31200 | V16: 28046 | W16: =V16/U16-1 -> -0.10108974 | X16: =V16/T16-1 -> 0.23801536 | Y16: ='2024년 실적'!AA16 -> 28088 | Z16: 35100 | AA16: 28563 | AB16: =AA16/Z16-1 -> -0.18623932 | AC16: =AA16/Y16-1 -> 0.016911136 | AD16: ='2024년 실적'!AF16 -> 32132 | AE16: 31200 | AF16: 31610 | AG16: =AF16/AE16-1 -> 0.013141026 | AH16: =AF16/AD16-1 -> -0.016245487 | AI16: ='2024년 실적'!AK16 -> 27494 | AJ16: 31200 | AK16: 30918 | AL16: =AK16/AJ16-1 -> -0.0090384615 | AM16: =AK16/AI16-1 -> 0.12453626 | AN16: ='2024년 실적'!AP16 -> 28060 | AO16: 31200 | AP16: 27004 | AQ16: =AP16/AO16-1 -> -0.13448718 | AR16: =AP16/AN16-1 -> -0.037633642 | AS16: ='2024년 실적'!AU16 -> 30993 | AT16: 31200 | AU16: 32372 | AV16: =AU16/AT16-1 -> 0.037564103 | AW16: =AU16/AS16-1 -> 0.044493918 | AX16: ='2024년 실적'!AZ16 -> 30145 | AY16: 31200 | AZ16: 28788 | BA16: =AZ16/AY16-1 -> -0.077307692 | BB16: =AZ16/AX16-1 -> -0.045015757 | BC16: ='2024년 실적'!BE16 -> 25653 | BD16: 31200 | BE16: 30937 | BF16: =BE16/BD16-1 -> -0.0084294872 | BG16: =BE16/BC16-1 -> 0.20597981 | BH16: ='2024년 실적'!BJ16 -> 32744 | BI16: 37050 | BJ16: 29983 | BK16: =BJ16/BI16-1 -> -0.19074224 | BL16: =BJ16/BH16-1 -> -0.084320792 | BM16: ='2024년 실적'!BO16 -> 30570 | BN16: 37050 | BP16: =BO16/BN16-1 -> -1 | BQ16: =BO16/BM16-1 -> -1 | BR16: ='2024년 실적'!BT16 -> 31710 | BS16: 35100 | BU16: =BT16/BS16-1 -> -1 | BV16: =BT16/BR16-1 -> -1 | BW16: =L16/$BW$1*12 -> 354831.6 | BX16: =L16-J16 -> 12774 | BZ16: =L16/H16 -> 0.75818718
E17: 미추홀팀 | F17: ='2024년 실적'!G17 -> 554782 | G17: ='2024년 실적'!L17 -> 681035 | H17: 750000 | I17: =H17/G17-1 -> 0.10126499 | J17: =O17+T17+Y17+AD17+AI17+AN17+AS17+AX17+BC17+BH17 -> 575469 | K17: =P17+U17+Z17+AE17+AJ17+AO17+AT17+AY17+BD17+BI17 -> 611250 | L17: =Q17+V17+AA17+AF17+AK17+AP17+AU17+AZ17+BE17+BJ17 -> 595025 | M17: =L17/K17-1 -> -0.026543967 | N17: =L17/J17-1 -> 0.033982717 | O17: ='2024년 실적'!Q17 -> 51458 | P17: 52500 | Q17: 43848 | R17: =Q17/P17-1 -> -0.1648 | S17: =Q17/O17-1 -> -0.1478876 | T17: ='2024년 실적'!V17 -> 41572 | U17: 60000 | V17: 49035 | W17: =V17/U17-1 -> -0.18275 | X17: =V17/T17-1 -> 0.17951987 | Y17: ='2024년 실적'!AA17 -> 111312 | Z17: 67500 | AA17: 60892 | AB17: =AA17/Z17-1 -> -0.097896296 | AC17: =AA17/Y17-1 -> -0.45296105 | AD17: ='2024년 실적'!AF17 -> 45296 | AE17: 60000 | AF17: 66140 | AG17: =AF17/AE17-1 -> 0.10233333 | AH17: =AF17/AD17-1 -> 0.46017308 | AI17: ='2024년 실적'!AK17 -> 45576 | AJ17: 60000 | AK17: 81294 | AL17: =AK17/AJ17-1 -> 0.3549 | AM17: =AK17/AI17-1 -> 0.78370195 | AN17: ='2024년 실적'!AP17 -> 57196 | AO17: 60000 | AP17: 77020 | AQ17: =AP17/AO17-1 -> 0.28366667 | AR17: =AP17/AN17-1 -> 0.34659766 | AS17: ='2024년 실적'!AU17 -> 45164 | AT17: 60000 | AU17: 45132 | AV17: =AU17/AT17-1 -> -0.2478 | AW17: =AU17/AS17-1 -> -0.00070852892 | AX17: ='2024년 실적'!AZ17 -> 49634 | AY17: 60000 | AZ17: 49406 | BA17: =AZ17/AY17-1 -> -0.17656667 | BB17: =AZ17/AX17-1 -> -0.0045936253 | BC17: ='2024년 실적'!BE17 -> 47638 | BD17: 60000 | BE17: 60172 | BF17: =BE17/BD17-1 -> 0.0028666667 | BG17: =BE17/BC17-1 -> 0.26310928 | BH17: ='2024년 실적'!BJ17 -> 80623 | BI17: 71250 | BJ17: 62086 | BK17: =BJ17/BI17-1 -> -0.12861754 | BL17: =BJ17/BH17-1 -> -0.22992198 | BM17: ='2024년 실적'!BO17 -> 51218 | BN17: 71250 | BP17: =BO17/BN17-1 -> -1 | BQ17: =BO17/BM17-1 -> -1 | BR17: ='2024년 실적'!BT17 -> 54348 | BS17: 67500 | BU17: =BT17/BS17-1 -> -1 | BV17: =BT17/BR17-1 -> -1 | BW17: =L17/$BW$1*12 -> 714030 | BX17: =L17-J17 -> 19556 | BZ17: =L17/H17 -> 0.79336667
E18: 랜더스팀 | F18: ='2024년 실적'!G18 -> 316827 | G18: ='2024년 실적'!L18 -> 265074 | H18: 300000 | I18: =H18/G18-1 -> 0.13175943 | J18: =O18+T18+Y18+AD18+AI18+AN18+AS18+AX18+BC18+BH18 -> 216703 | K18: =P18+U18+Z18+AE18+AJ18+AO18+AT18+AY18+BD18+BI18 -> 244500 | L18: =Q18+V18+AA18+AF18+AK18+AP18+AU18+AZ18+BE18+BJ18 -> 230987 | M18: =L18/K18-1 -> -0.055267894 | N18: =L18/J18-1 -> 0.0659151 | O18: ='2024년 실적'!Q18 -> 21467 | P18: 21000 | Q18: 16550 | R18: =Q18/P18-1 -> -0.21190476 | S18: =Q18/O18-1 -> -0.22904924 | T18: ='2024년 실적'!V18 -> 19730 | U18: 24000 | V18: 20077 | W18: =V18/U18-1 -> -0.16345833 | X18: =V18/T18-1 -> 0.01758743 | Y18: ='2024년 실적'!AA18 -> 20764 | Z18: 27000 | AA18: 21952 | AB18: =AA18/Z18-1 -> -0.18696296 | AC18: =AA18/Y18-1 -> 0.05721441 | AD18: ='2024년 실적'!AF18 -> 21938 | AE18: 24000 | AF18: 24115 | AG18: =AF18/AE18-1 -> 0.0047916667 | AH18: =AF18/AD18-1 -> 0.099234205 | AI18: ='2024년 실적'!AK18 -> 22265 | AJ18: 24000 | AK18: 26146 | AL18: =AK18/AJ18-1 -> 0.089416667 | AM18: =AK18/AI18-1 -> 0.17430945 | AN18: ='2024년 실적'!AP18 -> 21398 | AO18: 24000 | AP18: 23244 | AQ18: =AP18/AO18-1 -> -0.0315 | AR18: =AP18/AN18-1 -> 0.086269745 | AS18: ='2024년 실적'!AU18 -> 22294 | AT18: 24000 | AU18: 24062 | AV18: =AU18/AT18-1 -> 0.0025833333 | AW18: =AU18/AS18-1 -> 0.079303849 | AX18: ='2024년 실적'!AZ18 -> 22017 | AY18: 24000 | AZ18: 22573 | BA18: =AZ18/AY18-1 -> -0.059458333 | BB18: =AZ18/AX18-1 -> 0.025253213 | BC18: ='2024년 실적'!BE18 -> 20017 | BD18: 24000 | BE18: 26159 | BF18: =BE18/BD18-1 -> 0.089958333 | BG18: =BE18/BC18-1 -> 0.30683919 | BH18: ='2024년 실적'!BJ18 -> 24813 | BI18: 28500 | BJ18: 26109 | BK18: =BJ18/BI18-1 -> -0.083894737 | BL18: =BJ18/BH18-1 -> 0.052230686 | BM18: ='2024년 실적'!BO18 -> 25063 | BN18: 28500 | BP18: =BO18/BN18-1 -> -1 | BQ18: =BO18/BM18-1 -> -1 | BR18: ='2024년 실적'!BT18 -> 23308 | BS18: 27000 | BU18: =BT18/BS18-1 -> -1 | BV18: =BT18/BR18-1 -> -1 | BW18: =L18/$BW$1*12 -> 277184.4 | BX18: =L18-J18 -> 14284 | BZ18: =L18/H18 -> 0.76995667
E19: 사무실 | F19: ='2024년 실적'!G19 -> 666952 | G19: ='2024년 실적'!L19 -> 669366 | H19: 698000 | I19: =H19/G19-1 -> 0.042777793 | J19: =O19+T19+Y19+AD19+AI19+AN19+AS19+AX19+BC19+BH19 -> 548123 | K19: =P19+U19+Z19+AE19+AJ19+AO19+AT19+AY19+BD19+BI19 -> 568870 | L19: =Q19+V19+AA19+AF19+AK19+AP19+AU19+AZ19+BE19+BJ19 -> 551571 | M19: =L19/K19-1 -> -0.030409408 | N19: =L19/J19-1 -> 0.0062905589 | O19: ='2024년 실적'!Q19 -> 41822 | P19: 48860 | Q19: 57133 | R19: =Q19/P19-1 -> 0.16932051 | S19: =Q19/O19-1 -> 0.36609918 | T19: ='2024년 실적'!V19 -> 39970 | U19: 55840 | V19: 64272 | W19: =V19/U19-1 -> 0.15100287 | X19: =V19/T19-1 -> 0.608006 | Y19: ='2024년 실적'!AA19 -> 54988 | Z19: 62820 | AA19: 43316 | AB19: =AA19/Z19-1 -> -0.31047437 | AC19: =AA19/Y19-1 -> -0.21226449 | AD19: ='2024년 실적'!AF19 -> 69684 | AE19: 55840 | AF19: 55264 | AG19: =AF19/AE19-1 -> -0.010315186 | AH19: =AF19/AD19-1 -> -0.20693416 | AI19: ='2024년 실적'!AK19 -> 54288 | AJ19: 55840 | AK19: 49971 | AL19: =AK19/AJ19-1 -> -0.10510387 | AM19: =AK19/AI19-1 -> -0.079520336 | AN19: ='2024년 실적'!AP19 -> 64667 | AO19: 55840 | AP19: 55724 | AQ19: =AP19/AO19-1 -> -0.0020773639 | AR19: =AP19/AN19-1 -> -0.1382931 | AS19: ='2024년 실적'!AU19 -> 64020 | AT19: 55840 | AU19: 51623 | AV19: =AU19/AT19-1 -> -0.075519341 | AW19: =AU19/AS19-1 -> -0.19364261 | AX19: ='2024년 실적'!AZ19 -> 53627 | AY19: 55840 | AZ19: 61007 | BA19: =AZ19/AY19-1 -> 0.092532235 | BB19: =AZ19/AX19-1 -> 0.13761725 | BC19: ='2024년 실적'!BE19 -> 49995 | BD19: 55840 | BE19: 63774 | BF19: =BE19/BD19-1 -> 0.14208453 | BG19: =BE19/BC19-1 -> 0.27560756 | BH19: ='2024년 실적'!BJ19 -> 55062 | BI19: 66310 | BJ19: 49487 | BK19: =BJ19/BI19-1 -> -0.25370231 | BL19: =BJ19/BH19-1 -> -0.1012495 | BM19: ='2024년 실적'!BO19 -> 63034 | BN19: 66310 | BP19: =BO19/BN19-1 -> -1 | BQ19: =BO19/BM19-1 -> -1 | BR19: ='2024년 실적'!BT19 -> 58209 | BS19: 62820 | BU19: =BT19/BS19-1 -> -1 | BV19: =BT19/BR19-1 -> -1 | BW19: =L19/$BW$1*12 -> 661885.2 | BX19: =L19-J19 -> 3448 | BZ19: =L19/H19 -> 0.79021633
E20: 소계 | F20: ='2024년 실적'!G20 -> 1804453 | G20: ='2024년 실적'!L20 -> 1960674 | H20: =SUM(H16:H19) -> 2138000 | I20: =H20/G20-1 -> 0.090441348 | J20: =SUM(J16:J19) -> 1623214 | K20: =SUM(K16:K19) -> 1742470 | L20: =SUM(L16:L19) -> 1673276 | M20: =L20/K20-1 -> -0.039710296 | N20: =L20/J20-1 -> 0.030841282 | O20: =SUM(O16:O19) -> 139703 | P20: =SUM(P16:P19) -> 149660 | Q20: =SUM(Q16:Q19) -> 145003 | R20: =Q20/P20-1 -> -0.031117199 | S20: =Q20/O20-1 -> 0.037937625 | T20: =SUM(T16:T19) -> 123926 | U20: =SUM(U16:U19) -> 171040 | V20: =SUM(V16:V19) -> 161430 | W20: =V20/U20-1 -> -0.056185688 | X20: =V20/T20-1 -> 0.30263222 | Y20: =SUM(Y16:Y19) -> 215152 | Z20: =SUM(Z16:Z19) -> 192420 | AA20: =SUM(AA16:AA19) -> 154723 | AB20: =AA20/Z20-1 -> -0.19590999 | AC20: =AA20/Y20-1 -> -0.28086655 | AD20: =SUM(AD16:AD19) -> 169050 | AE20: =SUM(AE16:AE19) -> 171040 | AF20: =SUM(AF16:AF19) -> 177129 | AG20: =AF20/AE20-1 -> 0.03559986 | AH20: =AF20/AD20-1 -> 0.047790594 | AI20: =SUM(AI16:AI19) -> 149623 | AJ20: =SUM(AJ16:AJ19) -> 171040 | AK20: =SUM(AK16:AK19) -> 188329 | AL20: =AK20/AJ20-1 -> 0.10108162 | AM20: =AK20/AI20-1 -> 0.25869017 | AN20: =SUM(AN16:AN19) -> 171321 | AO20: =SUM(AO16:AO19) -> 171040 | AP20: =SUM(AP16:AP19) -> 182992 | AQ20: =AP20/AO20-1 -> 0.069878391 | AR20: =AP20/AN20-1 -> 0.068123581 | AS20: =SUM(AS16:AS19) -> 162471 | AT20: =SUM(AT16:AT19) -> 171040 | AU20: =SUM(AU16:AU19) -> 153189 | AV20: =AU20/AT20-1 -> -0.1043674 | AW20: =AU20/AS20-1 -> -0.057130196 | AX20: =SUM(AX16:AX19) -> 155423 | AY20: =SUM(AY16:AY19) -> 171040 | AZ20: =SUM(AZ16:AZ19) -> 161774 | BA20: =AZ20/AY20-1 -> -0.054174462 | BB20: =AZ20/AX20-1 -> 0.040862678 | BC20: =SUM(BC16:BC19) -> 143303 | BD20: =SUM(BD16:BD19) -> 171040 | BE20: =SUM(BE16:BE19) -> 181042 | BF20: =BE20/BD20-1 -> 0.058477549 | BG20: =BE20/BC20-1 -> 0.26335108 | BH20: =SUM(BH16:BH19) -> 193242 | BI20: =SUM(BI16:BI19) -> 203110 | BJ20: =SUM(BJ16:BJ19) -> 167665 | BK20: =BJ20/BI20-1 -> -0.17451135 | BL20: =BJ20/BH20-1 -> -0.13235736 | BM20: =SUM(BM16:BM19) -> 169885 | BN20: =SUM(BN16:BN19) -> 203110 | BO20: =SUM(BO16:BO19) -> 0 | BP20: =BO20/BN20-1 -> -1 | BQ20: =BO20/BM20-1 -> -1 | BR20: =SUM(BR16:BR19) -> 167575 | BS20: =SUM(BS16:BS19) -> 192420 | BT20: =SUM(BT16:BT19) -> 0 | BU20: =BT20/BS20-1 -> -1 | BV20: =BT20/BR20-1 -> -1 | BW20: =L20/$BW$1*12 -> 2007931.2 | BX20: =L20-J20 -> 50062 | BZ20: =L20/H20 -> 0.78263611
D21: 중부 | E21: 클라쓰팀 | F21: ='2024년 실적'!G21 -> 567346 | G21: ='2024년 실적'!L21 -> 647422 | H21: 730000 | I21: =H21/G21-1 -> 0.12754896 | J21: =O21+T21+Y21+AD21+AI21+AN21+AS21+AX21+BC21+BH21 -> 540607 | K21: =P21+U21+Z21+AE21+AJ21+AO21+AT21+AY21+BD21+BI21 -> 594950 | L21: =Q21+V21+AA21+AF21+AK21+AP21+AU21+AZ21+BE21+BJ21 -> 580834 | M21: =L21/K21-1 -> -0.023726364 | N21: =L21/J21-1 -> 0.074410801 | O21: ='2024년 실적'!Q21 -> 44434 | P21: 51100 | Q21: 37914 | R21: =Q21/P21-1 -> -0.25804305 | S21: =Q21/O21-1 -> -0.14673448 | T21: ='2024년 실적'!V21 -> 38792 | U21: 58400 | V21: 50462 | W21: =V21/U21-1 -> -0.13592466 | X21: =V21/T21-1 -> 0.30083522 | Y21: ='2024년 실적'!AA21 -> 51640 | Z21: 65700 | AA21: 55146 | AB21: =AA21/Z21-1 -> -0.16063927 | AC21: =AA21/Y21-1 -> 0.067893106 | AD21: ='2024년 실적'!AF21 -> 67734 | AE21: 58400 | AF21: 69178 | AG21: =AF21/AE21-1 -> 0.18455479 | AH21: =AF21/AD21-1 -> 0.021318688 | AI21: ='2024년 실적'!AK21 -> 47127 | AJ21: 58400 | AK21: 70765 | AL21: =AK21/AJ21-1 -> 0.21172945 | AM21: =AK21/AI21-1 -> 0.50158083 | AN21: ='2024년 실적'!AP21 -> 50438 | AO21: 58400 | AP21: 51257 | AQ21: =AP21/AO21-1 -> -0.12231164 | AR21: =AP21/AN21-1 -> 0.016237757 | AS21: ='2024년 실적'!AU21 -> 48176 | AT21: 58400 | AU21: 53898 | AV21: =AU21/AT21-1 -> -0.077089041 | AW21: =AU21/AS21-1 -> 0.11877283 | AX21: ='2024년 실적'!AZ21 -> 53422 | AY21: 58400 | AZ21: 49422 | BA21: =AZ21/AY21-1 -> -0.15373288 | BB21: =AZ21/AX21-1 -> -0.074875519 | BC21: ='2024년 실적'!BE21 -> 55410 | BD21: 58400 | BE21: 67494 | BF21: =BE21/BD21-1 -> 0.15571918 | BG21: =BE21/BC21-1 -> 0.21808338 | BH21: ='2024년 실적'!BJ21 -> 83434 | BI21: 69350 | BJ21: 75298 | BK21: =BJ21/BI21-1 -> 0.085767844 | BL21: =BJ21/BH21-1 -> -0.097514203 | BM21: ='2024년 실적'!BO21 -> 55539 | BN21: 69350 | BP21: =BO21/BN21-1 -> -1 | BQ21: =BO21/BM21-1 -> -1 | BR21: ='2024년 실적'!BT21 -> 51276 | BS21: 65700 | BU21: =BT21/BS21-1 -> -1 | BV21: =BT21/BR21-1 -> -1 | BW21: =L21/$BW$1*12 -> 697000.8 | BX21: =L21-J21 -> 40227 | BZ21: =L21/H21 -> 0.79566301
E22: 사무실 | F22: ='2024년 실적'!G22 -> 12804 | G22: ='2024년 실적'!L22 -> 11862 | H22: 12000 | I22: =H22/G22-1 -> 0.011633789 | J22: =O22+T22+Y22+AD22+AI22+AN22+AS22+AX22+BC22+BH22 -> 8252 | K22: =P22+U22+Z22+AE22+AJ22+AO22+AT22+AY22+BD22+BI22 -> 9780 | L22: =Q22+V22+AA22+AF22+AK22+AP22+AU22+AZ22+BE22+BJ22 -> 8324 | M22: =L22/K22-1 -> -0.14887526 | N22: =L22/J22-1 -> 0.0087251575 | O22: ='2024년 실적'!Q22 -> 70 | P22: 840 | Q22: 58 | R22: =Q22/P22-1 -> -0.93095238 | S22: =Q22/O22-1 -> -0.17142857 | T22: ='2024년 실적'!V22 -> 30 | U22: 960 | V22: 168 | W22: =V22/U22-1 -> -0.825 | X22: =V22/T22-1 -> 4.6 | Y22: ='2024년 실적'!AA22 -> 1308 | Z22: 1080 | AA22: 2300 | AB22: =AA22/Z22-1 -> 1.1296296 | AC22: =AA22/Y22-1 -> 0.75840979 | AD22: ='2024년 실적'!AF22 -> 508 | AE22: 960 | AF22: 58 | AG22: =AF22/AE22-1 -> -0.93958333 | AH22: =AF22/AD22-1 -> -0.88582677 | AI22: ='2024년 실적'!AK22 -> 892 | AJ22: 960 | AK22: 1114 | AL22: =AK22/AJ22-1 -> 0.16041667 | AM22: =AK22/AI22-1 -> 0.24887892 | AN22: ='2024년 실적'!AP22 -> 1254 | AO22: 960 | AP22: 1770 | AQ22: =AP22/AO22-1 -> 0.84375 | AR22: =AP22/AN22-1 -> 0.41148325 | AS22: ='2024년 실적'!AU22 -> 150 | AT22: 960 | AU22: 1522 | AV22: =AU22/AT22-1 -> 0.58541667 | AW22: =AU22/AS22-1 -> 9.1466667 | AX22: ='2024년 실적'!AZ22 -> 2894 | AY22: 960 | AZ22: 54 | BA22: =AZ22/AY22-1 -> -0.94375 | BB22: =AZ22/AX22-1 -> -0.9813407 | BC22: ='2024년 실적'!BE22 -> 52 | BD22: 960 | BE22: 196 | BF22: =BE22/BD22-1 -> -0.79583333 | BG22: =BE22/BC22-1 -> 2.7692308 | BH22: ='2024년 실적'!BJ22 -> 1094 | BI22: 1140 | BJ22: 1084 | BK22: =BJ22/BI22-1 -> -0.049122807 | BL22: =BJ22/BH22-1 -> -0.0091407678 | BM22: ='2024년 실적'!BO22 -> 1714 | BN22: 1140 | BP22: =BO22/BN22-1 -> -1 | BQ22: =BO22/BM22-1 -> -1 | BR22: ='2024년 실적'!BT22 -> 1896 | BS22: 1080 | BU22: =BT22/BS22-1 -> -1 | BV22: =BT22/BR22-1 -> -1 | BW22: =L22/$BW$1*12 -> 9988.8 | BX22: =L22-J22 -> 72 | BZ22: =L22/H22 -> 0.69366667
E23: 소계 | F23: ='2024년 실적'!G23 -> 580150 | G23: ='2024년 실적'!L23 -> 659284 | H23: =SUM(H21:H22) -> 742000 | I23: =H23/G23-1 -> 0.12546338 | J23: =SUM(J21:J22) -> 548859 | K23: =SUM(K21:K22) -> 604730 | L23: =SUM(L21:L22) -> 589158 | M23: =L23/K23-1 -> -0.025750335 | N23: =L23/J23-1 -> 0.073423229 | O23: =SUM(O21:O22) -> 44504 | P23: =SUM(P21:P22) -> 51940 | Q23: =SUM(Q21:Q22) -> 37972 | R23: =Q23/P23-1 -> -0.26892568 | S23: =Q23/O23-1 -> -0.14677332 | T23: =SUM(T21:T22) -> 38822 | U23: =SUM(U21:U22) -> 59360 | V23: =SUM(V21:V22) -> 50630 | W23: =V23/U23-1 -> -0.14706873 | X23: =V23/T23-1 -> 0.30415744 | Y23: =SUM(Y21:Y22) -> 52948 | Z23: =SUM(Z21:Z22) -> 66780 | AA23: =SUM(AA21:AA22) -> 57446 | AB23: =AA23/Z23-1 -> -0.13977239 | AC23: =AA23/Y23-1 -> 0.084951273 | AD23: =SUM(AD21:AD22) -> 68242 | AE23: =SUM(AE21:AE22) -> 59360 | AF23: =SUM(AF21:AF22) -> 69236 | AG23: =AF23/AE23-1 -> 0.16637466 | AH23: =AF23/AD23-1 -> 0.01456581 | AI23: =SUM(AI21:AI22) -> 48019 | AJ23: =SUM(AJ21:AJ22) -> 59360 | AK23: =SUM(AK21:AK22) -> 71879 | AL23: =AK23/AJ23-1 -> 0.2108996 | AM23: =AK23/AI23-1 -> 0.49688665 | AN23: =SUM(AN21:AN22) -> 51692 | AO23: =SUM(AO21:AO22) -> 59360 | AP23: =SUM(AP21:AP22) -> 53027 | AQ23: =AP23/AO23-1 -> -0.10668801 | AR23: =AP23/AN23-1 -> 0.025826047 | AS23: ='2024년 실적'!AU23 -> 48326 | AT23: =SUM(AT21:AT22) -> 59360 | AU23: =SUM(AU21:AU22) -> 55420 | AV23: =AU23/AT23-1 -> -0.066374663 | AW23: =AU23/AS23-1 -> 0.14679469 | AX23: =SUM(AX21:AX22) -> 56316 | AY23: =SUM(AY21:AY22) -> 59360 | AZ23: =SUM(AZ21:AZ22) -> 49476 | BA23: =AZ23/AY23-1 -> -0.16650943 | BB23: =AZ23/AX23-1 -> -0.12145749 | BC23: =SUM(BC21:BC22) -> 55462 | BD23: =SUM(BD21:BD22) -> 59360 | BE23: =SUM(BE21:BE22) -> 67690 | BF23: =BE23/BD23-1 -> 0.14033019 | BG23: =BE23/BC23-1 -> 0.22047528 | BH23: =SUM(BH21:BH22) -> 84528 | BI23: =SUM(BI21:BI22) -> 70490 | BJ23: =SUM(BJ21:BJ22) -> 76382 | BK23: =BJ23/BI23-1 -> 0.083586324 | BL23: =BJ23/BH23-1 -> -0.096370433 | BM23: =SUM(BM21:BM22) -> 57253 | BN23: =SUM(BN21:BN22) -> 70490 | BO23: =SUM(BO21:BO22) -> 0 | BP23: =BO23/BN23-1 -> -1 | BQ23: =BO23/BM23-1 -> -1 | BR23: =SUM(BR21:BR22) -> 53172 | BS23: =SUM(BS21:BS22) -> 66780 | BT23: =SUM(BT21:BT22) -> 0 | BU23: =BT23/BS23-1 -> -1 | BV23: =BT23/BR23-1 -> -1 | BW23: =L23/$BW$1*12 -> 706989.6 | BX23: =L23-J23 -> 40299 | BZ23: =L23/H23 -> 0.79401348
D24: 제주 | E24: 삼다도팀 | F24: ='2024년 실적'!G24 -> 79851 | G24: ='2024년 실적'!L24 -> 84553 | H24: 100000 | I24: =H24/G24-1 -> 0.18269015 | J24: =O24+T24+Y24+AD24+AI24+AN24+AS24+AX24+BC24+BH24 -> 68997 | K24: =P24+U24+Z24+AE24+AJ24+AO24+AT24+AY24+BD24+BI24 -> 81500 | L24: =Q24+V24+AA24+AF24+AK24+AP24+AU24+AZ24+BE24+BJ24 -> 79721 | M24: =L24/K24-1 -> -0.021828221 | N24: =L24/J24-1 -> 0.15542705 | O24: ='2024년 실적'!Q24 -> 6046 | P24: 7000 | Q24: 7984 | R24: =Q24/P24-1 -> 0.14057143 | S24: =Q24/O24-1 -> 0.32054251 | T24: ='2024년 실적'!V24 -> 6432 | U24: 8000 | V24: 8036 | W24: =V24/U24-1 -> 0.0045 | X24: =V24/T24-1 -> 0.24937811 | Y24: ='2024년 실적'!AA24 -> 6184 | Z24: 9000 | AA24: 9066 | AB24: =AA24/Z24-1 -> 0.0073333333 | AC24: =AA24/Y24-1 -> 0.4660414 | AD24: ='2024년 실적'!AF24 -> 6456 | AE24: 8000 | AF24: 9488 | AG24: =AF24/AE24-1 -> 0.186 | AH24: =AF24/AD24-1 -> 0.46964064 | AI24: ='2024년 실적'!AK24 -> 6824 | AJ24: 8000 | AK24: 6766 | AL24: =AK24/AJ24-1 -> -0.15425 | AM24: =AK24/AI24-1 -> -0.0084994138 | AN24: ='2024년 실적'!AP24 -> 6668 | AO24: 8000 | AP24: 7530 | AQ24: =AP24/AO24-1 -> -0.05875 | AR24: =AP24/AN24-1 -> 0.12927415 | AS24: ='2024년 실적'!AU24 -> 8026 | AT24: 8000 | AU24: 7240 | AV24: =AU24/AT24-1 -> -0.095 | AW24: =AU24/AS24-1 -> -0.097931722 | AX24: ='2024년 실적'!AZ24 -> 5699 | AY24: 8000 | AZ24: 7493 | BA24: =AZ24/AY24-1 -> -0.063375 | BB24: =AZ24/AX24-1 -> 0.31479207 | BC24: ='2024년 실적'!BE24 -> 6446 | BD24: 8000 | BE24: 7118 | BF24: =BE24/BD24-1 -> -0.11025 | BG24: =BE24/BC24-1 -> 0.1042507 | BH24: ='2024년 실적'!BJ24 -> 10216 | BI24: 9500 | BJ24: 9000 | BK24: =BJ24/BI24-1 -> -0.052631579 | BL24: =BJ24/BH24-1 -> -0.11902897 | BM24: ='2024년 실적'!BO24 -> 7686 | BN24: 9500 | BP24: =BO24/BN24-1 -> -1 | BQ24: =BO24/BM24-1 -> -1 | BR24: ='2024년 실적'!BT24 -> 7870 | BS24: 9000 | BU24: =BT24/BS24-1 -> -1 | BV24: =BT24/BR24-1 -> -1 | BW24: =L24/$BW$1*12 -> 95665.2 | BX24: =L24-J24 -> 10724 | BZ24: =L24/H24 -> 0.79721
D25: 남부지사 | E25: 남부지사 | F25: ='2024년 실적'!G25 -> 610171 | G25: ='2024년 실적'!L25 -> 557613 | H25: 650000 | I25: =H25/G25-1 -> 0.16568301 | J25: =O25+T25+Y25+AD25+AI25+AN25+AS25+AX25+BC25+BH25 -> 450121 | K25: =P25+U25+Z25+AE25+AJ25+AO25+AT25+AY25+BD25+BI25 -> 529750 | L25: =Q25+V25+AA25+AF25+AK25+AP25+AU25+AZ25+BE25+BJ25 -> 479396 | M25: =L25/K25-1 -> -0.095052383 | N25: =L25/J25-1 -> 0.065038068 | O25: ='2024년 실적'!Q25 -> 21880 | P25: 45500 | Q25: 35432 | R25: =Q25/P25-1 -> -0.22127473 | S25: =Q25/O25-1 -> 0.61937843 | T25: ='2024년 실적'!V25 -> 44547 | U25: 52000 | V25: 47352 | W25: =V25/U25-1 -> -0.089384615 | X25: =V25/T25-1 -> 0.062967203 | Y25: ='2024년 실적'!AA25 -> 46817 | Z25: 58500 | AA25: 50988 | AB25: =AA25/Z25-1 -> -0.12841026 | AC25: =AA25/Y25-1 -> 0.089091569 | AD25: ='2024년 실적'!AF25 -> 52212 | AE25: 52000 | AF25: 51164 | AG25: =AF25/AE25-1 -> -0.016076923 | AH25: =AF25/AD25-1 -> -0.020072014 | AI25: ='2024년 실적'!AK25 -> 45220 | AJ25: 52000 | AK25: 45652 | AL25: =AK25/AJ25-1 -> -0.12207692 | AM25: =AK25/AI25-1 -> 0.009553295 | AN25: ='2024년 실적'!AP25 -> 40278 | AO25: 52000 | AP25: 61776 | AQ25: =AP25/AO25-1 -> 0.188 | AR25: =AP25/AN25-1 -> 0.5337405 | AS25: ='2024년 실적'!AU25 -> 60084 | AT25: 52000 | AU25: 47720 | AV25: =AU25/AT25-1 -> -0.082307692 | AW25: =AU25/AS25-1 -> -0.20577858 | AX25: ='2024년 실적'!AZ25 -> 34006 | AY25: 52000 | AZ25: 42798 | BA25: =AZ25/AY25-1 -> -0.17696154 | BB25: =AZ25/AX25-1 -> 0.25854261 | BC25: ='2024년 실적'!BE25 -> 40544 | BD25: 52000 | BE25: 51776 | BF25: =BE25/BD25-1 -> -0.0043076923 | BG25: =BE25/BC25-1 -> 0.27703236 | BH25: ='2024년 실적'!BJ25 -> 64533 | BI25: 61750 | BJ25: 44738 | BK25: =BJ25/BI25-1 -> -0.27549798 | BL25: =BJ25/BH25-1 -> -0.30674229 | BM25: ='2024년 실적'!BO25 -> 57024 | BN25: 61750 | BP25: =BO25/BN25-1 -> -1 | BQ25: =BO25/BM25-1 -> -1 | BR25: ='2024년 실적'!BT25 -> 50468 | BS25: 58500 | BU25: =BT25/BS25-1 -> -1 | BV25: =BT25/BR25-1 -> -1 | BW25: =L25/$BW$1*12 -> 575275.2 | BX25: =L25-J25 -> 29275 | BZ25: =L25/H25 -> 0.73753231
B26: B2B | D26: B2B Auto소계 | F26: ='2024년 실적'!G26 -> 835396 | G26: ='2024년 실적'!L26 -> 904015 | H26: 1000000 | I26: =H26/G26-1 -> 0.10617634 | J26: =O26+T26+Y26+AD26+AI26+AN26+AS26+AX26+BC26 -> 659496 | K26: =P26+U26+Z26+AE26+AJ26+AO26+AT26+AY26+BD26 -> 720000 | L26: =Q26+V26+AA26+AF26+AK26+AP26+AU26+AZ26+BE26 -> 737635 | M26: =L26/K26-1 -> 0.024493056 | N26: =L26/J26-1 -> 0.1184829 | O26: ='2024년 실적'!Q26 -> 53893 | P26: 70000 | Q26: 55574 | R26: =Q26/P26-1 -> -0.20608571 | S26: =Q26/O26-1 -> 0.031191435 | T26: ='2024년 실적'!V26 -> 78147 | U26: 80000 | V26: 87652 | W26: =V26/U26-1 -> 0.09565 | X26: =V26/T26-1 -> 0.12162975 | Y26: ='2024년 실적'!AA26 -> 71656 | Z26: 90000 | AA26: 59323 | AB26: =AA26/Z26-1 -> -0.34085556 | AC26: =AA26/Y26-1 -> -0.17211399 | AD26: ='2024년 실적'!AF26 -> 82813 | AE26: 80000 | AF26: 75280 | AG26: =AF26/AE26-1 -> -0.059 | AH26: =AF26/AD26-1 -> -0.090963979 | AI26: ='2024년 실적'!AK26 -> 78617 | AJ26: 80000 | AK26: 91644 | AL26: =AK26/AJ26-1 -> 0.14555 | AM26: =AK26/AI26-1 -> 0.16570207 | AN26: ='2024년 실적'!AP26 -> 67379 | AO26: 80000 | AP26: 91998 | AQ26: =AP26/AO26-1 -> 0.149975 | AR26: =AP26/AN26-1 -> 0.36538091 | AS26: ='2024년 실적'!AU26 -> 83193 | AT26: 80000 | AU26: 80614 | AV26: =AU26/AT26-1 -> 0.007675 | AW26: =AU26/AS26-1 -> -0.031000204 | AX26: ='2024년 실적'!AZ26 -> 81329 | AY26: 80000 | AZ26: 99818 | BA26: =AZ26/AY26-1 -> 0.247725 | BB26: =AZ26/AX26-1 -> 0.22733588 | BC26: ='2024년 실적'!BE26 -> 62469 | BD26: 80000 | BE26: 95732 | BF26: =BE26/BD26-1 -> 0.19665 | BG26: =BE26/BC26-1 -> 0.53247211 | BH26: ='2024년 실적'!BJ26 -> 86174 | BI26: 95000 | BJ26: 97428 | BK26: =BJ26/BI26-1 -> 0.025557895 | BL26: =BJ26/BH26-1 -> 0.13059624 | BM26: ='2024년 실적'!BO26 -> 87868 | BN26: 95000 | BP26: =BO26/BN26-1 -> -1 | BQ26: =BO26/BM26-1 -> -1 | BR26: ='2024년 실적'!BT26 -> 70477 | BS26: 90000 | BU26: =BT26/BS26-1 -> -1 | BV26: =BT26/BR26-1 -> -1 | BW26: =L26/$BW$1*12 -> 885162 | BX26: =L26-J26 -> 78139 | BZ26: =L26/H26 -> 0.737635
C27: IL | D27: 재고 | F27: ='2024년 실적'!G27 -> 410638 | G27: ='2024년 실적'!L27 -> 359989 | H27: =ROUND(H28/24,0) -> 255208 | I27: =H27/G27-1 -> -0.29106723 | J27: =BH27 -> 383612 | K27: =BI27 -> 255209 | L27: =BJ27 -> 316005 | M27: =L27/K27-1 -> 0.23822044 | N27: =L27/J27-1 -> -0.17623797 | O27: ='2024년 실적'!Q27 -> 329768 | P27: =ROUND(P28/2,2) -> 255209 | Q27: 303093 | S27: =Q27/O27-1 -> -0.080890202 | T27: ='2024년 실적'!V27 -> 278123 | U27: =U28/2 -> 255209 | V27: 328213 | W27: =V27/U27-1 -> 0.28605574 | X27: =V27/T27-1 -> 0.18010017 | Y27: ='2024년 실적'!AA27 -> 341100 | Z27: =Z28/2 -> 255209 | AA27: 341795 | AB27: =AA27/Z27-1 -> 0.33927487 | AC27: =AA27/Y27-1 -> 0.0020375257 | AD27: ='2024년 실적'!AF27 -> 330935 | AE27: =AE28/2 -> 255209 | AF27: 372100 | AG27: =AF27/AE27-1 -> 0.45802068 | AH27: =AF27/AD27-1 -> 0.12438999 | AI27: ='2024년 실적'!AK27 -> 405927 | AJ27: =AJ28/2 -> 255209 | AK27: 344116 | AL27: =AK27/AJ27-1 -> 0.34836938 | AM27: =AK27/AI27-1 -> -0.15227122 | AN27: ='2024년 실적'!AP27 -> 419353 | AO27: =AO28/2 -> 255209 | AP27: 289079 | AQ27: =AP27/AO27-1 -> 0.13271476 | AR27: =AP27/AN27-1 -> -0.31065475 | AS27: ='2024년 실적'!AU27 -> 291707 | AT27: =AT28/2 -> 255209 | AU27: 372167 | AV27: =AU27/AT27-1 -> 0.45828321 | AW27: =AU27/AS27-1 -> 0.27582471 | AX27: ='2024년 실적'!AZ27 -> 277172 | AY27: =AY29/2 -> 255209 | AZ27: 337591 | BA27: =AZ27/AY27-1 -> 0.3228021 | BB27: =AZ27/AX27-1 -> 0.21798378 | BC27: ='2024년 실적'!BE27 -> 314825 | BD27: =BD29/2 -> 255209 | BE27: 381405 | BF27: =BE27/BD27-1 -> 0.49448099 | BG27: =BE27/BC27-1 -> 0.21148257 | BH27: ='2024년 실적'!BJ27 -> 383612 | BI27: =BI28/2 -> 255209 | BJ27: 316005 | BK27: =BJ27/BI27-1 -> 0.23822044 | BL27: =BJ27/BH27-1 -> -0.17623797 | BM27: ='2024년 실적'!BO27 -> 374969 | BN27: =BN28/2 -> 255209 | BP27: =BO27/BN27-1 -> -1 | BQ27: =BO27/BM27-1 -> -1 | BR27: ='2024년 실적'!BT27 -> 359989 | BS27: =BS29/2 -> 255209 | BU27: =BT27/BS27-1 -> -1 | BV27: =BT27/BR27-1 -> -1
D28: sell-in | F28: ='2024년 실적'!G28 -> 5704093 | G28: ='2024년 실적'!L28 -> 5381839 | H28: =H29 -> 6125000 | I28: =H28/G28-1 -> 0.13808681 | J28: =O28+T28+Y28+AD28+AI28+AN28+AS28+AX28+BC28+BH28 -> 4363561 | K28: =P28+U28+Z28+AE28+AJ28+AO28+AT28+AY28+BD28+BI28 -> 5104180 | L28: =Q28+V28+AA28+AF28+AK28+AP28+AU28+AZ28+BE28+BJ28 -> 4442941 | M28: =L28/K28-1 -> -0.12954853 | N28: =L28/J28-1 -> 0.018191564 | O28: ='2024년 실적'!Q28 -> 341246 | P28: =P29 -> 510418 | Q28: 327291 | R28: =Q28/P28-1 -> -0.35877849 | S28: =Q28/O28-1 -> -0.040894252 | T28: ='2024년 실적'!V28 -> 397040 | U28: =U29 -> 510418 | V28: 484947 | W28: =V28/U28-1 -> -0.049902237 | X28: =V28/T28-1 -> 0.2214059 | Y28: ='2024년 실적'!AA28 -> 468286 | Z28: =Z29 -> 510418 | AA28: 436468 | AB28: =AA28/Z28-1 -> -0.14488125 | AC28: =AA28/Y28-1 -> -0.067945657 | AD28: ='2024년 실적'!AF28 -> 447362 | AE28: =AE29 -> 510418 | AF28: 548060 | AG28: =AF28/AE28-1 -> 0.073747399 | AH28: =AF28/AD28-1 -> 0.22509288 | AI28: ='2024년 실적'!AK28 -> 551104 | AJ28: =AJ29 -> 510418 | AK28: 436838 | AL28: =AK28/AJ28-1 -> -0.14415636 | AM28: =AK28/AI28-1 -> -0.20734018 | AN28: ='2024년 실적'!AP28 -> 416686 | AO28: =AO29 -> 510418 | AP28: 473319 | AQ28: =AP28/AO28-1 -> -0.072683565 | AR28: =AP28/AN28-1 -> 0.13591289 | AS28: ='2024년 실적'!AU28 -> 400169 | AT28: =AT29 -> 510418 | AU28: 472169 | AV28: =AU28/AT28-1 -> -0.074936621 | AW28: =AU28/AS28-1 -> 0.17992398 | AX28: ='2024년 실적'!AZ28 -> 440920 | AY28: =AY29 -> 510418 | AZ28: 409542 | BA28: =AZ28/AY28-1 -> -0.1976341 | BB28: =AZ28/AX28-1 -> -0.071164837 | BC28: ='2024년 실적'!BE28 -> 343048 | BD28: =BD29 -> 510418 | BE28: 541065 | BF28: =BE28/BD28-1 -> 0.060042945 | BG28: =BE28/BC28-1 -> 0.57722826 | BH28: ='2024년 실적'!BJ28 -> 557700 | BI28: =BI29 -> 510418 | BJ28: 313242 | BK28: =BJ28/BI28-1 -> -0.38630299 | BL28: =BJ28/BH28-1 -> -0.43833244 | BM28: ='2024년 실적'!BO28 -> 500870 | BN28: =BN29 -> 510418 | BP28: =BO28/BN28-1 -> -1 | BQ28: =BO28/BM28-1 -> -1 | BR28: ='2024년 실적'!BT28 -> 517408 | BS28: =BS29 -> 510418 | BU28: =BT28/BS28-1 -> -1 | BV28: =BT28/BR28-1 -> -1 | BX28: =L28-J28 -> 79380
D29: IL 합계 | F29: ='2024년 실적'!G29 -> 5796942 | G29: ='2024년 실적'!L29 -> 5433492 | H29: =SUM(H30:H36) -> 6125000 | I29: =H29/G29-1 -> 0.12726769 | J29: =SUM(J30:J36) -> 4399651 | K29: =SUM(K30:K36) -> 5104180 | L29: =SUM(L30:L36) -> 4480649 | M29: =L29/K29-1 -> -0.12216086 | N29: =L29/J29-1 -> 0.018410097 | O29: =SUM(O30:O36) -> 422415 | P29: =SUM(P30:P36) -> 510418 | Q29: =SUM(Q30:Q36) -> 382857 | R29: =Q29/P29-1 -> -0.24991478 | S29: =Q29/O29-1 -> -0.093647243 | T29: =SUM(T30:T36) -> 385426 | U29: =SUM(U30:U36) -> 510418 | V29: =SUM(V30:V36) -> 456307 | W29: =V29/U29-1 -> -0.10601311 | X29: =V29/T29-1 -> 0.18390301 | Y29: =SUM(Y30:Y36) -> 475886 | Z29: =SUM(Z30:Z36) -> 510418 | AA29: =SUM(AA30:AA36) -> 427070 | AB29: =AA29/Z29-1 -> -0.16329361 | AC29: =AA29/Y29-1 -> -0.10257919 | AD29: =SUM(AD30:AD36) -> 444047 | AE29: =SUM(AE30:AE36) -> 510418 | AF29: =SUM(AF30:AF36) -> 514992 | AG29: =AF29/AE29-1 -> 0.0089612827 | AH29: =AF29/AD29-1 -> 0.15976912 | AI29: =SUM(AI30:AI36) -> 492593 | AJ29: =SUM(AJ30:AJ36) -> 510418 | AK29: =SUM(AK30:AK36) -> 464179 | AL29: =AK29/AJ29-1 -> -0.090590457 | AM29: =AK29/AI29-1 -> -0.057682509 | AN29: =SUM(AN30:AN36) -> 401955 | AO29: =SUM(AO30:AO36) -> 510418 | AP29: =SUM(AP30:AP36) -> 491774 | AQ29: =AP29/AO29-1 -> -0.036526925 | AR29: =AP29/AN29-1 -> 0.22345536 | AS29: =SUM(AS30:AS36) -> 484454 | AT29: =SUM(AT30:AT36) -> 510418 | AU29: =SUM(AU30:AU36) -> 424605 | AV29: =AU29/AT29-1 -> -0.16812299 | AW29: =AU29/AS29-1 -> -0.12353908 | AX29: =SUM(AX30:AX36) -> 424912 | AY29: =SUM(AY30:AY36) -> 510418 | AZ29: =SUM(AZ30:AZ36) -> 444086 | BA29: =AZ29/AY29-1 -> -0.12995623 | BB29: =AZ29/AX29-1 -> 0.045124638 | BC29: =SUM(BC30:BC36) -> 378745 | BD29: =SUM(BD30:BD36) -> 510418 | BE29: =SUM(BE30:BE36) -> 496736 | BF29: =BE29/BD29-1 -> -0.026805481 | BG29: =BE29/BC29-1 -> 0.31153151 | BH29: =SUM(BH30:BH36) -> 489218 | BI29: =SUM(BI30:BI36) -> 510418 | BJ29: =SUM(BJ30:BJ36) -> 378043 | BK29: =BJ29/BI29-1 -> -0.25934626 | BL29: =BJ29/BH29-1 -> -0.22725043 | BM29: =SUM(BM30:BM36) -> 501510 | BN29: =SUM(BN30:BN36) -> 510418 | BO29: =SUM(BO30:BO36) -> 0 | BP29: =BO29/BN29-1 -> -1 | BQ29: =BO29/BM29-1 -> -1 | BR29: =SUM(BR30:BR36) -> 532331 | BS29: =SUM(BS30:BS36) -> 510418 | BT29: =SUM(BT30:BT36) -> 0 | BU29: =BT29/BS29-1 -> -1 | BV29: =BT29/BR29-1 -> -1 | BW29: =L29/$BW$1*12 -> 5376778.8 | BX29: =L29-J29 -> 80998 | BZ29: =L29/H29 -> 0.73153453
D30: 산업1팀 | F30: ='2024년 실적'!G30 -> 901787 | G30: ='2024년 실적'!L30 -> 611096 | H30: 792000 | I30: =H30/G30-1 -> 0.29603205 | J30: =O30+T30+Y30+AD30+AI30+AN30+AS30+AX30+BC30+BH30 -> 500277 | K30: =P30+U30+Z30+AE30+AJ30+AO30+AT30+AY30+BD30+BI30 -> 660000 | L30: =Q30+V30+AA30+AF30+AK30+AP30+AU30+AZ30+BE30+BJ30 -> 486789 | M30: =L30/K30-1 -> -0.26244091 | N30: =L30/J30-1 -> -0.026961064 | O30: ='2024년 실적'!Q30 -> 68175 | P30: =ROUND($H$30/12,0) -> 66000 | Q30: 25157 | R30: =Q30/P30-1 -> -0.61883333 | S30: =Q30/O30-1 -> -0.63099377 | T30: ='2024년 실적'!V30 -> 42265 | U30: =ROUND($H$30/12,0) -> 66000 | V30: 53946 | W30: =V30/U30-1 -> -0.18263636 | X30: =V30/T30-1 -> 0.27637525 | Y30: ='2024년 실적'!AA30 -> 45367 | Z30: =ROUND($H$30/12,0) -> 66000 | AA30: 36368 | AB30: =AA30/Z30-1 -> -0.4489697 | AC30: =AA30/Y30-1 -> -0.19836004 | AD30: ='2024년 실적'!AF30 -> 32159 | AE30: =ROUND($H$30/12,0) -> 66000 | AF30: 73721 | AG30: =AF30/AE30-1 -> 0.11698485 | AH30: =AF30/AD30-1 -> 1.2923909 | AI30: ='2024년 실적'!AK30 -> 60432 | AJ30: =ROUND($H$30/12,0) -> 66000 | AK30: 40691 | AL30: =AK30/AJ30-1 -> -0.3834697 | AM30: =AK30/AI30-1 -> -0.32666468 | AN30: ='2024년 실적'!AP30 -> 38891 | AO30: =ROUND($H$30/12,0) -> 66000 | AP30: 42325 | AQ30: =AP30/AO30-1 -> -0.35871212 | AR30: =AP30/AN30-1 -> 0.088298064 | AS30: ='2024년 실적'!AU30 -> 87598 | AT30: =ROUND($H$30/12,0) -> 66000 | AU30: 48509 | AV30: =AU30/AT30-1 -> -0.26501515 | AW30: =AU30/AS30-1 -> -0.44623165 | AX30: ='2024년 실적'!AZ30 -> 33546 | AY30: =ROUND($H$30/12,0) -> 66000 | AZ30: 87662 | BA30: =AZ30/AY30-1 -> 0.32821212 | BB30: =AZ30/AX30-1 -> 1.6131879 | BC30: ='2024년 실적'!BE30 -> 53620 | BD30: =ROUND($H$30/12,0) -> 66000 | BE30: 43394 | BF30: =BE30/BD30-1 -> -0.34251515 | BG30: =BE30/BC30-1 -> -0.19071242 | BH30: ='2024년 실적'!BJ30 -> 38224 | BI30: =ROUND($H$30/12,0) -> 66000 | BJ30: 35016 | BK30: =BJ30/BI30-1 -> -0.46945455 | BL30: =BJ30/BH30-1 -> -0.083926329 | BM30: ='2024년 실적'!BO30 -> 35128 | BN30: =ROUND($H$30/12,0) -> 66000 | BP30: =BO30/BN30-1 -> -1 | BQ30: =BO30/BM30-1 -> -1 | BR30: ='2024년 실적'!BT30 -> 75691 | BS30: =ROUND($H$30/12,0) -> 66000 | BU30: =BT30/BS30-1 -> -1 | BV30: =BT30/BR30-1 -> -1 | BW30: =L30/$BW$1*12 -> 584146.8 | BX30: =L30-J30 -> -13488 | BZ30: =L30/H30 -> 0.61463258
D31: 산업2팀 | F31: ='2024년 실적'!G31 -> 1808203 | G31: ='2024년 실적'!L31 -> 1755221 | H31: 1982000 | I31: =H31/G31-1 -> 0.12920253 | J31: =O31+T31+Y31+AD31+AI31+AN31+AS31+AX31+BC31+BH31 -> 1415512 | K31: =P31+U31+Z31+AE31+AJ31+AO31+AT31+AY31+BD31+BI31 -> 1651670 | L31: =Q31+V31+AA31+AF31+AK31+AP31+AU31+AZ31+BE31+BJ31 -> 1500061 | M31: =L31/K31-1 -> -0.091791338 | N31: =L31/J31-1 -> 0.059730331 | O31: ='2024년 실적'!Q31 -> 111538 | P31: =ROUND($H$31/12,0) -> 165167 | Q31: 154674 | R31: =Q31/P31-1 -> -0.06352964 | S31: =Q31/O31-1 -> 0.38673815 | T31: ='2024년 실적'!V31 -> 124449 | U31: =ROUND($H$31/12,0) -> 165167 | V31: 141990 | W31: =V31/U31-1 -> -0.14032464 | X31: =V31/T31-1 -> 0.1409493 | Y31: ='2024년 실적'!AA31 -> 124151 | Z31: =ROUND($H$31/12,0) -> 165167 | AA31: 123768 | AB31: =AA31/Z31-1 -> -0.25064934 | AC31: =AA31/Y31-1 -> -0.003084953 | AD31: ='2024년 실적'!AF31 -> 143766 | AE31: =ROUND($H$31/12,0) -> 165167 | AF31: 164305 | AG31: =AF31/AE31-1 -> -0.0052189602 | AH31: =AF31/AD31-1 -> 0.1428641 | AI31: ='2024년 실적'!AK31 -> 152604 | AJ31: =ROUND($H$31/12,0) -> 165167 | AK31: 114418 | AL31: =AK31/AJ31-1 -> -0.30725871 | AM31: =AK31/AI31-1 -> -0.25022935 | AN31: ='2024년 실적'!AP31 -> 149480 | AO31: =ROUND($H$31/12,0) -> 165167 | AP31: 192426 | AQ31: =AP31/AO31-1 -> 0.16503902 | AR31: =AP31/AN31-1 -> 0.28730265 | AS31: ='2024년 실적'!AU31 -> 162718 | AT31: =ROUND($H$31/12,0) -> 165167 | AU31: 129643 | AV31: =AU31/AT31-1 -> -0.21507928 | AW31: =AU31/AS31-1 -> -0.20326577 | AX31: ='2024년 실적'!AZ31 -> 158523 | AY31: =ROUND($H$31/12,0) -> 165167 | AZ31: 139157 | BA31: =AZ31/AY31-1 -> -0.15747698 | BB31: =AZ31/AX31-1 -> -0.12216524 | BC31: ='2024년 실적'!BE31 -> 107225 | BD31: =ROUND($H$31/12,0) -> 165167 | BE31: 190459 | BF31: =BE31/BD31-1 -> 0.15312986 | BG31: =BE31/BC31-1 -> 0.77625554 | BH31: ='2024년 실적'!BJ31 -> 181058 | BI31: =ROUND($H$31/12,0) -> 165167 | BJ31: 149221 | BK31: =BJ31/BI31-1 -> -0.096544709 | BL31: =BJ31/BH31-1 -> -0.17583868 | BM31: ='2024년 실적'!BO31 -> 158741 | BN31: =ROUND($H$31/12,0) -> 165167 | BP31: =BO31/BN31-1 -> -1 | BQ31: =BO31/BM31-1 -> -1 | BR31: ='2024년 실적'!BT31 -> 180968 | BS31: =ROUND($H$31/12,0) -> 165167 | BU31: =BT31/BS31-1 -> -1 | BV31: =BT31/BR31-1 -> -1 | BW31: =L31/$BW$1*12 -> 1800073.2 | BX31: =L31-J31 -> 84549 | BZ31: =L31/H31 -> 0.75684208
