Workbook

Sheet 통합
A2: ▣ 통합
A3: 단위 : Liter | D3: 43131 | E3: 44620 | F3: 43190 | G3: 43220 | H3: 43251 | I3: 43281 | J3: 43312 | K3: 43343 | L3: 43373 | M3: 43404 | N3: 11월 30일 | O3: 12월 31일 | P3: 변동재고 | Q3: 45962 | R3: 45963 | S3: 45964 | T3: 45965 | U3: 45966 | V3: 45967 | W3: 45968 | X3: 45969 | Y3: 45970 | Z3: 45971 | AA3: 45972 | AB3: 45973 | AC3: 45974 | AD3: 45975 | AE3: 45976 | AF3: 45977 | AG3: 45978 | AH3: 45979 | AI3: 45980 | AJ3: 45981 | AK3: 45982 | AL3: 45983 | AM3: 45984 | AN3: 45985 | AO3: 45986 | AP3: 45987 | AQ3: 45988 | AR3: 45989 | AS3: 45990 | AT3: 45991 | AU3: 45992 | AV3: 월 합계
A4: 기초재고 | B4: Auto | C4: Flagship | D4: =+'화성(서울)'!D4+'창원'!D4+'남양주'!D4+'인천'!D4+'화성오토'!D4+'제주'!D4+'부산'!D4 -> 35519 | E4: =+'화성(서울)'!E4+'창원'!E4+'남양주'!E4+'인천'!E4+'화성오토'!E4+'제주'!E4+'부산'!E4 -> 30012 | F4: =+'화성(서울)'!F4+'창원'!F4+'남양주'!F4+'인천'!F4+'화성오토'!F4+'제주'!F4+'부산'!F4 -> 34542 | G4: =+'화성(서울)'!G4+'창원'!G4+'남양주'!G4+'인천'!G4+'화성오토'!G4+'제주'!G4+'부산'!G4 -> 38938 | H4: =+'화성(서울)'!H4+'창원'!H4+'남양주'!H4+'인천'!H4+'화성오토'!H4+'제주'!H4+'부산'!H4 -> 49365 | I4: =+'화성(서울)'!I4+'창원'!I4+'남양주'!I4+'인천'!I4+'화성오토'!I4+'제주'!I4+'부산'!I4 -> 38532 | J4: =+'화성(서울)'!J4+'창원'!J4+'남양주'!J4+'인천'!J4+'화성오토'!J4+'제주'!J4+'부산'!J4 -> 47460 | K4: =+'화성(서울)'!K4+'창원'!K4+'남양주'!K4+'인천'!K4+'화성오토'!K4+'제주'!K4+'부산'!K4 -> 46308 | ... N4: =+'화성(서울)'!N4+'창원'!N4+'남양주'!N4+'인천'!N4+'화성오토'!N4+'제주'!N4+'부산'!N4 -> 38518 | O4: =N24 -> 38518 | P4: 38518 | Q4: =P24 -> 38518 | R4: =Q24 -> 38518 | S4: =R24 -> 38518 | T4: =S24 -> 39573 | U4: =T24 -> 40873 | V4: =U24 -> 29530 | W4: =V24 -> 31062 | X4: =W24 -> 29598 | ... AU4: =AT24 -> 30532 | AV4: =+'화성(서울)'!AV4+'창원'!AV4+'남양주'!AV4+'인천'!AV4+'화성오토'!AV4+'제주'!AV4+'부산'!AV4 -> 38518
C5: Others | D5: =+'화성(서울)'!D5+'창원'!D5+'남양주'!D5+'인천'!D5+'화성오토'!D5+'제주'!D5+'부산'!D5 -> 119567 | E5: =+'화성(서울)'!E5+'창원'!E5+'남양주'!E5+'인천'!E5+'화성오토'!E5+'제주'!E5+'부산'!E5 -> 110939 | F5: =+'화성(서울)'!F5+'창원'!F5+'남양주'!F5+'인천'!F5+'화성오토'!F5+'제주'!F5+'부산'!F5 -> 126181 | G5: =+'화성(서울)'!G5+'창원'!G5+'남양주'!G5+'인천'!G5+'화성오토'!G5+'제주'!G5+'부산'!G5 -> 152945 | H5: =+'화성(서울)'!H5+'창원'!H5+'남양주'!H5+'인천'!H5+'화성오토'!H5+'제주'!H5+'부산'!H5 -> 128508 | I5: =+'화성(서울)'!I5+'창원'!I5+'남양주'!I5+'인천'!I5+'화성오토'!I5+'제주'!I5+'부산'!I5 -> 121928 | J5: =+'화성(서울)'!J5+'창원'!J5+'남양주'!J5+'인천'!J5+'화성오토'!J5+'제주'!J5+'부산'!J5 -> 111129 | K5: =+'화성(서울)'!K5+'창원'!K5+'남양주'!K5+'인천'!K5+'화성오토'!K5+'제주'!K5+'부산'!K5 -> 133751 | ... N5: =+'화성(서울)'!N5+'창원'!N5+'남양주'!N5+'인천'!N5+'화성오토'!N5+'제주'!N5+'부산'!N5 -> 104881 | O5: =N25 -> 104881 | P5: 104881 | Q5: =P25 -> 104881 | R5: =Q25 -> 104881 | S5: =R25 -> 104881 | T5: =S25 -> 58841 | U5: =T25 -> 53751 | V5: =U25 -> 56617 | W5: =V25 -> 61885 | X5: =W25 -> 72195 | ... AU5: =AT25 -> 69387 | AV5: =+'화성(서울)'!AV5+'창원'!AV5+'남양주'!AV5+'인천'!AV5+'화성오토'!AV5+'제주'!AV5+'부산'!AV5 -> 104881
B6: IL | C6: Flagship | D6: =+'화성(서울)'!D6+'창원'!D6+'남양주'!D6+'인천'!D6+'화성오토'!D6+'제주'!D6+'부산'!D6 -> 28421 | E6: =+'화성(서울)'!E6+'창원'!E6+'남양주'!E6+'인천'!E6+'화성오토'!E6+'제주'!E6+'부산'!E6 -> 31357 | F6: =+'화성(서울)'!F6+'창원'!F6+'남양주'!F6+'인천'!F6+'화성오토'!F6+'제주'!F6+'부산'!F6 -> 37836 | G6: =+'화성(서울)'!G6+'창원'!G6+'남양주'!G6+'인천'!G6+'화성오토'!G6+'제주'!G6+'부산'!G6 -> 40837 | H6: =+'화성(서울)'!H6+'창원'!H6+'남양주'!H6+'인천'!H6+'화성오토'!H6+'제주'!H6+'부산'!H6 -> 33581 | I6: =+'화성(서울)'!I6+'창원'!I6+'남양주'!I6+'인천'!I6+'화성오토'!I6+'제주'!I6+'부산'!I6 -> 30370 | J6: =+'화성(서울)'!J6+'창원'!J6+'남양주'!J6+'인천'!J6+'화성오토'!J6+'제주'!J6+'부산'!J6 -> 33725 | K6: =+'화성(서울)'!K6+'창원'!K6+'남양주'!K6+'인천'!K6+'화성오토'!K6+'제주'!K6+'부산'!K6 -> 30783 | ... N6: =+'화성(서울)'!N6+'창원'!N6+'남양주'!N6+'인천'!N6+'화성오토'!N6+'제주'!N6+'부산'!N6 -> 41731 | O6: =N26 -> 41731 | P6: 41731 | Q6: =P26 -> 41731 | R6: =Q26 -> 41731 | S6: =R26 -> 41731 | T6: =S26 -> 34347 | U6: =T26 -> 35275 | V6: =U26 -> 34167 | W6: =V26 -> 34337 | X6: =W26 -> 29497 | ... AU6: =AT26 -> 25105 | AV6: =+'화성(서울)'!AV6+'창원'!AV6+'남양주'!AV6+'인천'!AV6+'화성오토'!AV6+'제주'!AV6+'부산'!AV6 -> 41731
C7: Others | D7: =+'화성(서울)'!D7+'창원'!D7+'남양주'!D7+'인천'!D7+'화성오토'!D7+'제주'!D7+'부산'!D7 -> 324420 | E7: =+'화성(서울)'!E7+'창원'!E7+'남양주'!E7+'인천'!E7+'화성오토'!E7+'제주'!E7+'부산'!E7 -> 262065 | F7: =+'화성(서울)'!F7+'창원'!F7+'남양주'!F7+'인천'!F7+'화성오토'!F7+'제주'!F7+'부산'!F7 -> 290924 | G7: =+'화성(서울)'!G7+'창원'!G7+'남양주'!G7+'인천'!G7+'화성오토'!G7+'제주'!G7+'부산'!G7 -> 280983 | H7: =+'화성(서울)'!H7+'창원'!H7+'남양주'!H7+'인천'!H7+'화성오토'!H7+'제주'!H7+'부산'!H7 -> 340223 | I7: =+'화성(서울)'!I7+'창원'!I7+'남양주'!I7+'인천'!I7+'화성오토'!I7+'제주'!I7+'부산'!I7 -> 313712 | J7: =+'화성(서울)'!J7+'창원'!J7+'남양주'!J7+'인천'!J7+'화성오토'!J7+'제주'!J7+'부산'!J7 -> 283625 | K7: =+'화성(서울)'!K7+'창원'!K7+'남양주'!K7+'인천'!K7+'화성오토'!K7+'제주'!K7+'부산'!K7 -> 343171 | ... N7: =+'화성(서울)'!N7+'창원'!N7+'남양주'!N7+'인천'!N7+'화성오토'!N7+'제주'!N7+'부산'!N7 -> 281180 | O7: =N27 -> 281180 | P7: 281180 | Q7: =P27 -> 281180 | R7: =Q27 -> 281180 | S7: =R27 -> 281180 | T7: =S27 -> 294838 | U7: =T27 -> 299983 | V7: =U27 -> 298209 | W7: =V27 -> 318987 | X7: =W27 -> 293722 | ... AU7: =AT27 -> 283454 | AV7: =+'화성(서울)'!AV7+'창원'!AV7+'남양주'!AV7+'인천'!AV7+'화성오토'!AV7+'제주'!AV7+'부산'!AV7 -> 281180
B8: MB | C8: Others | D8: =+'화성(서울)'!D8+'창원'!D8+'남양주'!D8+'인천'!D8+'화성오토'!D8+'제주'!D8+'부산'!D8 -> 170096 | E8: =+'화성(서울)'!E8+'창원'!E8+'남양주'!E8+'인천'!E8+'화성오토'!E8+'제주'!E8+'부산'!E8 -> 106928 | F8: =+'화성(서울)'!F8+'창원'!F8+'남양주'!F8+'인천'!F8+'화성오토'!F8+'제주'!F8+'부산'!F8 -> 234060 | G8: =+'화성(서울)'!G8+'창원'!G8+'남양주'!G8+'인천'!G8+'화성오토'!G8+'제주'!G8+'부산'!G8 -> 164404 | H8: =+'화성(서울)'!H8+'창원'!H8+'남양주'!H8+'인천'!H8+'화성오토'!H8+'제주'!H8+'부산'!H8 -> 131908 | I8: =+'화성(서울)'!I8+'창원'!I8+'남양주'!I8+'인천'!I8+'화성오토'!I8+'제주'!I8+'부산'!I8 -> 199692 | J8: =+'화성(서울)'!J8+'창원'!J8+'남양주'!J8+'인천'!J8+'화성오토'!J8+'제주'!J8+'부산'!J8 -> 269888 | K8: =+'화성(서울)'!K8+'창원'!K8+'남양주'!K8+'인천'!K8+'화성오토'!K8+'제주'!K8+'부산'!K8 -> 141368 | ... N8: =+'화성(서울)'!N8+'창원'!N8+'남양주'!N8+'인천'!N8+'화성오토'!N8+'제주'!N8+'부산'!N8 -> 163884 | O8: =N28 -> 163884 | P8: 163884 | Q8: =P28 -> 163884 | R8: =Q28 -> 163884 | S8: =R28 -> 163884 | T8: =S28 -> 40220 | U8: =T28 -> 57692 | V8: =U28 -> 75372 | W8: =V28 -> 105444 | X8: =W28 -> 107052 | ... AU8: =AT28 -> 59748 | AV8: =+'화성(서울)'!AV8+'창원'!AV8+'남양주'!AV8+'인천'!AV8+'화성오토'!AV8+'제주'!AV8+'부산'!AV8 -> 163884
A9: 매입 | B9: Auto | C9: Flagship | D9: =+'화성(서울)'!D9+'창원'!D9+'남양주'!D9+'인천'!D9+'화성오토'!D9+'제주'!D9+'부산'!D9 -> 36325 | E9: =+'화성(서울)'!E9+'창원'!E9+'남양주'!E9+'인천'!E9+'화성오토'!E9+'제주'!E9+'부산'!E9 -> 45643 | F9: =+'화성(서울)'!F9+'창원'!F9+'남양주'!F9+'인천'!F9+'화성오토'!F9+'제주'!F9+'부산'!F9 -> 56679 | G9: =+'화성(서울)'!G9+'창원'!G9+'남양주'!G9+'인천'!G9+'화성오토'!G9+'제주'!G9+'부산'!G9 -> 62790 | H9: =+'화성(서울)'!H9+'창원'!H9+'남양주'!H9+'인천'!H9+'화성오토'!H9+'제주'!H9+'부산'!H9 -> 61047 | I9: =+'화성(서울)'!I9+'창원'!I9+'남양주'!I9+'인천'!I9+'화성오토'!I9+'제주'!I9+'부산'!I9 -> 89552 | J9: =+'화성(서울)'!J9+'창원'!J9+'남양주'!J9+'인천'!J9+'화성오토'!J9+'제주'!J9+'부산'!J9 -> 58917 | K9: =+'화성(서울)'!K9+'창원'!K9+'남양주'!K9+'인천'!K9+'화성오토'!K9+'제주'!K9+'부산'!K9 -> 65810 | ... P9: =+'화성(서울)'!P9+'창원'!P9+'남양주'!P9+'인천'!P9+'화성오토'!P9+'제주'!P9+'부산'!P9 -> 0 | Q9: ='화성(서울)'!Q9+'창원'!Q9+'남양주'!Q9+'인천'!Q9+'화성오토'!Q9+'제주'!Q9+'부산'!Q9 -> 0 | R9: ='화성(서울)'!R9+'창원'!R9+'남양주'!R9+'인천'!R9+'화성오토'!R9+'제주'!R9+'부산'!R9 -> 0 | S9: ='화성(서울)'!S9+'창원'!S9+'남양주'!S9+'인천'!S9+'화성오토'!S9+'제주'!S9+'부산'!S9 -> 7602 | T9: ='화성(서울)'!T9+'창원'!T9+'남양주'!T9+'인천'!T9+'화성오토'!T9+'제주'!T9+'부산'!T9 -> 2440 | U9: ='화성(서울)'!U9+'창원'!U9+'남양주'!U9+'인천'!U9+'화성오토'!U9+'제주'!U9+'부산'!U9 -> 1656 | V9: ='화성(서울)'!V9+'창원'!V9+'남양주'!V9+'인천'!V9+'화성오토'!V9+'제주'!V9+'부산'!V9 -> 6260 | W9: ='화성(서울)'!W9+'창원'!W9+'남양주'!W9+'인천'!W9+'화성오토'!W9+'제주'!W9+'부산'!W9 -> 2188 | X9: ='화성(서울)'!X9+'창원'!X9+'남양주'!X9+'인천'!X9+'화성오토'!X9+'제주'!X9+'부산'!X9 -> 0 | ... AU9: ='화성(서울)'!AU9+'창원'!AU9+'남양주'!AU9+'인천'!AU9+'화성오토'!AU9+'제주'!AU9+'부산'!AU9 -> 0 | AV9: =+'화성(서울)'!AV9+'창원'!AV9+'남양주'!AV9+'인천'!AV9+'화성오토'!AV9+'제주'!AV9+'부산'!AV9 -> 22145
C10: Others | D10: =+'화성(서울)'!D10+'창원'!D10+'남양주'!D10+'인천'!D10+'화성오토'!D10+'제주'!D10+'부산'!D10 -> 301320 | E10: =+'화성(서울)'!E10+'창원'!E10+'남양주'!E10+'인천'!E10+'화성오토'!E10+'제주'!E10+'부산'!E10 -> 419654 | F10: =+'화성(서울)'!F10+'창원'!F10+'남양주'!F10+'인천'!F10+'화성오토'!F10+'제주'!F10+'부산'!F10 -> 390896 | G10: =+'화성(서울)'!G10+'창원'!G10+'남양주'!G10+'인천'!G10+'화성오토'!G10+'제주'!G10+'부산'!G10 -> 383932 | H10: =+'화성(서울)'!H10+'창원'!H10+'남양주'!H10+'인천'!H10+'화성오토'!H10+'제주'!H10+'부산'!H10 -> 407488 | I10: =+'화성(서울)'!I10+'창원'!I10+'남양주'!I10+'인천'!I10+'화성오토'!I10+'제주'!I10+'부산'!I10 -> 456844 | J10: =+'화성(서울)'!J10+'창원'!J10+'남양주'!J10+'인천'!J10+'화성오토'!J10+'제주'!J10+'부산'!J10 -> 354072 | K10: =+'화성(서울)'!K10+'창원'!K10+'남양주'!K10+'인천'!K10+'화성오토'!K10+'제주'!K10+'부산'!K10 -> 352702 | ... P10: =+'화성(서울)'!P10+'창원'!P10+'남양주'!P10+'인천'!P10+'화성오토'!P10+'제주'!P10+'부산'!P10 -> 0 | Q10: ='화성(서울)'!Q10+'창원'!Q10+'남양주'!Q10+'인천'!Q10+'화성오토'!Q10+'제주'!Q10+'부산'!Q10 -> 0 | R10: ='화성(서울)'!R10+'창원'!R10+'남양주'!R10+'인천'!R10+'화성오토'!R10+'제주'!R10+'부산'!R10 -> 0 | S10: ='화성(서울)'!S10+'창원'!S10+'남양주'!S10+'인천'!S10+'화성오토'!S10+'제주'!S10+'부산'!S10 -> 43960 | T10: ='화성(서울)'!T10+'창원'!T10+'남양주'!T10+'인천'!T10+'화성오토'!T10+'제주'!T10+'부산'!T10 -> 35692 | U10: ='화성(서울)'!U10+'창원'!U10+'남양주'!U10+'인천'!U10+'화성오토'!U10+'제주'!U10+'부산'!U10 -> 18578 | V10: ='화성(서울)'!V10+'창원'!V10+'남양주'!V10+'인천'!V10+'화성오토'!V10+'제주'!V10+'부산'!V10 -> 25222 | W10: ='화성(서울)'!W10+'창원'!W10+'남양주'!W10+'인천'!W10+'화성오토'!W10+'제주'!W10+'부산'!W10 -> 18500 | X10: ='화성(서울)'!X10+'창원'!X10+'남양주'!X10+'인천'!X10+'화성오토'!X10+'제주'!X10+'부산'!X10 -> 0 | ... AU10: ='화성(서울)'!AU10+'창원'!AU10+'남양주'!AU10+'인천'!AU10+'화성오토'!AU10+'제주'!AU10+'부산'!AU10 -> 0 | AV10: =+'화성(서울)'!AV10+'창원'!AV10+'남양주'!AV10+'인천'!AV10+'화성오토'!AV10+'제주'!AV10+'부산'!AV10 -> 160878
B11: IL | C11: Flagship | D11: =+'화성(서울)'!D11+'창원'!D11+'남양주'!D11+'인천'!D11+'화성오토'!D11+'제주'!D11+'부산'!D11 -> 37232 | E11: =+'화성(서울)'!E11+'창원'!E11+'남양주'!E11+'인천'!E11+'화성오토'!E11+'제주'!E11+'부산'!E11 -> 37913 | F11: =+'화성(서울)'!F11+'창원'!F11+'남양주'!F11+'인천'!F11+'화성오토'!F11+'제주'!F11+'부산'!F11 -> 36155 | G11: =+'화성(서울)'!G11+'창원'!G11+'남양주'!G11+'인천'!G11+'화성오토'!G11+'제주'!G11+'부산'!G11 -> 28642 | H11: =+'화성(서울)'!H11+'창원'!H11+'남양주'!H11+'인천'!H11+'화성오토'!H11+'제주'!H11+'부산'!H11 -> 50736 | I11: =+'화성(서울)'!I11+'창원'!I11+'남양주'!I11+'인천'!I11+'화성오토'!I11+'제주'!I11+'부산'!I11 -> 38538 | J11: =+'화성(서울)'!J11+'창원'!J11+'남양주'!J11+'인천'!J11+'화성오토'!J11+'제주'!J11+'부산'!J11 -> 27890 | K11: =+'화성(서울)'!K11+'창원'!K11+'남양주'!K11+'인천'!K11+'화성오토'!K11+'제주'!K11+'부산'!K11 -> 36111 | ... P11: =+'화성(서울)'!P11+'창원'!P11+'남양주'!P11+'인천'!P11+'화성오토'!P11+'제주'!P11+'부산'!P11 -> 0 | Q11: ='화성(서울)'!Q11+'창원'!Q11+'남양주'!Q11+'인천'!Q11+'화성오토'!Q11+'제주'!Q11+'부산'!Q11 -> 0 | R11: ='화성(서울)'!R11+'창원'!R11+'남양주'!R11+'인천'!R11+'화성오토'!R11+'제주'!R11+'부산'!R11 -> 0 | S11: ='화성(서울)'!S11+'창원'!S11+'남양주'!S11+'인천'!S11+'화성오토'!S11+'제주'!S11+'부산'!S11 -> 3345 | T11: ='화성(서울)'!T11+'창원'!T11+'남양주'!T11+'인천'!T11+'화성오토'!T11+'제주'!T11+'부산'!T11 -> 2000 | U11: ='화성(서울)'!U11+'창원'!U11+'남양주'!U11+'인천'!U11+'화성오토'!U11+'제주'!U11+'부산'!U11 -> 1752 | V11: ='화성(서울)'!V11+'창원'!V11+'남양주'!V11+'인천'!V11+'화성오토'!V11+'제주'!V11+'부산'!V11 -> 977 | W11: ='화성(서울)'!W11+'창원'!W11+'남양주'!W11+'인천'!W11+'화성오토'!W11+'제주'!W11+'부산'!W11 -> 128 | X11: ='화성(서울)'!X11+'창원'!X11+'남양주'!X11+'인천'!X11+'화성오토'!X11+'제주'!X11+'부산'!X11 -> 0 | ... AU11: ='화성(서울)'!AU11+'창원'!AU11+'남양주'!AU11+'인천'!AU11+'화성오토'!AU11+'제주'!AU11+'부산'!AU11 -> 0 | AV11: =+'화성(서울)'!AV11+'창원'!AV11+'남양주'!AV11+'인천'!AV11+'화성오토'!AV11+'제주'!AV11+'부산'!AV11 -> 8202
C12: Others | D12: =+'화성(서울)'!D12+'창원'!D12+'남양주'!D12+'인천'!D12+'화성오토'!D12+'제주'!D12+'부산'!D12 -> 303097 | E12: =+'화성(서울)'!E12+'창원'!E12+'남양주'!E12+'인천'!E12+'화성오토'!E12+'제주'!E12+'부산'!E12 -> 453852 | F12: =+'화성(서울)'!F12+'창원'!F12+'남양주'!F12+'인천'!F12+'화성오토'!F12+'제주'!F12+'부산'!F12 -> 407804 | G12: =+'화성(서울)'!G12+'창원'!G12+'남양주'!G12+'인천'!G12+'화성오토'!G12+'제주'!G12+'부산'!G12 -> 525256 | H12: =+'화성(서울)'!H12+'창원'!H12+'남양주'!H12+'인천'!H12+'화성오토'!H12+'제주'!H12+'부산'!H12 -> 394878 | I12: =+'화성(서울)'!I12+'창원'!I12+'남양주'!I12+'인천'!I12+'화성오토'!I12+'제주'!I12+'부산'!I12 -> 442131 | J12: =+'화성(서울)'!J12+'창원'!J12+'남양주'!J12+'인천'!J12+'화성오토'!J12+'제주'!J12+'부산'!J12 -> 451745 | K12: =+'화성(서울)'!K12+'창원'!K12+'남양주'!K12+'인천'!K12+'화성오토'!K12+'제주'!K12+'부산'!K12 -> 382124 | ... P12: =+'화성(서울)'!P12+'창원'!P12+'남양주'!P12+'인천'!P12+'화성오토'!P12+'제주'!P12+'부산'!P12 -> 0 | Q12: ='화성(서울)'!Q12+'창원'!Q12+'남양주'!Q12+'인천'!Q12+'화성오토'!Q12+'제주'!Q12+'부산'!Q12 -> 0 | R12: ='화성(서울)'!R12+'창원'!R12+'남양주'!R12+'인천'!R12+'화성오토'!R12+'제주'!R12+'부산'!R12 -> 0 | S12: ='화성(서울)'!S12+'창원'!S12+'남양주'!S12+'인천'!S12+'화성오토'!S12+'제주'!S12+'부산'!S12 -> 56792 | T12: ='화성(서울)'!T12+'창원'!T12+'남양주'!T12+'인천'!T12+'화성오토'!T12+'제주'!T12+'부산'!T12 -> 29424 | U12: ='화성(서울)'!U12+'창원'!U12+'남양주'!U12+'인천'!U12+'화성오토'!U12+'제주'!U12+'부산'!U12 -> 50542 | V12: ='화성(서울)'!V12+'창원'!V12+'남양주'!V12+'인천'!V12+'화성오토'!V12+'제주'!V12+'부산'!V12 -> 14500 | W12: ='화성(서울)'!W12+'창원'!W12+'남양주'!W12+'인천'!W12+'화성오토'!W12+'제주'!W12+'부산'!W12 -> 7087 | X12: ='화성(서울)'!X12+'창원'!X12+'남양주'!X12+'인천'!X12+'화성오토'!X12+'제주'!X12+'부산'!X12 -> 0 | ... AU12: ='화성(서울)'!AU12+'창원'!AU12+'남양주'!AU12+'인천'!AU12+'화성오토'!AU12+'제주'!AU12+'부산'!AU12 -> 0 | AV12: =+'화성(서울)'!AV12+'창원'!AV12+'남양주'!AV12+'인천'!AV12+'화성오토'!AV12+'제주'!AV12+'부산'!AV12 -> 165025
B13: MB | C13: Others | D13: =+'화성(서울)'!D13+'창원'!D13+'남양주'!D13+'인천'!D13+'화성오토'!D13+'제주'!D13+'부산'!D13 -> 217924 | E13: =+'화성(서울)'!E13+'창원'!E13+'남양주'!E13+'인천'!E13+'화성오토'!E13+'제주'!E13+'부산'!E13 -> 329228 | F13: =+'화성(서울)'!F13+'창원'!F13+'남양주'!F13+'인천'!F13+'화성오토'!F13+'제주'!F13+'부산'!F13 -> 159436 | G13: =+'화성(서울)'!G13+'창원'!G13+'남양주'!G13+'인천'!G13+'화성오토'!G13+'제주'!G13+'부산'!G13 -> 290116 | H13: =+'화성(서울)'!H13+'창원'!H13+'남양주'!H13+'인천'!H13+'화성오토'!H13+'제주'!H13+'부산'!H13 -> 280612 | I13: =+'화성(서울)'!I13+'창원'!I13+'남양주'!I13+'인천'!I13+'화성오토'!I13+'제주'!I13+'부산'!I13 -> 296008 | J13: =+'화성(서울)'!J13+'창원'!J13+'남양주'!J13+'인천'!J13+'화성오토'!J13+'제주'!J13+'부산'!J13 -> 177440 | K13: =+'화성(서울)'!K13+'창원'!K13+'남양주'!K13+'인천'!K13+'화성오토'!K13+'제주'!K13+'부산'!K13 -> 223840 | ... P13: =+'화성(서울)'!P13+'창원'!P13+'남양주'!P13+'인천'!P13+'화성오토'!P13+'제주'!P13+'부산'!P13 -> 0 | Q13: ='화성(서울)'!Q13+'창원'!Q13+'남양주'!Q13+'인천'!Q13+'화성오토'!Q13+'제주'!Q13+'부산'!Q13 -> 0 | R13: ='화성(서울)'!R13+'창원'!R13+'남양주'!R13+'인천'!R13+'화성오토'!R13+'제주'!R13+'부산'!R13 -> 0 | S13: ='화성(서울)'!S13+'창원'!S13+'남양주'!S13+'인천'!S13+'화성오토'!S13+'제주'!S13+'부산'!S13 -> 16432 | T13: ='화성(서울)'!T13+'창원'!T13+'남양주'!T13+'인천'!T13+'화성오토'!T13+'제주'!T13+'부산'!T13 -> 17472 | U13: ='화성(서울)'!U13+'창원'!U13+'남양주'!U13+'인천'!U13+'화성오토'!U13+'제주'!U13+'부산'!U13 -> 17680 | V13: ='화성(서울)'!V13+'창원'!V13+'남양주'!V13+'인천'!V13+'화성오토'!V13+'제주'!V13+'부산'!V13 -> 30072 | W13: ='화성(서울)'!W13+'창원'!W13+'남양주'!W13+'인천'!W13+'화성오토'!W13+'제주'!W13+'부산'!W13 -> 1608 | X13: ='화성(서울)'!X13+'창원'!X13+'남양주'!X13+'인천'!X13+'화성오토'!X13+'제주'!X13+'부산'!X13 -> 0 | ... AU13: ='화성(서울)'!AU13+'창원'!AU13+'남양주'!AU13+'인천'!AU13+'화성오토'!AU13+'제주'!AU13+'부산'!AU13 -> 0 | AV13: =+'화성(서울)'!AV13+'창원'!AV13+'남양주'!AV13+'인천'!AV13+'화성오토'!AV13+'제주'!AV13+'부산'!AV13 -> 89296 | AW13: =SUM(AV9:AV13) -> 445546
A14: 매출 | B14: Auto | C14: Flagship | D14: =+'화성(서울)'!D14+'창원'!D14+'남양주'!D14+'인천'!D14+'화성오토'!D14+'제주'!D14+'부산'!D14 -> 49258 | E14: =+'화성(서울)'!E14+'창원'!E14+'남양주'!E14+'인천'!E14+'화성오토'!E14+'제주'!E14+'부산'!E14 -> 47762 | F14: =+'화성(서울)'!F14+'창원'!F14+'남양주'!F14+'인천'!F14+'화성오토'!F14+'제주'!F14+'부산'!F14 -> 52231 | G14: =+'화성(서울)'!G14+'창원'!G14+'남양주'!G14+'인천'!G14+'화성오토'!G14+'제주'!G14+'부산'!G14 -> 54628 | H14: =+'화성(서울)'!H14+'창원'!H14+'남양주'!H14+'인천'!H14+'화성오토'!H14+'제주'!H14+'부산'!H14 -> 71820 | I14: =+'화성(서울)'!I14+'창원'!I14+'남양주'!I14+'인천'!I14+'화성오토'!I14+'제주'!I14+'부산'!I14 -> 83593 | J14: =+'화성(서울)'!J14+'창원'!J14+'남양주'!J14+'인천'!J14+'화성오토'!J14+'제주'!J14+'부산'!J14 -> 66804 | K14: =+'화성(서울)'!K14+'창원'!K14+'남양주'!K14+'인천'!K14+'화성오토'!K14+'제주'!K14+'부산'!K14 -> 68795 | ... P14: =+'화성(서울)'!P14+'창원'!P14+'남양주'!P14+'인천'!P14+'화성오토'!P14+'제주'!P14+'부산'!P14 -> 0 | Q14: ='화성(서울)'!Q14+'창원'!Q14+'남양주'!Q14+'인천'!Q14+'화성오토'!Q14+'제주'!Q14+'부산'!Q14 -> 0 | R14: ='화성(서울)'!R14+'창원'!R14+'남양주'!R14+'인천'!R14+'화성오토'!R14+'제주'!R14+'부산'!R14 -> 0 | S14: ='화성(서울)'!S14+'창원'!S14+'남양주'!S14+'인천'!S14+'화성오토'!S14+'제주'!S14+'부산'!S14 -> 6542 | T14: ='화성(서울)'!T14+'창원'!T14+'남양주'!T14+'인천'!T14+'화성오토'!T14+'제주'!T14+'부산'!T14 -> 1140 | U14: ='화성(서울)'!U14+'창원'!U14+'남양주'!U14+'인천'!U14+'화성오토'!U14+'제주'!U14+'부산'!U14 -> 12998 | V14: ='화성(서울)'!V14+'창원'!V14+'남양주'!V14+'인천'!V14+'화성오토'!V14+'제주'!V14+'부산'!V14 -> 4728 | W14: ='화성(서울)'!W14+'창원'!W14+'남양주'!W14+'인천'!W14+'화성오토'!W14+'제주'!W14+'부산'!W14 -> 3652 | X14: ='화성(서울)'!X14+'창원'!X14+'남양주'!X14+'인천'!X14+'화성오토'!X14+'제주'!X14+'부산'!X14 -> 0 | ... AU14: ='화성(서울)'!AU14+'창원'!AU14+'남양주'!AU14+'인천'!AU14+'화성오토'!AU14+'제주'!AU14+'부산'!AU14 -> 0 | AV14: =+'화성(서울)'!AV14+'창원'!AV14+'남양주'!AV14+'인천'!AV14+'화성오토'!AV14+'제주'!AV14+'부산'!AV14 -> 30087
C15: Others | D15: =+'화성(서울)'!D15+'창원'!D15+'남양주'!D15+'인천'!D15+'화성오토'!D15+'제주'!D15+'부산'!D15 -> 309350 | E15: =+'화성(서울)'!E15+'창원'!E15+'남양주'!E15+'인천'!E15+'화성오토'!E15+'제주'!E15+'부산'!E15 -> 405316 | F15: =+'화성(서울)'!F15+'창원'!F15+'남양주'!F15+'인천'!F15+'화성오토'!F15+'제주'!F15+'부산'!F15 -> 363618 | G15: =+'화성(서울)'!G15+'창원'!G15+'남양주'!G15+'인천'!G15+'화성오토'!G15+'제주'!G15+'부산'!G15 -> 411500 | H15: =+'화성(서울)'!H15+'창원'!H15+'남양주'!H15+'인천'!H15+'화성오토'!H15+'제주'!H15+'부산'!H15 -> 417488 | I15: =+'화성(서울)'!I15+'창원'!I15+'남양주'!I15+'인천'!I15+'화성오토'!I15+'제주'!I15+'부산'!I15 -> 475720 | J15: =+'화성(서울)'!J15+'창원'!J15+'남양주'!J15+'인천'!J15+'화성오토'!J15+'제주'!J15+'부산'!J15 -> 331084 | K15: =+'화성(서울)'!K15+'창원'!K15+'남양주'!K15+'인천'!K15+'화성오토'!K15+'제주'!K15+'부산'!K15 -> 351640 | ... P15: =+'화성(서울)'!P15+'창원'!P15+'남양주'!P15+'인천'!P15+'화성오토'!P15+'제주'!P15+'부산'!P15 -> 0 | Q15: ='화성(서울)'!Q15+'창원'!Q15+'남양주'!Q15+'인천'!Q15+'화성오토'!Q15+'제주'!Q15+'부산'!Q15 -> 0 | R15: ='화성(서울)'!R15+'창원'!R15+'남양주'!R15+'인천'!R15+'화성오토'!R15+'제주'!R15+'부산'!R15 -> 0 | S15: ='화성(서울)'!S15+'창원'!S15+'남양주'!S15+'인천'!S15+'화성오토'!S15+'제주'!S15+'부산'!S15 -> 90000 | T15: ='화성(서울)'!T15+'창원'!T15+'남양주'!T15+'인천'!T15+'화성오토'!T15+'제주'!T15+'부산'!T15 -> 40630 | U15: ='화성(서울)'!U15+'창원'!U15+'남양주'!U15+'인천'!U15+'화성오토'!U15+'제주'!U15+'부산'!U15 -> 15712 | V15: ='화성(서울)'!V15+'창원'!V15+'남양주'!V15+'인천'!V15+'화성오토'!V15+'제주'!V15+'부산'!V15 -> 19954 | W15: ='화성(서울)'!W15+'창원'!W15+'남양주'!W15+'인천'!W15+'화성오토'!W15+'제주'!W15+'부산'!W15 -> 8190 | X15: ='화성(서울)'!X15+'창원'!X15+'남양주'!X15+'인천'!X15+'화성오토'!X15+'제주'!X15+'부산'!X15 -> 0 | ... AU15: ='화성(서울)'!AU15+'창원'!AU15+'남양주'!AU15+'인천'!AU15+'화성오토'!AU15+'제주'!AU15+'부산'!AU15 -> 0 | AV15: =+'화성(서울)'!AV15+'창원'!AV15+'남양주'!AV15+'인천'!AV15+'화성오토'!AV15+'제주'!AV15+'부산'!AV15 -> 196180
B16: IL | C16: Flagship | D16: =+'화성(서울)'!D16+'창원'!D16+'남양주'!D16+'인천'!D16+'화성오토'!D16+'제주'!D16+'부산'!D16 -> 37221 | E16: =+'화성(서울)'!E16+'창원'!E16+'남양주'!E16+'인천'!E16+'화성오토'!E16+'제주'!E16+'부산'!E16 -> 35701 | F16: =+'화성(서울)'!F16+'창원'!F16+'남양주'!F16+'인천'!F16+'화성오토'!F16+'제주'!F16+'부산'!F16 -> 35769 | G16: =+'화성(서울)'!G16+'창원'!G16+'남양주'!G16+'인천'!G16+'화성오토'!G16+'제주'!G16+'부산'!G16 -> 36676 | H16: =+'화성(서울)'!H16+'창원'!H16+'남양주'!H16+'인천'!H16+'화성오토'!H16+'제주'!H16+'부산'!H16 -> 54043 | I16: =+'화성(서울)'!I16+'창원'!I16+'남양주'!I16+'인천'!I16+'화성오토'!I16+'제주'!I16+'부산'!I16 -> 35197 | J16: =+'화성(서울)'!J16+'창원'!J16+'남양주'!J16+'인천'!J16+'화성오토'!J16+'제주'!J16+'부산'!J16 -> 31244 | K16: =+'화성(서울)'!K16+'창원'!K16+'남양주'!K16+'인천'!K16+'화성오토'!K16+'제주'!K16+'부산'!K16 -> 31736 | ... P16: =+'화성(서울)'!P16+'창원'!P16+'남양주'!P16+'인천'!P16+'화성오토'!P16+'제주'!P16+'부산'!P16 -> 0 | Q16: ='화성(서울)'!Q16+'창원'!Q16+'남양주'!Q16+'인천'!Q16+'화성오토'!Q16+'제주'!Q16+'부산'!Q16 -> 0 | R16: ='화성(서울)'!R16+'창원'!R16+'남양주'!R16+'인천'!R16+'화성오토'!R16+'제주'!R16+'부산'!R16 -> 0 | S16: ='화성(서울)'!S16+'창원'!S16+'남양주'!S16+'인천'!S16+'화성오토'!S16+'제주'!S16+'부산'!S16 -> 10729 | T16: ='화성(서울)'!T16+'창원'!T16+'남양주'!T16+'인천'!T16+'화성오토'!T16+'제주'!T16+'부산'!T16 -> 1072 | U16: ='화성(서울)'!U16+'창원'!U16+'남양주'!U16+'인천'!U16+'화성오토'!U16+'제주'!U16+'부산'!U16 -> 2860 | V16: ='화성(서울)'!V16+'창원'!V16+'남양주'!V16+'인천'!V16+'화성오토'!V16+'제주'!V16+'부산'!V16 -> 807 | W16: ='화성(서울)'!W16+'창원'!W16+'남양주'!W16+'인천'!W16+'화성오토'!W16+'제주'!W16+'부산'!W16 -> 4968 | X16: ='화성(서울)'!X16+'창원'!X16+'남양주'!X16+'인천'!X16+'화성오토'!X16+'제주'!X16+'부산'!X16 -> 0 | ... AU16: ='화성(서울)'!AU16+'창원'!AU16+'남양주'!AU16+'인천'!AU16+'화성오토'!AU16+'제주'!AU16+'부산'!AU16 -> 0 | AV16: =+'화성(서울)'!AV16+'창원'!AV16+'남양주'!AV16+'인천'!AV16+'화성오토'!AV16+'제주'!AV16+'부산'!AV16 -> 24828
C17: Others | D17: =+'화성(서울)'!D17+'창원'!D17+'남양주'!D17+'인천'!D17+'화성오토'!D17+'제주'!D17+'부산'!D17 -> 371044 | E17: =+'화성(서울)'!E17+'창원'!E17+'남양주'!E17+'인천'!E17+'화성오토'!E17+'제주'!E17+'부산'!E17 -> 431009 | F17: =+'화성(서울)'!F17+'창원'!F17+'남양주'!F17+'인천'!F17+'화성오토'!F17+'제주'!F17+'부산'!F17 -> 421545 | G17: =+'화성(서울)'!G17+'창원'!G17+'남양주'!G17+'인천'!G17+'화성오토'!G17+'제주'!G17+'부산'!G17 -> 482381 | H17: =+'화성(서울)'!H17+'창원'!H17+'남양주'!H17+'인천'!H17+'화성오토'!H17+'제주'!H17+'부산'!H17 -> 421770 | I17: =+'화성(서울)'!I17+'창원'!I17+'남양주'!I17+'인천'!I17+'화성오토'!I17+'제주'!I17+'부산'!I17 -> 481524 | J17: =+'화성(서울)'!J17+'창원'!J17+'남양주'!J17+'인천'!J17+'화성오토'!J17+'제주'!J17+'부산'!J17 -> 400621 | K17: =+'화성(서울)'!K17+'창원'!K17+'남양주'!K17+'인천'!K17+'화성오토'!K17+'제주'!K17+'부산'!K17 -> 428715 | ... P17: =+'화성(서울)'!P17+'창원'!P17+'남양주'!P17+'인천'!P17+'화성오토'!P17+'제주'!P17+'부산'!P17 -> 0 | Q17: ='화성(서울)'!Q17+'창원'!Q17+'남양주'!Q17+'인천'!Q17+'화성오토'!Q17+'제주'!Q17+'부산'!Q17 -> 0 | R17: ='화성(서울)'!R17+'창원'!R17+'남양주'!R17+'인천'!R17+'화성오토'!R17+'제주'!R17+'부산'!R17 -> 0 | S17: ='화성(서울)'!S17+'창원'!S17+'남양주'!S17+'인천'!S17+'화성오토'!S17+'제주'!S17+'부산'!S17 -> 43133 | T17: ='화성(서울)'!T17+'창원'!T17+'남양주'!T17+'인천'!T17+'화성오토'!T17+'제주'!T17+'부산'!T17 -> 24279 | U17: ='화성(서울)'!U17+'창원'!U17+'남양주'!U17+'인천'!U17+'화성오토'!U17+'제주'!U17+'부산'!U17 -> 30236 | V17: ='화성(서울)'!V17+'창원'!V17+'남양주'!V17+'인천'!V17+'화성오토'!V17+'제주'!V17+'부산'!V17 -> 15802 | W17: ='화성(서울)'!W17+'창원'!W17+'남양주'!W17+'인천'!W17+'화성오토'!W17+'제주'!W17+'부산'!W17 -> 32352 | X17: ='화성(서울)'!X17+'창원'!X17+'남양주'!X17+'인천'!X17+'화성오토'!X17+'제주'!X17+'부산'!X17 -> 0 | ... AU17: ='화성(서울)'!AU17+'창원'!AU17+'남양주'!AU17+'인천'!AU17+'화성오토'!AU17+'제주'!AU17+'부산'!AU17 -> 0 | AV17: =+'화성(서울)'!AV17+'창원'!AV17+'남양주'!AV17+'인천'!AV17+'화성오토'!AV17+'제주'!AV17+'부산'!AV17 -> 162750
B18: MB | C18: Others | D18: =+'화성(서울)'!D18+'창원'!D18+'남양주'!D18+'인천'!D18+'화성오토'!D18+'제주'!D18+'부산'!D18 -> 281092 | E18: =+'화성(서울)'!E18+'창원'!E18+'남양주'!E18+'인천'!E18+'화성오토'!E18+'제주'!E18+'부산'!E18 -> 202096 | F18: =+'화성(서울)'!F18+'창원'!F18+'남양주'!F18+'인천'!F18+'화성오토'!F18+'제주'!F18+'부산'!F18 -> 229092 | G18: =+'화성(서울)'!G18+'창원'!G18+'남양주'!G18+'인천'!G18+'화성오토'!G18+'제주'!G18+'부산'!G18 -> 322612 | H18: =+'화성(서울)'!H18+'창원'!H18+'남양주'!H18+'인천'!H18+'화성오토'!H18+'제주'!H18+'부산'!H18 -> 212816 | I18: =+'화성(서울)'!I18+'창원'!I18+'남양주'!I18+'인천'!I18+'화성오토'!I18+'제주'!I18+'부산'!I18 -> 225800 | J18: =+'화성(서울)'!J18+'창원'!J18+'남양주'!J18+'인천'!J18+'화성오토'!J18+'제주'!J18+'부산'!J18 -> 305960 | K18: =+'화성(서울)'!K18+'창원'!K18+'남양주'!K18+'인천'!K18+'화성오토'!K18+'제주'!K18+'부산'!K18 -> 213836 | ... P18: =+'화성(서울)'!P18+'창원'!P18+'남양주'!P18+'인천'!P18+'화성오토'!P18+'제주'!P18+'부산'!P18 -> 0 | Q18: ='화성(서울)'!Q18+'창원'!Q18+'남양주'!Q18+'인천'!Q18+'화성오토'!Q18+'제주'!Q18+'부산'!Q18 -> 0 | R18: ='화성(서울)'!R18+'창원'!R18+'남양주'!R18+'인천'!R18+'화성오토'!R18+'제주'!R18+'부산'!R18 -> 0 | S18: ='화성(서울)'!S18+'창원'!S18+'남양주'!S18+'인천'!S18+'화성오토'!S18+'제주'!S18+'부산'!S18 -> 140096 | T18: ='화성(서울)'!T18+'창원'!T18+'남양주'!T18+'인천'!T18+'화성오토'!T18+'제주'!T18+'부산'!T18 -> 0 | U18: ='화성(서울)'!U18+'창원'!U18+'남양주'!U18+'인천'!U18+'화성오토'!U18+'제주'!U18+'부산'!U18 -> 0 | V18: ='화성(서울)'!V18+'창원'!V18+'남양주'!V18+'인천'!V18+'화성오토'!V18+'제주'!V18+'부산'!V18 -> 0 | W18: ='화성(서울)'!W18+'창원'!W18+'남양주'!W18+'인천'!W18+'화성오토'!W18+'제주'!W18+'부산'!W18 -> 0 | X18: ='화성(서울)'!X18+'창원'!X18+'남양주'!X18+'인천'!X18+'화성오토'!X18+'제주'!X18+'부산'!X18 -> 0 | ... AU18: ='화성(서울)'!AU18+'창원'!AU18+'남양주'!AU18+'인천'!AU18+'화성오토'!AU18+'제주'!AU18+'부산'!AU18 -> 0 | AV18: =+'화성(서울)'!AV18+'창원'!AV18+'남양주'!AV18+'인천'!AV18+'화성오토'!AV18+'제주'!AV18+'부산'!AV18 -> 193432 | AW18: =SUM(AV14:AV18) -> 607277
A19: 이동 | B19: Auto | C19: Flagship | D19: =+'화성(서울)'!D19+'창원'!D19+'남양주'!D19+'인천'!D19+'화성오토'!D19+'제주'!D19+'부산'!D19 -> -7426 | E19: =+'화성(서울)'!E19+'창원'!E19+'남양주'!E19+'인천'!E19+'화성오토'!E19+'제주'!E19+'부산'!E19 -> -6649 | F19: =+'화성(서울)'!F19+'창원'!F19+'남양주'!F19+'인천'!F19+'화성오토'!F19+'제주'!F19+'부산'!F19 -> 52 | G19: =+'화성(서울)'!G19+'창원'!G19+'남양주'!G19+'인천'!G19+'화성오토'!G19+'제주'!G19+'부산'!G19 -> -2265 | H19: =+'화성(서울)'!H19+'창원'!H19+'남양주'!H19+'인천'!H19+'화성오토'!H19+'제주'!H19+'부산'!H19 -> 60 | I19: -2969 | J19: =+'화성(서울)'!J19+'창원'!J19+'남양주'!J19+'인천'!J19+'화성오토'!J19+'제주'!J19+'부산'!J19 -> -6735 | K19: =+'화성(서울)'!K19+'창원'!K19+'남양주'!K19+'인천'!K19+'화성오토'!K19+'제주'!K19+'부산'!K19 -> 107 | L19: =+'화성(서울)'!L19+'창원'!L19+'남양주'!L19+'인천'!L19+'화성오토'!L19+'제주'!L19+'부산'!L19 -> 78 | M19: =+'화성(서울)'!M19+'창원'!M19+'남양주'!M19+'인천'!M19+'화성오토'!M19+'제주'!M19+'부산'!M19 -> -115 | N19: =+'화성(서울)'!N19+'창원'!N19+'남양주'!N19+'인천'!N19+'화성오토'!N19+'제주'!N19+'부산'!N19 -> 0 | O19: =+'화성(서울)'!O19+'창원'!O19+'남양주'!O19+'인천'!O19+'화성오토'!O19+'제주'!O19+'부산'!O19 -> 0 | P19: =+'화성(서울)'!P19+'창원'!P19+'남양주'!P19+'인천'!P19+'화성오토'!P19+'제주'!P19+'부산'!P19 -> 0 | Q19: 0 | R19: 0 | S19: 5 | T19: 0 | U19: 1 | V19: 0 | W19: 0 | X19: 0 | Y19: 0 | Z19: 38 | AA19: 0 | AB19: 0 | AC19: 0 | AD19: 0 | AE19: 0 | AF19: 0 | AG19: 0 | AH19: 0 | AI19: 0 | AJ19: 0 | AK19: 0 | AL19: 0 | AM19: 0 | AN19: 0 | AO19: 0 | AP19: 0 | AQ19: 0 | AR19: 0 | AS19: 0 | AT19: 0 | AU19: 0 | AV19: =SUM(Q19:AU19) -> 44
C20: Others | D20: =+'화성(서울)'!D20+'창원'!D20+'남양주'!D20+'인천'!D20+'화성오토'!D20+'제주'!D20+'부산'!D20 -> 598 | E20: =+'화성(서울)'!E20+'창원'!E20+'남양주'!E20+'인천'!E20+'화성오토'!E20+'제주'!E20+'부산'!E20 -> -904 | F20: =+'화성(서울)'!F20+'창원'!F20+'남양주'!F20+'인천'!F20+'화성오토'!F20+'제주'!F20+'부산'!F20 -> 514 | G20: =+'화성(서울)'!G20+'창원'!G20+'남양주'!G20+'인천'!G20+'화성오토'!G20+'제주'!G20+'부산'!G20 -> -3131 | H20: =+'화성(서울)'!H20+'창원'!H20+'남양주'!H20+'인천'!H20+'화성오토'!H20+'제주'!H20+'부산'!H20 -> -3420 | I20: -8077 | J20: =+'화성(서울)'!J20+'창원'!J20+'남양주'!J20+'인천'!J20+'화성오토'!J20+'제주'!J20+'부산'!J20 -> 366 | K20: =+'화성(서울)'!K20+'창원'!K20+'남양주'!K20+'인천'!K20+'화성오토'!K20+'제주'!K20+'부산'!K20 -> 1454 | L20: =+'화성(서울)'!L20+'창원'!L20+'남양주'!L20+'인천'!L20+'화성오토'!L20+'제주'!L20+'부산'!L20 -> 416 | M20: =+'화성(서울)'!M20+'창원'!M20+'남양주'!M20+'인천'!M20+'화성오토'!M20+'제주'!M20+'부산'!M20 -> -2006 | N20: =+'화성(서울)'!N20+'창원'!N20+'남양주'!N20+'인천'!N20+'화성오토'!N20+'제주'!N20+'부산'!N20 -> 0 | O20: =+'화성(서울)'!O20+'창원'!O20+'남양주'!O20+'인천'!O20+'화성오토'!O20+'제주'!O20+'부산'!O20 -> 0 | P20: =+'화성(서울)'!P20+'창원'!P20+'남양주'!P20+'인천'!P20+'화성오토'!P20+'제주'!P20+'부산'!P20 -> 0 | Q20: 0 | R20: 0 | S20: 0 | T20: 152 | U20: 0 | V20: 0 | W20: 0 | X20: 0 | Y20: 0 | Z20: 40 | AA20: 0 | AB20: 0 | AC20: 0 | AD20: 0 | AE20: 0 | AF20: 0 | AG20: 0 | AH20: 0 | AI20: 0 | AJ20: 0 | AK20: 0 | AL20: 0 | AM20: 0 | AN20: 0 | AO20: 0 | AP20: 0 | AQ20: 0 | AR20: 0 | AS20: 0 | AT20: 0 | AU20: 0 | AV20: =SUM(Q20:AU20) -> 192
B21: IL | C21: Flagship | D21: =+'화성(서울)'!D21+'창원'!D21+'남양주'!D21+'인천'!D21+'화성오토'!D21+'제주'!D21+'부산'!D21 -> -2925 | E21: =+'화성(서울)'!E21+'창원'!E21+'남양주'!E21+'인천'!E21+'화성오토'!E21+'제주'!E21+'부산'!E21 -> -4267 | F21: =+'화성(서울)'!F21+'창원'!F21+'남양주'!F21+'인천'!F21+'화성오토'!F21+'제주'!F21+'부산'!F21 -> -2615 | G21: =+'화성(서울)'!G21+'창원'!G21+'남양주'!G21+'인천'!G21+'화성오토'!G21+'제주'!G21+'부산'!G21 -> -778 | H21: =+'화성(서울)'!H21+'창원'!H21+'남양주'!H21+'인천'!H21+'화성오토'!H21+'제주'!H21+'부산'!H21 -> -96 | I21: -14 | J21: =+'화성(서울)'!J21+'창원'!J21+'남양주'!J21+'인천'!J21+'화성오토'!J21+'제주'!J21+'부산'!J21 -> -412 | K21: =+'화성(서울)'!K21+'창원'!K21+'남양주'!K21+'인천'!K21+'화성오토'!K21+'제주'!K21+'부산'!K21 -> 32 | L21: =+'화성(서울)'!L21+'창원'!L21+'남양주'!L21+'인천'!L21+'화성오토'!L21+'제주'!L21+'부산'!L21 -> -5286 | M21: =+'화성(서울)'!M21+'창원'!M21+'남양주'!M21+'인천'!M21+'화성오토'!M21+'제주'!M21+'부산'!M21 -> -3225 | N21: =+'화성(서울)'!N21+'창원'!N21+'남양주'!N21+'인천'!N21+'화성오토'!N21+'제주'!N21+'부산'!N21 -> 0 | O21: =+'화성(서울)'!O21+'창원'!O21+'남양주'!O21+'인천'!O21+'화성오토'!O21+'제주'!O21+'부산'!O21 -> 0 | P21: =+'화성(서울)'!P21+'창원'!P21+'남양주'!P21+'인천'!P21+'화성오토'!P21+'제주'!P21+'부산'!P21 -> 0 | Q21: 0 | R21: 0 | S21: 0 | T21: 0 | U21: 0 | V21: 0 | W21: 0 | X21: 0 | Y21: 0 | Z21: 0 | AA21: 0 | AB21: 0 | AC21: 0 | AD21: 0 | AE21: 0 | AF21: 0 | AG21: 0 | AH21: 0 | AI21: 0 | AJ21: 0 | AK21: 0 | AL21: 0 | AM21: 0 | AN21: 0 | AO21: 0 | AP21: 0 | AQ21: 0 | AR21: 0 | AS21: 0 | AT21: 0 | AU21: 0 | AV21: =SUM(Q21:AU21) -> 0
C22: Others | D22: =+'화성(서울)'!D22+'창원'!D22+'남양주'!D22+'인천'!D22+'화성오토'!D22+'제주'!D22+'부산'!D22 -> -5592 | E22: =+'화성(서울)'!E22+'창원'!E22+'남양주'!E22+'인천'!E22+'화성오토'!E22+'제주'!E22+'부산'!E22 -> -6016 | F22: =+'화성(서울)'!F22+'창원'!F22+'남양주'!F22+'인천'!F22+'화성오토'!F22+'제주'!F22+'부산'!F22 -> -3800 | G22: =+'화성(서울)'!G22+'창원'!G22+'남양주'!G22+'인천'!G22+'화성오토'!G22+'제주'!G22+'부산'!G22 -> -16365 | H22: =+'화성(서울)'!H22+'창원'!H22+'남양주'!H22+'인천'!H22+'화성오토'!H22+'제주'!H22+'부산'!H22 -> -381 | I22: -9306 | J22: =+'화성(서울)'!J22+'창원'!J22+'남양주'!J22+'인천'!J22+'화성오토'!J22+'제주'!J22+'부산'!J22 -> -8422 | K22: =+'화성(서울)'!K22+'창원'!K22+'남양주'!K22+'인천'!K22+'화성오토'!K22+'제주'!K22+'부산'!K22 -> -101 | L22: =+'화성(서울)'!L22+'창원'!L22+'남양주'!L22+'인천'!L22+'화성오토'!L22+'제주'!L22+'부산'!L22 -> -4004 | M22: =+'화성(서울)'!M22+'창원'!M22+'남양주'!M22+'인천'!M22+'화성오토'!M22+'제주'!M22+'부산'!M22 -> -9307 | N22: =+'화성(서울)'!N22+'창원'!N22+'남양주'!N22+'인천'!N22+'화성오토'!N22+'제주'!N22+'부산'!N22 -> 0 | O22: =+'화성(서울)'!O22+'창원'!O22+'남양주'!O22+'인천'!O22+'화성오토'!O22+'제주'!O22+'부산'!O22 -> 0 | P22: =+'화성(서울)'!P22+'창원'!P22+'남양주'!P22+'인천'!P22+'화성오토'!P22+'제주'!P22+'부산'!P22 -> 0 | Q22: 0 | R22: 0 | S22: 1 | T22: 0 | U22: 22080 | V22: -22080 | W22: 0 | X22: 0 | Y22: 0 | Z22: 0 | AA22: 0 | AB22: 0 | AC22: 0 | AD22: 0 | AE22: 0 | AF22: 0 | AG22: 0 | AH22: 0 | AI22: 0 | AJ22: 0 | AK22: 0 | AL22: 0 | AM22: 0 | AN22: 0 | AO22: 0 | AP22: 0 | AQ22: 0 | AR22: 0 | AS22: 0 | AT22: 0 | AU22: 0 | AV22: =SUM(Q22:AU22) -> 1
B23: MB | C23: Others | D23: =+'화성(서울)'!D23+'창원'!D23+'남양주'!D23+'인천'!D23+'화성오토'!D23+'제주'!D23+'부산'!D23 -> 0 | E23: =+'화성(서울)'!E23+'창원'!E23+'남양주'!E23+'인천'!E23+'화성오토'!E23+'제주'!E23+'부산'!E23 -> 0 | F23: =+'화성(서울)'!F23+'창원'!F23+'남양주'!F23+'인천'!F23+'화성오토'!F23+'제주'!F23+'부산'!F23 -> 0 | G23: =+'화성(서울)'!G23+'창원'!G23+'남양주'!G23+'인천'!G23+'화성오토'!G23+'제주'!G23+'부산'!G23 -> 0 | H23: =+'화성(서울)'!H23+'창원'!H23+'남양주'!H23+'인천'!H23+'화성오토'!H23+'제주'!H23+'부산'!H23 -> 12 | I23: 12 | J23: =+'화성(서울)'!J23+'창원'!J23+'남양주'!J23+'인천'!J23+'화성오토'!J23+'제주'!J23+'부산'!J23 -> 0 | K23: =+'화성(서울)'!K23+'창원'!K23+'남양주'!K23+'인천'!K23+'화성오토'!K23+'제주'!K23+'부산'!K23 -> -796 | L23: =+'화성(서울)'!L23+'창원'!L23+'남양주'!L23+'인천'!L23+'화성오토'!L23+'제주'!L23+'부산'!L23 -> 0 | M23: =+'화성(서울)'!M23+'창원'!M23+'남양주'!M23+'인천'!M23+'화성오토'!M23+'제주'!M23+'부산'!M23 -> 0 | N23: =+'화성(서울)'!N23+'창원'!N23+'남양주'!N23+'인천'!N23+'화성오토'!N23+'제주'!N23+'부산'!N23 -> 0 | O23: =+'화성(서울)'!O23+'창원'!O23+'남양주'!O23+'인천'!O23+'화성오토'!O23+'제주'!O23+'부산'!O23 -> 0 | P23: =+'화성(서울)'!P23+'창원'!P23+'남양주'!P23+'인천'!P23+'화성오토'!P23+'제주'!P23+'부산'!P23 -> 0 | Q23: 0 | R23: 0 | S23: 0 | T23: 0 | U23: 0 | V23: 0 | W23: 0 | X23: 0 | Y23: 0 | Z23: 0 | AA23: 0 | AB23: 0 | AC23: 0 | AD23: 0 | AE23: 0 | AF23: 0 | AG23: 0 | AH23: 0 | AI23: 0 | AJ23: 0 | AK23: 0 | AL23: 0 | AM23: 0 | AN23: 0 | AO23: 0 | AP23: 0 | AQ23: 0 | AR23: 0 | AS23: 0 | AT23: 0 | AU23: 0 | AV23: =SUM(Q23:AU23) -> 0
A24: 재고 | B24: Auto | C24: Flagship | D24: =+'화성(서울)'!D24+'창원'!D24+'남양주'!D24+'인천'!D24+'화성오토'!D24+'제주'!D24+'부산'!D24 -> 30012 | E24: =+'화성(서울)'!E24+'창원'!E24+'남양주'!E24+'인천'!E24+'화성오토'!E24+'제주'!E24+'부산'!E24 -> 34542 | F24: =+'화성(서울)'!F24+'창원'!F24+'남양주'!F24+'인천'!F24+'화성오토'!F24+'제주'!F24+'부산'!F24 -> 38938 | G24: =+'화성(서울)'!G24+'창원'!G24+'남양주'!G24+'인천'!G24+'화성오토'!G24+'제주'!G24+'부산'!G24 -> 49365 | H24: =+'화성(서울)'!H24+'창원'!H24+'남양주'!H24+'인천'!H24+'화성오토'!H24+'제주'!H24+'부산'!H24 -> 38532 | I24: =+'화성(서울)'!I24+'창원'!I24+'남양주'!I24+'인천'!I24+'화성오토'!I24+'제주'!I24+'부산'!I24 -> 47460 | J24: =+'화성(서울)'!J24+'창원'!J24+'남양주'!J24+'인천'!J24+'화성오토'!J24+'제주'!J24+'부산'!J24 -> 46308 | K24: =+'화성(서울)'!K24+'창원'!K24+'남양주'!K24+'인천'!K24+'화성오토'!K24+'제주'!K24+'부산'!K24 -> 43216 | ... O24: =+'화성(서울)'!O24+'창원'!O24+'남양주'!O24+'인천'!O24+'화성오토'!O24+'제주'!O24+'부산'!O24 -> 38518 | P24: =P4 -> 38518 | Q24: =+Q4+Q9-Q14-Q19 -> 38518 | R24: =+R4+R9-R14-R19 -> 38518 | S24: =+S4+S9-S14-S19 -> 39573 | T24: =+T4+T9-T14-T19 -> 40873 | U24: =+U4+U9-U14-U19 -> 29530 | V24: =+V4+V9-V14-V19 -> 31062 | W24: =+W4+W9-W14-W19 -> 29598 | X24: =+X4+X9-X14-X19 -> 29598 | ... AV24: =+AV4+AV9-AV14-AV19 -> 30532
C25: Others | D25: =+'화성(서울)'!D25+'창원'!D25+'남양주'!D25+'인천'!D25+'화성오토'!D25+'제주'!D25+'부산'!D25 -> 110939 | E25: =+'화성(서울)'!E25+'창원'!E25+'남양주'!E25+'인천'!E25+'화성오토'!E25+'제주'!E25+'부산'!E25 -> 126181 | F25: =+'화성(서울)'!F25+'창원'!F25+'남양주'!F25+'인천'!F25+'화성오토'!F25+'제주'!F25+'부산'!F25 -> 152945 | G25: =+'화성(서울)'!G25+'창원'!G25+'남양주'!G25+'인천'!G25+'화성오토'!G25+'제주'!G25+'부산'!G25 -> 128508 | H25: =+'화성(서울)'!H25+'창원'!H25+'남양주'!H25+'인천'!H25+'화성오토'!H25+'제주'!H25+'부산'!H25 -> 121928 | I25: =+'화성(서울)'!I25+'창원'!I25+'남양주'!I25+'인천'!I25+'화성오토'!I25+'제주'!I25+'부산'!I25 -> 111129 | J25: =+'화성(서울)'!J25+'창원'!J25+'남양주'!J25+'인천'!J25+'화성오토'!J25+'제주'!J25+'부산'!J25 -> 133751 | K25: =+'화성(서울)'!K25+'창원'!K25+'남양주'!K25+'인천'!K25+'화성오토'!K25+'제주'!K25+'부산'!K25 -> 133359 | ... O25: =+'화성(서울)'!O25+'창원'!O25+'남양주'!O25+'인천'!O25+'화성오토'!O25+'제주'!O25+'부산'!O25 -> 104881 | P25: =P5 -> 104881 | Q25: =+Q5+Q10-Q15-Q20 -> 104881 | R25: =+R5+R10-R15-R20 -> 104881 | S25: =+S5+S10-S15-S20 -> 58841 | T25: =+T5+T10-T15-T20 -> 53751 | U25: =+U5+U10-U15-U20 -> 56617 | V25: =+V5+V10-V15-V20 -> 61885 | W25: =+W5+W10-W15-W20 -> 72195 | X25: =+X5+X10-X15-X20 -> 72195 | ... AV25: =+AV5+AV10-AV15-AV20 -> 69387
B26: IL | C26: Flagship | D26: =+'화성(서울)'!D26+'창원'!D26+'남양주'!D26+'인천'!D26+'화성오토'!D26+'제주'!D26+'부산'!D26 -> 31357 | E26: =+'화성(서울)'!E26+'창원'!E26+'남양주'!E26+'인천'!E26+'화성오토'!E26+'제주'!E26+'부산'!E26 -> 37836 | F26: =+'화성(서울)'!F26+'창원'!F26+'남양주'!F26+'인천'!F26+'화성오토'!F26+'제주'!F26+'부산'!F26 -> 40837 | G26: =+'화성(서울)'!G26+'창원'!G26+'남양주'!G26+'인천'!G26+'화성오토'!G26+'제주'!G26+'부산'!G26 -> 33581 | H26: =+'화성(서울)'!H26+'창원'!H26+'남양주'!H26+'인천'!H26+'화성오토'!H26+'제주'!H26+'부산'!H26 -> 30370 | I26: =+'화성(서울)'!I26+'창원'!I26+'남양주'!I26+'인천'!I26+'화성오토'!I26+'제주'!I26+'부산'!I26 -> 33725 | J26: =+'화성(서울)'!J26+'창원'!J26+'남양주'!J26+'인천'!J26+'화성오토'!J26+'제주'!J26+'부산'!J26 -> 30783 | K26: =+'화성(서울)'!K26+'창원'!K26+'남양주'!K26+'인천'!K26+'화성오토'!K26+'제주'!K26+'부산'!K26 -> 35126 | ... O26: =+'화성(서울)'!O26+'창원'!O26+'남양주'!O26+'인천'!O26+'화성오토'!O26+'제주'!O26+'부산'!O26 -> 41731 | P26: =P6 -> 41731 | Q26: =+Q6+Q11-Q16-Q21 -> 41731 | R26: =+R6+R11-R16-R21 -> 41731 | S26: =+S6+S11-S16-S21 -> 34347 | T26: =+T6+T11-T16-T21 -> 35275 | U26: =+U6+U11-U16-U21 -> 34167 | V26: =+V6+V11-V16-V21 -> 34337 | W26: =+W6+W11-W16-W21 -> 29497 | X26: =+X6+X11-X16-X21 -> 29497 | ... AV26: =+AV6+AV11-AV16-AV21 -> 25105
C27: Others | D27: =+'화성(서울)'!D27+'창원'!D27+'남양주'!D27+'인천'!D27+'화성오토'!D27+'제주'!D27+'부산'!D27 -> 262065 | E27: =+'화성(서울)'!E27+'창원'!E27+'남양주'!E27+'인천'!E27+'화성오토'!E27+'제주'!E27+'부산'!E27 -> 290924 | F27: =+'화성(서울)'!F27+'창원'!F27+'남양주'!F27+'인천'!F27+'화성오토'!F27+'제주'!F27+'부산'!F27 -> 280983 | G27: =+'화성(서울)'!G27+'창원'!G27+'남양주'!G27+'인천'!G27+'화성오토'!G27+'제주'!G27+'부산'!G27 -> 340223 | H27: =+'화성(서울)'!H27+'창원'!H27+'남양주'!H27+'인천'!H27+'화성오토'!H27+'제주'!H27+'부산'!H27 -> 313712 | I27: =+'화성(서울)'!I27+'창원'!I27+'남양주'!I27+'인천'!I27+'화성오토'!I27+'제주'!I27+'부산'!I27 -> 283625 | J27: =+'화성(서울)'!J27+'창원'!J27+'남양주'!J27+'인천'!J27+'화성오토'!J27+'제주'!J27+'부산'!J27 -> 343171 | K27: =+'화성(서울)'!K27+'창원'!K27+'남양주'!K27+'인천'!K27+'화성오토'!K27+'제주'!K27+'부산'!K27 -> 296681 | ... O27: =+'화성(서울)'!O27+'창원'!O27+'남양주'!O27+'인천'!O27+'화성오토'!O27+'제주'!O27+'부산'!O27 -> 281180 | P27: =P7 -> 281180 | Q27: =+Q7+Q12-Q17-Q22 -> 281180 | R27: =+R7+R12-R17-R22 -> 281180 | S27: =+S7+S12-S17-S22 -> 294838 | T27: =+T7+T12-T17-T22 -> 299983 | U27: =+U7+U12-U17-U22 -> 298209 | V27: =+V7+V12-V17-V22 -> 318987 | W27: =+W7+W12-W17-W22 -> 293722 | X27: =+X7+X12-X17-X22 -> 293722 | ... AV27: =+AV7+AV12-AV17-AV22 -> 283454
B28: MB | C28: Others | D28: =+'화성(서울)'!D28+'창원'!D28+'남양주'!D28+'인천'!D28+'화성오토'!D28+'제주'!D28+'부산'!D28 -> 106928 | E28: =+'화성(서울)'!E28+'창원'!E28+'남양주'!E28+'인천'!E28+'화성오토'!E28+'제주'!E28+'부산'!E28 -> 234060 | F28: =+'화성(서울)'!F28+'창원'!F28+'남양주'!F28+'인천'!F28+'화성오토'!F28+'제주'!F28+'부산'!F28 -> 164404 | G28: =+'화성(서울)'!G28+'창원'!G28+'남양주'!G28+'인천'!G28+'화성오토'!G28+'제주'!G28+'부산'!G28 -> 131908 | H28: =+'화성(서울)'!H28+'창원'!H28+'남양주'!H28+'인천'!H28+'화성오토'!H28+'제주'!H28+'부산'!H28 -> 199692 | I28: =+'화성(서울)'!I28+'창원'!I28+'남양주'!I28+'인천'!I28+'화성오토'!I28+'제주'!I28+'부산'!I28 -> 269888 | J28: =+'화성(서울)'!J28+'창원'!J28+'남양주'!J28+'인천'!J28+'화성오토'!J28+'제주'!J28+'부산'!J28 -> 141368 | K28: =+'화성(서울)'!K28+'창원'!K28+'남양주'!K28+'인천'!K28+'화성오토'!K28+'제주'!K28+'부산'!K28 -> 152168 | ... O28: =+'화성(서울)'!O28+'창원'!O28+'남양주'!O28+'인천'!O28+'화성오토'!O28+'제주'!O28+'부산'!O28 -> 163884 | P28: =P8 -> 163884 | Q28: =+Q8+Q13-Q18-Q23 -> 163884 | R28: =+R8+R13-R18-R23 -> 163884 | S28: =+S8+S13-S18-S23 -> 40220 | T28: =+T8+T13-T18-T23 -> 57692 | U28: =+U8+U13-U18-U23 -> 75372 | V28: =+V8+V13-V18-V23 -> 105444 | W28: =+W8+W13-W18-W23 -> 107052 | X28: =+X8+X13-X18-X23 -> 107052 | ... AV28: =+AV8+AV13-AV18-AV23 -> 59748
D29: =SUM(D24:D28) -> 541301 | E29: =SUM(E24:E28) -> 723543 | F29: =SUM(F24:F28) -> 678107 | G29: =SUM(G24:G28) -> 683585 | H29: =SUM(H24:H28) -> 704234 | I29: =SUM(I24:I28) -> 745827 | J29: =SUM(J24:J28) -> 695381 | K29: =SUM(K24:K28) -> 660550 | ... O29: =SUM(O24:O28) -> 630194 | Q29: =SUM(Q24:Q28) -> 630194 | R29: =SUM(R24:R28) -> 630194 | S29: =SUM(S24:S28) -> 467819 | T29: =SUM(T24:T28) -> 487574 | U29: =SUM(U24:U28) -> 493895 | V29: =SUM(V24:V28) -> 551715 | W29: =SUM(W24:W28) -> 532064 | X29: =SUM(X24:X28) -> 532064 | ... AV29: =SUM(AV24:AV28) -> 468226
A31: 재고 D/M계 | B31: Auto | C31: Flagship | D31: =ROUND(D24/200,0) -> 150 | E31: =ROUND(E24/200,0) -> 173 | F31: =ROUND(F24/200,0) -> 195 | G31: =ROUND(G24/200,0) -> 247 | H31: =ROUND(H24/200,0) -> 193 | I31: =ROUND(I24/200,0) -> 237 | J31: =ROUND(J24/200,0) -> 232 | K31: =ROUND(K24/200,0) -> 216 | ... AV31: =ROUND(AV24/200,0) -> 153
C32: Others | D32: =ROUND(D25/200,0) -> 555 | E32: =ROUND(E25/200,0) -> 631 | F32: =ROUND(F25/200,0) -> 765 | G32: =ROUND(G25/200,0) -> 643 | H32: =ROUND(H25/200,0) -> 610 | I32: =ROUND(I25/200,0) -> 556 | J32: =ROUND(J25/200,0) -> 669 | K32: =ROUND(K25/200,0) -> 667 | ... AV32: =ROUND(AV25/200,0) -> 347
B33: IL | C33: Flagship | D33: =ROUND(D26/200,0) -> 157 | E33: =ROUND(E26/200,0) -> 189 | F33: =ROUND(F26/200,0) -> 204 | G33: =ROUND(G26/200,0) -> 168 | H33: =ROUND(H26/200,0) -> 152 | I33: =ROUND(I26/200,0) -> 169 | J33: =ROUND(J26/200,0) -> 154 | K33: =ROUND(K26/200,0) -> 176 | ... AV33: =ROUND(AV26/200,0) -> 126
C34: Others | D34: =ROUND(D27/200,0) -> 1310 | E34: =ROUND(E27/200,0) -> 1455 | F34: =ROUND(F27/200,0) -> 1405 | G34: =ROUND(G27/200,0) -> 1701 | H34: =ROUND(H27/200,0) -> 1569 | I34: =ROUND(I27/200,0) -> 1418 | J34: =ROUND(J27/200,0) -> 1716 | K34: =ROUND(K27/200,0) -> 1483 | ... AV34: =ROUND(AV27/200,0) -> 1417
B35: MB | C35: Others | D35: =ROUND(D28/200,0) -> 535 | E35: =ROUND(E28/200,0) -> 1170 | F35: =ROUND(F28/200,0) -> 822 | G35: =ROUND(G28/200,0) -> 660 | H35: =ROUND(H28/200,0) -> 998 | I35: =ROUND(I28/200,0) -> 1349 | J35: =ROUND(J28/200,0) -> 707 | K35: =ROUND(K28/200,0) -> 761 | ... AV35: =ROUND(AV28/200,0) -> 299
A37: 총재고 | D37: =D29+D44+D50 -> 693867 | E37: =E29+E44+E50 -> 899720 | F37: =F29+F44+F50 -> 858401 | G37: =G29+G44+G50 -> 857497 | H37: =H29+H44+H50 -> 879464 | I37: =I29+I44+I50 -> 985558 | J37: =J29+J44+J50 -> 906436 | K37: =K29+K44+K50 -> 855855 | ... AV37: =AV29+AV44+AV50 -> 640304 | AW37: 영일+동부+서부
A39: 동부재고 | B39: Auto | C39: Flagship | D39: 7942 | E39: 8082 | F39: 7952 | G39: 6727 | H39: 8729 | I39: 11680 | J39: 6568 | K39: 6897 | L39: 9251 | M39: 7783 | O39: 5466 | Q39: 7783 | R39: 7783 | S39: 5431 | T39: 6779 | U39: 6599 | V39: 6143 | W39: 6803 | X39: 6803 | Y39: 6803 | Z39: 6707 | AV39: 6707
C40: Others | D40: 47008 | E40: 57254 | F40: 52510 | G40: 48977 | H40: 54496 | I40: 58364 | J40: 48134 | K40: 47160 | L40: 71627 | M40: 53466 | O40: 47395 | Q40: 53466 | R40: 53466 | S40: 43788 | T40: 47350 | U40: 47738 | V40: 44392 | W40: 46712 | X40: 46712 | Y40: 46712 | Z40: 42328 | AV40: 42328
B41: IL | C41: Flagship | D41: 0 | E41: 0 | F41: 139 | G41: 139 | H41: 139 | I41: 139 | J41: 0 | K41: 0 | L41: 0 | M41: 0 | O41: 0 | Q41: 0 | R41: 0 | S41: 0 | T41: 0 | U41: 0 | V41: 0 | W41: 0 | X41: 0 | Y41: 0 | Z41: 0 | AV41: 0
C42: Others | D42: 1435 | E42: 1547 | F42: 2135 | G42: 1356 | H42: 1308 | I42: 1024 | J42: 1172 | K42: 216 | L42: 168 | M42: 668 | O42: 627 | Q42: 668 | R42: 668 | S42: 600 | T42: 600 | U42: 600 | V42: 600 | W42: 600 | X42: 600 | Y42: 600 | Z42: 600 | AV42: 600
B43: MB | C43: Others | D43: 0 | E43: 0 | F43: 0 | G43: 0 | H43: 0 | I43: 0 | J43: 0 | K43: 0 | L43: 0 | M43: 0 | O43: 0 | Q43: 0 | R43: 0 | S43: 0 | T43: 0 | U43: 0 | V43: 0 | W43: 0 | X43: 0 | Y43: 0 | Z43: 0 | AV43: 0
D44: =SUM(D39:D43) -> 56385 | E44: =SUM(E39:E43) -> 66883 | F44: =SUM(F39:F43) -> 62736 | G44: =SUM(G39:G43) -> 57199 | H44: =SUM(H39:H43) -> 64672 | I44: =SUM(I39:I43) -> 71207 | J44: =SUM(J39:J43) -> 55874 | K44: =SUM(K39:K43) -> 54273 | ... AV44: =SUM(AV39:AV43) -> 49635
...

Sheet 화성(서울)
A2: ▣ 화성
A3: 단위 : Liter | D3: 45322 | E3: 44620 | F3: 44651 | G3: 44681 | H3: 44712 | I3: 44742 | J3: 44773 | K3: 44804 | L3: 44834 | M3: 44865 | N3: 44895 | O3: 44926 | P3: 변동재고 | Q3: 45962 | R3: 45963 | S3: 45964 | T3: 45965 | U3: 45966 | V3: 45967 | W3: 45968 | X3: 45969 | Y3: 45970 | Z3: 45971 | AA3: 45972 | AB3: 45973 | AC3: 45974 | AD3: 45975 | AE3: 45976 | AF3: 45977 | AG3: 45978 | AH3: 45979 | AI3: 45980 | AJ3: 45981 | AK3: 45982 | AL3: 45983 | AM3: 45984 | AN3: 45985 | AO3: 45986 | AP3: 45987 | AQ3: 45988 | AR3: 45989 | AS3: 45990 | AT3: 45991 | AU3: 45992 | AV3: 합계
A4: 기초재고 | B4: Auto | C4: Flagship | D4: 10119 | E4: =D24 -> 9008 | F4: =E24 -> 8440 | G4: =F24 -> 14400 | H4: =G24 -> 19564 | I4: =H24 -> 13960 | J4: =I24 -> 16164 | K4: =J24 -> 17523 | L4: =K24 -> 16736 | ... O4: =N24 -> 11324 | P4: 11324 | Q4: =+P24 -> 11324 | R4: =+Q24 -> 11324 | S4: =+R24 -> 11324 | T4: =+S24 -> 8438 | U4: =+T24 -> 7322 | V4: =+U24 -> -592 | W4: =+V24 -> -4152 | X4: =+W24 -> -5744 | ... AU4: =+AT24 -> -5804 | AV4: =P24 -> 11324
C5: Others | D5: 14321 | E5: =D25 -> 12889 | F5: =E25 -> 12979 | G5: =F25 -> 24115 | H5: =G25 -> 19523 | I5: =H25 -> 15255 | J5: =I25 -> 8155 | K5: =J25 -> 7575 | L5: =K25 -> 8599 | ... O5: =N25 -> 4639 | P5: 4639 | Q5: =+P25 -> 4639 | R5: =+Q25 -> 4639 | S5: =+R25 -> 4639 | T5: =+S25 -> 19999 | U5: =+T25 -> 20799 | V5: =+U25 -> 20331 | W5: =+V25 -> 20331 | X5: =+W25 -> 24959 | ... AU5: =+AT25 -> 24559 | AV5: =P25 -> 4639
B6: IL | C6: Flagship | D6: 18913 | E6: =D26 -> 19963 | F6: =E26 -> 26400 | G6: =F26 -> 25990 | H6: =G26 -> 21593 | I6: =H26 -> 18630 | J6: =I26 -> 19363 | K6: =J26 -> 18380 | L6: =K26 -> 17345 | ... O6: =N26 -> 23996 | P6: 23996 | Q6: =+P26 -> 23996 | R6: =+Q26 -> 23996 | S6: =+R26 -> 23996 | T6: =+S26 -> 15749 | U6: =+T26 -> 16736 | V6: =+U26 -> 17860 | W6: =+V26 -> 17409 | X6: =+W26 -> 13053 | ... AU6: =+AT26 -> 11497 | AV6: =P26 -> 23996
C7: Others | D7: 191085 | E7: =D27 -> 158027 | F7: =E27 -> 201548 | G7: =F27 -> 184019 | H7: =G27 -> 180668 | I7: =H27 -> 178234 | J7: =I27 -> 171646 | K7: =J27 -> 215855 | L7: =K27 -> 150195 | ... O7: =N27 -> 160043 | P7: 160043 | Q7: =+P27 -> 160043 | R7: =+Q27 -> 160043 | S7: =+R27 -> 160043 | T7: =+S27 -> 183236 | U7: =+T27 -> 186136 | V7: =+U27 -> 206356 | W7: =+V27 -> 203508 | X7: =+W27 -> 187868 | ... AU7: =+AT27 -> 178540 | AV7: =P27 -> 160043
B8: MB | C8: Others | D8: 52528 | E8: =D28 -> 38092 | F8: =E28 -> 92852 | G8: =F28 -> 45860 | H8: =G28 -> 39296 | I8: =H28 -> 58160 | J8: =I28 -> 101496 | K8: =J28 -> 44660 | L8: =K28 -> 45320 | ... O8: =N28 -> 43108 | P8: 43108 | Q8: =+P28 -> 43108 | R8: =+Q28 -> 43108 | S8: =+R28 -> 43108 | T8: =+S28 -> 22608 | U8: =+T28 -> 35088 | V8: =+U28 -> 35088 | W8: =+V28 -> 35088 | X8: =+W28 -> 35088 | ... AU8: =+AT28 -> 35088 | AV8: =P28 -> 43108
A9: 매입 | B9: Auto | C9: Flagship | D9: 10891 | E9: 9635 | F9: 18211 | G9: 18466 | H9: 26148 | I9: 31814 | J9: 27166 | K9: 33021 | L9: 29341 | M9: 18006 | Q9: 0 | R9: 0 | S9: 1614 | T9: 0 | U9: 1240 | V9: 0 | W9: 940 | X9: 0 | Y9: 0 | Z9: 0 | AA9: 0 | AB9: 0 | AC9: 0 | AD9: 0 | AE9: 0 | AF9: 0 | AG9: 0 | AH9: 0 | AI9: 0 | AJ9: 0 | AK9: 0 | AL9: 0 | AM9: 0 | AN9: 0 | AO9: 0 | AP9: 0 | AQ9: 0 | AR9: 0 | AS9: 0 | AT9: 0 | AU9: 0 | AV9: =SUM(Q9:AU9) -> 3794
C10: Others | D10: 52896 | E10: 87098 | F10: 75196 | G10: 64764 | H10: 69824 | I10: 68740 | J10: 53124 | K10: 62772 | L10: 62870 | M10: 90970 | Q10: 0 | R10: 0 | S10: 20384 | T10: 840 | U10: 0 | V10: 0 | W10: 4780 | X10: 0 | Y10: 0 | Z10: 0 | AA10: 0 | AB10: 0 | AC10: 0 | AD10: 0 | AE10: 0 | AF10: 0 | AG10: 0 | AH10: 0 | AI10: 0 | AJ10: 0 | AK10: 0 | AL10: 0 | AM10: 0 | AN10: 0 | AO10: 0 | AP10: 0 | AQ10: 0 | AR10: 0 | AS10: 0 | AT10: 0 | AU10: 0 | AV10: =SUM(Q10:AU10) -> 26004
B11: IL | C11: Flagship | D11: 24523 | E11: 23172 | F11: 18656 | G11: 14705 | H11: 39992 | I11: 25542 | J11: 20268 | K11: 18465 | L11: 42951 | M11: 35551 | Q11: 0 | R11: 0 | S11: 1068 | T11: 2000 | U11: 1184 | V11: 288 | W11: 88 | X11: 0 | Y11: 0 | Z11: 0 | AA11: 0 | AB11: 0 | AC11: 0 | AD11: 0 | AE11: 0 | AF11: 0 | AG11: 0 | AH11: 0 | AI11: 0 | AJ11: 0 | AK11: 0 | AL11: 0 | AM11: 0 | AN11: 0 | AO11: 0 | AP11: 0 | AQ11: 0 | AR11: 0 | AS11: 0 | AT11: 0 | AU11: 0 | AV11: =SUM(Q11:AU11) -> 4628
C12: Others | D12: 200609 | E12: 282429 | F12: 245040 | G12: 317982 | H12: 259888 | I12: 309179 | J12: 315007 | K12: 223946 | L12: 351915 | M12: 179778 | Q12: 0 | R12: 0 | S12: 49592 | T12: 16704 | U12: 40220 | V12: 8580 | W12: 600 | X12: 0 | Y12: 0 | Z12: 1120 | AA12: 0 | AB12: 0 | AC12: 0 | AD12: 0 | AE12: 0 | AF12: 0 | AG12: 0 | AH12: 0 | AI12: 0 | AJ12: 0 | AK12: 0 | AL12: 0 | AM12: 0 | AN12: 0 | AO12: 0 | AP12: 0 | AQ12: 0 | AR12: 0 | AS12: 0 | AT12: 0 | AU12: 0 | AV12: =SUM(Q12:AU12) -> 116816
B13: MB | C13: Others | D13: 58016 | E13: 101328 | F13: 3360 | G13: 57888 | H13: 69684 | I13: 92800 | J13: 31440 | K13: 45312 | L13: 37264 | M13: 71168 | Q13: 0 | R13: 0 | S13: 3328 | T13: 12480 | U13: 0 | V13: 0 | W13: 0 | X13: 0 | Y13: 0 | Z13: 0 | AA13: 0 | AB13: 0 | AC13: 0 | AD13: 0 | AE13: 0 | AF13: 0 | AG13: 0 | AH13: 0 | AI13: 0 | AJ13: 0 | AK13: 0 | AL13: 0 | AM13: 0 | AN13: 0 | AO13: 0 | AP13: 0 | AQ13: 0 | AR13: 0 | AS13: 0 | AT13: 0 | AU13: 0 | AV13: =SUM(Q13:AU13) -> 15808
A14: 매출 | B14: Auto | C14: Flagship | D14: 35496 | E14: 32774 | F14: 34839 | G14: 38060 | H14: 51936 | I14: 52014 | J14: 55138 | K14: 56914 | L14: 54780 | M14: 38484 | Q14: 0 | R14: 0 | S14: 4500 | T14: 1116 | U14: 9154 | V14: 3560 | W14: 2532 | X14: 0 | Y14: 0 | Z14: 60 | AA14: 0 | AB14: 0 | AC14: 0 | AD14: 0 | AE14: 0 | AF14: 0 | AG14: 0 | AH14: 0 | AI14: 0 | AJ14: 0 | AK14: 0 | AL14: 0 | AM14: 0 | AN14: 0 | AO14: 0 | AP14: 0 | AQ14: 0 | AR14: 0 | AS14: 0 | AT14: 0 | AU14: 0 | AV14: =SUM(Q14:AU14) -> 20922
C15: Others | D15: 22276 | E15: 47120 | F15: 19712 | G15: 27560 | H15: 30364 | I15: 34896 | J15: 18396 | K15: 26508 | L15: 27800 | M15: 51560 | Q15: 0 | R15: 0 | S15: 5024 | T15: 40 | U15: 468 | V15: 0 | W15: 152 | X15: 0 | Y15: 0 | Z15: 400 | AA15: 0 | AB15: 0 | AC15: 0 | AD15: 0 | AE15: 0 | AF15: 0 | AG15: 0 | AH15: 0 | AI15: 0 | AJ15: 0 | AK15: 0 | AL15: 0 | AM15: 0 | AN15: 0 | AO15: 0 | AP15: 0 | AQ15: 0 | AR15: 0 | AS15: 0 | AT15: 0 | AU15: 0 | AV15: =SUM(Q15:AU15) -> 6084
B16: IL | C16: Flagship | D16: 33303 | E16: 23712 | F16: 28079 | G16: 23523 | H16: 26356 | I16: 28900 | J16: 26561 | K16: 23780 | L16: 48996 | M16: 43531 | Q16: 0 | R16: 0 | S16: 9315 | T16: 1013 | U16: 60 | V16: 739 | W16: 4444 | X16: 0 | Y16: 0 | Z16: 1556 | AA16: 0 | AB16: 0 | AC16: 0 | AD16: 0 | AE16: 0 | AF16: 0 | AG16: 0 | AH16: 0 | AI16: 0 | AJ16: 0 | AK16: 0 | AL16: 0 | AM16: 0 | AN16: 0 | AO16: 0 | AP16: 0 | AQ16: 0 | AR16: 0 | AS16: 0 | AT16: 0 | AU16: 0 | AV16: =SUM(Q16:AU16) -> 17127
C17: Others | D17: 232716 | E17: 244216 | F17: 261400 | G17: 313286 | H17: 263698 | I17: 280023 | J17: 260404 | K17: 273799 | L17: 292430 | M17: 225723 | Q17: 0 | R17: 0 | S17: 26399 | T17: 13804 | U17: 20000 | V17: 11428 | W17: 16240 | X17: 0 | Y17: 0 | Z17: 10448 | AA17: 0 | AB17: 0 | AC17: 0 | AD17: 0 | AE17: 0 | AF17: 0 | AG17: 0 | AH17: 0 | AI17: 0 | AJ17: 0 | AK17: 0 | AL17: 0 | AM17: 0 | AN17: 0 | AO17: 0 | AP17: 0 | AQ17: 0 | AR17: 0 | AS17: 0 | AT17: 0 | AU17: 0 | AV17: =SUM(Q17:AU17) -> 98319
B18: MB | C18: Others | D18: 60388 | E18: 41168 | F18: 49104 | G18: 64452 | H18: 48764 | I18: 44264 | J18: 66020 | K18: 43968 | L18: 62112 | M18: 32972 | Q18: 0 | R18: 0 | S18: 23828 | T18: 0 | U18: 0 | V18: 0 | W18: 0 | X18: 0 | Y18: 0 | Z18: 0 | AA18: 0 | AB18: 0 | AC18: 0 | AD18: 0 | AE18: 0 | AF18: 0 | AG18: 0 | AH18: 0 | AI18: 0 | AJ18: 0 | AK18: 0 | AL18: 0 | AM18: 0 | AN18: 0 | AO18: 0 | AP18: 0 | AQ18: 0 | AR18: 0 | AS18: 0 | AT18: 0 | AU18: 0 | AV18: =SUM(Q18:AU18) -> 23828
A19: 이동 | B19: Auto | C19: Flagship | D19: -23494 | E19: -22571 | F19: -22588 | G19: -24758 | H19: -20184 | I19: -22404 | J19: -29331 | K19: -23106 | L19: -23759 | M19: -16746 | Q19: 0 | R19: 0 | S19: 0 | T19: 0 | U19: 0 | V19: 0 | W19: 0 | X19: 0 | Y19: 0 | Z19: 0 | AA19: 0 | AB19: 0 | AC19: 0 | AD19: 0 | AE19: 0 | AF19: 0 | AG19: 0 | AH19: 0 | AI19: 0 | AJ19: 0 | AK19: 0 | AL19: 0 | AM19: 0 | AN19: 0 | AO19: 0 | AP19: 0 | AQ19: 0 | AR19: 0 | AS19: 0 | AT19: 0 | AU19: 0 | AV19: =SUM(Q19:AU19) -> 0
C20: Others | D20: 32052 | E20: 39888 | F20: 44348 | G20: 41796 | H20: 43728 | I20: 40944 | J20: 35308 | K20: 35240 | L20: 35628 | M20: 42812 | Q20: 0 | R20: 0 | S20: 0 | T20: 0 | U20: 0 | V20: 0 | W20: 0 | X20: 0 | Y20: 0 | Z20: 0 | AA20: 0 | AB20: 0 | AC20: 0 | AD20: 0 | AE20: 0 | AF20: 0 | AG20: 0 | AH20: 0 | AI20: 0 | AJ20: 0 | AK20: 0 | AL20: 0 | AM20: 0 | AN20: 0 | AO20: 0 | AP20: 0 | AQ20: 0 | AR20: 0 | AS20: 0 | AT20: 0 | AU20: 0 | AV20: =SUM(Q20:AU20) -> 0
B21: IL | C21: Flagship | D21: -9830 | E21: -6977 | F21: -9013 | G21: -4421 | H21: 16599 | I21: -4091 | J21: -5310 | K21: -4280 | L21: -13777 | M21: -6899 | Q21: 0 | R21: 0 | S21: 0 | T21: 0 | U21: 0 | V21: 0 | W21: 0 | X21: 0 | Y21: 0 | Z21: 0 | AA21: 0 | AB21: 0 | AC21: 0 | AD21: 0 | AE21: 0 | AF21: 0 | AG21: 0 | AH21: 0 | AI21: 0 | AJ21: 0 | AK21: 0 | AL21: 0 | AM21: 0 | AN21: 0 | AO21: 0 | AP21: 0 | AQ21: 0 | AR21: 0 | AS21: 0 | AT21: 0 | AU21: 0 | AV21: =SUM(Q21:AU21) -> 0
C22: Others | D22: 951 | E22: -5308 | F22: 1169 | G22: 8047 | H22: -1376 | I22: 35744 | J22: 10394 | K22: 15807 | L22: 12655 | M22: -8963 | Q22: 0 | R22: 0 | S22: 0 | T22: 0 | U22: 0 | V22: 0 | W22: 0 | X22: 0 | Y22: 0 | Z22: 0 | AA22: 0 | AB22: 0 | AC22: 0 | AD22: 0 | AE22: 0 | AF22: 0 | AG22: 0 | AH22: 0 | AI22: 0 | AJ22: 0 | AK22: 0 | AL22: 0 | AM22: 0 | AN22: 0 | AO22: 0 | AP22: 0 | AQ22: 0 | AR22: 0 | AS22: 0 | AT22: 0 | AU22: 0 | AV22: =SUM(Q22:AU22) -> 0
B23: MB | C23: Others | D23: 12064 | E23: 5400 | F23: 1248 | G23: 0 | H23: 2056 | I23: 5200 | J23: 22256 | K23: 684 | L23: 13272 | M23: 2288 | Q23: 0 | R23: 0 | S23: 0 | T23: 0 | U23: 0 | V23: 0 | W23: 0 | X23: 0 | Y23: 0 | Z23: 0 | AA23: 0 | AB23: 0 | AC23: 0 | AD23: 0 | AE23: 0 | AF23: 0 | AG23: 0 | AH23: 0 | AI23: 0 | AJ23: 0 | AK23: 0 | AL23: 0 | AM23: 0 | AN23: 0 | AO23: 0 | AP23: 0 | AQ23: 0 | AR23: 0 | AS23: 0 | AT23: 0 | AU23: 0 | AV23: =SUM(Q23:AU23) -> 0
A24: 재고 | B24: Auto | C24: Flagship | D24: =+D4+D9-D14-D19 -> 9008 | E24: =+E4+E9-E14-E19 -> 8440 | F24: =+F4+F9-F14-F19 -> 14400 | G24: =+G4+G9-G14-G19 -> 19564 | H24: =+H4+H9-H14-H19 -> 13960 | I24: =+I4+I9-I14-I19 -> 16164 | J24: =+J4+J9-J14-J19 -> 17523 | K24: =+K4+K9-K14-K19 -> 16736 | ... AV24: =+AV4+AV9-AV14-AV19 -> -5804
C25: Others | D25: =+D5+D10-D15-D20 -> 12889 | E25: =+E5+E10-E15-E20 -> 12979 | F25: =+F5+F10-F15-F20 -> 24115 | G25: =+G5+G10-G15-G20 -> 19523 | H25: =+H5+H10-H15-H20 -> 15255 | I25: =+I5+I10-I15-I20 -> 8155 | J25: =+J5+J10-J15-J20 -> 7575 | K25: =+K5+K10-K15-K20 -> 8599 | ... AV25: =+AV5+AV10-AV15-AV20 -> 24559
B26: IL | C26: Flagship | D26: =+D6+D11-D16-D21 -> 19963 | E26: =+E6+E11-E16-E21 -> 26400 | F26: =+F6+F11-F16-F21 -> 25990 | G26: =+G6+G11-G16-G21 -> 21593 | H26: =+H6+H11-H16-H21 -> 18630 | I26: =+I6+I11-I16-I21 -> 19363 | J26: =+J6+J11-J16-J21 -> 18380 | K26: =+K6+K11-K16-K21 -> 17345 | ... AV26: =+AV6+AV11-AV16-AV21 -> 11497
C27: Others | D27: =+D7+D12-D17-D22 -> 158027 | E27: =+E7+E12-E17-E22 -> 201548 | F27: =+F7+F12-F17-F22 -> 184019 | G27: =+G7+G12-G17-G22 -> 180668 | H27: =+H7+H12-H17-H22 -> 178234 | I27: =+I7+I12-I17-I22 -> 171646 | J27: =+J7+J12-J17-J22 -> 215855 | K27: =+K7+K12-K17-K22 -> 150195 | ... AV27: =+AV7+AV12-AV17-AV22 -> 178540
B28: MB | C28: Others | D28: =+D8+D13-D18-D23 -> 38092 | E28: =+E8+E13-E18-E23 -> 92852 | F28: =+F8+F13-F18-F23 -> 45860 | G28: =+G8+G13-G18-G23 -> 39296 | H28: =+H8+H13-H18-H23 -> 58160 | I28: =+I8+I13-I18-I23 -> 101496 | J28: =+J8+J13-J18-J23 -> 44660 | K28: =+K8+K13-K18-K23 -> 45320 | ... AV28: =+AV8+AV13-AV18-AV23 -> 35088
D29: =SUM(D24:D28) -> 237979 | E29: =SUM(E24:E28) -> 342219 | F29: =SUM(F24:F28) -> 294384 | G29: =SUM(G24:G28) -> 280644 | H29: =SUM(H24:H28) -> 284239 | I29: =SUM(I24:I28) -> 316824 | J29: =SUM(J24:J28) -> 303993 | K29: =SUM(K24:K28) -> 238195 | ... AV29: =SUM(AV24:AV28) -> 243880
A31: 재고 D/M계 | B31: Auto | C31: Flagship | D31: 50.595 | E31: =E24/200 -> 42.2 | F31: =F24/200 -> 72 | G31: =G24/200 -> 97.82 | H31: =H24/200 -> 69.8 | I31: =I24/200 -> 80.82 | J31: =J24/200 -> 87.615 | K31: =K24/200 -> 83.68 | L31: =L24/200 -> 75.28 | ... AV31: =AV24/200 -> -29.02
C32: Others | D32: 71.605 | E32: =E25/200 -> 64.895 | F32: =F25/200 -> 120.575 | G32: =G25/200 -> 97.615 | H32: =H25/200 -> 76.275 | I32: =I25/200 -> 40.775 | J32: =J25/200 -> 37.875 | K32: =K25/200 -> 42.995 | L32: =L25/200 -> 40.205 | ... AV32: =AV25/200 -> 122.795
B33: IL | C33: Flagship | D33: 94.565 | E33: =E26/200 -> 132 | F33: =F26/200 -> 129.95 | G33: =G26/200 -> 107.965 | H33: =H26/200 -> 93.15 | I33: =I26/200 -> 96.815 | J33: =J26/200 -> 91.9 | K33: =K26/200 -> 86.725 | L33: =L26/200 -> 125.385 | ... AV33: =AV26/200 -> 57.485
C34: Others | D34: 955.425 | E34: =E27/200 -> 1007.74 | F34: =F27/200 -> 920.095 | G34: =G27/200 -> 903.34 | H34: =H27/200 -> 891.17 | I34: =I27/200 -> 858.23 | J34: =J27/200 -> 1079.275 | K34: =K27/200 -> 750.975 | L34: =L27/200 -> 985.125 | ... AV34: =AV27/200 -> 892.7
B35: MB | C35: Others | D35: 262.64 | E35: =E28/200 -> 464.26 | F35: =F28/200 -> 229.3 | G35: =G28/200 -> 196.48 | H35: =H28/200 -> 290.8 | I35: =I28/200 -> 507.48 | J35: =J28/200 -> 223.3 | K35: =K28/200 -> 226.6 | L35: =L28/200 -> 36 | ... AV35: =AV28/200 -> 175.44

Sheet 창원
A2: ▣ 창원
A3: 단위 : Liter | D3: 45322 | E3: 44620 | F3: 44651 | G3: 44681 | H3: 44712 | I3: 44742 | J3: 44773 | K3: 44804 | L3: 44834 | M3: 44865 | N3: 44895 | O3: 44926 | P3: 변동재고 | Q3: 45962 | R3: 45963 | S3: 45964 | T3: 45965 | U3: 45966 | V3: 45967 | W3: 45968 | X3: 45969 | Y3: 45970 | Z3: 45971 | AA3: 45972 | AB3: 45973 | AC3: 45974 | AD3: 45975 | AE3: 45976 | AF3: 45977 | AG3: 45978 | AH3: 45979 | AI3: 45980 | AJ3: 45981 | AK3: 45982 | AL3: 45983 | AM3: 45984 | AN3: 45985 | AO3: 45986 | AP3: 45987 | AQ3: 45988 | AR3: 45989 | AS3: 45990 | AT3: 45991 | AU3: 45992 | AV3: 합계
A4: 기초재고 | B4: Auto | C4: Flagship | D4: 4152 | E4: =D24 -> 3696 | F4: =E24 -> 5942 | G4: =F24 -> 3762 | H4: =G24 -> 5158 | I4: =H24 -> 4550 | J4: =I24 -> 4310 | K4: =J24 -> 5382 | L4: =K24 -> 4658 | ... O4: =N24 -> 3782 | P4: 3782 | Q4: =+P24 -> 3782 | R4: =+Q24 -> 3782 | S4: =+R24 -> 3782 | T4: =+S24 -> 4922 | U4: =+T24 -> 4922 | V4: =+U24 -> 5338 | W4: =+V24 -> 5338 | X4: =+W24 -> 6586 | ... AU4: =+AT24 -> 6554 | AV4: =P24 -> 3782
C5: Others | D5: 5592 | E5: =D25 -> 5428 | F5: =E25 -> 9712 | G5: =F25 -> 14620 | H5: =G25 -> 9348 | I5: =H25 -> 12696 | J5: =I25 -> 8592 | K5: =J25 -> 13040 | L5: =K25 -> 12024 | ... O5: =N25 -> 7800 | P5: 7800 | Q5: =+P25 -> 7800 | R5: =+Q25 -> 7800 | S5: =+R25 -> 7800 | T5: =+S25 -> 5040 | U5: =+T25 -> 4740 | V5: =+U25 -> 4820 | W5: =+V25 -> 3808 | X5: =+W25 -> 5008 | ... AU5: =+AT25 -> 6328 | AV5: =P25 -> 7800
B6: IL | C6: Flagship | D6: 6687 | E6: =D26 -> 9501 | F6: =E26 -> 8921 | G6: =F26 -> 11511 | H6: =G26 -> 8707 | I6: =H26 -> 8607 | J6: =I26 -> 11713 | K6: =J26 -> 8846 | L6: =K26 -> 14626 | ... O6: =N26 -> 14598 | P6: 14598 | Q6: =+P26 -> 14598 | R6: =+Q26 -> 14598 | S6: =+R26 -> 14598 | T6: =+S26 -> 15461 | U6: =+T26 -> 15461 | V6: =+U26 -> 13229 | W6: =+V26 -> 13850 | X6: =+W26 -> 13474 | ... AU6: =+AT26 -> 10754 | AV6: =P26 -> 14598
C7: Others | D7: 112035 | E7: =D27 -> 91278 | F7: =E27 -> 73664 | G7: =F27 -> 82229 | H7: =G27 -> 144098 | I7: =H27 -> 119649 | J7: =I27 -> 97884 | K7: =J27 -> 112603 | L7: =K27 -> 127009 | ... O7: =N27 -> 104269 | P7: 104269 | Q7: =+P27 -> 104269 | R7: =+Q27 -> 104269 | S7: =+R27 -> 104269 | T7: =+S27 -> 94775 | U7: =+T27 -> 102754 | V7: =+U27 -> 104600 | W7: =+V27 -> 106614 | X7: =+W27 -> 100825 | ... AU7: =+AT27 -> 99765 | AV7: =P27 -> 104269
B8: MB | C8: Others | D8: 16604 | E8: =D28 -> 13528 | F8: =E28 -> 24744 | G8: =F28 -> 13616 | H8: =G28 -> 13536 | I8: =H28 -> 23460 | J8: =I28 -> 26600 | K8: =J28 -> 12316 | L8: =K28 -> 14856 | ... O8: =N28 -> 25900 | P8: 25900 | Q8: =+P28 -> 25900 | R8: =+Q28 -> 25900 | S8: =+R28 -> 25900 | T8: =+S28 -> 5780 | U8: =+T28 -> 5780 | V8: =+U28 -> 5780 | W8: =+V28 -> 11604 | X8: =+W28 -> 13212 | ... AU8: =+AT28 -> 7180 | AV8: =P28 -> 25900
A9: 매입 | B9: Auto | C9: Flagship | D9: 72 | E9: 2788 | F9: 976 | G9: 4596 | H9: 908 | I9: 2972 | J9: 4408 | K9: 3896 | L9: 2420 | M9: 2596 | Q9: 0 | R9: 0 | S9: 2080 | T9: 0 | U9: 416 | V9: 0 | W9: 1248 | X9: 0 | Y9: 0 | Z9: 200 | AA9: 0 | AB9: 0 | AC9: 0 | AD9: 0 | AE9: 0 | AF9: 0 | AG9: 0 | AH9: 0 | AI9: 0 | AJ9: 0 | AK9: 0 | AL9: 0 | AM9: 0 | AN9: 0 | AO9: 0 | AP9: 0 | AQ9: 0 | AR9: 0 | AS9: 0 | AT9: 0 | AU9: 0 | AV9: =SUM(Q9:AU9) -> 3944
C10: Others | D10: 1080 | E10: 8960 | F10: 10628 | G10: 1280 | H10: 5080 | I10: 6512 | J10: 8340 | K10: 13176 | L10: 7920 | M10: 4012 | Q10: 0 | R10: 0 | S10: 200 | T10: 0 | U10: 80 | V10: 0 | W10: 1240 | X10: 0 | Y10: 0 | Z10: 2160 | AA10: 0 | AB10: 0 | AC10: 0 | AD10: 0 | AE10: 0 | AF10: 0 | AG10: 0 | AH10: 0 | AI10: 0 | AJ10: 0 | AK10: 0 | AL10: 0 | AM10: 0 | AN10: 0 | AO10: 0 | AP10: 0 | AQ10: 0 | AR10: 0 | AS10: 0 | AT10: 0 | AU10: 0 | AV10: =SUM(Q10:AU10) -> 3680
B11: IL | C11: Flagship | D11: 8136 | E11: 10781 | F11: 11521 | G11: 10628 | H11: 5125 | I11: 9176 | J11: 4230 | K11: 12734 | L11: 18831 | M11: 2270 | Q11: 0 | R11: 0 | S11: 2277 | T11: 0 | U11: 568 | V11: 689 | W11: 40 | X11: 0 | Y11: 0 | Z11: 0 | AA11: 0 | AB11: 0 | AC11: 0 | AD11: 0 | AE11: 0 | AF11: 0 | AG11: 0 | AH11: 0 | AI11: 0 | AJ11: 0 | AK11: 0 | AL11: 0 | AM11: 0 | AN11: 0 | AO11: 0 | AP11: 0 | AQ11: 0 | AR11: 0 | AS11: 0 | AT11: 0 | AU11: 0 | AV11: =SUM(Q11:AU11) -> 3574
C12: Others | D12: 95632 | E12: 150599 | F12: 155445 | G12: 194696 | H12: 123501 | I12: 121049 | J12: 127072 | K12: 145434 | L12: 130860 | M12: 95033 | Q12: 0 | R12: 0 | S12: 6064 | T12: 11720 | U12: 10122 | V12: 5200 | W12: 6487 | X12: 0 | Y12: 0 | Z12: 5160 | AA12: 0 | AB12: 0 | AC12: 0 | AD12: 0 | AE12: 0 | AF12: 0 | AG12: 0 | AH12: 0 | AI12: 0 | AJ12: 0 | AK12: 0 | AL12: 0 | AM12: 0 | AN12: 0 | AO12: 0 | AP12: 0 | AQ12: 0 | AR12: 0 | AS12: 0 | AT12: 0 | AU12: 0 | AV12: =SUM(Q12:AU12) -> 44753
B13: MB | C13: Others | D13: 28416 | E13: 40988 | F13: 17152 | G13: 44684 | H13: 41492 | I13: 33324 | J13: 26700 | K13: 30104 | L13: 31032 | M13: 36800 | Q13: 0 | R13: 0 | S13: 0 | T13: 0 | U13: 0 | V13: 5824 | W13: 1608 | X13: 0 | Y13: 0 | Z13: 4160 | AA13: 0 | AB13: 0 | AC13: 0 | AD13: 0 | AE13: 0 | AF13: 0 | AG13: 0 | AH13: 0 | AI13: 0 | AJ13: 0 | AK13: 0 | AL13: 0 | AM13: 0 | AN13: 0 | AO13: 0 | AP13: 0 | AQ13: 0 | AR13: 0 | AS13: 0 | AT13: 0 | AU13: 0 | AV13: =SUM(Q13:AU13) -> 11592
A14: 매출 | B14: Auto | C14: Flagship | D14: 491 | E14: 842 | F14: 1112 | G14: 1356 | H14: 536 | I14: 2720 | J14: 1516 | K14: 1904 | L14: 2172 | M14: 1280 | Q14: 0 | R14: 0 | S14: 940 | T14: 0 | U14: 0 | V14: 0 | W14: 0 | X14: 0 | Y14: 0 | Z14: 232 | AA14: 0 | AB14: 0 | AC14: 0 | AD14: 0 | AE14: 0 | AF14: 0 | AG14: 0 | AH14: 0 | AI14: 0 | AJ14: 0 | AK14: 0 | AL14: 0 | AM14: 0 | AN14: 0 | AO14: 0 | AP14: 0 | AQ14: 0 | AR14: 0 | AS14: 0 | AT14: 0 | AU14: 0 | AV14: =SUM(Q14:AU14) -> 1172
C15: Others | D15: 892 | E15: 3732 | F15: 4260 | G15: 6152 | H15: 7680 | I15: 12968 | J15: 3788 | K15: 13232 | L15: 9560 | M15: 4484 | Q15: 0 | R15: 0 | S15: 2960 | T15: 300 | U15: 0 | V15: 1012 | W15: 40 | X15: 0 | Y15: 0 | Z15: 840 | AA15: 0 | AB15: 0 | AC15: 0 | AD15: 0 | AE15: 0 | AF15: 0 | AG15: 0 | AH15: 0 | AI15: 0 | AJ15: 0 | AK15: 0 | AL15: 0 | AM15: 0 | AN15: 0 | AO15: 0 | AP15: 0 | AQ15: 0 | AR15: 0 | AS15: 0 | AT15: 0 | AU15: 0 | AV15: =SUM(Q15:AU15) -> 5152
B16: IL | C16: Flagship | D16: 2553 | E16: 10253 | F16: 4139 | G16: 11594 | H16: 25957 | I16: 4712 | J16: 3930 | K16: 6049 | L16: 13887 | M16: 3993 | Q16: 0 | R16: 0 | S16: 1414 | T16: 0 | U16: 2800 | V16: 68 | W16: 416 | X16: 0 | Y16: 0 | Z16: 2720 | AA16: 0 | AB16: 0 | AC16: 0 | AD16: 0 | AE16: 0 | AF16: 0 | AG16: 0 | AH16: 0 | AI16: 0 | AJ16: 0 | AK16: 0 | AL16: 0 | AM16: 0 | AN16: 0 | AO16: 0 | AP16: 0 | AQ16: 0 | AR16: 0 | AS16: 0 | AT16: 0 | AU16: 0 | AV16: =SUM(Q16:AU16) -> 7418
